2021-03-08 08:05:31,509 INFO org.apache.hadoop.yarn.server.resourcemanager.ResourceManager: STARTUP_MSG: 
/************************************************************
STARTUP_MSG: Starting ResourceManager
STARTUP_MSG:   host = master/192.168.244.130
STARTUP_MSG:   args = []
STARTUP_MSG:   version = 2.7.7
STARTUP_MSG:   build = Unknown -r c1aad84bd27cd79c3d1a7dd58202a8c3ee1ed3ac; compiled by 'stevel' on 2018-07-18T22:47Z
STARTUP_MSG:   java = 15.0.2
************************************************************/
2021-03-08 08:05:31,521 INFO org.apache.hadoop.yarn.server.resourcemanager.ResourceManager: registered UNIX signal handlers for [TERM, HUP, INT]
2021-03-08 08:05:31,765 INFO org.apache.hadoop.conf.Configuration: found resource core-site.xml at file:/home/hadoopuser/hadoop/etc/hadoop/core-site.xml
2021-03-08 08:05:31,880 WARN org.apache.hadoop.util.NativeCodeLoader: Unable to load native-hadoop library for your platform... using builtin-java classes where applicable
2021-03-08 08:05:31,906 INFO org.apache.hadoop.security.Groups: clearing userToGroupsMap cache
2021-03-08 08:05:31,962 INFO org.apache.hadoop.conf.Configuration: found resource yarn-site.xml at file:/home/hadoopuser/hadoop/etc/hadoop/yarn-site.xml
2021-03-08 08:05:32,193 INFO org.apache.hadoop.yarn.event.AsyncDispatcher: Registering class org.apache.hadoop.yarn.server.resourcemanager.RMFatalEventType for class org.apache.hadoop.yarn.server.resourcemanager.ResourceManager$RMFatalEventDispatcher
2021-03-08 08:05:32,312 INFO org.apache.hadoop.yarn.server.resourcemanager.security.NMTokenSecretManagerInRM: NMTokenKeyRollingInterval: 86400000ms and NMTokenKeyActivationDelay: 900000ms
2021-03-08 08:05:32,321 INFO org.apache.hadoop.yarn.server.resourcemanager.security.RMContainerTokenSecretManager: ContainerTokenKeyRollingInterval: 86400000ms and ContainerTokenKeyActivationDelay: 900000ms
2021-03-08 08:05:32,344 INFO org.apache.hadoop.yarn.server.resourcemanager.security.AMRMTokenSecretManager: AMRMTokenKeyRollingInterval: 86400000ms and AMRMTokenKeyActivationDelay: 900000 ms
2021-03-08 08:05:32,398 INFO org.apache.hadoop.yarn.event.AsyncDispatcher: Registering class org.apache.hadoop.yarn.server.resourcemanager.recovery.RMStateStoreEventType for class org.apache.hadoop.yarn.server.resourcemanager.recovery.RMStateStore$ForwardingEventHandler
2021-03-08 08:05:32,400 INFO org.apache.hadoop.yarn.event.AsyncDispatcher: Registering class org.apache.hadoop.yarn.server.resourcemanager.NodesListManagerEventType for class org.apache.hadoop.yarn.server.resourcemanager.NodesListManager
2021-03-08 08:05:32,400 INFO org.apache.hadoop.yarn.server.resourcemanager.ResourceManager: Using Scheduler: org.apache.hadoop.yarn.server.resourcemanager.scheduler.capacity.CapacityScheduler
2021-03-08 08:05:32,423 INFO org.apache.hadoop.yarn.event.AsyncDispatcher: Registering class org.apache.hadoop.yarn.server.resourcemanager.scheduler.event.SchedulerEventType for class org.apache.hadoop.yarn.server.resourcemanager.ResourceManager$SchedulerEventDispatcher
2021-03-08 08:05:32,425 INFO org.apache.hadoop.yarn.event.AsyncDispatcher: Registering class org.apache.hadoop.yarn.server.resourcemanager.rmapp.RMAppEventType for class org.apache.hadoop.yarn.server.resourcemanager.ResourceManager$ApplicationEventDispatcher
2021-03-08 08:05:32,426 INFO org.apache.hadoop.yarn.event.AsyncDispatcher: Registering class org.apache.hadoop.yarn.server.resourcemanager.rmapp.attempt.RMAppAttemptEventType for class org.apache.hadoop.yarn.server.resourcemanager.ResourceManager$ApplicationAttemptEventDispatcher
2021-03-08 08:05:32,428 INFO org.apache.hadoop.yarn.event.AsyncDispatcher: Registering class org.apache.hadoop.yarn.server.resourcemanager.rmnode.RMNodeEventType for class org.apache.hadoop.yarn.server.resourcemanager.ResourceManager$NodeEventDispatcher
2021-03-08 08:05:32,544 INFO org.apache.hadoop.metrics2.impl.MetricsConfig: loaded properties from hadoop-metrics2.properties
2021-03-08 08:05:32,755 INFO org.apache.hadoop.metrics2.impl.MetricsSystemImpl: Scheduled snapshot period at 10 second(s).
2021-03-08 08:05:32,755 INFO org.apache.hadoop.metrics2.impl.MetricsSystemImpl: ResourceManager metrics system started
2021-03-08 08:05:32,768 INFO org.apache.hadoop.yarn.event.AsyncDispatcher: Registering class org.apache.hadoop.yarn.server.resourcemanager.RMAppManagerEventType for class org.apache.hadoop.yarn.server.resourcemanager.RMAppManager
2021-03-08 08:05:32,778 INFO org.apache.hadoop.yarn.event.AsyncDispatcher: Registering class org.apache.hadoop.yarn.server.resourcemanager.amlauncher.AMLauncherEventType for class org.apache.hadoop.yarn.server.resourcemanager.amlauncher.ApplicationMasterLauncher
2021-03-08 08:05:32,781 INFO org.apache.hadoop.yarn.server.resourcemanager.RMNMInfo: Registered RMNMInfo MBean
2021-03-08 08:05:32,785 INFO org.apache.hadoop.yarn.security.YarnAuthorizationProvider: org.apache.hadoop.yarn.security.ConfiguredYarnAuthorizer is instiantiated.
2021-03-08 08:05:32,787 INFO org.apache.hadoop.util.HostsFileReader: Refreshing hosts (include/exclude) list
2021-03-08 08:05:32,789 INFO org.apache.hadoop.conf.Configuration: found resource capacity-scheduler.xml at file:/home/hadoopuser/hadoop/etc/hadoop/capacity-scheduler.xml
2021-03-08 08:05:32,860 INFO org.apache.hadoop.yarn.server.resourcemanager.scheduler.capacity.CapacitySchedulerConfiguration: max alloc mb per queue for root is undefined
2021-03-08 08:05:32,861 INFO org.apache.hadoop.yarn.server.resourcemanager.scheduler.capacity.CapacitySchedulerConfiguration: max alloc vcore per queue for root is undefined
2021-03-08 08:05:32,866 INFO org.apache.hadoop.yarn.server.resourcemanager.scheduler.capacity.ParentQueue: root, capacity=1.0, asboluteCapacity=1.0, maxCapacity=1.0, asboluteMaxCapacity=1.0, state=RUNNING, acls=ADMINISTER_QUEUE:*SUBMIT_APP:*, labels=*,
, reservationsContinueLooking=true
2021-03-08 08:05:32,866 INFO org.apache.hadoop.yarn.server.resourcemanager.scheduler.capacity.ParentQueue: Initialized parent-queue root name=root, fullname=root
2021-03-08 08:05:32,874 INFO org.apache.hadoop.yarn.server.resourcemanager.scheduler.capacity.CapacitySchedulerConfiguration: max alloc mb per queue for root.default is undefined
2021-03-08 08:05:32,874 INFO org.apache.hadoop.yarn.server.resourcemanager.scheduler.capacity.CapacitySchedulerConfiguration: max alloc vcore per queue for root.default is undefined
2021-03-08 08:05:32,876 INFO org.apache.hadoop.yarn.server.resourcemanager.scheduler.capacity.LeafQueue: Initializing default
capacity = 1.0 [= (float) configuredCapacity / 100 ]
asboluteCapacity = 1.0 [= parentAbsoluteCapacity * capacity ]
maxCapacity = 1.0 [= configuredMaxCapacity ]
absoluteMaxCapacity = 1.0 [= 1.0 maximumCapacity undefined, (parentAbsoluteMaxCapacity * maximumCapacity) / 100 otherwise ]
userLimit = 100 [= configuredUserLimit ]
userLimitFactor = 1.0 [= configuredUserLimitFactor ]
maxApplications = 10000 [= configuredMaximumSystemApplicationsPerQueue or (int)(configuredMaximumSystemApplications * absoluteCapacity)]
maxApplicationsPerUser = 10000 [= (int)(maxApplications * (userLimit / 100.0f) * userLimitFactor) ]
usedCapacity = 0.0 [= usedResourcesMemory / (clusterResourceMemory * absoluteCapacity)]
absoluteUsedCapacity = 0.0 [= usedResourcesMemory / clusterResourceMemory]
maxAMResourcePerQueuePercent = 0.1 [= configuredMaximumAMResourcePercent ]
minimumAllocationFactor = 0.875 [= (float)(maximumAllocationMemory - minimumAllocationMemory) / maximumAllocationMemory ]
maximumAllocation = <memory:8192, vCores:32> [= configuredMaxAllocation ]
numContainers = 0 [= currentNumContainers ]
state = RUNNING [= configuredState ]
acls = ADMINISTER_QUEUE:*SUBMIT_APP:* [= configuredAcls ]
nodeLocalityDelay = 40
labels=*,
nodeLocalityDelay = 40
reservationsContinueLooking = true
preemptionDisabled = true

2021-03-08 08:05:32,876 INFO org.apache.hadoop.yarn.server.resourcemanager.scheduler.capacity.CapacityScheduler: Initialized queue: default: capacity=1.0, absoluteCapacity=1.0, usedResources=<memory:0, vCores:0>, usedCapacity=0.0, absoluteUsedCapacity=0.0, numApps=0, numContainers=0
2021-03-08 08:05:32,876 INFO org.apache.hadoop.yarn.server.resourcemanager.scheduler.capacity.CapacityScheduler: Initialized queue: root: numChildQueue= 1, capacity=1.0, absoluteCapacity=1.0, usedResources=<memory:0, vCores:0>usedCapacity=0.0, numApps=0, numContainers=0
2021-03-08 08:05:32,877 INFO org.apache.hadoop.yarn.server.resourcemanager.scheduler.capacity.CapacityScheduler: Initialized root queue root: numChildQueue= 1, capacity=1.0, absoluteCapacity=1.0, usedResources=<memory:0, vCores:0>usedCapacity=0.0, numApps=0, numContainers=0
2021-03-08 08:05:32,877 INFO org.apache.hadoop.yarn.server.resourcemanager.scheduler.capacity.CapacityScheduler: Initialized queue mappings, override: false
2021-03-08 08:05:32,878 INFO org.apache.hadoop.yarn.server.resourcemanager.scheduler.capacity.CapacityScheduler: Initialized CapacityScheduler with calculator=class org.apache.hadoop.yarn.util.resource.DefaultResourceCalculator, minimumAllocation=<<memory:1024, vCores:1>>, maximumAllocation=<<memory:8192, vCores:32>>, asynchronousScheduling=false, asyncScheduleInterval=5ms
2021-03-08 08:05:32,890 INFO org.apache.hadoop.yarn.server.resourcemanager.metrics.SystemMetricsPublisher: YARN system metrics publishing service is not enabled
2021-03-08 08:05:32,890 INFO org.apache.hadoop.yarn.server.resourcemanager.ResourceManager: Transitioning to active state
2021-03-08 08:05:32,910 INFO org.apache.hadoop.yarn.server.resourcemanager.recovery.RMStateStore: Updating AMRMToken
2021-03-08 08:05:32,910 INFO org.apache.hadoop.yarn.server.resourcemanager.security.RMContainerTokenSecretManager: Rolling master-key for container-tokens
2021-03-08 08:05:32,910 INFO org.apache.hadoop.yarn.server.resourcemanager.security.NMTokenSecretManagerInRM: Rolling master-key for nm-tokens
2021-03-08 08:05:32,910 INFO org.apache.hadoop.security.token.delegation.AbstractDelegationTokenSecretManager: Updating the current master key for generating delegation tokens
2021-03-08 08:05:32,911 INFO org.apache.hadoop.yarn.server.resourcemanager.security.RMDelegationTokenSecretManager: storing master key with keyID 1
2021-03-08 08:05:32,911 INFO org.apache.hadoop.yarn.server.resourcemanager.recovery.RMStateStore: Storing RMDTMasterKey.
2021-03-08 08:05:32,918 INFO org.apache.hadoop.security.token.delegation.AbstractDelegationTokenSecretManager: Starting expired delegation token remover thread, tokenRemoverScanInterval=60 min(s)
2021-03-08 08:05:32,918 INFO org.apache.hadoop.security.token.delegation.AbstractDelegationTokenSecretManager: Updating the current master key for generating delegation tokens
2021-03-08 08:05:32,918 INFO org.apache.hadoop.yarn.server.resourcemanager.security.RMDelegationTokenSecretManager: storing master key with keyID 2
2021-03-08 08:05:32,918 INFO org.apache.hadoop.yarn.server.resourcemanager.recovery.RMStateStore: Storing RMDTMasterKey.
2021-03-08 08:05:32,921 INFO org.apache.hadoop.yarn.event.AsyncDispatcher: Registering class org.apache.hadoop.yarn.nodelabels.event.NodeLabelsStoreEventType for class org.apache.hadoop.yarn.nodelabels.CommonNodeLabelsManager$ForwardingEventHandler
2021-03-08 08:05:32,956 INFO org.apache.hadoop.ipc.CallQueueManager: Using callQueue: class java.util.concurrent.LinkedBlockingQueue queueCapacity: 5000
2021-03-08 08:05:32,975 INFO org.apache.hadoop.ipc.Server: Starting Socket Reader #1 for port 8031
2021-03-08 08:05:33,141 INFO org.apache.hadoop.yarn.factories.impl.pb.RpcServerFactoryPBImpl: Adding protocol org.apache.hadoop.yarn.server.api.ResourceTrackerPB to the server
2021-03-08 08:05:33,142 INFO org.apache.hadoop.ipc.Server: IPC Server Responder: starting
2021-03-08 08:05:33,144 INFO org.apache.hadoop.ipc.Server: IPC Server listener on 8031: starting
2021-03-08 08:05:33,167 INFO org.apache.hadoop.ipc.CallQueueManager: Using callQueue: class java.util.concurrent.LinkedBlockingQueue queueCapacity: 5000
2021-03-08 08:05:33,171 INFO org.apache.hadoop.ipc.Server: Starting Socket Reader #1 for port 8030
2021-03-08 08:05:33,181 INFO org.apache.hadoop.yarn.factories.impl.pb.RpcServerFactoryPBImpl: Adding protocol org.apache.hadoop.yarn.api.ApplicationMasterProtocolPB to the server
2021-03-08 08:05:33,181 INFO org.apache.hadoop.ipc.Server: IPC Server Responder: starting
2021-03-08 08:05:33,182 INFO org.apache.hadoop.ipc.Server: IPC Server listener on 8030: starting
2021-03-08 08:05:33,301 INFO org.apache.hadoop.ipc.CallQueueManager: Using callQueue: class java.util.concurrent.LinkedBlockingQueue queueCapacity: 5000
2021-03-08 08:05:33,301 INFO org.apache.hadoop.ipc.Server: Starting Socket Reader #1 for port 8032
2021-03-08 08:05:33,308 INFO org.apache.hadoop.yarn.factories.impl.pb.RpcServerFactoryPBImpl: Adding protocol org.apache.hadoop.yarn.api.ApplicationClientProtocolPB to the server
2021-03-08 08:05:33,308 INFO org.apache.hadoop.ipc.Server: IPC Server Responder: starting
2021-03-08 08:05:33,308 INFO org.apache.hadoop.ipc.Server: IPC Server listener on 8032: starting
2021-03-08 08:05:33,325 INFO org.apache.hadoop.yarn.server.resourcemanager.ResourceManager: Transitioned to active state
2021-03-08 08:05:33,425 INFO org.mortbay.log: Logging to org.slf4j.impl.Log4jLoggerAdapter(org.mortbay.log) via org.mortbay.log.Slf4jLog
2021-03-08 08:05:33,429 INFO org.apache.hadoop.security.authentication.server.AuthenticationFilter: Unable to initialize FileSignerSecretProvider, falling back to use random secrets.
2021-03-08 08:05:33,441 INFO org.apache.hadoop.http.HttpRequestLog: Http request log for http.requests.resourcemanager is not defined
2021-03-08 08:05:33,448 INFO org.apache.hadoop.http.HttpServer2: Added global filter 'safety' (class=org.apache.hadoop.http.HttpServer2$QuotingInputFilter)
2021-03-08 08:05:33,450 INFO org.apache.hadoop.http.HttpServer2: Added filter RMAuthenticationFilter (class=org.apache.hadoop.yarn.server.security.http.RMAuthenticationFilter) to context cluster
2021-03-08 08:05:33,450 INFO org.apache.hadoop.http.HttpServer2: Added filter RMAuthenticationFilter (class=org.apache.hadoop.yarn.server.security.http.RMAuthenticationFilter) to context static
2021-03-08 08:05:33,450 INFO org.apache.hadoop.http.HttpServer2: Added filter RMAuthenticationFilter (class=org.apache.hadoop.yarn.server.security.http.RMAuthenticationFilter) to context logs
2021-03-08 08:05:33,451 INFO org.apache.hadoop.http.HttpServer2: Added filter static_user_filter (class=org.apache.hadoop.http.lib.StaticUserWebFilter$StaticUserFilter) to context cluster
2021-03-08 08:05:33,451 INFO org.apache.hadoop.http.HttpServer2: Added filter static_user_filter (class=org.apache.hadoop.http.lib.StaticUserWebFilter$StaticUserFilter) to context static
2021-03-08 08:05:33,451 INFO org.apache.hadoop.http.HttpServer2: Added filter static_user_filter (class=org.apache.hadoop.http.lib.StaticUserWebFilter$StaticUserFilter) to context logs
2021-03-08 08:05:33,453 INFO org.apache.hadoop.http.HttpServer2: adding path spec: /cluster/*
2021-03-08 08:05:33,453 INFO org.apache.hadoop.http.HttpServer2: adding path spec: /ws/*
2021-03-08 08:05:33,677 INFO org.apache.hadoop.yarn.webapp.WebApps: Registered webapp guice modules
2021-03-08 08:05:33,679 INFO org.apache.hadoop.http.HttpServer2: Jetty bound to port 8088
2021-03-08 08:05:33,679 INFO org.mortbay.log: jetty-6.1.26
2021-03-08 08:05:33,703 INFO org.mortbay.log: Extract jar:file:/home/hadoopuser/hadoop/share/hadoop/yarn/hadoop-yarn-common-2.7.7.jar!/webapps/cluster to /tmp/Jetty_master_8088_cluster____i4ls4w/webapp
2021-03-08 08:05:33,781 INFO org.apache.hadoop.security.token.delegation.AbstractDelegationTokenSecretManager: Updating the current master key for generating delegation tokens
2021-03-08 08:05:33,787 INFO org.apache.hadoop.security.token.delegation.AbstractDelegationTokenSecretManager: Starting expired delegation token remover thread, tokenRemoverScanInterval=60 min(s)
2021-03-08 08:05:33,787 INFO org.apache.hadoop.security.token.delegation.AbstractDelegationTokenSecretManager: Updating the current master key for generating delegation tokens
2021-03-08 08:05:34,312 INFO org.mortbay.log: Started HttpServer2$SelectChannelConnectorWithSafeStartup@master:8088
2021-03-08 08:05:34,312 INFO org.apache.hadoop.yarn.webapp.WebApps: Web app cluster started at 8088
2021-03-08 08:05:34,329 INFO org.apache.hadoop.ipc.CallQueueManager: Using callQueue: class java.util.concurrent.LinkedBlockingQueue queueCapacity: 100
2021-03-08 08:05:34,330 INFO org.apache.hadoop.ipc.Server: Starting Socket Reader #1 for port 8033
2021-03-08 08:05:34,332 INFO org.apache.hadoop.yarn.factories.impl.pb.RpcServerFactoryPBImpl: Adding protocol org.apache.hadoop.yarn.server.api.ResourceManagerAdministrationProtocolPB to the server
2021-03-08 08:05:34,337 INFO org.apache.hadoop.ipc.Server: IPC Server Responder: starting
2021-03-08 08:05:34,337 INFO org.apache.hadoop.ipc.Server: IPC Server listener on 8033: starting
2021-03-08 08:06:41,303 ERROR org.apache.hadoop.yarn.server.resourcemanager.ResourceManager: RECEIVED SIGNAL 15: SIGTERM
2021-03-08 08:06:41,313 ERROR org.apache.hadoop.security.token.delegation.AbstractDelegationTokenSecretManager: ExpiredTokenRemover received java.lang.InterruptedException: sleep interrupted
2021-03-08 08:06:41,315 INFO org.mortbay.log: Stopped HttpServer2$SelectChannelConnectorWithSafeStartup@master:8088
2021-03-08 08:06:41,416 INFO org.apache.hadoop.ipc.Server: Stopping server on 8032
2021-03-08 08:06:41,421 INFO org.apache.hadoop.ipc.Server: Stopping server on 8033
2021-03-08 08:06:41,421 INFO org.apache.hadoop.ipc.Server: Stopping IPC Server Responder
2021-03-08 08:06:41,421 INFO org.apache.hadoop.ipc.Server: Stopping IPC Server listener on 8032
2021-03-08 08:06:41,421 INFO org.apache.hadoop.ipc.Server: Stopping IPC Server listener on 8033
2021-03-08 08:06:41,423 INFO org.apache.hadoop.ipc.Server: Stopping IPC Server Responder
2021-03-08 08:06:41,423 INFO org.apache.hadoop.yarn.server.resourcemanager.ResourceManager: Transitioning to standby state
2021-03-08 08:06:41,423 WARN org.apache.hadoop.yarn.server.resourcemanager.amlauncher.ApplicationMasterLauncher: org.apache.hadoop.yarn.server.resourcemanager.amlauncher.ApplicationMasterLauncher$LauncherThread interrupted. Returning.
2021-03-08 08:06:41,423 INFO org.apache.hadoop.ipc.Server: Stopping server on 8030
2021-03-08 08:06:41,429 INFO org.apache.hadoop.ipc.Server: Stopping server on 8031
2021-03-08 08:06:41,429 INFO org.apache.hadoop.ipc.Server: Stopping IPC Server listener on 8030
2021-03-08 08:06:41,429 INFO org.apache.hadoop.ipc.Server: Stopping IPC Server Responder
2021-03-08 08:06:41,434 INFO org.apache.hadoop.ipc.Server: Stopping IPC Server Responder
2021-03-08 08:06:41,434 INFO org.apache.hadoop.ipc.Server: Stopping IPC Server listener on 8031
2021-03-08 08:06:41,435 INFO org.apache.hadoop.yarn.util.AbstractLivelinessMonitor: NMLivelinessMonitor thread interrupted
2021-03-08 08:06:41,435 ERROR org.apache.hadoop.yarn.server.resourcemanager.ResourceManager: Returning, interrupted : java.lang.InterruptedException
2021-03-08 08:06:41,435 INFO org.apache.hadoop.yarn.event.AsyncDispatcher: AsyncDispatcher is draining to stop, igonring any new events.
2021-03-08 08:06:41,435 INFO org.apache.hadoop.yarn.util.AbstractLivelinessMonitor: AMLivelinessMonitor thread interrupted
2021-03-08 08:06:41,435 INFO org.apache.hadoop.yarn.util.AbstractLivelinessMonitor: org.apache.hadoop.yarn.server.resourcemanager.rmcontainer.ContainerAllocationExpirer thread interrupted
2021-03-08 08:06:41,435 INFO org.apache.hadoop.yarn.util.AbstractLivelinessMonitor: AMLivelinessMonitor thread interrupted
2021-03-08 08:06:41,436 ERROR org.apache.hadoop.security.token.delegation.AbstractDelegationTokenSecretManager: ExpiredTokenRemover received java.lang.InterruptedException: sleep interrupted
2021-03-08 08:06:41,436 INFO org.apache.hadoop.metrics2.impl.MetricsSystemImpl: Stopping ResourceManager metrics system...
2021-03-08 08:06:41,437 INFO org.apache.hadoop.metrics2.impl.MetricsSystemImpl: ResourceManager metrics system stopped.
2021-03-08 08:06:41,437 INFO org.apache.hadoop.metrics2.impl.MetricsSystemImpl: ResourceManager metrics system shutdown complete.
2021-03-08 08:06:41,437 INFO org.apache.hadoop.yarn.event.AsyncDispatcher: AsyncDispatcher is draining to stop, igonring any new events.
2021-03-08 08:06:41,437 INFO org.apache.hadoop.yarn.server.resourcemanager.ResourceManager: Transitioned to standby state
2021-03-08 08:06:41,437 INFO org.apache.hadoop.yarn.server.resourcemanager.ResourceManager: SHUTDOWN_MSG: 
/************************************************************
SHUTDOWN_MSG: Shutting down ResourceManager at master/192.168.244.130
************************************************************/
2021-03-08 08:07:13,746 INFO org.apache.hadoop.yarn.server.resourcemanager.ResourceManager: STARTUP_MSG: 
/************************************************************
STARTUP_MSG: Starting ResourceManager
STARTUP_MSG:   host = master/192.168.244.130
STARTUP_MSG:   args = []
STARTUP_MSG:   version = 2.7.7
STARTUP_MSG:   build = Unknown -r c1aad84bd27cd79c3d1a7dd58202a8c3ee1ed3ac; compiled by 'stevel' on 2018-07-18T22:47Z
STARTUP_MSG:   java = 15.0.2
************************************************************/
2021-03-08 08:07:13,750 INFO org.apache.hadoop.yarn.server.resourcemanager.ResourceManager: registered UNIX signal handlers for [TERM, HUP, INT]
2021-03-08 08:07:13,977 INFO org.apache.hadoop.conf.Configuration: found resource core-site.xml at file:/home/hadoopuser/hadoop/etc/hadoop/core-site.xml
2021-03-08 08:07:14,037 WARN org.apache.hadoop.util.NativeCodeLoader: Unable to load native-hadoop library for your platform... using builtin-java classes where applicable
2021-03-08 08:07:14,054 INFO org.apache.hadoop.security.Groups: clearing userToGroupsMap cache
2021-03-08 08:07:14,151 INFO org.apache.hadoop.conf.Configuration: found resource yarn-site.xml at file:/home/hadoopuser/hadoop/etc/hadoop/yarn-site.xml
2021-03-08 08:07:14,265 INFO org.apache.hadoop.yarn.event.AsyncDispatcher: Registering class org.apache.hadoop.yarn.server.resourcemanager.RMFatalEventType for class org.apache.hadoop.yarn.server.resourcemanager.ResourceManager$RMFatalEventDispatcher
2021-03-08 08:07:14,343 INFO org.apache.hadoop.yarn.server.resourcemanager.security.NMTokenSecretManagerInRM: NMTokenKeyRollingInterval: 86400000ms and NMTokenKeyActivationDelay: 900000ms
2021-03-08 08:07:14,345 INFO org.apache.hadoop.yarn.server.resourcemanager.security.RMContainerTokenSecretManager: ContainerTokenKeyRollingInterval: 86400000ms and ContainerTokenKeyActivationDelay: 900000ms
2021-03-08 08:07:14,352 INFO org.apache.hadoop.yarn.server.resourcemanager.security.AMRMTokenSecretManager: AMRMTokenKeyRollingInterval: 86400000ms and AMRMTokenKeyActivationDelay: 900000 ms
2021-03-08 08:07:14,377 INFO org.apache.hadoop.yarn.event.AsyncDispatcher: Registering class org.apache.hadoop.yarn.server.resourcemanager.recovery.RMStateStoreEventType for class org.apache.hadoop.yarn.server.resourcemanager.recovery.RMStateStore$ForwardingEventHandler
2021-03-08 08:07:14,379 INFO org.apache.hadoop.yarn.event.AsyncDispatcher: Registering class org.apache.hadoop.yarn.server.resourcemanager.NodesListManagerEventType for class org.apache.hadoop.yarn.server.resourcemanager.NodesListManager
2021-03-08 08:07:14,379 INFO org.apache.hadoop.yarn.server.resourcemanager.ResourceManager: Using Scheduler: org.apache.hadoop.yarn.server.resourcemanager.scheduler.capacity.CapacityScheduler
2021-03-08 08:07:14,390 INFO org.apache.hadoop.yarn.event.AsyncDispatcher: Registering class org.apache.hadoop.yarn.server.resourcemanager.scheduler.event.SchedulerEventType for class org.apache.hadoop.yarn.server.resourcemanager.ResourceManager$SchedulerEventDispatcher
2021-03-08 08:07:14,390 INFO org.apache.hadoop.yarn.event.AsyncDispatcher: Registering class org.apache.hadoop.yarn.server.resourcemanager.rmapp.RMAppEventType for class org.apache.hadoop.yarn.server.resourcemanager.ResourceManager$ApplicationEventDispatcher
2021-03-08 08:07:14,391 INFO org.apache.hadoop.yarn.event.AsyncDispatcher: Registering class org.apache.hadoop.yarn.server.resourcemanager.rmapp.attempt.RMAppAttemptEventType for class org.apache.hadoop.yarn.server.resourcemanager.ResourceManager$ApplicationAttemptEventDispatcher
2021-03-08 08:07:14,391 INFO org.apache.hadoop.yarn.event.AsyncDispatcher: Registering class org.apache.hadoop.yarn.server.resourcemanager.rmnode.RMNodeEventType for class org.apache.hadoop.yarn.server.resourcemanager.ResourceManager$NodeEventDispatcher
2021-03-08 08:07:14,458 INFO org.apache.hadoop.metrics2.impl.MetricsConfig: loaded properties from hadoop-metrics2.properties
2021-03-08 08:07:14,511 INFO org.apache.hadoop.metrics2.impl.MetricsSystemImpl: Scheduled snapshot period at 10 second(s).
2021-03-08 08:07:14,511 INFO org.apache.hadoop.metrics2.impl.MetricsSystemImpl: ResourceManager metrics system started
2021-03-08 08:07:14,520 INFO org.apache.hadoop.yarn.event.AsyncDispatcher: Registering class org.apache.hadoop.yarn.server.resourcemanager.RMAppManagerEventType for class org.apache.hadoop.yarn.server.resourcemanager.RMAppManager
2021-03-08 08:07:14,523 INFO org.apache.hadoop.yarn.event.AsyncDispatcher: Registering class org.apache.hadoop.yarn.server.resourcemanager.amlauncher.AMLauncherEventType for class org.apache.hadoop.yarn.server.resourcemanager.amlauncher.ApplicationMasterLauncher
2021-03-08 08:07:14,525 INFO org.apache.hadoop.yarn.server.resourcemanager.RMNMInfo: Registered RMNMInfo MBean
2021-03-08 08:07:14,525 INFO org.apache.hadoop.yarn.security.YarnAuthorizationProvider: org.apache.hadoop.yarn.security.ConfiguredYarnAuthorizer is instiantiated.
2021-03-08 08:07:14,526 INFO org.apache.hadoop.util.HostsFileReader: Refreshing hosts (include/exclude) list
2021-03-08 08:07:14,527 INFO org.apache.hadoop.conf.Configuration: found resource capacity-scheduler.xml at file:/home/hadoopuser/hadoop/etc/hadoop/capacity-scheduler.xml
2021-03-08 08:07:14,555 INFO org.apache.hadoop.yarn.server.resourcemanager.scheduler.capacity.CapacitySchedulerConfiguration: max alloc mb per queue for root is undefined
2021-03-08 08:07:14,555 INFO org.apache.hadoop.yarn.server.resourcemanager.scheduler.capacity.CapacitySchedulerConfiguration: max alloc vcore per queue for root is undefined
2021-03-08 08:07:14,557 INFO org.apache.hadoop.yarn.server.resourcemanager.scheduler.capacity.ParentQueue: root, capacity=1.0, asboluteCapacity=1.0, maxCapacity=1.0, asboluteMaxCapacity=1.0, state=RUNNING, acls=SUBMIT_APP:*ADMINISTER_QUEUE:*, labels=*,
, reservationsContinueLooking=true
2021-03-08 08:07:14,557 INFO org.apache.hadoop.yarn.server.resourcemanager.scheduler.capacity.ParentQueue: Initialized parent-queue root name=root, fullname=root
2021-03-08 08:07:14,561 INFO org.apache.hadoop.yarn.server.resourcemanager.scheduler.capacity.CapacitySchedulerConfiguration: max alloc mb per queue for root.default is undefined
2021-03-08 08:07:14,561 INFO org.apache.hadoop.yarn.server.resourcemanager.scheduler.capacity.CapacitySchedulerConfiguration: max alloc vcore per queue for root.default is undefined
2021-03-08 08:07:14,562 INFO org.apache.hadoop.yarn.server.resourcemanager.scheduler.capacity.LeafQueue: Initializing default
capacity = 1.0 [= (float) configuredCapacity / 100 ]
asboluteCapacity = 1.0 [= parentAbsoluteCapacity * capacity ]
maxCapacity = 1.0 [= configuredMaxCapacity ]
absoluteMaxCapacity = 1.0 [= 1.0 maximumCapacity undefined, (parentAbsoluteMaxCapacity * maximumCapacity) / 100 otherwise ]
userLimit = 100 [= configuredUserLimit ]
userLimitFactor = 1.0 [= configuredUserLimitFactor ]
maxApplications = 10000 [= configuredMaximumSystemApplicationsPerQueue or (int)(configuredMaximumSystemApplications * absoluteCapacity)]
maxApplicationsPerUser = 10000 [= (int)(maxApplications * (userLimit / 100.0f) * userLimitFactor) ]
usedCapacity = 0.0 [= usedResourcesMemory / (clusterResourceMemory * absoluteCapacity)]
absoluteUsedCapacity = 0.0 [= usedResourcesMemory / clusterResourceMemory]
maxAMResourcePerQueuePercent = 0.1 [= configuredMaximumAMResourcePercent ]
minimumAllocationFactor = 0.875 [= (float)(maximumAllocationMemory - minimumAllocationMemory) / maximumAllocationMemory ]
maximumAllocation = <memory:8192, vCores:32> [= configuredMaxAllocation ]
numContainers = 0 [= currentNumContainers ]
state = RUNNING [= configuredState ]
acls = SUBMIT_APP:*ADMINISTER_QUEUE:* [= configuredAcls ]
nodeLocalityDelay = 40
labels=*,
nodeLocalityDelay = 40
reservationsContinueLooking = true
preemptionDisabled = true

2021-03-08 08:07:14,562 INFO org.apache.hadoop.yarn.server.resourcemanager.scheduler.capacity.CapacityScheduler: Initialized queue: default: capacity=1.0, absoluteCapacity=1.0, usedResources=<memory:0, vCores:0>, usedCapacity=0.0, absoluteUsedCapacity=0.0, numApps=0, numContainers=0
2021-03-08 08:07:14,562 INFO org.apache.hadoop.yarn.server.resourcemanager.scheduler.capacity.CapacityScheduler: Initialized queue: root: numChildQueue= 1, capacity=1.0, absoluteCapacity=1.0, usedResources=<memory:0, vCores:0>usedCapacity=0.0, numApps=0, numContainers=0
2021-03-08 08:07:14,562 INFO org.apache.hadoop.yarn.server.resourcemanager.scheduler.capacity.CapacityScheduler: Initialized root queue root: numChildQueue= 1, capacity=1.0, absoluteCapacity=1.0, usedResources=<memory:0, vCores:0>usedCapacity=0.0, numApps=0, numContainers=0
2021-03-08 08:07:14,562 INFO org.apache.hadoop.yarn.server.resourcemanager.scheduler.capacity.CapacityScheduler: Initialized queue mappings, override: false
2021-03-08 08:07:14,562 INFO org.apache.hadoop.yarn.server.resourcemanager.scheduler.capacity.CapacityScheduler: Initialized CapacityScheduler with calculator=class org.apache.hadoop.yarn.util.resource.DefaultResourceCalculator, minimumAllocation=<<memory:1024, vCores:1>>, maximumAllocation=<<memory:8192, vCores:32>>, asynchronousScheduling=false, asyncScheduleInterval=5ms
2021-03-08 08:07:14,568 INFO org.apache.hadoop.yarn.server.resourcemanager.metrics.SystemMetricsPublisher: YARN system metrics publishing service is not enabled
2021-03-08 08:07:14,568 INFO org.apache.hadoop.yarn.server.resourcemanager.ResourceManager: Transitioning to active state
2021-03-08 08:07:14,572 INFO org.apache.hadoop.yarn.server.resourcemanager.recovery.RMStateStore: Updating AMRMToken
2021-03-08 08:07:14,573 INFO org.apache.hadoop.yarn.server.resourcemanager.security.RMContainerTokenSecretManager: Rolling master-key for container-tokens
2021-03-08 08:07:14,573 INFO org.apache.hadoop.yarn.server.resourcemanager.security.NMTokenSecretManagerInRM: Rolling master-key for nm-tokens
2021-03-08 08:07:14,573 INFO org.apache.hadoop.security.token.delegation.AbstractDelegationTokenSecretManager: Updating the current master key for generating delegation tokens
2021-03-08 08:07:14,573 INFO org.apache.hadoop.yarn.server.resourcemanager.security.RMDelegationTokenSecretManager: storing master key with keyID 1
2021-03-08 08:07:14,574 INFO org.apache.hadoop.yarn.server.resourcemanager.recovery.RMStateStore: Storing RMDTMasterKey.
2021-03-08 08:07:14,575 INFO org.apache.hadoop.security.token.delegation.AbstractDelegationTokenSecretManager: Starting expired delegation token remover thread, tokenRemoverScanInterval=60 min(s)
2021-03-08 08:07:14,575 INFO org.apache.hadoop.security.token.delegation.AbstractDelegationTokenSecretManager: Updating the current master key for generating delegation tokens
2021-03-08 08:07:14,575 INFO org.apache.hadoop.yarn.server.resourcemanager.security.RMDelegationTokenSecretManager: storing master key with keyID 2
2021-03-08 08:07:14,575 INFO org.apache.hadoop.yarn.server.resourcemanager.recovery.RMStateStore: Storing RMDTMasterKey.
2021-03-08 08:07:14,582 INFO org.apache.hadoop.yarn.event.AsyncDispatcher: Registering class org.apache.hadoop.yarn.nodelabels.event.NodeLabelsStoreEventType for class org.apache.hadoop.yarn.nodelabels.CommonNodeLabelsManager$ForwardingEventHandler
2021-03-08 08:07:14,633 INFO org.apache.hadoop.ipc.CallQueueManager: Using callQueue: class java.util.concurrent.LinkedBlockingQueue queueCapacity: 5000
2021-03-08 08:07:14,659 INFO org.apache.hadoop.ipc.Server: Starting Socket Reader #1 for port 8031
2021-03-08 08:07:14,816 INFO org.apache.hadoop.yarn.factories.impl.pb.RpcServerFactoryPBImpl: Adding protocol org.apache.hadoop.yarn.server.api.ResourceTrackerPB to the server
2021-03-08 08:07:14,816 INFO org.apache.hadoop.ipc.Server: IPC Server Responder: starting
2021-03-08 08:07:14,835 INFO org.apache.hadoop.ipc.Server: IPC Server listener on 8031: starting
2021-03-08 08:07:14,867 INFO org.apache.hadoop.ipc.CallQueueManager: Using callQueue: class java.util.concurrent.LinkedBlockingQueue queueCapacity: 5000
2021-03-08 08:07:14,871 INFO org.apache.hadoop.ipc.Server: Starting Socket Reader #1 for port 8030
2021-03-08 08:07:14,882 INFO org.apache.hadoop.yarn.factories.impl.pb.RpcServerFactoryPBImpl: Adding protocol org.apache.hadoop.yarn.api.ApplicationMasterProtocolPB to the server
2021-03-08 08:07:14,882 INFO org.apache.hadoop.ipc.Server: IPC Server Responder: starting
2021-03-08 08:07:14,885 INFO org.apache.hadoop.ipc.Server: IPC Server listener on 8030: starting
2021-03-08 08:07:14,919 INFO org.apache.hadoop.ipc.CallQueueManager: Using callQueue: class java.util.concurrent.LinkedBlockingQueue queueCapacity: 5000
2021-03-08 08:07:14,921 INFO org.apache.hadoop.ipc.Server: Starting Socket Reader #1 for port 8032
2021-03-08 08:07:14,926 INFO org.apache.hadoop.yarn.factories.impl.pb.RpcServerFactoryPBImpl: Adding protocol org.apache.hadoop.yarn.api.ApplicationClientProtocolPB to the server
2021-03-08 08:07:14,926 INFO org.apache.hadoop.ipc.Server: IPC Server Responder: starting
2021-03-08 08:07:14,926 INFO org.apache.hadoop.ipc.Server: IPC Server listener on 8032: starting
2021-03-08 08:07:14,946 INFO org.apache.hadoop.yarn.server.resourcemanager.ResourceManager: Transitioned to active state
2021-03-08 08:07:15,012 INFO org.mortbay.log: Logging to org.slf4j.impl.Log4jLoggerAdapter(org.mortbay.log) via org.mortbay.log.Slf4jLog
2021-03-08 08:07:15,023 INFO org.apache.hadoop.security.authentication.server.AuthenticationFilter: Unable to initialize FileSignerSecretProvider, falling back to use random secrets.
2021-03-08 08:07:15,028 INFO org.apache.hadoop.http.HttpRequestLog: Http request log for http.requests.resourcemanager is not defined
2021-03-08 08:07:15,038 INFO org.apache.hadoop.http.HttpServer2: Added global filter 'safety' (class=org.apache.hadoop.http.HttpServer2$QuotingInputFilter)
2021-03-08 08:07:15,044 INFO org.apache.hadoop.http.HttpServer2: Added filter RMAuthenticationFilter (class=org.apache.hadoop.yarn.server.security.http.RMAuthenticationFilter) to context cluster
2021-03-08 08:07:15,045 INFO org.apache.hadoop.http.HttpServer2: Added filter RMAuthenticationFilter (class=org.apache.hadoop.yarn.server.security.http.RMAuthenticationFilter) to context logs
2021-03-08 08:07:15,045 INFO org.apache.hadoop.http.HttpServer2: Added filter RMAuthenticationFilter (class=org.apache.hadoop.yarn.server.security.http.RMAuthenticationFilter) to context static
2021-03-08 08:07:15,045 INFO org.apache.hadoop.http.HttpServer2: Added filter static_user_filter (class=org.apache.hadoop.http.lib.StaticUserWebFilter$StaticUserFilter) to context cluster
2021-03-08 08:07:15,046 INFO org.apache.hadoop.http.HttpServer2: Added filter static_user_filter (class=org.apache.hadoop.http.lib.StaticUserWebFilter$StaticUserFilter) to context logs
2021-03-08 08:07:15,046 INFO org.apache.hadoop.http.HttpServer2: Added filter static_user_filter (class=org.apache.hadoop.http.lib.StaticUserWebFilter$StaticUserFilter) to context static
2021-03-08 08:07:15,050 INFO org.apache.hadoop.http.HttpServer2: adding path spec: /cluster/*
2021-03-08 08:07:15,050 INFO org.apache.hadoop.http.HttpServer2: adding path spec: /ws/*
2021-03-08 08:07:15,623 INFO org.apache.hadoop.yarn.webapp.WebApps: Registered webapp guice modules
2021-03-08 08:07:15,626 INFO org.apache.hadoop.http.HttpServer2: Jetty bound to port 8088
2021-03-08 08:07:15,626 INFO org.mortbay.log: jetty-6.1.26
2021-03-08 08:07:15,664 INFO org.mortbay.log: Extract jar:file:/home/hadoopuser/hadoop/share/hadoop/yarn/hadoop-yarn-common-2.7.7.jar!/webapps/cluster to /tmp/Jetty_master_8088_cluster____i4ls4w/webapp
2021-03-08 08:07:15,787 INFO org.apache.hadoop.security.token.delegation.AbstractDelegationTokenSecretManager: Updating the current master key for generating delegation tokens
2021-03-08 08:07:15,794 INFO org.apache.hadoop.security.token.delegation.AbstractDelegationTokenSecretManager: Starting expired delegation token remover thread, tokenRemoverScanInterval=60 min(s)
2021-03-08 08:07:15,794 INFO org.apache.hadoop.security.token.delegation.AbstractDelegationTokenSecretManager: Updating the current master key for generating delegation tokens
2021-03-08 08:07:17,181 INFO org.mortbay.log: Started HttpServer2$SelectChannelConnectorWithSafeStartup@master:8088
2021-03-08 08:07:17,181 INFO org.apache.hadoop.yarn.webapp.WebApps: Web app cluster started at 8088
2021-03-08 08:07:17,196 INFO org.apache.hadoop.ipc.CallQueueManager: Using callQueue: class java.util.concurrent.LinkedBlockingQueue queueCapacity: 100
2021-03-08 08:07:17,197 INFO org.apache.hadoop.ipc.Server: Starting Socket Reader #1 for port 8033
2021-03-08 08:07:17,200 INFO org.apache.hadoop.yarn.factories.impl.pb.RpcServerFactoryPBImpl: Adding protocol org.apache.hadoop.yarn.server.api.ResourceManagerAdministrationProtocolPB to the server
2021-03-08 08:07:17,205 INFO org.apache.hadoop.ipc.Server: IPC Server Responder: starting
2021-03-08 08:07:17,209 INFO org.apache.hadoop.ipc.Server: IPC Server listener on 8033: starting
2021-03-08 08:07:20,646 INFO org.apache.hadoop.yarn.util.RackResolver: Resolved tutrung-slave2 to /default-rack
2021-03-08 08:07:20,648 INFO org.apache.hadoop.yarn.server.resourcemanager.ResourceTrackerService: NodeManager from node tutrung-slave2(cmPort: 37119 httpPort: 8042) registered with capability: <memory:8192, vCores:8>, assigned nodeId tutrung-slave2:37119
2021-03-08 08:07:20,650 INFO org.apache.hadoop.yarn.server.resourcemanager.rmnode.RMNodeImpl: tutrung-slave2:37119 Node Transitioned from NEW to RUNNING
2021-03-08 08:07:20,651 INFO org.apache.hadoop.yarn.server.resourcemanager.scheduler.capacity.CapacityScheduler: Added node tutrung-slave2:37119 clusterResource: <memory:8192, vCores:8>
2021-03-08 08:07:24,465 INFO org.apache.hadoop.yarn.util.RackResolver: Resolved tutrung-slave1 to /default-rack
2021-03-08 08:07:24,465 INFO org.apache.hadoop.yarn.server.resourcemanager.ResourceTrackerService: NodeManager from node tutrung-slave1(cmPort: 37241 httpPort: 8042) registered with capability: <memory:8192, vCores:8>, assigned nodeId tutrung-slave1:37241
2021-03-08 08:07:24,465 INFO org.apache.hadoop.yarn.server.resourcemanager.rmnode.RMNodeImpl: tutrung-slave1:37241 Node Transitioned from NEW to RUNNING
2021-03-08 08:07:24,466 INFO org.apache.hadoop.yarn.server.resourcemanager.scheduler.capacity.CapacityScheduler: Added node tutrung-slave1:37241 clusterResource: <memory:16384, vCores:16>
2021-03-08 08:10:10,902 INFO org.apache.hadoop.yarn.server.resourcemanager.ClientRMService: Allocated new applicationId: 1
2021-03-08 08:10:11,784 INFO org.apache.hadoop.yarn.server.resourcemanager.rmapp.RMAppImpl: Storing application with id application_1615219634569_0001
2021-03-08 08:10:11,785 INFO org.apache.hadoop.yarn.server.resourcemanager.ClientRMService: Application with id 1 submitted by user hadoopuser
2021-03-08 08:10:11,789 INFO org.apache.hadoop.yarn.server.resourcemanager.recovery.RMStateStore: Storing info for app: application_1615219634569_0001
2021-03-08 08:10:11,790 INFO org.apache.hadoop.yarn.server.resourcemanager.rmapp.RMAppImpl: application_1615219634569_0001 State change from NEW to NEW_SAVING on event=START
2021-03-08 08:10:11,790 INFO org.apache.hadoop.yarn.server.resourcemanager.rmapp.RMAppImpl: application_1615219634569_0001 State change from NEW_SAVING to SUBMITTED on event=APP_NEW_SAVED
2021-03-08 08:10:11,791 INFO org.apache.hadoop.yarn.server.resourcemanager.RMAuditLogger: USER=hadoopuser	IP=192.168.244.130	OPERATION=Submit Application Request	TARGET=ClientRMService	RESULT=SUCCESS	APPID=application_1615219634569_0001
2021-03-08 08:10:11,791 INFO org.apache.hadoop.yarn.server.resourcemanager.scheduler.capacity.ParentQueue: Application added - appId: application_1615219634569_0001 user: hadoopuser leaf-queue of parent: root #applications: 1
2021-03-08 08:10:11,791 INFO org.apache.hadoop.yarn.server.resourcemanager.scheduler.capacity.CapacityScheduler: Accepted application application_1615219634569_0001 from user: hadoopuser, in queue: default
2021-03-08 08:10:11,801 INFO org.apache.hadoop.yarn.server.resourcemanager.rmapp.RMAppImpl: application_1615219634569_0001 State change from SUBMITTED to ACCEPTED on event=APP_ACCEPTED
2021-03-08 08:10:11,816 INFO org.apache.hadoop.yarn.server.resourcemanager.ApplicationMasterService: Registering app attempt : appattempt_1615219634569_0001_000001
2021-03-08 08:10:11,816 INFO org.apache.hadoop.yarn.server.resourcemanager.rmapp.attempt.RMAppAttemptImpl: appattempt_1615219634569_0001_000001 State change from NEW to SUBMITTED
2021-03-08 08:10:11,827 INFO org.apache.hadoop.yarn.server.resourcemanager.scheduler.capacity.LeafQueue: Application application_1615219634569_0001 from user: hadoopuser activated in queue: default
2021-03-08 08:10:11,828 INFO org.apache.hadoop.yarn.server.resourcemanager.scheduler.capacity.LeafQueue: Application added - appId: application_1615219634569_0001 user: org.apache.hadoop.yarn.server.resourcemanager.scheduler.capacity.LeafQueue$User@6da7529, leaf-queue: default #user-pending-applications: 0 #user-active-applications: 1 #queue-pending-applications: 0 #queue-active-applications: 1
2021-03-08 08:10:11,828 INFO org.apache.hadoop.yarn.server.resourcemanager.scheduler.capacity.CapacityScheduler: Added Application Attempt appattempt_1615219634569_0001_000001 to scheduler from user hadoopuser in queue default
2021-03-08 08:10:11,830 INFO org.apache.hadoop.yarn.server.resourcemanager.rmapp.attempt.RMAppAttemptImpl: appattempt_1615219634569_0001_000001 State change from SUBMITTED to SCHEDULED
2021-03-08 08:10:12,380 INFO org.apache.hadoop.yarn.server.resourcemanager.rmcontainer.RMContainerImpl: container_1615219634569_0001_01_000001 Container Transitioned from NEW to ALLOCATED
2021-03-08 08:10:12,381 INFO org.apache.hadoop.yarn.server.resourcemanager.RMAuditLogger: USER=hadoopuser	OPERATION=AM Allocated Container	TARGET=SchedulerApp	RESULT=SUCCESS	APPID=application_1615219634569_0001	CONTAINERID=container_1615219634569_0001_01_000001
2021-03-08 08:10:12,381 INFO org.apache.hadoop.yarn.server.resourcemanager.scheduler.SchedulerNode: Assigned container container_1615219634569_0001_01_000001 of capacity <memory:2048, vCores:1> on host tutrung-slave2:37119, which has 1 containers, <memory:2048, vCores:1> used and <memory:6144, vCores:7> available after allocation
2021-03-08 08:10:12,381 INFO org.apache.hadoop.yarn.server.resourcemanager.scheduler.capacity.LeafQueue: assignedContainer application attempt=appattempt_1615219634569_0001_000001 container=Container: [ContainerId: container_1615219634569_0001_01_000001, NodeId: tutrung-slave2:37119, NodeHttpAddress: tutrung-slave2:8042, Resource: <memory:2048, vCores:1>, Priority: 0, Token: null, ] queue=default: capacity=1.0, absoluteCapacity=1.0, usedResources=<memory:0, vCores:0>, usedCapacity=0.0, absoluteUsedCapacity=0.0, numApps=1, numContainers=0 clusterResource=<memory:16384, vCores:16> type=OFF_SWITCH requestedPartition=
2021-03-08 08:10:12,384 INFO org.apache.hadoop.yarn.server.resourcemanager.scheduler.capacity.ParentQueue: Re-sorting assigned queue: root.default stats: default: capacity=1.0, absoluteCapacity=1.0, usedResources=<memory:2048, vCores:1>, usedCapacity=0.125, absoluteUsedCapacity=0.125, numApps=1, numContainers=1
2021-03-08 08:10:12,384 INFO org.apache.hadoop.yarn.server.resourcemanager.scheduler.capacity.ParentQueue: assignedContainer queue=root usedCapacity=0.125 absoluteUsedCapacity=0.125 used=<memory:2048, vCores:1> cluster=<memory:16384, vCores:16>
2021-03-08 08:10:12,391 INFO org.apache.hadoop.yarn.server.resourcemanager.security.NMTokenSecretManagerInRM: Sending NMToken for nodeId : tutrung-slave2:37119 for container : container_1615219634569_0001_01_000001
2021-03-08 08:10:12,397 INFO org.apache.hadoop.yarn.server.resourcemanager.rmcontainer.RMContainerImpl: container_1615219634569_0001_01_000001 Container Transitioned from ALLOCATED to ACQUIRED
2021-03-08 08:10:12,397 INFO org.apache.hadoop.yarn.server.resourcemanager.security.NMTokenSecretManagerInRM: Clear node set for appattempt_1615219634569_0001_000001
2021-03-08 08:10:12,398 INFO org.apache.hadoop.yarn.server.resourcemanager.rmapp.attempt.RMAppAttemptImpl: Storing attempt: AppId: application_1615219634569_0001 AttemptId: appattempt_1615219634569_0001_000001 MasterContainer: Container: [ContainerId: container_1615219634569_0001_01_000001, NodeId: tutrung-slave2:37119, NodeHttpAddress: tutrung-slave2:8042, Resource: <memory:2048, vCores:1>, Priority: 0, Token: Token { kind: ContainerToken, service: 192.168.244.132:37119 }, ]
2021-03-08 08:10:12,405 INFO org.apache.hadoop.yarn.server.resourcemanager.rmapp.attempt.RMAppAttemptImpl: appattempt_1615219634569_0001_000001 State change from SCHEDULED to ALLOCATED_SAVING
2021-03-08 08:10:12,407 INFO org.apache.hadoop.yarn.server.resourcemanager.rmapp.attempt.RMAppAttemptImpl: appattempt_1615219634569_0001_000001 State change from ALLOCATED_SAVING to ALLOCATED
2021-03-08 08:10:12,409 INFO org.apache.hadoop.yarn.server.resourcemanager.amlauncher.AMLauncher: Launching masterappattempt_1615219634569_0001_000001
2021-03-08 08:10:12,432 INFO org.apache.hadoop.yarn.server.resourcemanager.amlauncher.AMLauncher: Setting up container Container: [ContainerId: container_1615219634569_0001_01_000001, NodeId: tutrung-slave2:37119, NodeHttpAddress: tutrung-slave2:8042, Resource: <memory:2048, vCores:1>, Priority: 0, Token: Token { kind: ContainerToken, service: 192.168.244.132:37119 }, ] for AM appattempt_1615219634569_0001_000001
2021-03-08 08:10:12,432 INFO org.apache.hadoop.yarn.server.resourcemanager.amlauncher.AMLauncher: Command to launch container container_1615219634569_0001_01_000001 : $JAVA_HOME/bin/java -Djava.io.tmpdir=$PWD/tmp -Dlog4j.configuration=container-log4j.properties -Dyarn.app.container.log.dir=<LOG_DIR> -Dyarn.app.container.log.filesize=0 -Dhadoop.root.logger=INFO,CLA -Dhadoop.root.logfile=syslog  -Xmx1024m org.apache.hadoop.mapreduce.v2.app.MRAppMaster 1><LOG_DIR>/stdout 2><LOG_DIR>/stderr 
2021-03-08 08:10:12,435 INFO org.apache.hadoop.yarn.server.resourcemanager.security.AMRMTokenSecretManager: Create AMRMToken for ApplicationAttempt: appattempt_1615219634569_0001_000001
2021-03-08 08:10:12,437 INFO org.apache.hadoop.yarn.server.resourcemanager.security.AMRMTokenSecretManager: Creating password for appattempt_1615219634569_0001_000001
2021-03-08 08:10:13,105 INFO org.apache.hadoop.yarn.server.resourcemanager.amlauncher.AMLauncher: Done launching container Container: [ContainerId: container_1615219634569_0001_01_000001, NodeId: tutrung-slave2:37119, NodeHttpAddress: tutrung-slave2:8042, Resource: <memory:2048, vCores:1>, Priority: 0, Token: Token { kind: ContainerToken, service: 192.168.244.132:37119 }, ] for AM appattempt_1615219634569_0001_000001
2021-03-08 08:10:13,105 INFO org.apache.hadoop.yarn.server.resourcemanager.rmapp.attempt.RMAppAttemptImpl: appattempt_1615219634569_0001_000001 State change from ALLOCATED to LAUNCHED
2021-03-08 08:10:13,414 INFO org.apache.hadoop.yarn.server.resourcemanager.rmcontainer.RMContainerImpl: container_1615219634569_0001_01_000001 Container Transitioned from ACQUIRED to RUNNING
2021-03-08 08:10:20,414 INFO SecurityLogger.org.apache.hadoop.ipc.Server: Auth successful for appattempt_1615219634569_0001_000001 (auth:SIMPLE)
2021-03-08 08:10:20,418 INFO org.apache.hadoop.yarn.server.resourcemanager.ApplicationMasterService: AM registration appattempt_1615219634569_0001_000001
2021-03-08 08:10:20,419 INFO org.apache.hadoop.yarn.server.resourcemanager.RMAuditLogger: USER=hadoopuser	IP=192.168.244.132	OPERATION=Register App Master	TARGET=ApplicationMasterService	RESULT=SUCCESS	APPID=application_1615219634569_0001	APPATTEMPTID=appattempt_1615219634569_0001_000001
2021-03-08 08:10:20,419 INFO org.apache.hadoop.yarn.server.resourcemanager.rmapp.attempt.RMAppAttemptImpl: appattempt_1615219634569_0001_000001 State change from LAUNCHED to RUNNING
2021-03-08 08:10:20,419 INFO org.apache.hadoop.yarn.server.resourcemanager.rmapp.RMAppImpl: application_1615219634569_0001 State change from ACCEPTED to RUNNING on event=ATTEMPT_REGISTERED
2021-03-08 08:10:21,578 INFO org.apache.hadoop.yarn.server.resourcemanager.rmcontainer.RMContainerImpl: container_1615219634569_0001_01_000002 Container Transitioned from NEW to ALLOCATED
2021-03-08 08:10:21,578 INFO org.apache.hadoop.yarn.server.resourcemanager.RMAuditLogger: USER=hadoopuser	OPERATION=AM Allocated Container	TARGET=SchedulerApp	RESULT=SUCCESS	APPID=application_1615219634569_0001	CONTAINERID=container_1615219634569_0001_01_000002
2021-03-08 08:10:21,578 INFO org.apache.hadoop.yarn.server.resourcemanager.scheduler.SchedulerNode: Assigned container container_1615219634569_0001_01_000002 of capacity <memory:1024, vCores:1> on host tutrung-slave1:37241, which has 1 containers, <memory:1024, vCores:1> used and <memory:7168, vCores:7> available after allocation
2021-03-08 08:10:21,578 INFO org.apache.hadoop.yarn.server.resourcemanager.scheduler.capacity.LeafQueue: assignedContainer application attempt=appattempt_1615219634569_0001_000001 container=Container: [ContainerId: container_1615219634569_0001_01_000002, NodeId: tutrung-slave1:37241, NodeHttpAddress: tutrung-slave1:8042, Resource: <memory:1024, vCores:1>, Priority: 20, Token: null, ] queue=default: capacity=1.0, absoluteCapacity=1.0, usedResources=<memory:2048, vCores:1>, usedCapacity=0.125, absoluteUsedCapacity=0.125, numApps=1, numContainers=1 clusterResource=<memory:16384, vCores:16> type=NODE_LOCAL requestedPartition=
2021-03-08 08:10:21,578 INFO org.apache.hadoop.yarn.server.resourcemanager.scheduler.capacity.ParentQueue: Re-sorting assigned queue: root.default stats: default: capacity=1.0, absoluteCapacity=1.0, usedResources=<memory:3072, vCores:2>, usedCapacity=0.1875, absoluteUsedCapacity=0.1875, numApps=1, numContainers=2
2021-03-08 08:10:21,578 INFO org.apache.hadoop.yarn.server.resourcemanager.scheduler.capacity.ParentQueue: assignedContainer queue=root usedCapacity=0.1875 absoluteUsedCapacity=0.1875 used=<memory:3072, vCores:2> cluster=<memory:16384, vCores:16>
2021-03-08 08:10:21,579 INFO org.apache.hadoop.yarn.server.resourcemanager.rmcontainer.RMContainerImpl: container_1615219634569_0001_01_000003 Container Transitioned from NEW to ALLOCATED
2021-03-08 08:10:21,579 INFO org.apache.hadoop.yarn.server.resourcemanager.RMAuditLogger: USER=hadoopuser	OPERATION=AM Allocated Container	TARGET=SchedulerApp	RESULT=SUCCESS	APPID=application_1615219634569_0001	CONTAINERID=container_1615219634569_0001_01_000003
2021-03-08 08:10:21,579 INFO org.apache.hadoop.yarn.server.resourcemanager.scheduler.SchedulerNode: Assigned container container_1615219634569_0001_01_000003 of capacity <memory:1024, vCores:1> on host tutrung-slave1:37241, which has 2 containers, <memory:2048, vCores:2> used and <memory:6144, vCores:6> available after allocation
2021-03-08 08:10:21,579 INFO org.apache.hadoop.yarn.server.resourcemanager.scheduler.capacity.LeafQueue: assignedContainer application attempt=appattempt_1615219634569_0001_000001 container=Container: [ContainerId: container_1615219634569_0001_01_000003, NodeId: tutrung-slave1:37241, NodeHttpAddress: tutrung-slave1:8042, Resource: <memory:1024, vCores:1>, Priority: 20, Token: null, ] queue=default: capacity=1.0, absoluteCapacity=1.0, usedResources=<memory:3072, vCores:2>, usedCapacity=0.1875, absoluteUsedCapacity=0.1875, numApps=1, numContainers=2 clusterResource=<memory:16384, vCores:16> type=NODE_LOCAL requestedPartition=
2021-03-08 08:10:21,579 INFO org.apache.hadoop.yarn.server.resourcemanager.scheduler.capacity.ParentQueue: Re-sorting assigned queue: root.default stats: default: capacity=1.0, absoluteCapacity=1.0, usedResources=<memory:4096, vCores:3>, usedCapacity=0.25, absoluteUsedCapacity=0.25, numApps=1, numContainers=3
2021-03-08 08:10:21,579 INFO org.apache.hadoop.yarn.server.resourcemanager.scheduler.capacity.ParentQueue: assignedContainer queue=root usedCapacity=0.25 absoluteUsedCapacity=0.25 used=<memory:4096, vCores:3> cluster=<memory:16384, vCores:16>
2021-03-08 08:10:22,525 INFO org.apache.hadoop.yarn.server.resourcemanager.security.NMTokenSecretManagerInRM: Sending NMToken for nodeId : tutrung-slave1:37241 for container : container_1615219634569_0001_01_000002
2021-03-08 08:10:22,527 INFO org.apache.hadoop.yarn.server.resourcemanager.rmcontainer.RMContainerImpl: container_1615219634569_0001_01_000002 Container Transitioned from ALLOCATED to ACQUIRED
2021-03-08 08:10:22,532 INFO org.apache.hadoop.yarn.server.resourcemanager.rmcontainer.RMContainerImpl: container_1615219634569_0001_01_000003 Container Transitioned from ALLOCATED to ACQUIRED
2021-03-08 08:10:23,575 INFO org.apache.hadoop.yarn.server.resourcemanager.scheduler.AppSchedulingInfo: checking for deactivate of application :application_1615219634569_0001
2021-03-08 08:10:23,650 INFO org.apache.hadoop.yarn.server.resourcemanager.rmcontainer.RMContainerImpl: container_1615219634569_0001_01_000002 Container Transitioned from ACQUIRED to RUNNING
2021-03-08 08:10:23,650 INFO org.apache.hadoop.yarn.server.resourcemanager.rmcontainer.RMContainerImpl: container_1615219634569_0001_01_000003 Container Transitioned from ACQUIRED to RUNNING
2021-03-08 08:10:35,557 INFO org.apache.hadoop.yarn.server.resourcemanager.rmcontainer.RMContainerImpl: container_1615219634569_0001_01_000003 Container Transitioned from RUNNING to COMPLETED
2021-03-08 08:10:35,557 INFO org.apache.hadoop.yarn.server.resourcemanager.scheduler.common.fica.FiCaSchedulerApp: Completed container: container_1615219634569_0001_01_000003 in state: COMPLETED event:FINISHED
2021-03-08 08:10:35,557 INFO org.apache.hadoop.yarn.server.resourcemanager.RMAuditLogger: USER=hadoopuser	OPERATION=AM Released Container	TARGET=SchedulerApp	RESULT=SUCCESS	APPID=application_1615219634569_0001	CONTAINERID=container_1615219634569_0001_01_000003
2021-03-08 08:10:35,557 INFO org.apache.hadoop.yarn.server.resourcemanager.scheduler.SchedulerNode: Released container container_1615219634569_0001_01_000003 of capacity <memory:1024, vCores:1> on host tutrung-slave1:37241, which currently has 1 containers, <memory:1024, vCores:1> used and <memory:7168, vCores:7> available, release resources=true
2021-03-08 08:10:35,557 INFO org.apache.hadoop.yarn.server.resourcemanager.scheduler.capacity.LeafQueue: default used=<memory:3072, vCores:2> numContainers=2 user=hadoopuser user-resources=<memory:3072, vCores:2>
2021-03-08 08:10:35,557 INFO org.apache.hadoop.yarn.server.resourcemanager.scheduler.capacity.LeafQueue: completedContainer container=Container: [ContainerId: container_1615219634569_0001_01_000003, NodeId: tutrung-slave1:37241, NodeHttpAddress: tutrung-slave1:8042, Resource: <memory:1024, vCores:1>, Priority: 20, Token: Token { kind: ContainerToken, service: 192.168.244.131:37241 }, ] queue=default: capacity=1.0, absoluteCapacity=1.0, usedResources=<memory:3072, vCores:2>, usedCapacity=0.1875, absoluteUsedCapacity=0.1875, numApps=1, numContainers=2 cluster=<memory:16384, vCores:16>
2021-03-08 08:10:35,557 INFO org.apache.hadoop.yarn.server.resourcemanager.scheduler.capacity.ParentQueue: completedContainer queue=root usedCapacity=0.1875 absoluteUsedCapacity=0.1875 used=<memory:3072, vCores:2> cluster=<memory:16384, vCores:16>
2021-03-08 08:10:35,557 INFO org.apache.hadoop.yarn.server.resourcemanager.scheduler.capacity.ParentQueue: Re-sorting completed queue: root.default stats: default: capacity=1.0, absoluteCapacity=1.0, usedResources=<memory:3072, vCores:2>, usedCapacity=0.1875, absoluteUsedCapacity=0.1875, numApps=1, numContainers=2
2021-03-08 08:10:35,557 INFO org.apache.hadoop.yarn.server.resourcemanager.scheduler.capacity.CapacityScheduler: Application attempt appattempt_1615219634569_0001_000001 released container container_1615219634569_0001_01_000003 on node: host: tutrung-slave1:37241 #containers=1 available=<memory:7168, vCores:7> used=<memory:1024, vCores:1> with event: FINISHED
2021-03-08 08:10:36,011 INFO org.apache.hadoop.yarn.server.resourcemanager.rmcontainer.RMContainerImpl: container_1615219634569_0001_01_000002 Container Transitioned from RUNNING to COMPLETED
2021-03-08 08:10:36,011 INFO org.apache.hadoop.yarn.server.resourcemanager.scheduler.common.fica.FiCaSchedulerApp: Completed container: container_1615219634569_0001_01_000002 in state: COMPLETED event:FINISHED
2021-03-08 08:10:36,011 INFO org.apache.hadoop.yarn.server.resourcemanager.RMAuditLogger: USER=hadoopuser	OPERATION=AM Released Container	TARGET=SchedulerApp	RESULT=SUCCESS	APPID=application_1615219634569_0001	CONTAINERID=container_1615219634569_0001_01_000002
2021-03-08 08:10:36,011 INFO org.apache.hadoop.yarn.server.resourcemanager.scheduler.SchedulerNode: Released container container_1615219634569_0001_01_000002 of capacity <memory:1024, vCores:1> on host tutrung-slave1:37241, which currently has 0 containers, <memory:0, vCores:0> used and <memory:8192, vCores:8> available, release resources=true
2021-03-08 08:10:36,011 INFO org.apache.hadoop.yarn.server.resourcemanager.scheduler.capacity.LeafQueue: default used=<memory:2048, vCores:1> numContainers=1 user=hadoopuser user-resources=<memory:2048, vCores:1>
2021-03-08 08:10:36,011 INFO org.apache.hadoop.yarn.server.resourcemanager.scheduler.capacity.LeafQueue: completedContainer container=Container: [ContainerId: container_1615219634569_0001_01_000002, NodeId: tutrung-slave1:37241, NodeHttpAddress: tutrung-slave1:8042, Resource: <memory:1024, vCores:1>, Priority: 20, Token: Token { kind: ContainerToken, service: 192.168.244.131:37241 }, ] queue=default: capacity=1.0, absoluteCapacity=1.0, usedResources=<memory:2048, vCores:1>, usedCapacity=0.125, absoluteUsedCapacity=0.125, numApps=1, numContainers=1 cluster=<memory:16384, vCores:16>
2021-03-08 08:10:36,011 INFO org.apache.hadoop.yarn.server.resourcemanager.scheduler.capacity.ParentQueue: completedContainer queue=root usedCapacity=0.125 absoluteUsedCapacity=0.125 used=<memory:2048, vCores:1> cluster=<memory:16384, vCores:16>
2021-03-08 08:10:36,011 INFO org.apache.hadoop.yarn.server.resourcemanager.scheduler.capacity.ParentQueue: Re-sorting completed queue: root.default stats: default: capacity=1.0, absoluteCapacity=1.0, usedResources=<memory:2048, vCores:1>, usedCapacity=0.125, absoluteUsedCapacity=0.125, numApps=1, numContainers=1
2021-03-08 08:10:36,011 INFO org.apache.hadoop.yarn.server.resourcemanager.scheduler.capacity.CapacityScheduler: Application attempt appattempt_1615219634569_0001_000001 released container container_1615219634569_0001_01_000002 on node: host: tutrung-slave1:37241 #containers=0 available=<memory:8192, vCores:8> used=<memory:0, vCores:0> with event: FINISHED
2021-03-08 08:10:37,014 INFO org.apache.hadoop.yarn.server.resourcemanager.rmcontainer.RMContainerImpl: container_1615219634569_0001_01_000004 Container Transitioned from NEW to ALLOCATED
2021-03-08 08:10:37,014 INFO org.apache.hadoop.yarn.server.resourcemanager.RMAuditLogger: USER=hadoopuser	OPERATION=AM Allocated Container	TARGET=SchedulerApp	RESULT=SUCCESS	APPID=application_1615219634569_0001	CONTAINERID=container_1615219634569_0001_01_000004
2021-03-08 08:10:37,016 INFO org.apache.hadoop.yarn.server.resourcemanager.scheduler.SchedulerNode: Assigned container container_1615219634569_0001_01_000004 of capacity <memory:1024, vCores:1> on host tutrung-slave1:37241, which has 1 containers, <memory:1024, vCores:1> used and <memory:7168, vCores:7> available after allocation
2021-03-08 08:10:37,016 INFO org.apache.hadoop.yarn.server.resourcemanager.scheduler.capacity.LeafQueue: assignedContainer application attempt=appattempt_1615219634569_0001_000001 container=Container: [ContainerId: container_1615219634569_0001_01_000004, NodeId: tutrung-slave1:37241, NodeHttpAddress: tutrung-slave1:8042, Resource: <memory:1024, vCores:1>, Priority: 10, Token: null, ] queue=default: capacity=1.0, absoluteCapacity=1.0, usedResources=<memory:2048, vCores:1>, usedCapacity=0.125, absoluteUsedCapacity=0.125, numApps=1, numContainers=1 clusterResource=<memory:16384, vCores:16> type=OFF_SWITCH requestedPartition=
2021-03-08 08:10:37,016 INFO org.apache.hadoop.yarn.server.resourcemanager.scheduler.capacity.ParentQueue: Re-sorting assigned queue: root.default stats: default: capacity=1.0, absoluteCapacity=1.0, usedResources=<memory:3072, vCores:2>, usedCapacity=0.1875, absoluteUsedCapacity=0.1875, numApps=1, numContainers=2
2021-03-08 08:10:37,016 INFO org.apache.hadoop.yarn.server.resourcemanager.scheduler.capacity.ParentQueue: assignedContainer queue=root usedCapacity=0.1875 absoluteUsedCapacity=0.1875 used=<memory:3072, vCores:2> cluster=<memory:16384, vCores:16>
2021-03-08 08:10:37,676 INFO org.apache.hadoop.yarn.server.resourcemanager.rmcontainer.RMContainerImpl: container_1615219634569_0001_01_000004 Container Transitioned from ALLOCATED to ACQUIRED
2021-03-08 08:10:38,018 INFO org.apache.hadoop.yarn.server.resourcemanager.rmcontainer.RMContainerImpl: container_1615219634569_0001_01_000004 Container Transitioned from ACQUIRED to RUNNING
2021-03-08 08:10:38,679 INFO org.apache.hadoop.yarn.server.resourcemanager.scheduler.AppSchedulingInfo: checking for deactivate of application :application_1615219634569_0001
2021-03-08 08:10:40,007 INFO org.apache.hadoop.yarn.server.resourcemanager.rmcontainer.RMContainerImpl: container_1615219634569_0001_01_000004 Container Transitioned from RUNNING to COMPLETED
2021-03-08 08:10:40,007 INFO org.apache.hadoop.yarn.server.resourcemanager.scheduler.common.fica.FiCaSchedulerApp: Completed container: container_1615219634569_0001_01_000004 in state: COMPLETED event:FINISHED
2021-03-08 08:10:40,007 INFO org.apache.hadoop.yarn.server.resourcemanager.RMAuditLogger: USER=hadoopuser	OPERATION=AM Released Container	TARGET=SchedulerApp	RESULT=SUCCESS	APPID=application_1615219634569_0001	CONTAINERID=container_1615219634569_0001_01_000004
2021-03-08 08:10:40,007 INFO org.apache.hadoop.yarn.server.resourcemanager.scheduler.SchedulerNode: Released container container_1615219634569_0001_01_000004 of capacity <memory:1024, vCores:1> on host tutrung-slave1:37241, which currently has 0 containers, <memory:0, vCores:0> used and <memory:8192, vCores:8> available, release resources=true
2021-03-08 08:10:40,007 INFO org.apache.hadoop.yarn.server.resourcemanager.scheduler.capacity.LeafQueue: default used=<memory:2048, vCores:1> numContainers=1 user=hadoopuser user-resources=<memory:2048, vCores:1>
2021-03-08 08:10:40,007 INFO org.apache.hadoop.yarn.server.resourcemanager.scheduler.capacity.LeafQueue: completedContainer container=Container: [ContainerId: container_1615219634569_0001_01_000004, NodeId: tutrung-slave1:37241, NodeHttpAddress: tutrung-slave1:8042, Resource: <memory:1024, vCores:1>, Priority: 10, Token: Token { kind: ContainerToken, service: 192.168.244.131:37241 }, ] queue=default: capacity=1.0, absoluteCapacity=1.0, usedResources=<memory:2048, vCores:1>, usedCapacity=0.125, absoluteUsedCapacity=0.125, numApps=1, numContainers=1 cluster=<memory:16384, vCores:16>
2021-03-08 08:10:40,007 INFO org.apache.hadoop.yarn.server.resourcemanager.scheduler.capacity.ParentQueue: completedContainer queue=root usedCapacity=0.125 absoluteUsedCapacity=0.125 used=<memory:2048, vCores:1> cluster=<memory:16384, vCores:16>
2021-03-08 08:10:40,007 INFO org.apache.hadoop.yarn.server.resourcemanager.scheduler.capacity.ParentQueue: Re-sorting completed queue: root.default stats: default: capacity=1.0, absoluteCapacity=1.0, usedResources=<memory:2048, vCores:1>, usedCapacity=0.125, absoluteUsedCapacity=0.125, numApps=1, numContainers=1
2021-03-08 08:10:40,007 INFO org.apache.hadoop.yarn.server.resourcemanager.scheduler.capacity.CapacityScheduler: Application attempt appattempt_1615219634569_0001_000001 released container container_1615219634569_0001_01_000004 on node: host: tutrung-slave1:37241 #containers=0 available=<memory:8192, vCores:8> used=<memory:0, vCores:0> with event: FINISHED
2021-03-08 08:10:40,216 INFO org.apache.hadoop.yarn.server.resourcemanager.rmapp.attempt.RMAppAttemptImpl: Updating application attempt appattempt_1615219634569_0001_000001 with final state: FINISHING, and exit status: -1000
2021-03-08 08:10:40,216 INFO org.apache.hadoop.yarn.server.resourcemanager.rmapp.attempt.RMAppAttemptImpl: appattempt_1615219634569_0001_000001 State change from RUNNING to FINAL_SAVING
2021-03-08 08:10:40,216 INFO org.apache.hadoop.yarn.server.resourcemanager.rmapp.attempt.RMAppAttemptImpl: appattempt_1615219634569_0001_000001 State change from FINAL_SAVING to FINISHING
2021-03-08 08:10:40,216 INFO org.apache.hadoop.yarn.server.resourcemanager.rmapp.RMAppImpl: Updating application application_1615219634569_0001 with final state: FINISHING
2021-03-08 08:10:40,217 INFO org.apache.hadoop.yarn.server.resourcemanager.rmapp.RMAppImpl: application_1615219634569_0001 State change from RUNNING to FINAL_SAVING on event=ATTEMPT_UNREGISTERED
2021-03-08 08:10:40,217 INFO org.apache.hadoop.yarn.server.resourcemanager.recovery.RMStateStore: Updating info for app: application_1615219634569_0001
2021-03-08 08:10:40,217 INFO org.apache.hadoop.yarn.server.resourcemanager.rmapp.RMAppImpl: application_1615219634569_0001 State change from FINAL_SAVING to FINISHING on event=APP_UPDATE_SAVED
2021-03-08 08:10:41,230 INFO org.apache.hadoop.yarn.server.resourcemanager.ApplicationMasterService: application_1615219634569_0001 unregistered successfully. 
2021-03-08 08:10:46,841 INFO org.apache.hadoop.yarn.server.resourcemanager.rmcontainer.RMContainerImpl: container_1615219634569_0001_01_000001 Container Transitioned from RUNNING to COMPLETED
2021-03-08 08:10:46,842 INFO org.apache.hadoop.yarn.server.resourcemanager.scheduler.common.fica.FiCaSchedulerApp: Completed container: container_1615219634569_0001_01_000001 in state: COMPLETED event:FINISHED
2021-03-08 08:10:46,842 INFO org.apache.hadoop.yarn.server.resourcemanager.RMAuditLogger: USER=hadoopuser	OPERATION=AM Released Container	TARGET=SchedulerApp	RESULT=SUCCESS	APPID=application_1615219634569_0001	CONTAINERID=container_1615219634569_0001_01_000001
2021-03-08 08:10:46,842 INFO org.apache.hadoop.yarn.server.resourcemanager.scheduler.SchedulerNode: Released container container_1615219634569_0001_01_000001 of capacity <memory:2048, vCores:1> on host tutrung-slave2:37119, which currently has 0 containers, <memory:0, vCores:0> used and <memory:8192, vCores:8> available, release resources=true
2021-03-08 08:10:46,842 INFO org.apache.hadoop.yarn.server.resourcemanager.scheduler.capacity.LeafQueue: default used=<memory:0, vCores:0> numContainers=0 user=hadoopuser user-resources=<memory:0, vCores:0>
2021-03-08 08:10:46,842 INFO org.apache.hadoop.yarn.server.resourcemanager.scheduler.capacity.LeafQueue: completedContainer container=Container: [ContainerId: container_1615219634569_0001_01_000001, NodeId: tutrung-slave2:37119, NodeHttpAddress: tutrung-slave2:8042, Resource: <memory:2048, vCores:1>, Priority: 0, Token: Token { kind: ContainerToken, service: 192.168.244.132:37119 }, ] queue=default: capacity=1.0, absoluteCapacity=1.0, usedResources=<memory:0, vCores:0>, usedCapacity=0.0, absoluteUsedCapacity=0.0, numApps=1, numContainers=0 cluster=<memory:16384, vCores:16>
2021-03-08 08:10:46,842 INFO org.apache.hadoop.yarn.server.resourcemanager.scheduler.capacity.ParentQueue: completedContainer queue=root usedCapacity=0.0 absoluteUsedCapacity=0.0 used=<memory:0, vCores:0> cluster=<memory:16384, vCores:16>
2021-03-08 08:10:46,842 INFO org.apache.hadoop.yarn.server.resourcemanager.scheduler.capacity.ParentQueue: Re-sorting completed queue: root.default stats: default: capacity=1.0, absoluteCapacity=1.0, usedResources=<memory:0, vCores:0>, usedCapacity=0.0, absoluteUsedCapacity=0.0, numApps=1, numContainers=0
2021-03-08 08:10:46,842 INFO org.apache.hadoop.yarn.server.resourcemanager.scheduler.capacity.CapacityScheduler: Application attempt appattempt_1615219634569_0001_000001 released container container_1615219634569_0001_01_000001 on node: host: tutrung-slave2:37119 #containers=0 available=<memory:8192, vCores:8> used=<memory:0, vCores:0> with event: FINISHED
2021-03-08 08:10:46,842 INFO org.apache.hadoop.yarn.server.resourcemanager.ApplicationMasterService: Unregistering app attempt : appattempt_1615219634569_0001_000001
2021-03-08 08:10:46,842 INFO org.apache.hadoop.yarn.server.resourcemanager.security.AMRMTokenSecretManager: Application finished, removing password for appattempt_1615219634569_0001_000001
2021-03-08 08:10:46,842 INFO org.apache.hadoop.yarn.server.resourcemanager.rmapp.attempt.RMAppAttemptImpl: appattempt_1615219634569_0001_000001 State change from FINISHING to FINISHED
2021-03-08 08:10:46,843 INFO org.apache.hadoop.yarn.server.resourcemanager.rmapp.RMAppImpl: application_1615219634569_0001 State change from FINISHING to FINISHED on event=ATTEMPT_FINISHED
2021-03-08 08:10:46,843 INFO org.apache.hadoop.yarn.server.resourcemanager.RMAuditLogger: USER=hadoopuser	OPERATION=Application Finished - Succeeded	TARGET=RMAppManager	RESULT=SUCCESS	APPID=application_1615219634569_0001
2021-03-08 08:10:46,843 INFO org.apache.hadoop.yarn.server.resourcemanager.amlauncher.AMLauncher: Cleaning master appattempt_1615219634569_0001_000001
2021-03-08 08:10:46,844 INFO org.apache.hadoop.yarn.server.resourcemanager.RMAppManager$ApplicationSummary: appId=application_1615219634569_0001,name=word count,user=hadoopuser,queue=default,state=FINISHED,trackingUrl=http://master:8088/proxy/application_1615219634569_0001/,appMasterHost=tutrung-slave2,startTime=1615219811783,finishTime=1615219840216,finalStatus=SUCCEEDED,memorySeconds=102729,vcoreSeconds=63,preemptedAMContainers=0,preemptedNonAMContainers=0,preemptedResources=<memory:0\, vCores:0>,applicationType=MAPREDUCE
2021-03-08 08:10:46,844 INFO org.apache.hadoop.yarn.server.resourcemanager.scheduler.capacity.CapacityScheduler: Application Attempt appattempt_1615219634569_0001_000001 is done. finalState=FINISHED
2021-03-08 08:10:46,844 INFO org.apache.hadoop.yarn.server.resourcemanager.scheduler.AppSchedulingInfo: Application application_1615219634569_0001 requests cleared
2021-03-08 08:10:46,844 INFO org.apache.hadoop.yarn.server.resourcemanager.scheduler.capacity.LeafQueue: Application removed - appId: application_1615219634569_0001 user: hadoopuser queue: default #user-pending-applications: 0 #user-active-applications: 0 #queue-pending-applications: 0 #queue-active-applications: 0
2021-03-08 08:10:46,845 INFO org.apache.hadoop.yarn.server.resourcemanager.scheduler.capacity.ParentQueue: Application removed - appId: application_1615219634569_0001 user: hadoopuser leaf-queue of parent: root #applications: 0
2021-03-08 08:10:48,029 INFO org.apache.hadoop.yarn.server.resourcemanager.scheduler.capacity.CapacityScheduler: Null container completed...
                                                                                                                                                                                                                                                                                                                                                                                                                                                                                                                                                                                                                                                                                                                                                                                                                                                                                                                                                                                                                                                                                                                                                                                                                                                                                                                                                                                                                                                                                   2021-03-09 21:38:58,237 INFO org.apache.hadoop.yarn.server.resourcemanager.ResourceManager: STARTUP_MSG: 
/************************************************************
STARTUP_MSG: Starting ResourceManager
STARTUP_MSG:   host = master/192.168.244.130
STARTUP_MSG:   args = []
STARTUP_MSG:   version = 2.7.7
STARTUP_MSG:   build = Unknown -r c1aad84bd27cd79c3d1a7dd58202a8c3ee1ed3ac; compiled by 'stevel' on 2018-07-18T22:47Z
STARTUP_MSG:   java = 15.0.2
************************************************************/
2021-03-09 21:38:58,242 INFO org.apache.hadoop.yarn.server.resourcemanager.ResourceManager: registered UNIX signal handlers for [TERM, HUP, INT]
2021-03-09 21:38:58,637 INFO org.apache.hadoop.conf.Configuration: found resource core-site.xml at file:/home/hadoopuser/hadoop/etc/hadoop/core-site.xml
2021-03-09 21:38:58,731 WARN org.apache.hadoop.util.NativeCodeLoader: Unable to load native-hadoop library for your platform... using builtin-java classes where applicable
2021-03-09 21:38:58,745 INFO org.apache.hadoop.security.Groups: clearing userToGroupsMap cache
2021-03-09 21:38:58,871 INFO org.apache.hadoop.conf.Configuration: found resource yarn-site.xml at file:/home/hadoopuser/hadoop/etc/hadoop/yarn-site.xml
2021-03-09 21:38:59,026 INFO org.apache.hadoop.yarn.event.AsyncDispatcher: Registering class org.apache.hadoop.yarn.server.resourcemanager.RMFatalEventType for class org.apache.hadoop.yarn.server.resourcemanager.ResourceManager$RMFatalEventDispatcher
2021-03-09 21:38:59,093 INFO org.apache.hadoop.yarn.server.resourcemanager.security.NMTokenSecretManagerInRM: NMTokenKeyRollingInterval: 86400000ms and NMTokenKeyActivationDelay: 900000ms
2021-03-09 21:38:59,103 INFO org.apache.hadoop.yarn.server.resourcemanager.security.RMContainerTokenSecretManager: ContainerTokenKeyRollingInterval: 86400000ms and ContainerTokenKeyActivationDelay: 900000ms
2021-03-09 21:38:59,107 INFO org.apache.hadoop.yarn.server.resourcemanager.security.AMRMTokenSecretManager: AMRMTokenKeyRollingInterval: 86400000ms and AMRMTokenKeyActivationDelay: 900000 ms
2021-03-09 21:38:59,158 INFO org.apache.hadoop.yarn.event.AsyncDispatcher: Registering class org.apache.hadoop.yarn.server.resourcemanager.recovery.RMStateStoreEventType for class org.apache.hadoop.yarn.server.resourcemanager.recovery.RMStateStore$ForwardingEventHandler
2021-03-09 21:38:59,162 INFO org.apache.hadoop.yarn.event.AsyncDispatcher: Registering class org.apache.hadoop.yarn.server.resourcemanager.NodesListManagerEventType for class org.apache.hadoop.yarn.server.resourcemanager.NodesListManager
2021-03-09 21:38:59,162 INFO org.apache.hadoop.yarn.server.resourcemanager.ResourceManager: Using Scheduler: org.apache.hadoop.yarn.server.resourcemanager.scheduler.capacity.CapacityScheduler
2021-03-09 21:38:59,202 INFO org.apache.hadoop.yarn.event.AsyncDispatcher: Registering class org.apache.hadoop.yarn.server.resourcemanager.scheduler.event.SchedulerEventType for class org.apache.hadoop.yarn.server.resourcemanager.ResourceManager$SchedulerEventDispatcher
2021-03-09 21:38:59,203 INFO org.apache.hadoop.yarn.event.AsyncDispatcher: Registering class org.apache.hadoop.yarn.server.resourcemanager.rmapp.RMAppEventType for class org.apache.hadoop.yarn.server.resourcemanager.ResourceManager$ApplicationEventDispatcher
2021-03-09 21:38:59,208 INFO org.apache.hadoop.yarn.event.AsyncDispatcher: Registering class org.apache.hadoop.yarn.server.resourcemanager.rmapp.attempt.RMAppAttemptEventType for class org.apache.hadoop.yarn.server.resourcemanager.ResourceManager$ApplicationAttemptEventDispatcher
2021-03-09 21:38:59,214 INFO org.apache.hadoop.yarn.event.AsyncDispatcher: Registering class org.apache.hadoop.yarn.server.resourcemanager.rmnode.RMNodeEventType for class org.apache.hadoop.yarn.server.resourcemanager.ResourceManager$NodeEventDispatcher
2021-03-09 21:38:59,321 INFO org.apache.hadoop.metrics2.impl.MetricsConfig: loaded properties from hadoop-metrics2.properties
2021-03-09 21:38:59,584 INFO org.apache.hadoop.metrics2.impl.MetricsSystemImpl: Scheduled snapshot period at 10 second(s).
2021-03-09 21:38:59,584 INFO org.apache.hadoop.metrics2.impl.MetricsSystemImpl: ResourceManager metrics system started
2021-03-09 21:38:59,669 INFO org.apache.hadoop.yarn.event.AsyncDispatcher: Registering class org.apache.hadoop.yarn.server.resourcemanager.RMAppManagerEventType for class org.apache.hadoop.yarn.server.resourcemanager.RMAppManager
2021-03-09 21:38:59,696 INFO org.apache.hadoop.yarn.event.AsyncDispatcher: Registering class org.apache.hadoop.yarn.server.resourcemanager.amlauncher.AMLauncherEventType for class org.apache.hadoop.yarn.server.resourcemanager.amlauncher.ApplicationMasterLauncher
2021-03-09 21:38:59,705 INFO org.apache.hadoop.yarn.server.resourcemanager.RMNMInfo: Registered RMNMInfo MBean
2021-03-09 21:38:59,720 INFO org.apache.hadoop.yarn.security.YarnAuthorizationProvider: org.apache.hadoop.yarn.security.ConfiguredYarnAuthorizer is instiantiated.
2021-03-09 21:38:59,738 INFO org.apache.hadoop.util.HostsFileReader: Refreshing hosts (include/exclude) list
2021-03-09 21:38:59,748 INFO org.apache.hadoop.conf.Configuration: found resource capacity-scheduler.xml at file:/home/hadoopuser/hadoop/etc/hadoop/capacity-scheduler.xml
2021-03-09 21:38:59,979 INFO org.apache.hadoop.yarn.server.resourcemanager.scheduler.capacity.CapacitySchedulerConfiguration: max alloc mb per queue for root is undefined
2021-03-09 21:38:59,979 INFO org.apache.hadoop.yarn.server.resourcemanager.scheduler.capacity.CapacitySchedulerConfiguration: max alloc vcore per queue for root is undefined
2021-03-09 21:38:59,985 INFO org.apache.hadoop.yarn.server.resourcemanager.scheduler.capacity.ParentQueue: root, capacity=1.0, asboluteCapacity=1.0, maxCapacity=1.0, asboluteMaxCapacity=1.0, state=RUNNING, acls=ADMINISTER_QUEUE:*SUBMIT_APP:*, labels=*,
, reservationsContinueLooking=true
2021-03-09 21:38:59,985 INFO org.apache.hadoop.yarn.server.resourcemanager.scheduler.capacity.ParentQueue: Initialized parent-queue root name=root, fullname=root
2021-03-09 21:38:59,995 INFO org.apache.hadoop.yarn.server.resourcemanager.scheduler.capacity.CapacitySchedulerConfiguration: max alloc mb per queue for root.default is undefined
2021-03-09 21:38:59,995 INFO org.apache.hadoop.yarn.server.resourcemanager.scheduler.capacity.CapacitySchedulerConfiguration: max alloc vcore per queue for root.default is undefined
2021-03-09 21:38:59,996 INFO org.apache.hadoop.yarn.server.resourcemanager.scheduler.capacity.LeafQueue: Initializing default
capacity = 1.0 [= (float) configuredCapacity / 100 ]
asboluteCapacity = 1.0 [= parentAbsoluteCapacity * capacity ]
maxCapacity = 1.0 [= configuredMaxCapacity ]
absoluteMaxCapacity = 1.0 [= 1.0 maximumCapacity undefined, (parentAbsoluteMaxCapacity * maximumCapacity) / 100 otherwise ]
userLimit = 100 [= configuredUserLimit ]
userLimitFactor = 1.0 [= configuredUserLimitFactor ]
maxApplications = 10000 [= configuredMaximumSystemApplicationsPerQueue or (int)(configuredMaximumSystemApplications * absoluteCapacity)]
maxApplicationsPerUser = 10000 [= (int)(maxApplications * (userLimit / 100.0f) * userLimitFactor) ]
usedCapacity = 0.0 [= usedResourcesMemory / (clusterResourceMemory * absoluteCapacity)]
absoluteUsedCapacity = 0.0 [= usedResourcesMemory / clusterResourceMemory]
maxAMResourcePerQueuePercent = 0.1 [= configuredMaximumAMResourcePercent ]
minimumAllocationFactor = 0.875 [= (float)(maximumAllocationMemory - minimumAllocationMemory) / maximumAllocationMemory ]
maximumAllocation = <memory:8192, vCores:32> [= configuredMaxAllocation ]
numContainers = 0 [= currentNumContainers ]
state = RUNNING [= configuredState ]
acls = ADMINISTER_QUEUE:*SUBMIT_APP:* [= configuredAcls ]
nodeLocalityDelay = 40
labels=*,
nodeLocalityDelay = 40
reservationsContinueLooking = true
preemptionDisabled = true

2021-03-09 21:38:59,997 INFO org.apache.hadoop.yarn.server.resourcemanager.scheduler.capacity.CapacityScheduler: Initialized queue: default: capacity=1.0, absoluteCapacity=1.0, usedResources=<memory:0, vCores:0>, usedCapacity=0.0, absoluteUsedCapacity=0.0, numApps=0, numContainers=0
2021-03-09 21:38:59,997 INFO org.apache.hadoop.yarn.server.resourcemanager.scheduler.capacity.CapacityScheduler: Initialized queue: root: numChildQueue= 1, capacity=1.0, absoluteCapacity=1.0, usedResources=<memory:0, vCores:0>usedCapacity=0.0, numApps=0, numContainers=0
2021-03-09 21:38:59,998 INFO org.apache.hadoop.yarn.server.resourcemanager.scheduler.capacity.CapacityScheduler: Initialized root queue root: numChildQueue= 1, capacity=1.0, absoluteCapacity=1.0, usedResources=<memory:0, vCores:0>usedCapacity=0.0, numApps=0, numContainers=0
2021-03-09 21:38:59,998 INFO org.apache.hadoop.yarn.server.resourcemanager.scheduler.capacity.CapacityScheduler: Initialized queue mappings, override: false
2021-03-09 21:38:59,998 INFO org.apache.hadoop.yarn.server.resourcemanager.scheduler.capacity.CapacityScheduler: Initialized CapacityScheduler with calculator=class org.apache.hadoop.yarn.util.resource.DefaultResourceCalculator, minimumAllocation=<<memory:1024, vCores:1>>, maximumAllocation=<<memory:8192, vCores:32>>, asynchronousScheduling=false, asyncScheduleInterval=5ms
2021-03-09 21:39:00,019 INFO org.apache.hadoop.yarn.server.resourcemanager.metrics.SystemMetricsPublisher: YARN system metrics publishing service is not enabled
2021-03-09 21:39:00,019 INFO org.apache.hadoop.yarn.server.resourcemanager.ResourceManager: Transitioning to active state
2021-03-09 21:39:00,047 INFO org.apache.hadoop.yarn.server.resourcemanager.recovery.RMStateStore: Updating AMRMToken
2021-03-09 21:39:00,047 INFO org.apache.hadoop.yarn.server.resourcemanager.security.RMContainerTokenSecretManager: Rolling master-key for container-tokens
2021-03-09 21:39:00,047 INFO org.apache.hadoop.yarn.server.resourcemanager.security.NMTokenSecretManagerInRM: Rolling master-key for nm-tokens
2021-03-09 21:39:00,048 INFO org.apache.hadoop.security.token.delegation.AbstractDelegationTokenSecretManager: Updating the current master key for generating delegation tokens
2021-03-09 21:39:00,048 INFO org.apache.hadoop.yarn.server.resourcemanager.security.RMDelegationTokenSecretManager: storing master key with keyID 1
2021-03-09 21:39:00,049 INFO org.apache.hadoop.yarn.server.resourcemanager.recovery.RMStateStore: Storing RMDTMasterKey.
2021-03-09 21:39:00,057 INFO org.apache.hadoop.security.token.delegation.AbstractDelegationTokenSecretManager: Starting expired delegation token remover thread, tokenRemoverScanInterval=60 min(s)
2021-03-09 21:39:00,057 INFO org.apache.hadoop.security.token.delegation.AbstractDelegationTokenSecretManager: Updating the current master key for generating delegation tokens
2021-03-09 21:39:00,057 INFO org.apache.hadoop.yarn.server.resourcemanager.security.RMDelegationTokenSecretManager: storing master key with keyID 2
2021-03-09 21:39:00,057 INFO org.apache.hadoop.yarn.server.resourcemanager.recovery.RMStateStore: Storing RMDTMasterKey.
2021-03-09 21:39:00,067 INFO org.apache.hadoop.yarn.event.AsyncDispatcher: Registering class org.apache.hadoop.yarn.nodelabels.event.NodeLabelsStoreEventType for class org.apache.hadoop.yarn.nodelabels.CommonNodeLabelsManager$ForwardingEventHandler
2021-03-09 21:39:00,138 INFO org.apache.hadoop.ipc.CallQueueManager: Using callQueue: class java.util.concurrent.LinkedBlockingQueue queueCapacity: 5000
2021-03-09 21:39:00,176 INFO org.apache.hadoop.ipc.Server: Starting Socket Reader #1 for port 8031
2021-03-09 21:39:00,486 INFO org.apache.hadoop.yarn.factories.impl.pb.RpcServerFactoryPBImpl: Adding protocol org.apache.hadoop.yarn.server.api.ResourceTrackerPB to the server
2021-03-09 21:39:00,488 INFO org.apache.hadoop.ipc.Server: IPC Server Responder: starting
2021-03-09 21:39:00,494 INFO org.apache.hadoop.ipc.Server: IPC Server listener on 8031: starting
2021-03-09 21:39:00,697 INFO org.apache.hadoop.ipc.CallQueueManager: Using callQueue: class java.util.concurrent.LinkedBlockingQueue queueCapacity: 5000
2021-03-09 21:39:00,716 INFO org.apache.hadoop.ipc.Server: Starting Socket Reader #1 for port 8030
2021-03-09 21:39:00,754 INFO org.apache.hadoop.yarn.factories.impl.pb.RpcServerFactoryPBImpl: Adding protocol org.apache.hadoop.yarn.api.ApplicationMasterProtocolPB to the server
2021-03-09 21:39:00,760 INFO org.apache.hadoop.ipc.Server: IPC Server Responder: starting
2021-03-09 21:39:00,761 INFO org.apache.hadoop.ipc.Server: IPC Server listener on 8030: starting
2021-03-09 21:39:01,066 INFO org.apache.hadoop.ipc.CallQueueManager: Using callQueue: class java.util.concurrent.LinkedBlockingQueue queueCapacity: 5000
2021-03-09 21:39:01,072 INFO org.apache.hadoop.ipc.Server: Starting Socket Reader #1 for port 8032
2021-03-09 21:39:01,086 INFO org.apache.hadoop.yarn.factories.impl.pb.RpcServerFactoryPBImpl: Adding protocol org.apache.hadoop.yarn.api.ApplicationClientProtocolPB to the server
2021-03-09 21:39:01,089 INFO org.apache.hadoop.ipc.Server: IPC Server Responder: starting
2021-03-09 21:39:01,091 INFO org.apache.hadoop.ipc.Server: IPC Server listener on 8032: starting
2021-03-09 21:39:01,156 INFO org.apache.hadoop.yarn.server.resourcemanager.ResourceManager: Transitioned to active state
2021-03-09 21:39:01,278 INFO org.mortbay.log: Logging to org.slf4j.impl.Log4jLoggerAdapter(org.mortbay.log) via org.mortbay.log.Slf4jLog
2021-03-09 21:39:01,289 INFO org.apache.hadoop.security.authentication.server.AuthenticationFilter: Unable to initialize FileSignerSecretProvider, falling back to use random secrets.
2021-03-09 21:39:01,298 INFO org.apache.hadoop.http.HttpRequestLog: Http request log for http.requests.resourcemanager is not defined
2021-03-09 21:39:01,313 INFO org.apache.hadoop.http.HttpServer2: Added global filter 'safety' (class=org.apache.hadoop.http.HttpServer2$QuotingInputFilter)
2021-03-09 21:39:01,319 INFO org.apache.hadoop.http.HttpServer2: Added filter RMAuthenticationFilter (class=org.apache.hadoop.yarn.server.security.http.RMAuthenticationFilter) to context cluster
2021-03-09 21:39:01,320 INFO org.apache.hadoop.http.HttpServer2: Added filter RMAuthenticationFilter (class=org.apache.hadoop.yarn.server.security.http.RMAuthenticationFilter) to context static
2021-03-09 21:39:01,320 INFO org.apache.hadoop.http.HttpServer2: Added filter RMAuthenticationFilter (class=org.apache.hadoop.yarn.server.security.http.RMAuthenticationFilter) to context logs
2021-03-09 21:39:01,321 INFO org.apache.hadoop.http.HttpServer2: Added filter static_user_filter (class=org.apache.hadoop.http.lib.StaticUserWebFilter$StaticUserFilter) to context cluster
2021-03-09 21:39:01,321 INFO org.apache.hadoop.http.HttpServer2: Added filter static_user_filter (class=org.apache.hadoop.http.lib.StaticUserWebFilter$StaticUserFilter) to context static
2021-03-09 21:39:01,321 INFO org.apache.hadoop.http.HttpServer2: Added filter static_user_filter (class=org.apache.hadoop.http.lib.StaticUserWebFilter$StaticUserFilter) to context logs
2021-03-09 21:39:01,328 INFO org.apache.hadoop.http.HttpServer2: adding path spec: /cluster/*
2021-03-09 21:39:01,328 INFO org.apache.hadoop.http.HttpServer2: adding path spec: /ws/*
2021-03-09 21:39:01,927 INFO org.apache.hadoop.yarn.webapp.WebApps: Registered webapp guice modules
2021-03-09 21:39:01,929 INFO org.apache.hadoop.http.HttpServer2: Jetty bound to port 8088
2021-03-09 21:39:01,930 INFO org.mortbay.log: jetty-6.1.26
2021-03-09 21:39:01,964 INFO org.mortbay.log: Extract jar:file:/home/hadoopuser/hadoop/share/hadoop/yarn/hadoop-yarn-common-2.7.7.jar!/webapps/cluster to /tmp/Jetty_master_8088_cluster____i4ls4w/webapp
2021-03-09 21:39:02,154 INFO org.apache.hadoop.security.token.delegation.AbstractDelegationTokenSecretManager: Updating the current master key for generating delegation tokens
2021-03-09 21:39:02,184 INFO org.apache.hadoop.security.token.delegation.AbstractDelegationTokenSecretManager: Starting expired delegation token remover thread, tokenRemoverScanInterval=60 min(s)
2021-03-09 21:39:02,184 INFO org.apache.hadoop.security.token.delegation.AbstractDelegationTokenSecretManager: Updating the current master key for generating delegation tokens
2021-03-09 21:39:04,027 INFO org.mortbay.log: Started HttpServer2$SelectChannelConnectorWithSafeStartup@master:8088
2021-03-09 21:39:04,028 INFO org.apache.hadoop.yarn.webapp.WebApps: Web app cluster started at 8088
2021-03-09 21:39:04,073 INFO org.apache.hadoop.ipc.CallQueueManager: Using callQueue: class java.util.concurrent.LinkedBlockingQueue queueCapacity: 100
2021-03-09 21:39:04,079 INFO org.apache.hadoop.ipc.Server: Starting Socket Reader #1 for port 8033
2021-03-09 21:39:04,084 INFO org.apache.hadoop.yarn.factories.impl.pb.RpcServerFactoryPBImpl: Adding protocol org.apache.hadoop.yarn.server.api.ResourceManagerAdministrationProtocolPB to the server
2021-03-09 21:39:04,085 INFO org.apache.hadoop.ipc.Server: IPC Server Responder: starting
2021-03-09 21:39:04,087 INFO org.apache.hadoop.ipc.Server: IPC Server listener on 8033: starting
2021-03-09 21:39:06,284 INFO org.apache.hadoop.yarn.util.RackResolver: Resolved tutrung-slave2 to /default-rack
2021-03-09 21:39:06,287 INFO org.apache.hadoop.yarn.server.resourcemanager.ResourceTrackerService: NodeManager from node tutrung-slave2(cmPort: 36325 httpPort: 8042) registered with capability: <memory:8192, vCores:8>, assigned nodeId tutrung-slave2:36325
2021-03-09 21:39:06,290 INFO org.apache.hadoop.yarn.server.resourcemanager.rmnode.RMNodeImpl: tutrung-slave2:36325 Node Transitioned from NEW to RUNNING
2021-03-09 21:39:06,294 INFO org.apache.hadoop.yarn.server.resourcemanager.scheduler.capacity.CapacityScheduler: Added node tutrung-slave2:36325 clusterResource: <memory:8192, vCores:8>
2021-03-09 21:39:08,602 INFO org.apache.hadoop.yarn.util.RackResolver: Resolved tutrung-slave1 to /default-rack
2021-03-09 21:39:08,602 INFO org.apache.hadoop.yarn.server.resourcemanager.ResourceTrackerService: NodeManager from node tutrung-slave1(cmPort: 41367 httpPort: 8042) registered with capability: <memory:8192, vCores:8>, assigned nodeId tutrung-slave1:41367
2021-03-09 21:39:08,603 INFO org.apache.hadoop.yarn.server.resourcemanager.rmnode.RMNodeImpl: tutrung-slave1:41367 Node Transitioned from NEW to RUNNING
2021-03-09 21:39:08,607 INFO org.apache.hadoop.yarn.server.resourcemanager.scheduler.capacity.CapacityScheduler: Added node tutrung-slave1:41367 clusterResource: <memory:16384, vCores:16>
2021-03-09 21:48:59,749 INFO org.apache.hadoop.yarn.server.resourcemanager.scheduler.AbstractYarnScheduler: Release request cache is cleaned up
2021-03-09 22:20:21,993 ERROR org.apache.hadoop.yarn.server.resourcemanager.ResourceManager: RECEIVED SIGNAL 15: SIGTERM
2021-03-09 22:20:22,033 ERROR org.apache.hadoop.security.token.delegation.AbstractDelegationTokenSecretManager: ExpiredTokenRemover received java.lang.InterruptedException: sleep interrupted
2021-03-09 22:20:22,036 INFO org.mortbay.log: Stopped HttpServer2$SelectChannelConnectorWithSafeStartup@master:8088
2021-03-09 22:20:22,037 INFO org.apache.hadoop.ipc.Server: Stopping server on 8032
2021-03-09 22:20:22,052 INFO org.apache.hadoop.ipc.Server: Stopping IPC Server listener on 8032
2021-03-09 22:20:22,054 INFO org.apache.hadoop.ipc.Server: Stopping IPC Server Responder
2021-03-09 22:20:22,054 INFO org.apache.hadoop.ipc.Server: Stopping server on 8033
2021-03-09 22:20:22,056 INFO org.apache.hadoop.ipc.Server: Stopping IPC Server listener on 8033
2021-03-09 22:20:22,057 INFO org.apache.hadoop.ipc.Server: Stopping IPC Server Responder
2021-03-09 22:20:22,058 INFO org.apache.hadoop.yarn.server.resourcemanager.ResourceManager: Transitioning to standby state
2021-03-09 22:20:22,060 WARN org.apache.hadoop.yarn.server.resourcemanager.amlauncher.ApplicationMasterLauncher: org.apache.hadoop.yarn.server.resourcemanager.amlauncher.ApplicationMasterLauncher$LauncherThread interrupted. Returning.
2021-03-09 22:20:22,060 INFO org.apache.hadoop.ipc.Server: Stopping server on 8030
2021-03-09 22:20:22,074 INFO org.apache.hadoop.ipc.Server: Stopping server on 8031
2021-03-09 22:20:22,074 INFO org.apache.hadoop.ipc.Server: Stopping IPC Server Responder
2021-03-09 22:20:22,076 INFO org.apache.hadoop.ipc.Server: Stopping IPC Server listener on 8030
2021-03-09 22:20:22,084 INFO org.apache.hadoop.ipc.Server: Stopping IPC Server listener on 8031
2021-03-09 22:20:22,088 INFO org.apache.hadoop.yarn.util.AbstractLivelinessMonitor: NMLivelinessMonitor thread interrupted
2021-03-09 22:20:22,088 INFO org.apache.hadoop.ipc.Server: Stopping IPC Server Responder
2021-03-09 22:20:22,092 ERROR org.apache.hadoop.yarn.server.resourcemanager.ResourceManager: Returning, interrupted : java.lang.InterruptedException
2021-03-09 22:20:22,092 INFO org.apache.hadoop.yarn.event.AsyncDispatcher: AsyncDispatcher is draining to stop, igonring any new events.
2021-03-09 22:20:22,094 INFO org.apache.hadoop.yarn.util.AbstractLivelinessMonitor: AMLivelinessMonitor thread interrupted
2021-03-09 22:20:22,094 INFO org.apache.hadoop.yarn.util.AbstractLivelinessMonitor: AMLivelinessMonitor thread interrupted
2021-03-09 22:20:22,095 INFO org.apache.hadoop.yarn.util.AbstractLivelinessMonitor: org.apache.hadoop.yarn.server.resourcemanager.rmcontainer.ContainerAllocationExpirer thread interrupted
2021-03-09 22:20:22,095 ERROR org.apache.hadoop.security.token.delegation.AbstractDelegationTokenSecretManager: ExpiredTokenRemover received java.lang.InterruptedException: sleep interrupted
2021-03-09 22:20:22,101 INFO org.apache.hadoop.metrics2.impl.MetricsSystemImpl: Stopping ResourceManager metrics system...
2021-03-09 22:20:22,103 INFO org.apache.hadoop.metrics2.impl.MetricsSystemImpl: ResourceManager metrics system stopped.
2021-03-09 22:20:22,107 INFO org.apache.hadoop.metrics2.impl.MetricsSystemImpl: ResourceManager metrics system shutdown complete.
2021-03-09 22:20:22,108 INFO org.apache.hadoop.yarn.event.AsyncDispatcher: AsyncDispatcher is draining to stop, igonring any new events.
2021-03-09 22:20:22,109 INFO org.apache.hadoop.yarn.server.resourcemanager.ResourceManager: Transitioned to standby state
2021-03-09 22:20:22,109 INFO org.apache.hadoop.yarn.server.resourcemanager.ResourceManager: SHUTDOWN_MSG: 
/************************************************************
SHUTDOWN_MSG: Shutting down ResourceManager at master/192.168.244.130
************************************************************/
2021-03-09 23:53:12,923 INFO org.apache.hadoop.yarn.server.resourcemanager.ResourceManager: STARTUP_MSG: 
/************************************************************
STARTUP_MSG: Starting ResourceManager
STARTUP_MSG:   host = master/192.168.244.130
STARTUP_MSG:   args = []
STARTUP_MSG:   version = 2.7.7
STARTUP_MSG:   build = Unknown -r c1aad84bd27cd79c3d1a7dd58202a8c3ee1ed3ac; compiled by 'stevel' on 2018-07-18T22:47Z
STARTUP_MSG:   java = 15.0.2
************************************************************/
2021-03-09 23:53:12,928 INFO org.apache.hadoop.yarn.server.resourcemanager.ResourceManager: registered UNIX signal handlers for [TERM, HUP, INT]
2021-03-09 23:53:13,182 INFO org.apache.hadoop.conf.Configuration: found resource core-site.xml at file:/home/hadoopuser/hadoop/etc/hadoop/core-site.xml
2021-03-09 23:53:13,276 WARN org.apache.hadoop.util.NativeCodeLoader: Unable to load native-hadoop library for your platform... using builtin-java classes where applicable
2021-03-09 23:53:13,290 INFO org.apache.hadoop.security.Groups: clearing userToGroupsMap cache
2021-03-09 23:53:13,365 INFO org.apache.hadoop.conf.Configuration: found resource yarn-site.xml at file:/home/hadoopuser/hadoop/etc/hadoop/yarn-site.xml
2021-03-09 23:53:13,524 INFO org.apache.hadoop.yarn.event.AsyncDispatcher: Registering class org.apache.hadoop.yarn.server.resourcemanager.RMFatalEventType for class org.apache.hadoop.yarn.server.resourcemanager.ResourceManager$RMFatalEventDispatcher
2021-03-09 23:53:13,592 INFO org.apache.hadoop.yarn.server.resourcemanager.security.NMTokenSecretManagerInRM: NMTokenKeyRollingInterval: 86400000ms and NMTokenKeyActivationDelay: 900000ms
2021-03-09 23:53:13,595 INFO org.apache.hadoop.yarn.server.resourcemanager.security.RMContainerTokenSecretManager: ContainerTokenKeyRollingInterval: 86400000ms and ContainerTokenKeyActivationDelay: 900000ms
2021-03-09 23:53:13,597 INFO org.apache.hadoop.yarn.server.resourcemanager.security.AMRMTokenSecretManager: AMRMTokenKeyRollingInterval: 86400000ms and AMRMTokenKeyActivationDelay: 900000 ms
2021-03-09 23:53:13,616 INFO org.apache.hadoop.yarn.event.AsyncDispatcher: Registering class org.apache.hadoop.yarn.server.resourcemanager.recovery.RMStateStoreEventType for class org.apache.hadoop.yarn.server.resourcemanager.recovery.RMStateStore$ForwardingEventHandler
2021-03-09 23:53:13,618 INFO org.apache.hadoop.yarn.event.AsyncDispatcher: Registering class org.apache.hadoop.yarn.server.resourcemanager.NodesListManagerEventType for class org.apache.hadoop.yarn.server.resourcemanager.NodesListManager
2021-03-09 23:53:13,618 INFO org.apache.hadoop.yarn.server.resourcemanager.ResourceManager: Using Scheduler: org.apache.hadoop.yarn.server.resourcemanager.scheduler.capacity.CapacityScheduler
2021-03-09 23:53:13,634 INFO org.apache.hadoop.yarn.event.AsyncDispatcher: Registering class org.apache.hadoop.yarn.server.resourcemanager.scheduler.event.SchedulerEventType for class org.apache.hadoop.yarn.server.resourcemanager.ResourceManager$SchedulerEventDispatcher
2021-03-09 23:53:13,635 INFO org.apache.hadoop.yarn.event.AsyncDispatcher: Registering class org.apache.hadoop.yarn.server.resourcemanager.rmapp.RMAppEventType for class org.apache.hadoop.yarn.server.resourcemanager.ResourceManager$ApplicationEventDispatcher
2021-03-09 23:53:13,635 INFO org.apache.hadoop.yarn.event.AsyncDispatcher: Registering class org.apache.hadoop.yarn.server.resourcemanager.rmapp.attempt.RMAppAttemptEventType for class org.apache.hadoop.yarn.server.resourcemanager.ResourceManager$ApplicationAttemptEventDispatcher
2021-03-09 23:53:13,636 INFO org.apache.hadoop.yarn.event.AsyncDispatcher: Registering class org.apache.hadoop.yarn.server.resourcemanager.rmnode.RMNodeEventType for class org.apache.hadoop.yarn.server.resourcemanager.ResourceManager$NodeEventDispatcher
2021-03-09 23:53:13,683 INFO org.apache.hadoop.metrics2.impl.MetricsConfig: loaded properties from hadoop-metrics2.properties
2021-03-09 23:53:13,817 INFO org.apache.hadoop.metrics2.impl.MetricsSystemImpl: Scheduled snapshot period at 10 second(s).
2021-03-09 23:53:13,818 INFO org.apache.hadoop.metrics2.impl.MetricsSystemImpl: ResourceManager metrics system started
2021-03-09 23:53:13,836 INFO org.apache.hadoop.yarn.event.AsyncDispatcher: Registering class org.apache.hadoop.yarn.server.resourcemanager.RMAppManagerEventType for class org.apache.hadoop.yarn.server.resourcemanager.RMAppManager
2021-03-09 23:53:13,843 INFO org.apache.hadoop.yarn.event.AsyncDispatcher: Registering class org.apache.hadoop.yarn.server.resourcemanager.amlauncher.AMLauncherEventType for class org.apache.hadoop.yarn.server.resourcemanager.amlauncher.ApplicationMasterLauncher
2021-03-09 23:53:13,847 INFO org.apache.hadoop.yarn.server.resourcemanager.RMNMInfo: Registered RMNMInfo MBean
2021-03-09 23:53:13,850 INFO org.apache.hadoop.yarn.security.YarnAuthorizationProvider: org.apache.hadoop.yarn.security.ConfiguredYarnAuthorizer is instiantiated.
2021-03-09 23:53:13,851 INFO org.apache.hadoop.util.HostsFileReader: Refreshing hosts (include/exclude) list
2021-03-09 23:53:13,853 INFO org.apache.hadoop.conf.Configuration: found resource capacity-scheduler.xml at file:/home/hadoopuser/hadoop/etc/hadoop/capacity-scheduler.xml
2021-03-09 23:53:13,912 INFO org.apache.hadoop.yarn.server.resourcemanager.scheduler.capacity.CapacitySchedulerConfiguration: max alloc mb per queue for root is undefined
2021-03-09 23:53:13,912 INFO org.apache.hadoop.yarn.server.resourcemanager.scheduler.capacity.CapacitySchedulerConfiguration: max alloc vcore per queue for root is undefined
2021-03-09 23:53:13,917 INFO org.apache.hadoop.yarn.server.resourcemanager.scheduler.capacity.ParentQueue: root, capacity=1.0, asboluteCapacity=1.0, maxCapacity=1.0, asboluteMaxCapacity=1.0, state=RUNNING, acls=SUBMIT_APP:*ADMINISTER_QUEUE:*, labels=*,
, reservationsContinueLooking=true
2021-03-09 23:53:13,917 INFO org.apache.hadoop.yarn.server.resourcemanager.scheduler.capacity.ParentQueue: Initialized parent-queue root name=root, fullname=root
2021-03-09 23:53:13,924 INFO org.apache.hadoop.yarn.server.resourcemanager.scheduler.capacity.CapacitySchedulerConfiguration: max alloc mb per queue for root.default is undefined
2021-03-09 23:53:13,924 INFO org.apache.hadoop.yarn.server.resourcemanager.scheduler.capacity.CapacitySchedulerConfiguration: max alloc vcore per queue for root.default is undefined
2021-03-09 23:53:13,925 INFO org.apache.hadoop.yarn.server.resourcemanager.scheduler.capacity.LeafQueue: Initializing default
capacity = 1.0 [= (float) configuredCapacity / 100 ]
asboluteCapacity = 1.0 [= parentAbsoluteCapacity * capacity ]
maxCapacity = 1.0 [= configuredMaxCapacity ]
absoluteMaxCapacity = 1.0 [= 1.0 maximumCapacity undefined, (parentAbsoluteMaxCapacity * maximumCapacity) / 100 otherwise ]
userLimit = 100 [= configuredUserLimit ]
userLimitFactor = 1.0 [= configuredUserLimitFactor ]
maxApplications = 10000 [= configuredMaximumSystemApplicationsPerQueue or (int)(configuredMaximumSystemApplications * absoluteCapacity)]
maxApplicationsPerUser = 10000 [= (int)(maxApplications * (userLimit / 100.0f) * userLimitFactor) ]
usedCapacity = 0.0 [= usedResourcesMemory / (clusterResourceMemory * absoluteCapacity)]
absoluteUsedCapacity = 0.0 [= usedResourcesMemory / clusterResourceMemory]
maxAMResourcePerQueuePercent = 0.1 [= configuredMaximumAMResourcePercent ]
minimumAllocationFactor = 0.875 [= (float)(maximumAllocationMemory - minimumAllocationMemory) / maximumAllocationMemory ]
maximumAllocation = <memory:8192, vCores:32> [= configuredMaxAllocation ]
numContainers = 0 [= currentNumContainers ]
state = RUNNING [= configuredState ]
acls = SUBMIT_APP:*ADMINISTER_QUEUE:* [= configuredAcls ]
nodeLocalityDelay = 40
labels=*,
nodeLocalityDelay = 40
reservationsContinueLooking = true
preemptionDisabled = true

2021-03-09 23:53:13,925 INFO org.apache.hadoop.yarn.server.resourcemanager.scheduler.capacity.CapacityScheduler: Initialized queue: default: capacity=1.0, absoluteCapacity=1.0, usedResources=<memory:0, vCores:0>, usedCapacity=0.0, absoluteUsedCapacity=0.0, numApps=0, numContainers=0
2021-03-09 23:53:13,926 INFO org.apache.hadoop.yarn.server.resourcemanager.scheduler.capacity.CapacityScheduler: Initialized queue: root: numChildQueue= 1, capacity=1.0, absoluteCapacity=1.0, usedResources=<memory:0, vCores:0>usedCapacity=0.0, numApps=0, numContainers=0
2021-03-09 23:53:13,927 INFO org.apache.hadoop.yarn.server.resourcemanager.scheduler.capacity.CapacityScheduler: Initialized root queue root: numChildQueue= 1, capacity=1.0, absoluteCapacity=1.0, usedResources=<memory:0, vCores:0>usedCapacity=0.0, numApps=0, numContainers=0
2021-03-09 23:53:13,927 INFO org.apache.hadoop.yarn.server.resourcemanager.scheduler.capacity.CapacityScheduler: Initialized queue mappings, override: false
2021-03-09 23:53:13,927 INFO org.apache.hadoop.yarn.server.resourcemanager.scheduler.capacity.CapacityScheduler: Initialized CapacityScheduler with calculator=class org.apache.hadoop.yarn.util.resource.DefaultResourceCalculator, minimumAllocation=<<memory:1024, vCores:1>>, maximumAllocation=<<memory:8192, vCores:32>>, asynchronousScheduling=false, asyncScheduleInterval=5ms
2021-03-09 23:53:13,939 INFO org.apache.hadoop.yarn.server.resourcemanager.metrics.SystemMetricsPublisher: YARN system metrics publishing service is not enabled
2021-03-09 23:53:13,939 INFO org.apache.hadoop.yarn.server.resourcemanager.ResourceManager: Transitioning to active state
2021-03-09 23:53:13,953 INFO org.apache.hadoop.yarn.server.resourcemanager.recovery.RMStateStore: Updating AMRMToken
2021-03-09 23:53:13,953 INFO org.apache.hadoop.yarn.server.resourcemanager.security.RMContainerTokenSecretManager: Rolling master-key for container-tokens
2021-03-09 23:53:13,953 INFO org.apache.hadoop.yarn.server.resourcemanager.security.NMTokenSecretManagerInRM: Rolling master-key for nm-tokens
2021-03-09 23:53:13,953 INFO org.apache.hadoop.security.token.delegation.AbstractDelegationTokenSecretManager: Updating the current master key for generating delegation tokens
2021-03-09 23:53:13,954 INFO org.apache.hadoop.yarn.server.resourcemanager.security.RMDelegationTokenSecretManager: storing master key with keyID 1
2021-03-09 23:53:13,954 INFO org.apache.hadoop.yarn.server.resourcemanager.recovery.RMStateStore: Storing RMDTMasterKey.
2021-03-09 23:53:13,964 INFO org.apache.hadoop.yarn.event.AsyncDispatcher: Registering class org.apache.hadoop.yarn.nodelabels.event.NodeLabelsStoreEventType for class org.apache.hadoop.yarn.nodelabels.CommonNodeLabelsManager$ForwardingEventHandler
2021-03-09 23:53:13,965 INFO org.apache.hadoop.security.token.delegation.AbstractDelegationTokenSecretManager: Starting expired delegation token remover thread, tokenRemoverScanInterval=60 min(s)
2021-03-09 23:53:13,965 INFO org.apache.hadoop.security.token.delegation.AbstractDelegationTokenSecretManager: Updating the current master key for generating delegation tokens
2021-03-09 23:53:13,965 INFO org.apache.hadoop.yarn.server.resourcemanager.security.RMDelegationTokenSecretManager: storing master key with keyID 2
2021-03-09 23:53:13,966 INFO org.apache.hadoop.yarn.server.resourcemanager.recovery.RMStateStore: Storing RMDTMasterKey.
2021-03-09 23:53:13,991 INFO org.apache.hadoop.ipc.CallQueueManager: Using callQueue: class java.util.concurrent.LinkedBlockingQueue queueCapacity: 5000
2021-03-09 23:53:14,007 INFO org.apache.hadoop.ipc.Server: Starting Socket Reader #1 for port 8031
2021-03-09 23:53:14,122 INFO org.apache.hadoop.yarn.factories.impl.pb.RpcServerFactoryPBImpl: Adding protocol org.apache.hadoop.yarn.server.api.ResourceTrackerPB to the server
2021-03-09 23:53:14,131 INFO org.apache.hadoop.ipc.Server: IPC Server Responder: starting
2021-03-09 23:53:14,133 INFO org.apache.hadoop.ipc.Server: IPC Server listener on 8031: starting
2021-03-09 23:53:14,188 INFO org.apache.hadoop.ipc.CallQueueManager: Using callQueue: class java.util.concurrent.LinkedBlockingQueue queueCapacity: 5000
2021-03-09 23:53:14,193 INFO org.apache.hadoop.ipc.Server: Starting Socket Reader #1 for port 8030
2021-03-09 23:53:14,204 INFO org.apache.hadoop.yarn.factories.impl.pb.RpcServerFactoryPBImpl: Adding protocol org.apache.hadoop.yarn.api.ApplicationMasterProtocolPB to the server
2021-03-09 23:53:14,205 INFO org.apache.hadoop.ipc.Server: IPC Server Responder: starting
2021-03-09 23:53:14,205 INFO org.apache.hadoop.ipc.Server: IPC Server listener on 8030: starting
2021-03-09 23:53:14,367 INFO org.apache.hadoop.ipc.CallQueueManager: Using callQueue: class java.util.concurrent.LinkedBlockingQueue queueCapacity: 5000
2021-03-09 23:53:14,370 INFO org.apache.hadoop.ipc.Server: Starting Socket Reader #1 for port 8032
2021-03-09 23:53:14,380 INFO org.apache.hadoop.yarn.factories.impl.pb.RpcServerFactoryPBImpl: Adding protocol org.apache.hadoop.yarn.api.ApplicationClientProtocolPB to the server
2021-03-09 23:53:14,393 INFO org.apache.hadoop.ipc.Server: IPC Server Responder: starting
2021-03-09 23:53:14,394 INFO org.apache.hadoop.ipc.Server: IPC Server listener on 8032: starting
2021-03-09 23:53:14,431 INFO org.apache.hadoop.yarn.server.resourcemanager.ResourceManager: Transitioned to active state
2021-03-09 23:53:14,524 INFO org.mortbay.log: Logging to org.slf4j.impl.Log4jLoggerAdapter(org.mortbay.log) via org.mortbay.log.Slf4jLog
2021-03-09 23:53:14,541 INFO org.apache.hadoop.security.authentication.server.AuthenticationFilter: Unable to initialize FileSignerSecretProvider, falling back to use random secrets.
2021-03-09 23:53:14,555 INFO org.apache.hadoop.http.HttpRequestLog: Http request log for http.requests.resourcemanager is not defined
2021-03-09 23:53:14,573 INFO org.apache.hadoop.http.HttpServer2: Added global filter 'safety' (class=org.apache.hadoop.http.HttpServer2$QuotingInputFilter)
2021-03-09 23:53:14,576 INFO org.apache.hadoop.http.HttpServer2: Added filter RMAuthenticationFilter (class=org.apache.hadoop.yarn.server.security.http.RMAuthenticationFilter) to context cluster
2021-03-09 23:53:14,577 INFO org.apache.hadoop.http.HttpServer2: Added filter RMAuthenticationFilter (class=org.apache.hadoop.yarn.server.security.http.RMAuthenticationFilter) to context static
2021-03-09 23:53:14,577 INFO org.apache.hadoop.http.HttpServer2: Added filter RMAuthenticationFilter (class=org.apache.hadoop.yarn.server.security.http.RMAuthenticationFilter) to context logs
2021-03-09 23:53:14,577 INFO org.apache.hadoop.http.HttpServer2: Added filter static_user_filter (class=org.apache.hadoop.http.lib.StaticUserWebFilter$StaticUserFilter) to context cluster
2021-03-09 23:53:14,577 INFO org.apache.hadoop.http.HttpServer2: Added filter static_user_filter (class=org.apache.hadoop.http.lib.StaticUserWebFilter$StaticUserFilter) to context static
2021-03-09 23:53:14,577 INFO org.apache.hadoop.http.HttpServer2: Added filter static_user_filter (class=org.apache.hadoop.http.lib.StaticUserWebFilter$StaticUserFilter) to context logs
2021-03-09 23:53:14,581 INFO org.apache.hadoop.http.HttpServer2: adding path spec: /cluster/*
2021-03-09 23:53:14,581 INFO org.apache.hadoop.http.HttpServer2: adding path spec: /ws/*
2021-03-09 23:53:14,970 INFO org.apache.hadoop.yarn.webapp.WebApps: Registered webapp guice modules
2021-03-09 23:53:14,973 INFO org.apache.hadoop.http.HttpServer2: Jetty bound to port 8088
2021-03-09 23:53:14,973 INFO org.mortbay.log: jetty-6.1.26
2021-03-09 23:53:14,999 INFO org.mortbay.log: Extract jar:file:/home/hadoopuser/hadoop/share/hadoop/yarn/hadoop-yarn-common-2.7.7.jar!/webapps/cluster to /tmp/Jetty_master_8088_cluster____i4ls4w/webapp
2021-03-09 23:53:15,077 INFO org.apache.hadoop.security.token.delegation.AbstractDelegationTokenSecretManager: Updating the current master key for generating delegation tokens
2021-03-09 23:53:15,078 INFO org.apache.hadoop.security.token.delegation.AbstractDelegationTokenSecretManager: Starting expired delegation token remover thread, tokenRemoverScanInterval=60 min(s)
2021-03-09 23:53:15,083 INFO org.apache.hadoop.security.token.delegation.AbstractDelegationTokenSecretManager: Updating the current master key for generating delegation tokens
2021-03-09 23:53:16,250 INFO org.mortbay.log: Started HttpServer2$SelectChannelConnectorWithSafeStartup@master:8088
2021-03-09 23:53:16,251 INFO org.apache.hadoop.yarn.webapp.WebApps: Web app cluster started at 8088
2021-03-09 23:53:16,298 INFO org.apache.hadoop.ipc.CallQueueManager: Using callQueue: class java.util.concurrent.LinkedBlockingQueue queueCapacity: 100
2021-03-09 23:53:16,299 INFO org.apache.hadoop.ipc.Server: Starting Socket Reader #1 for port 8033
2021-03-09 23:53:16,310 INFO org.apache.hadoop.yarn.factories.impl.pb.RpcServerFactoryPBImpl: Adding protocol org.apache.hadoop.yarn.server.api.ResourceManagerAdministrationProtocolPB to the server
2021-03-09 23:53:16,311 INFO org.apache.hadoop.ipc.Server: IPC Server Responder: starting
2021-03-09 23:53:16,311 INFO org.apache.hadoop.ipc.Server: IPC Server listener on 8033: starting
2021-03-09 23:53:19,207 INFO org.apache.hadoop.yarn.util.RackResolver: Resolved tutrung-slave2 to /default-rack
2021-03-09 23:53:19,212 INFO org.apache.hadoop.yarn.server.resourcemanager.rmnode.RMNodeImpl: tutrung-slave2:35963 Node Transitioned from NEW to RUNNING
2021-03-09 23:53:19,214 INFO org.apache.hadoop.yarn.server.resourcemanager.scheduler.capacity.CapacityScheduler: Added node tutrung-slave2:35963 clusterResource: <memory:8192, vCores:8>
2021-03-09 23:53:19,218 INFO org.apache.hadoop.yarn.server.resourcemanager.ResourceTrackerService: NodeManager from node tutrung-slave2(cmPort: 35963 httpPort: 8042) registered with capability: <memory:8192, vCores:8>, assigned nodeId tutrung-slave2:35963
2021-03-09 23:53:20,393 INFO org.apache.hadoop.yarn.util.RackResolver: Resolved tutrung-slave1 to /default-rack
2021-03-09 23:53:20,394 INFO org.apache.hadoop.yarn.server.resourcemanager.ResourceTrackerService: NodeManager from node tutrung-slave1(cmPort: 40457 httpPort: 8042) registered with capability: <memory:8192, vCores:8>, assigned nodeId tutrung-slave1:40457
2021-03-09 23:53:20,394 INFO org.apache.hadoop.yarn.server.resourcemanager.rmnode.RMNodeImpl: tutrung-slave1:40457 Node Transitioned from NEW to RUNNING
2021-03-09 23:53:20,394 INFO org.apache.hadoop.yarn.server.resourcemanager.scheduler.capacity.CapacityScheduler: Added node tutrung-slave1:40457 clusterResource: <memory:16384, vCores:16>
                                                                                                                                                                                                                                                                                                                                                                                                                                                                                                                                                                                                                                                                                                                                                                                                                                                                                                                                                                                                                                                                                                                                                                                                                                                                                                                                                                                                                                                                                                                                                                                                                                                                                                                                                                                                                                                                                                                                                                                                                                                                                                                                                                                                                                                                                                                                                                                                                                                                                                                                                                                                                                                                                                                                                                                                                                                                                                                                                                                                                                                                                                                                                                                                                                                                                                                                                                                                                                                                                                                                                                                                                                                                                                                               2021-03-11 22:20:30,404 INFO org.apache.hadoop.yarn.server.resourcemanager.ResourceManager: STARTUP_MSG: 
/************************************************************
STARTUP_MSG: Starting ResourceManager
STARTUP_MSG:   host = master/192.168.244.130
STARTUP_MSG:   args = []
STARTUP_MSG:   version = 2.7.7
STARTUP_MSG:   build = Unknown -r c1aad84bd27cd79c3d1a7dd58202a8c3ee1ed3ac; compiled by 'stevel' on 2018-07-18T22:47Z
STARTUP_MSG:   java = 15.0.2
************************************************************/
2021-03-11 22:20:30,413 INFO org.apache.hadoop.yarn.server.resourcemanager.ResourceManager: registered UNIX signal handlers for [TERM, HUP, INT]
2021-03-11 22:20:30,790 INFO org.apache.hadoop.conf.Configuration: found resource core-site.xml at file:/home/hadoopuser/hadoop/etc/hadoop/core-site.xml
2021-03-11 22:20:30,908 WARN org.apache.hadoop.util.NativeCodeLoader: Unable to load native-hadoop library for your platform... using builtin-java classes where applicable
2021-03-11 22:20:30,927 INFO org.apache.hadoop.security.Groups: clearing userToGroupsMap cache
2021-03-11 22:20:31,058 INFO org.apache.hadoop.conf.Configuration: found resource yarn-site.xml at file:/home/hadoopuser/hadoop/etc/hadoop/yarn-site.xml
2021-03-11 22:20:31,402 INFO org.apache.hadoop.yarn.event.AsyncDispatcher: Registering class org.apache.hadoop.yarn.server.resourcemanager.RMFatalEventType for class org.apache.hadoop.yarn.server.resourcemanager.ResourceManager$RMFatalEventDispatcher
2021-03-11 22:20:31,536 INFO org.apache.hadoop.yarn.server.resourcemanager.security.NMTokenSecretManagerInRM: NMTokenKeyRollingInterval: 86400000ms and NMTokenKeyActivationDelay: 900000ms
2021-03-11 22:20:31,545 INFO org.apache.hadoop.yarn.server.resourcemanager.security.RMContainerTokenSecretManager: ContainerTokenKeyRollingInterval: 86400000ms and ContainerTokenKeyActivationDelay: 900000ms
2021-03-11 22:20:31,553 INFO org.apache.hadoop.yarn.server.resourcemanager.security.AMRMTokenSecretManager: AMRMTokenKeyRollingInterval: 86400000ms and AMRMTokenKeyActivationDelay: 900000 ms
2021-03-11 22:20:31,595 INFO org.apache.hadoop.yarn.event.AsyncDispatcher: Registering class org.apache.hadoop.yarn.server.resourcemanager.recovery.RMStateStoreEventType for class org.apache.hadoop.yarn.server.resourcemanager.recovery.RMStateStore$ForwardingEventHandler
2021-03-11 22:20:31,598 INFO org.apache.hadoop.yarn.event.AsyncDispatcher: Registering class org.apache.hadoop.yarn.server.resourcemanager.NodesListManagerEventType for class org.apache.hadoop.yarn.server.resourcemanager.NodesListManager
2021-03-11 22:20:31,598 INFO org.apache.hadoop.yarn.server.resourcemanager.ResourceManager: Using Scheduler: org.apache.hadoop.yarn.server.resourcemanager.scheduler.capacity.CapacityScheduler
2021-03-11 22:20:31,647 INFO org.apache.hadoop.yarn.event.AsyncDispatcher: Registering class org.apache.hadoop.yarn.server.resourcemanager.scheduler.event.SchedulerEventType for class org.apache.hadoop.yarn.server.resourcemanager.ResourceManager$SchedulerEventDispatcher
2021-03-11 22:20:31,648 INFO org.apache.hadoop.yarn.event.AsyncDispatcher: Registering class org.apache.hadoop.yarn.server.resourcemanager.rmapp.RMAppEventType for class org.apache.hadoop.yarn.server.resourcemanager.ResourceManager$ApplicationEventDispatcher
2021-03-11 22:20:31,649 INFO org.apache.hadoop.yarn.event.AsyncDispatcher: Registering class org.apache.hadoop.yarn.server.resourcemanager.rmapp.attempt.RMAppAttemptEventType for class org.apache.hadoop.yarn.server.resourcemanager.ResourceManager$ApplicationAttemptEventDispatcher
2021-03-11 22:20:31,650 INFO org.apache.hadoop.yarn.event.AsyncDispatcher: Registering class org.apache.hadoop.yarn.server.resourcemanager.rmnode.RMNodeEventType for class org.apache.hadoop.yarn.server.resourcemanager.ResourceManager$NodeEventDispatcher
2021-03-11 22:20:31,797 INFO org.apache.hadoop.metrics2.impl.MetricsConfig: loaded properties from hadoop-metrics2.properties
2021-03-11 22:20:32,358 INFO org.apache.hadoop.metrics2.impl.MetricsSystemImpl: Scheduled snapshot period at 10 second(s).
2021-03-11 22:20:32,358 INFO org.apache.hadoop.metrics2.impl.MetricsSystemImpl: ResourceManager metrics system started
2021-03-11 22:20:32,397 INFO org.apache.hadoop.yarn.event.AsyncDispatcher: Registering class org.apache.hadoop.yarn.server.resourcemanager.RMAppManagerEventType for class org.apache.hadoop.yarn.server.resourcemanager.RMAppManager
2021-03-11 22:20:32,407 INFO org.apache.hadoop.yarn.event.AsyncDispatcher: Registering class org.apache.hadoop.yarn.server.resourcemanager.amlauncher.AMLauncherEventType for class org.apache.hadoop.yarn.server.resourcemanager.amlauncher.ApplicationMasterLauncher
2021-03-11 22:20:32,410 INFO org.apache.hadoop.yarn.server.resourcemanager.RMNMInfo: Registered RMNMInfo MBean
2021-03-11 22:20:32,413 INFO org.apache.hadoop.yarn.security.YarnAuthorizationProvider: org.apache.hadoop.yarn.security.ConfiguredYarnAuthorizer is instiantiated.
2021-03-11 22:20:32,415 INFO org.apache.hadoop.util.HostsFileReader: Refreshing hosts (include/exclude) list
2021-03-11 22:20:32,421 INFO org.apache.hadoop.conf.Configuration: found resource capacity-scheduler.xml at file:/home/hadoopuser/hadoop/etc/hadoop/capacity-scheduler.xml
2021-03-11 22:20:32,499 INFO org.apache.hadoop.yarn.server.resourcemanager.scheduler.capacity.CapacitySchedulerConfiguration: max alloc mb per queue for root is undefined
2021-03-11 22:20:32,499 INFO org.apache.hadoop.yarn.server.resourcemanager.scheduler.capacity.CapacitySchedulerConfiguration: max alloc vcore per queue for root is undefined
2021-03-11 22:20:32,504 INFO org.apache.hadoop.yarn.server.resourcemanager.scheduler.capacity.ParentQueue: root, capacity=1.0, asboluteCapacity=1.0, maxCapacity=1.0, asboluteMaxCapacity=1.0, state=RUNNING, acls=SUBMIT_APP:*ADMINISTER_QUEUE:*, labels=*,
, reservationsContinueLooking=true
2021-03-11 22:20:32,504 INFO org.apache.hadoop.yarn.server.resourcemanager.scheduler.capacity.ParentQueue: Initialized parent-queue root name=root, fullname=root
2021-03-11 22:20:32,516 INFO org.apache.hadoop.yarn.server.resourcemanager.scheduler.capacity.CapacitySchedulerConfiguration: max alloc mb per queue for root.default is undefined
2021-03-11 22:20:32,516 INFO org.apache.hadoop.yarn.server.resourcemanager.scheduler.capacity.CapacitySchedulerConfiguration: max alloc vcore per queue for root.default is undefined
2021-03-11 22:20:32,519 INFO org.apache.hadoop.yarn.server.resourcemanager.scheduler.capacity.LeafQueue: Initializing default
capacity = 1.0 [= (float) configuredCapacity / 100 ]
asboluteCapacity = 1.0 [= parentAbsoluteCapacity * capacity ]
maxCapacity = 1.0 [= configuredMaxCapacity ]
absoluteMaxCapacity = 1.0 [= 1.0 maximumCapacity undefined, (parentAbsoluteMaxCapacity * maximumCapacity) / 100 otherwise ]
userLimit = 100 [= configuredUserLimit ]
userLimitFactor = 1.0 [= configuredUserLimitFactor ]
maxApplications = 10000 [= configuredMaximumSystemApplicationsPerQueue or (int)(configuredMaximumSystemApplications * absoluteCapacity)]
maxApplicationsPerUser = 10000 [= (int)(maxApplications * (userLimit / 100.0f) * userLimitFactor) ]
usedCapacity = 0.0 [= usedResourcesMemory / (clusterResourceMemory * absoluteCapacity)]
absoluteUsedCapacity = 0.0 [= usedResourcesMemory / clusterResourceMemory]
maxAMResourcePerQueuePercent = 0.1 [= configuredMaximumAMResourcePercent ]
minimumAllocationFactor = 0.875 [= (float)(maximumAllocationMemory - minimumAllocationMemory) / maximumAllocationMemory ]
maximumAllocation = <memory:8192, vCores:32> [= configuredMaxAllocation ]
numContainers = 0 [= currentNumContainers ]
state = RUNNING [= configuredState ]
acls = SUBMIT_APP:*ADMINISTER_QUEUE:* [= configuredAcls ]
nodeLocalityDelay = 40
labels=*,
nodeLocalityDelay = 40
reservationsContinueLooking = true
preemptionDisabled = true

2021-03-11 22:20:32,520 INFO org.apache.hadoop.yarn.server.resourcemanager.scheduler.capacity.CapacityScheduler: Initialized queue: default: capacity=1.0, absoluteCapacity=1.0, usedResources=<memory:0, vCores:0>, usedCapacity=0.0, absoluteUsedCapacity=0.0, numApps=0, numContainers=0
2021-03-11 22:20:32,520 INFO org.apache.hadoop.yarn.server.resourcemanager.scheduler.capacity.CapacityScheduler: Initialized queue: root: numChildQueue= 1, capacity=1.0, absoluteCapacity=1.0, usedResources=<memory:0, vCores:0>usedCapacity=0.0, numApps=0, numContainers=0
2021-03-11 22:20:32,521 INFO org.apache.hadoop.yarn.server.resourcemanager.scheduler.capacity.CapacityScheduler: Initialized root queue root: numChildQueue= 1, capacity=1.0, absoluteCapacity=1.0, usedResources=<memory:0, vCores:0>usedCapacity=0.0, numApps=0, numContainers=0
2021-03-11 22:20:32,521 INFO org.apache.hadoop.yarn.server.resourcemanager.scheduler.capacity.CapacityScheduler: Initialized queue mappings, override: false
2021-03-11 22:20:32,522 INFO org.apache.hadoop.yarn.server.resourcemanager.scheduler.capacity.CapacityScheduler: Initialized CapacityScheduler with calculator=class org.apache.hadoop.yarn.util.resource.DefaultResourceCalculator, minimumAllocation=<<memory:1024, vCores:1>>, maximumAllocation=<<memory:8192, vCores:32>>, asynchronousScheduling=false, asyncScheduleInterval=5ms
2021-03-11 22:20:32,539 INFO org.apache.hadoop.yarn.server.resourcemanager.metrics.SystemMetricsPublisher: YARN system metrics publishing service is not enabled
2021-03-11 22:20:32,539 INFO org.apache.hadoop.yarn.server.resourcemanager.ResourceManager: Transitioning to active state
2021-03-11 22:20:32,554 INFO org.apache.hadoop.yarn.server.resourcemanager.recovery.RMStateStore: Updating AMRMToken
2021-03-11 22:20:32,555 INFO org.apache.hadoop.yarn.server.resourcemanager.security.RMContainerTokenSecretManager: Rolling master-key for container-tokens
2021-03-11 22:20:32,555 INFO org.apache.hadoop.yarn.server.resourcemanager.security.NMTokenSecretManagerInRM: Rolling master-key for nm-tokens
2021-03-11 22:20:32,555 INFO org.apache.hadoop.security.token.delegation.AbstractDelegationTokenSecretManager: Updating the current master key for generating delegation tokens
2021-03-11 22:20:32,556 INFO org.apache.hadoop.yarn.server.resourcemanager.security.RMDelegationTokenSecretManager: storing master key with keyID 1
2021-03-11 22:20:32,556 INFO org.apache.hadoop.yarn.server.resourcemanager.recovery.RMStateStore: Storing RMDTMasterKey.
2021-03-11 22:20:32,562 INFO org.apache.hadoop.security.token.delegation.AbstractDelegationTokenSecretManager: Starting expired delegation token remover thread, tokenRemoverScanInterval=60 min(s)
2021-03-11 22:20:32,562 INFO org.apache.hadoop.security.token.delegation.AbstractDelegationTokenSecretManager: Updating the current master key for generating delegation tokens
2021-03-11 22:20:32,562 INFO org.apache.hadoop.yarn.server.resourcemanager.security.RMDelegationTokenSecretManager: storing master key with keyID 2
2021-03-11 22:20:32,562 INFO org.apache.hadoop.yarn.server.resourcemanager.recovery.RMStateStore: Storing RMDTMasterKey.
2021-03-11 22:20:32,574 INFO org.apache.hadoop.yarn.event.AsyncDispatcher: Registering class org.apache.hadoop.yarn.nodelabels.event.NodeLabelsStoreEventType for class org.apache.hadoop.yarn.nodelabels.CommonNodeLabelsManager$ForwardingEventHandler
2021-03-11 22:20:32,667 INFO org.apache.hadoop.ipc.CallQueueManager: Using callQueue: class java.util.concurrent.LinkedBlockingQueue queueCapacity: 5000
2021-03-11 22:20:32,706 INFO org.apache.hadoop.ipc.Server: Starting Socket Reader #1 for port 8031
2021-03-11 22:20:33,104 INFO org.apache.hadoop.yarn.factories.impl.pb.RpcServerFactoryPBImpl: Adding protocol org.apache.hadoop.yarn.server.api.ResourceTrackerPB to the server
2021-03-11 22:20:33,107 INFO org.apache.hadoop.ipc.Server: IPC Server Responder: starting
2021-03-11 22:20:33,110 INFO org.apache.hadoop.ipc.Server: IPC Server listener on 8031: starting
2021-03-11 22:20:33,162 INFO org.apache.hadoop.ipc.CallQueueManager: Using callQueue: class java.util.concurrent.LinkedBlockingQueue queueCapacity: 5000
2021-03-11 22:20:33,171 INFO org.apache.hadoop.ipc.Server: Starting Socket Reader #1 for port 8030
2021-03-11 22:20:33,198 INFO org.apache.hadoop.yarn.factories.impl.pb.RpcServerFactoryPBImpl: Adding protocol org.apache.hadoop.yarn.api.ApplicationMasterProtocolPB to the server
2021-03-11 22:20:33,199 INFO org.apache.hadoop.ipc.Server: IPC Server Responder: starting
2021-03-11 22:20:33,200 INFO org.apache.hadoop.ipc.Server: IPC Server listener on 8030: starting
2021-03-11 22:20:33,500 INFO org.apache.hadoop.ipc.CallQueueManager: Using callQueue: class java.util.concurrent.LinkedBlockingQueue queueCapacity: 5000
2021-03-11 22:20:33,502 INFO org.apache.hadoop.ipc.Server: Starting Socket Reader #1 for port 8032
2021-03-11 22:20:33,518 INFO org.apache.hadoop.yarn.factories.impl.pb.RpcServerFactoryPBImpl: Adding protocol org.apache.hadoop.yarn.api.ApplicationClientProtocolPB to the server
2021-03-11 22:20:33,525 INFO org.apache.hadoop.ipc.Server: IPC Server Responder: starting
2021-03-11 22:20:33,528 INFO org.apache.hadoop.ipc.Server: IPC Server listener on 8032: starting
2021-03-11 22:20:33,579 INFO org.apache.hadoop.yarn.server.resourcemanager.ResourceManager: Transitioned to active state
2021-03-11 22:20:33,779 INFO org.mortbay.log: Logging to org.slf4j.impl.Log4jLoggerAdapter(org.mortbay.log) via org.mortbay.log.Slf4jLog
2021-03-11 22:20:33,798 INFO org.apache.hadoop.security.authentication.server.AuthenticationFilter: Unable to initialize FileSignerSecretProvider, falling back to use random secrets.
2021-03-11 22:20:33,810 INFO org.apache.hadoop.http.HttpRequestLog: Http request log for http.requests.resourcemanager is not defined
2021-03-11 22:20:33,827 INFO org.apache.hadoop.http.HttpServer2: Added global filter 'safety' (class=org.apache.hadoop.http.HttpServer2$QuotingInputFilter)
2021-03-11 22:20:33,834 INFO org.apache.hadoop.http.HttpServer2: Added filter RMAuthenticationFilter (class=org.apache.hadoop.yarn.server.security.http.RMAuthenticationFilter) to context cluster
2021-03-11 22:20:33,834 INFO org.apache.hadoop.http.HttpServer2: Added filter RMAuthenticationFilter (class=org.apache.hadoop.yarn.server.security.http.RMAuthenticationFilter) to context static
2021-03-11 22:20:33,834 INFO org.apache.hadoop.http.HttpServer2: Added filter RMAuthenticationFilter (class=org.apache.hadoop.yarn.server.security.http.RMAuthenticationFilter) to context logs
2021-03-11 22:20:33,835 INFO org.apache.hadoop.http.HttpServer2: Added filter static_user_filter (class=org.apache.hadoop.http.lib.StaticUserWebFilter$StaticUserFilter) to context cluster
2021-03-11 22:20:33,836 INFO org.apache.hadoop.http.HttpServer2: Added filter static_user_filter (class=org.apache.hadoop.http.lib.StaticUserWebFilter$StaticUserFilter) to context static
2021-03-11 22:20:33,836 INFO org.apache.hadoop.http.HttpServer2: Added filter static_user_filter (class=org.apache.hadoop.http.lib.StaticUserWebFilter$StaticUserFilter) to context logs
2021-03-11 22:20:33,842 INFO org.apache.hadoop.http.HttpServer2: adding path spec: /cluster/*
2021-03-11 22:20:33,843 INFO org.apache.hadoop.http.HttpServer2: adding path spec: /ws/*
2021-03-11 22:20:34,786 INFO org.apache.hadoop.yarn.webapp.WebApps: Registered webapp guice modules
2021-03-11 22:20:34,793 INFO org.apache.hadoop.http.HttpServer2: Jetty bound to port 8088
2021-03-11 22:20:34,794 INFO org.mortbay.log: jetty-6.1.26
2021-03-11 22:20:34,855 INFO org.mortbay.log: Extract jar:file:/home/hadoopuser/hadoop/share/hadoop/yarn/hadoop-yarn-common-2.7.7.jar!/webapps/cluster to /tmp/Jetty_master_8088_cluster____i4ls4w/webapp
2021-03-11 22:20:35,410 INFO org.apache.hadoop.security.token.delegation.AbstractDelegationTokenSecretManager: Updating the current master key for generating delegation tokens
2021-03-11 22:20:35,420 INFO org.apache.hadoop.security.token.delegation.AbstractDelegationTokenSecretManager: Starting expired delegation token remover thread, tokenRemoverScanInterval=60 min(s)
2021-03-11 22:20:35,420 INFO org.apache.hadoop.security.token.delegation.AbstractDelegationTokenSecretManager: Updating the current master key for generating delegation tokens
2021-03-11 22:20:37,928 INFO org.mortbay.log: Started HttpServer2$SelectChannelConnectorWithSafeStartup@master:8088
2021-03-11 22:20:37,929 INFO org.apache.hadoop.yarn.webapp.WebApps: Web app cluster started at 8088
2021-03-11 22:20:37,998 INFO org.apache.hadoop.ipc.CallQueueManager: Using callQueue: class java.util.concurrent.LinkedBlockingQueue queueCapacity: 100
2021-03-11 22:20:37,999 INFO org.apache.hadoop.ipc.Server: Starting Socket Reader #1 for port 8033
2021-03-11 22:20:38,006 INFO org.apache.hadoop.yarn.factories.impl.pb.RpcServerFactoryPBImpl: Adding protocol org.apache.hadoop.yarn.server.api.ResourceManagerAdministrationProtocolPB to the server
2021-03-11 22:20:38,012 INFO org.apache.hadoop.ipc.Server: IPC Server Responder: starting
2021-03-11 22:20:38,016 INFO org.apache.hadoop.ipc.Server: IPC Server listener on 8033: starting
2021-03-11 22:20:40,743 INFO org.apache.hadoop.yarn.util.RackResolver: Resolved tutrung-slave1 to /default-rack
2021-03-11 22:20:40,751 INFO org.apache.hadoop.yarn.server.resourcemanager.ResourceTrackerService: NodeManager from node tutrung-slave1(cmPort: 41121 httpPort: 8042) registered with capability: <memory:8192, vCores:8>, assigned nodeId tutrung-slave1:41121
2021-03-11 22:20:40,757 INFO org.apache.hadoop.yarn.server.resourcemanager.rmnode.RMNodeImpl: tutrung-slave1:41121 Node Transitioned from NEW to RUNNING
2021-03-11 22:20:40,769 INFO org.apache.hadoop.yarn.server.resourcemanager.scheduler.capacity.CapacityScheduler: Added node tutrung-slave1:41121 clusterResource: <memory:8192, vCores:8>
2021-03-11 22:20:41,415 INFO org.apache.hadoop.yarn.util.RackResolver: Resolved tutrung-slave2 to /default-rack
2021-03-11 22:20:41,416 INFO org.apache.hadoop.yarn.server.resourcemanager.ResourceTrackerService: NodeManager from node tutrung-slave2(cmPort: 35059 httpPort: 8042) registered with capability: <memory:8192, vCores:8>, assigned nodeId tutrung-slave2:35059
2021-03-11 22:20:41,416 INFO org.apache.hadoop.yarn.server.resourcemanager.rmnode.RMNodeImpl: tutrung-slave2:35059 Node Transitioned from NEW to RUNNING
2021-03-11 22:20:41,417 INFO org.apache.hadoop.yarn.server.resourcemanager.scheduler.capacity.CapacityScheduler: Added node tutrung-slave2:35059 clusterResource: <memory:16384, vCores:16>
2021-03-11 22:30:32,421 INFO org.apache.hadoop.yarn.server.resourcemanager.scheduler.AbstractYarnScheduler: Release request cache is cleaned up
2021-03-11 22:48:25,809 INFO org.apache.hadoop.yarn.server.resourcemanager.ResourceManager: STARTUP_MSG: 
/************************************************************
STARTUP_MSG: Starting ResourceManager
STARTUP_MSG:   host = master/192.168.244.130
STARTUP_MSG:   args = []
STARTUP_MSG:   version = 2.7.7
STARTUP_MSG:   build = Unknown -r c1aad84bd27cd79c3d1a7dd58202a8c3ee1ed3ac; compiled by 'stevel' on 2018-07-18T22:47Z
STARTUP_MSG:   java = 15.0.2
************************************************************/
2021-03-11 22:48:25,818 INFO org.apache.hadoop.yarn.server.resourcemanager.ResourceManager: registered UNIX signal handlers for [TERM, HUP, INT]
2021-03-11 22:48:26,289 INFO org.apache.hadoop.conf.Configuration: found resource core-site.xml at file:/home/hadoopuser/hadoop/etc/hadoop/core-site.xml
2021-03-11 22:48:26,424 WARN org.apache.hadoop.util.NativeCodeLoader: Unable to load native-hadoop library for your platform... using builtin-java classes where applicable
2021-03-11 22:48:26,471 INFO org.apache.hadoop.security.Groups: clearing userToGroupsMap cache
2021-03-11 22:48:26,614 INFO org.apache.hadoop.conf.Configuration: found resource yarn-site.xml at file:/home/hadoopuser/hadoop/etc/hadoop/yarn-site.xml
2021-03-11 22:48:26,879 INFO org.apache.hadoop.yarn.event.AsyncDispatcher: Registering class org.apache.hadoop.yarn.server.resourcemanager.RMFatalEventType for class org.apache.hadoop.yarn.server.resourcemanager.ResourceManager$RMFatalEventDispatcher
2021-03-11 22:48:26,979 INFO org.apache.hadoop.yarn.server.resourcemanager.security.NMTokenSecretManagerInRM: NMTokenKeyRollingInterval: 86400000ms and NMTokenKeyActivationDelay: 900000ms
2021-03-11 22:48:26,984 INFO org.apache.hadoop.yarn.server.resourcemanager.security.RMContainerTokenSecretManager: ContainerTokenKeyRollingInterval: 86400000ms and ContainerTokenKeyActivationDelay: 900000ms
2021-03-11 22:48:26,995 INFO org.apache.hadoop.yarn.server.resourcemanager.security.AMRMTokenSecretManager: AMRMTokenKeyRollingInterval: 86400000ms and AMRMTokenKeyActivationDelay: 900000 ms
2021-03-11 22:48:27,038 INFO org.apache.hadoop.yarn.event.AsyncDispatcher: Registering class org.apache.hadoop.yarn.server.resourcemanager.recovery.RMStateStoreEventType for class org.apache.hadoop.yarn.server.resourcemanager.recovery.RMStateStore$ForwardingEventHandler
2021-03-11 22:48:27,042 INFO org.apache.hadoop.yarn.event.AsyncDispatcher: Registering class org.apache.hadoop.yarn.server.resourcemanager.NodesListManagerEventType for class org.apache.hadoop.yarn.server.resourcemanager.NodesListManager
2021-03-11 22:48:27,042 INFO org.apache.hadoop.yarn.server.resourcemanager.ResourceManager: Using Scheduler: org.apache.hadoop.yarn.server.resourcemanager.scheduler.capacity.CapacityScheduler
2021-03-11 22:48:27,067 INFO org.apache.hadoop.yarn.event.AsyncDispatcher: Registering class org.apache.hadoop.yarn.server.resourcemanager.scheduler.event.SchedulerEventType for class org.apache.hadoop.yarn.server.resourcemanager.ResourceManager$SchedulerEventDispatcher
2021-03-11 22:48:27,068 INFO org.apache.hadoop.yarn.event.AsyncDispatcher: Registering class org.apache.hadoop.yarn.server.resourcemanager.rmapp.RMAppEventType for class org.apache.hadoop.yarn.server.resourcemanager.ResourceManager$ApplicationEventDispatcher
2021-03-11 22:48:27,069 INFO org.apache.hadoop.yarn.event.AsyncDispatcher: Registering class org.apache.hadoop.yarn.server.resourcemanager.rmapp.attempt.RMAppAttemptEventType for class org.apache.hadoop.yarn.server.resourcemanager.ResourceManager$ApplicationAttemptEventDispatcher
2021-03-11 22:48:27,070 INFO org.apache.hadoop.yarn.event.AsyncDispatcher: Registering class org.apache.hadoop.yarn.server.resourcemanager.rmnode.RMNodeEventType for class org.apache.hadoop.yarn.server.resourcemanager.ResourceManager$NodeEventDispatcher
2021-03-11 22:48:27,190 INFO org.apache.hadoop.metrics2.impl.MetricsConfig: loaded properties from hadoop-metrics2.properties
2021-03-11 22:48:27,388 INFO org.apache.hadoop.metrics2.impl.MetricsSystemImpl: Scheduled snapshot period at 10 second(s).
2021-03-11 22:48:27,389 INFO org.apache.hadoop.metrics2.impl.MetricsSystemImpl: ResourceManager metrics system started
2021-03-11 22:48:27,430 INFO org.apache.hadoop.yarn.event.AsyncDispatcher: Registering class org.apache.hadoop.yarn.server.resourcemanager.RMAppManagerEventType for class org.apache.hadoop.yarn.server.resourcemanager.RMAppManager
2021-03-11 22:48:27,449 INFO org.apache.hadoop.yarn.event.AsyncDispatcher: Registering class org.apache.hadoop.yarn.server.resourcemanager.amlauncher.AMLauncherEventType for class org.apache.hadoop.yarn.server.resourcemanager.amlauncher.ApplicationMasterLauncher
2021-03-11 22:48:27,460 INFO org.apache.hadoop.yarn.server.resourcemanager.RMNMInfo: Registered RMNMInfo MBean
2021-03-11 22:48:27,464 INFO org.apache.hadoop.yarn.security.YarnAuthorizationProvider: org.apache.hadoop.yarn.security.ConfiguredYarnAuthorizer is instiantiated.
2021-03-11 22:48:27,466 INFO org.apache.hadoop.util.HostsFileReader: Refreshing hosts (include/exclude) list
2021-03-11 22:48:27,470 INFO org.apache.hadoop.conf.Configuration: found resource capacity-scheduler.xml at file:/home/hadoopuser/hadoop/etc/hadoop/capacity-scheduler.xml
2021-03-11 22:48:27,554 INFO org.apache.hadoop.yarn.server.resourcemanager.scheduler.capacity.CapacitySchedulerConfiguration: max alloc mb per queue for root is undefined
2021-03-11 22:48:27,554 INFO org.apache.hadoop.yarn.server.resourcemanager.scheduler.capacity.CapacitySchedulerConfiguration: max alloc vcore per queue for root is undefined
2021-03-11 22:48:27,578 INFO org.apache.hadoop.yarn.server.resourcemanager.scheduler.capacity.ParentQueue: root, capacity=1.0, asboluteCapacity=1.0, maxCapacity=1.0, asboluteMaxCapacity=1.0, state=RUNNING, acls=SUBMIT_APP:*ADMINISTER_QUEUE:*, labels=*,
, reservationsContinueLooking=true
2021-03-11 22:48:27,579 INFO org.apache.hadoop.yarn.server.resourcemanager.scheduler.capacity.ParentQueue: Initialized parent-queue root name=root, fullname=root
2021-03-11 22:48:27,592 INFO org.apache.hadoop.yarn.server.resourcemanager.scheduler.capacity.CapacitySchedulerConfiguration: max alloc mb per queue for root.default is undefined
2021-03-11 22:48:27,592 INFO org.apache.hadoop.yarn.server.resourcemanager.scheduler.capacity.CapacitySchedulerConfiguration: max alloc vcore per queue for root.default is undefined
2021-03-11 22:48:27,596 INFO org.apache.hadoop.yarn.server.resourcemanager.scheduler.capacity.LeafQueue: Initializing default
capacity = 1.0 [= (float) configuredCapacity / 100 ]
asboluteCapacity = 1.0 [= parentAbsoluteCapacity * capacity ]
maxCapacity = 1.0 [= configuredMaxCapacity ]
absoluteMaxCapacity = 1.0 [= 1.0 maximumCapacity undefined, (parentAbsoluteMaxCapacity * maximumCapacity) / 100 otherwise ]
userLimit = 100 [= configuredUserLimit ]
userLimitFactor = 1.0 [= configuredUserLimitFactor ]
maxApplications = 10000 [= configuredMaximumSystemApplicationsPerQueue or (int)(configuredMaximumSystemApplications * absoluteCapacity)]
maxApplicationsPerUser = 10000 [= (int)(maxApplications * (userLimit / 100.0f) * userLimitFactor) ]
usedCapacity = 0.0 [= usedResourcesMemory / (clusterResourceMemory * absoluteCapacity)]
absoluteUsedCapacity = 0.0 [= usedResourcesMemory / clusterResourceMemory]
maxAMResourcePerQueuePercent = 0.1 [= configuredMaximumAMResourcePercent ]
minimumAllocationFactor = 0.875 [= (float)(maximumAllocationMemory - minimumAllocationMemory) / maximumAllocationMemory ]
maximumAllocation = <memory:8192, vCores:32> [= configuredMaxAllocation ]
numContainers = 0 [= currentNumContainers ]
state = RUNNING [= configuredState ]
acls = SUBMIT_APP:*ADMINISTER_QUEUE:* [= configuredAcls ]
nodeLocalityDelay = 40
labels=*,
nodeLocalityDelay = 40
reservationsContinueLooking = true
preemptionDisabled = true

2021-03-11 22:48:27,596 INFO org.apache.hadoop.yarn.server.resourcemanager.scheduler.capacity.CapacityScheduler: Initialized queue: default: capacity=1.0, absoluteCapacity=1.0, usedResources=<memory:0, vCores:0>, usedCapacity=0.0, absoluteUsedCapacity=0.0, numApps=0, numContainers=0
2021-03-11 22:48:27,598 INFO org.apache.hadoop.yarn.server.resourcemanager.scheduler.capacity.CapacityScheduler: Initialized queue: root: numChildQueue= 1, capacity=1.0, absoluteCapacity=1.0, usedResources=<memory:0, vCores:0>usedCapacity=0.0, numApps=0, numContainers=0
2021-03-11 22:48:27,599 INFO org.apache.hadoop.yarn.server.resourcemanager.scheduler.capacity.CapacityScheduler: Initialized root queue root: numChildQueue= 1, capacity=1.0, absoluteCapacity=1.0, usedResources=<memory:0, vCores:0>usedCapacity=0.0, numApps=0, numContainers=0
2021-03-11 22:48:27,599 INFO org.apache.hadoop.yarn.server.resourcemanager.scheduler.capacity.CapacityScheduler: Initialized queue mappings, override: false
2021-03-11 22:48:27,600 INFO org.apache.hadoop.yarn.server.resourcemanager.scheduler.capacity.CapacityScheduler: Initialized CapacityScheduler with calculator=class org.apache.hadoop.yarn.util.resource.DefaultResourceCalculator, minimumAllocation=<<memory:1024, vCores:1>>, maximumAllocation=<<memory:8192, vCores:32>>, asynchronousScheduling=false, asyncScheduleInterval=5ms
2021-03-11 22:48:27,625 INFO org.apache.hadoop.yarn.server.resourcemanager.metrics.SystemMetricsPublisher: YARN system metrics publishing service is not enabled
2021-03-11 22:48:27,625 INFO org.apache.hadoop.yarn.server.resourcemanager.ResourceManager: Transitioning to active state
2021-03-11 22:48:27,644 INFO org.apache.hadoop.yarn.server.resourcemanager.recovery.RMStateStore: Updating AMRMToken
2021-03-11 22:48:27,644 INFO org.apache.hadoop.yarn.server.resourcemanager.security.RMContainerTokenSecretManager: Rolling master-key for container-tokens
2021-03-11 22:48:27,645 INFO org.apache.hadoop.yarn.server.resourcemanager.security.NMTokenSecretManagerInRM: Rolling master-key for nm-tokens
2021-03-11 22:48:27,645 INFO org.apache.hadoop.security.token.delegation.AbstractDelegationTokenSecretManager: Updating the current master key for generating delegation tokens
2021-03-11 22:48:27,646 INFO org.apache.hadoop.yarn.server.resourcemanager.security.RMDelegationTokenSecretManager: storing master key with keyID 1
2021-03-11 22:48:27,646 INFO org.apache.hadoop.yarn.server.resourcemanager.recovery.RMStateStore: Storing RMDTMasterKey.
2021-03-11 22:48:27,652 INFO org.apache.hadoop.security.token.delegation.AbstractDelegationTokenSecretManager: Starting expired delegation token remover thread, tokenRemoverScanInterval=60 min(s)
2021-03-11 22:48:27,653 INFO org.apache.hadoop.security.token.delegation.AbstractDelegationTokenSecretManager: Updating the current master key for generating delegation tokens
2021-03-11 22:48:27,653 INFO org.apache.hadoop.yarn.server.resourcemanager.security.RMDelegationTokenSecretManager: storing master key with keyID 2
2021-03-11 22:48:27,653 INFO org.apache.hadoop.yarn.server.resourcemanager.recovery.RMStateStore: Storing RMDTMasterKey.
2021-03-11 22:48:27,656 INFO org.apache.hadoop.yarn.event.AsyncDispatcher: Registering class org.apache.hadoop.yarn.nodelabels.event.NodeLabelsStoreEventType for class org.apache.hadoop.yarn.nodelabels.CommonNodeLabelsManager$ForwardingEventHandler
2021-03-11 22:48:27,701 INFO org.apache.hadoop.ipc.CallQueueManager: Using callQueue: class java.util.concurrent.LinkedBlockingQueue queueCapacity: 5000
2021-03-11 22:48:27,730 INFO org.apache.hadoop.ipc.Server: Starting Socket Reader #1 for port 8031
2021-03-11 22:48:27,995 INFO org.apache.hadoop.yarn.factories.impl.pb.RpcServerFactoryPBImpl: Adding protocol org.apache.hadoop.yarn.server.api.ResourceTrackerPB to the server
2021-03-11 22:48:28,006 INFO org.apache.hadoop.ipc.Server: IPC Server listener on 8031: starting
2021-03-11 22:48:28,011 INFO org.apache.hadoop.ipc.Server: IPC Server Responder: starting
2021-03-11 22:48:28,090 INFO org.apache.hadoop.ipc.CallQueueManager: Using callQueue: class java.util.concurrent.LinkedBlockingQueue queueCapacity: 5000
2021-03-11 22:48:28,100 INFO org.apache.hadoop.ipc.Server: Starting Socket Reader #1 for port 8030
2021-03-11 22:48:28,133 INFO org.apache.hadoop.yarn.factories.impl.pb.RpcServerFactoryPBImpl: Adding protocol org.apache.hadoop.yarn.api.ApplicationMasterProtocolPB to the server
2021-03-11 22:48:28,134 INFO org.apache.hadoop.ipc.Server: IPC Server Responder: starting
2021-03-11 22:48:28,134 INFO org.apache.hadoop.ipc.Server: IPC Server listener on 8030: starting
2021-03-11 22:48:28,319 INFO org.apache.hadoop.ipc.CallQueueManager: Using callQueue: class java.util.concurrent.LinkedBlockingQueue queueCapacity: 5000
2021-03-11 22:48:28,330 INFO org.apache.hadoop.ipc.Server: Starting Socket Reader #1 for port 8032
2021-03-11 22:48:28,348 INFO org.apache.hadoop.yarn.factories.impl.pb.RpcServerFactoryPBImpl: Adding protocol org.apache.hadoop.yarn.api.ApplicationClientProtocolPB to the server
2021-03-11 22:48:28,355 INFO org.apache.hadoop.ipc.Server: IPC Server Responder: starting
2021-03-11 22:48:28,356 INFO org.apache.hadoop.ipc.Server: IPC Server listener on 8032: starting
2021-03-11 22:48:28,411 INFO org.apache.hadoop.yarn.server.resourcemanager.ResourceManager: Transitioned to active state
2021-03-11 22:48:28,553 INFO org.mortbay.log: Logging to org.slf4j.impl.Log4jLoggerAdapter(org.mortbay.log) via org.mortbay.log.Slf4jLog
2021-03-11 22:48:28,598 INFO org.apache.hadoop.security.authentication.server.AuthenticationFilter: Unable to initialize FileSignerSecretProvider, falling back to use random secrets.
2021-03-11 22:48:28,661 INFO org.apache.hadoop.http.HttpRequestLog: Http request log for http.requests.resourcemanager is not defined
2021-03-11 22:48:28,738 INFO org.apache.hadoop.http.HttpServer2: Added global filter 'safety' (class=org.apache.hadoop.http.HttpServer2$QuotingInputFilter)
2021-03-11 22:48:28,756 INFO org.apache.hadoop.http.HttpServer2: Added filter RMAuthenticationFilter (class=org.apache.hadoop.yarn.server.security.http.RMAuthenticationFilter) to context cluster
2021-03-11 22:48:28,757 INFO org.apache.hadoop.http.HttpServer2: Added filter RMAuthenticationFilter (class=org.apache.hadoop.yarn.server.security.http.RMAuthenticationFilter) to context static
2021-03-11 22:48:28,757 INFO org.apache.hadoop.http.HttpServer2: Added filter RMAuthenticationFilter (class=org.apache.hadoop.yarn.server.security.http.RMAuthenticationFilter) to context logs
2021-03-11 22:48:28,757 INFO org.apache.hadoop.http.HttpServer2: Added filter static_user_filter (class=org.apache.hadoop.http.lib.StaticUserWebFilter$StaticUserFilter) to context cluster
2021-03-11 22:48:28,758 INFO org.apache.hadoop.http.HttpServer2: Added filter static_user_filter (class=org.apache.hadoop.http.lib.StaticUserWebFilter$StaticUserFilter) to context static
2021-03-11 22:48:28,758 INFO org.apache.hadoop.http.HttpServer2: Added filter static_user_filter (class=org.apache.hadoop.http.lib.StaticUserWebFilter$StaticUserFilter) to context logs
2021-03-11 22:48:28,766 INFO org.apache.hadoop.http.HttpServer2: adding path spec: /cluster/*
2021-03-11 22:48:28,767 INFO org.apache.hadoop.http.HttpServer2: adding path spec: /ws/*
2021-03-11 22:48:29,458 INFO org.apache.hadoop.yarn.webapp.WebApps: Registered webapp guice modules
2021-03-11 22:48:29,462 INFO org.apache.hadoop.http.HttpServer2: Jetty bound to port 8088
2021-03-11 22:48:29,462 INFO org.mortbay.log: jetty-6.1.26
2021-03-11 22:48:29,508 INFO org.mortbay.log: Extract jar:file:/home/hadoopuser/hadoop/share/hadoop/yarn/hadoop-yarn-common-2.7.7.jar!/webapps/cluster to /tmp/Jetty_master_8088_cluster____i4ls4w/webapp
2021-03-11 22:48:29,692 INFO org.apache.hadoop.security.token.delegation.AbstractDelegationTokenSecretManager: Updating the current master key for generating delegation tokens
2021-03-11 22:48:29,693 INFO org.apache.hadoop.security.token.delegation.AbstractDelegationTokenSecretManager: Starting expired delegation token remover thread, tokenRemoverScanInterval=60 min(s)
2021-03-11 22:48:29,698 INFO org.apache.hadoop.security.token.delegation.AbstractDelegationTokenSecretManager: Updating the current master key for generating delegation tokens
2021-03-11 22:48:31,966 INFO org.mortbay.log: Started HttpServer2$SelectChannelConnectorWithSafeStartup@master:8088
2021-03-11 22:48:31,967 INFO org.apache.hadoop.yarn.webapp.WebApps: Web app cluster started at 8088
2021-03-11 22:48:31,998 INFO org.apache.hadoop.ipc.CallQueueManager: Using callQueue: class java.util.concurrent.LinkedBlockingQueue queueCapacity: 100
2021-03-11 22:48:31,998 INFO org.apache.hadoop.ipc.Server: Starting Socket Reader #1 for port 8033
2021-03-11 22:48:32,004 INFO org.apache.hadoop.yarn.factories.impl.pb.RpcServerFactoryPBImpl: Adding protocol org.apache.hadoop.yarn.server.api.ResourceManagerAdministrationProtocolPB to the server
2021-03-11 22:48:32,005 INFO org.apache.hadoop.ipc.Server: IPC Server Responder: starting
2021-03-11 22:48:32,007 INFO org.apache.hadoop.ipc.Server: IPC Server listener on 8033: starting
2021-03-11 22:48:33,167 INFO org.apache.hadoop.yarn.util.RackResolver: Resolved tutrung-slave1 to /default-rack
2021-03-11 22:48:33,170 INFO org.apache.hadoop.yarn.server.resourcemanager.ResourceTrackerService: NodeManager from node tutrung-slave1(cmPort: 33619 httpPort: 8042) registered with capability: <memory:8192, vCores:8>, assigned nodeId tutrung-slave1:33619
2021-03-11 22:48:33,175 INFO org.apache.hadoop.yarn.server.resourcemanager.rmnode.RMNodeImpl: tutrung-slave1:33619 Node Transitioned from NEW to RUNNING
2021-03-11 22:48:33,179 INFO org.apache.hadoop.yarn.server.resourcemanager.scheduler.capacity.CapacityScheduler: Added node tutrung-slave1:33619 clusterResource: <memory:8192, vCores:8>
2021-03-11 22:48:33,456 INFO org.apache.hadoop.yarn.util.RackResolver: Resolved tutrung-slave2 to /default-rack
2021-03-11 22:48:33,456 INFO org.apache.hadoop.yarn.server.resourcemanager.ResourceTrackerService: NodeManager from node tutrung-slave2(cmPort: 46601 httpPort: 8042) registered with capability: <memory:8192, vCores:8>, assigned nodeId tutrung-slave2:46601
2021-03-11 22:48:33,456 INFO org.apache.hadoop.yarn.server.resourcemanager.rmnode.RMNodeImpl: tutrung-slave2:46601 Node Transitioned from NEW to RUNNING
2021-03-11 22:48:33,457 INFO org.apache.hadoop.yarn.server.resourcemanager.scheduler.capacity.CapacityScheduler: Added node tutrung-slave2:46601 clusterResource: <memory:16384, vCores:16>
2021-03-11 22:51:24,209 INFO org.apache.hadoop.yarn.server.resourcemanager.ClientRMService: Allocated new applicationId: 1
2021-03-11 22:51:25,426 INFO org.apache.hadoop.yarn.server.resourcemanager.ClientRMService: Application with id 1 submitted by user hadoopuser
2021-03-11 22:51:25,427 INFO org.apache.hadoop.yarn.server.resourcemanager.rmapp.RMAppImpl: Storing application with id application_1615531707627_0001
2021-03-11 22:51:25,430 INFO org.apache.hadoop.yarn.server.resourcemanager.RMAuditLogger: USER=hadoopuser	IP=192.168.244.130	OPERATION=Submit Application Request	TARGET=ClientRMService	RESULT=SUCCESS	APPID=application_1615531707627_0001
2021-03-11 22:51:25,450 INFO org.apache.hadoop.yarn.server.resourcemanager.rmapp.RMAppImpl: application_1615531707627_0001 State change from NEW to NEW_SAVING on event=START
2021-03-11 22:51:25,450 INFO org.apache.hadoop.yarn.server.resourcemanager.recovery.RMStateStore: Storing info for app: application_1615531707627_0001
2021-03-11 22:51:25,466 INFO org.apache.hadoop.yarn.server.resourcemanager.rmapp.RMAppImpl: application_1615531707627_0001 State change from NEW_SAVING to SUBMITTED on event=APP_NEW_SAVED
2021-03-11 22:51:25,469 INFO org.apache.hadoop.yarn.server.resourcemanager.scheduler.capacity.ParentQueue: Application added - appId: application_1615531707627_0001 user: hadoopuser leaf-queue of parent: root #applications: 1
2021-03-11 22:51:25,470 INFO org.apache.hadoop.yarn.server.resourcemanager.scheduler.capacity.CapacityScheduler: Accepted application application_1615531707627_0001 from user: hadoopuser, in queue: default
2021-03-11 22:51:25,472 INFO org.apache.hadoop.yarn.server.resourcemanager.rmapp.RMAppImpl: application_1615531707627_0001 State change from SUBMITTED to ACCEPTED on event=APP_ACCEPTED
2021-03-11 22:51:25,539 INFO org.apache.hadoop.yarn.server.resourcemanager.ApplicationMasterService: Registering app attempt : appattempt_1615531707627_0001_000001
2021-03-11 22:51:25,548 INFO org.apache.hadoop.yarn.server.resourcemanager.rmapp.attempt.RMAppAttemptImpl: appattempt_1615531707627_0001_000001 State change from NEW to SUBMITTED
2021-03-11 22:51:25,605 INFO org.apache.hadoop.yarn.server.resourcemanager.scheduler.capacity.LeafQueue: Application application_1615531707627_0001 from user: hadoopuser activated in queue: default
2021-03-11 22:51:25,605 INFO org.apache.hadoop.yarn.server.resourcemanager.scheduler.capacity.LeafQueue: Application added - appId: application_1615531707627_0001 user: org.apache.hadoop.yarn.server.resourcemanager.scheduler.capacity.LeafQueue$User@d742540, leaf-queue: default #user-pending-applications: 0 #user-active-applications: 1 #queue-pending-applications: 0 #queue-active-applications: 1
2021-03-11 22:51:25,606 INFO org.apache.hadoop.yarn.server.resourcemanager.scheduler.capacity.CapacityScheduler: Added Application Attempt appattempt_1615531707627_0001_000001 to scheduler from user hadoopuser in queue default
2021-03-11 22:51:25,608 INFO org.apache.hadoop.yarn.server.resourcemanager.rmapp.attempt.RMAppAttemptImpl: appattempt_1615531707627_0001_000001 State change from SUBMITTED to SCHEDULED
2021-03-11 22:51:26,045 INFO org.apache.hadoop.yarn.server.resourcemanager.rmcontainer.RMContainerImpl: container_1615531707627_0001_01_000001 Container Transitioned from NEW to ALLOCATED
2021-03-11 22:51:26,048 INFO org.apache.hadoop.yarn.server.resourcemanager.RMAuditLogger: USER=hadoopuser	OPERATION=AM Allocated Container	TARGET=SchedulerApp	RESULT=SUCCESS	APPID=application_1615531707627_0001	CONTAINERID=container_1615531707627_0001_01_000001
2021-03-11 22:51:26,050 INFO org.apache.hadoop.yarn.server.resourcemanager.scheduler.SchedulerNode: Assigned container container_1615531707627_0001_01_000001 of capacity <memory:2048, vCores:1> on host tutrung-slave2:46601, which has 1 containers, <memory:2048, vCores:1> used and <memory:6144, vCores:7> available after allocation
2021-03-11 22:51:26,051 INFO org.apache.hadoop.yarn.server.resourcemanager.scheduler.capacity.LeafQueue: assignedContainer application attempt=appattempt_1615531707627_0001_000001 container=Container: [ContainerId: container_1615531707627_0001_01_000001, NodeId: tutrung-slave2:46601, NodeHttpAddress: tutrung-slave2:8042, Resource: <memory:2048, vCores:1>, Priority: 0, Token: null, ] queue=default: capacity=1.0, absoluteCapacity=1.0, usedResources=<memory:0, vCores:0>, usedCapacity=0.0, absoluteUsedCapacity=0.0, numApps=1, numContainers=0 clusterResource=<memory:16384, vCores:16> type=OFF_SWITCH requestedPartition=
2021-03-11 22:51:26,052 INFO org.apache.hadoop.yarn.server.resourcemanager.scheduler.capacity.ParentQueue: Re-sorting assigned queue: root.default stats: default: capacity=1.0, absoluteCapacity=1.0, usedResources=<memory:2048, vCores:1>, usedCapacity=0.125, absoluteUsedCapacity=0.125, numApps=1, numContainers=1
2021-03-11 22:51:26,053 INFO org.apache.hadoop.yarn.server.resourcemanager.scheduler.capacity.ParentQueue: assignedContainer queue=root usedCapacity=0.125 absoluteUsedCapacity=0.125 used=<memory:2048, vCores:1> cluster=<memory:16384, vCores:16>
2021-03-11 22:51:26,093 INFO org.apache.hadoop.yarn.server.resourcemanager.security.NMTokenSecretManagerInRM: Sending NMToken for nodeId : tutrung-slave2:46601 for container : container_1615531707627_0001_01_000001
2021-03-11 22:51:26,110 INFO org.apache.hadoop.yarn.server.resourcemanager.rmcontainer.RMContainerImpl: container_1615531707627_0001_01_000001 Container Transitioned from ALLOCATED to ACQUIRED
2021-03-11 22:51:26,110 INFO org.apache.hadoop.yarn.server.resourcemanager.security.NMTokenSecretManagerInRM: Clear node set for appattempt_1615531707627_0001_000001
2021-03-11 22:51:26,115 INFO org.apache.hadoop.yarn.server.resourcemanager.rmapp.attempt.RMAppAttemptImpl: Storing attempt: AppId: application_1615531707627_0001 AttemptId: appattempt_1615531707627_0001_000001 MasterContainer: Container: [ContainerId: container_1615531707627_0001_01_000001, NodeId: tutrung-slave2:46601, NodeHttpAddress: tutrung-slave2:8042, Resource: <memory:2048, vCores:1>, Priority: 0, Token: Token { kind: ContainerToken, service: 192.168.244.132:46601 }, ]
2021-03-11 22:51:26,128 INFO org.apache.hadoop.yarn.server.resourcemanager.rmapp.attempt.RMAppAttemptImpl: appattempt_1615531707627_0001_000001 State change from SCHEDULED to ALLOCATED_SAVING
2021-03-11 22:51:26,143 INFO org.apache.hadoop.yarn.server.resourcemanager.rmapp.attempt.RMAppAttemptImpl: appattempt_1615531707627_0001_000001 State change from ALLOCATED_SAVING to ALLOCATED
2021-03-11 22:51:26,161 INFO org.apache.hadoop.yarn.server.resourcemanager.amlauncher.AMLauncher: Launching masterappattempt_1615531707627_0001_000001
2021-03-11 22:51:26,218 INFO org.apache.hadoop.yarn.server.resourcemanager.amlauncher.AMLauncher: Setting up container Container: [ContainerId: container_1615531707627_0001_01_000001, NodeId: tutrung-slave2:46601, NodeHttpAddress: tutrung-slave2:8042, Resource: <memory:2048, vCores:1>, Priority: 0, Token: Token { kind: ContainerToken, service: 192.168.244.132:46601 }, ] for AM appattempt_1615531707627_0001_000001
2021-03-11 22:51:26,219 INFO org.apache.hadoop.yarn.server.resourcemanager.amlauncher.AMLauncher: Command to launch container container_1615531707627_0001_01_000001 : $JAVA_HOME/bin/java -Djava.io.tmpdir=$PWD/tmp -Dlog4j.configuration=container-log4j.properties -Dyarn.app.container.log.dir=<LOG_DIR> -Dyarn.app.container.log.filesize=0 -Dhadoop.root.logger=INFO,CLA -Dhadoop.root.logfile=syslog  -Xmx1024m org.apache.hadoop.mapreduce.v2.app.MRAppMaster 1><LOG_DIR>/stdout 2><LOG_DIR>/stderr 
2021-03-11 22:51:26,222 INFO org.apache.hadoop.yarn.server.resourcemanager.security.AMRMTokenSecretManager: Create AMRMToken for ApplicationAttempt: appattempt_1615531707627_0001_000001
2021-03-11 22:51:26,227 INFO org.apache.hadoop.yarn.server.resourcemanager.security.AMRMTokenSecretManager: Creating password for appattempt_1615531707627_0001_000001
2021-03-11 22:51:26,880 INFO org.apache.hadoop.yarn.server.resourcemanager.rmcontainer.RMContainerImpl: container_1615531707627_0001_01_000001 Container Transitioned from ACQUIRED to RUNNING
2021-03-11 22:51:26,930 INFO org.apache.hadoop.yarn.server.resourcemanager.amlauncher.AMLauncher: Done launching container Container: [ContainerId: container_1615531707627_0001_01_000001, NodeId: tutrung-slave2:46601, NodeHttpAddress: tutrung-slave2:8042, Resource: <memory:2048, vCores:1>, Priority: 0, Token: Token { kind: ContainerToken, service: 192.168.244.132:46601 }, ] for AM appattempt_1615531707627_0001_000001
2021-03-11 22:51:26,931 INFO org.apache.hadoop.yarn.server.resourcemanager.rmapp.attempt.RMAppAttemptImpl: appattempt_1615531707627_0001_000001 State change from ALLOCATED to LAUNCHED
2021-03-11 22:51:38,024 INFO SecurityLogger.org.apache.hadoop.ipc.Server: Auth successful for appattempt_1615531707627_0001_000001 (auth:SIMPLE)
2021-03-11 22:51:38,035 INFO org.apache.hadoop.yarn.server.resourcemanager.ApplicationMasterService: AM registration appattempt_1615531707627_0001_000001
2021-03-11 22:51:38,036 INFO org.apache.hadoop.yarn.server.resourcemanager.rmapp.attempt.RMAppAttemptImpl: appattempt_1615531707627_0001_000001 State change from LAUNCHED to RUNNING
2021-03-11 22:51:38,036 INFO org.apache.hadoop.yarn.server.resourcemanager.rmapp.RMAppImpl: application_1615531707627_0001 State change from ACCEPTED to RUNNING on event=ATTEMPT_REGISTERED
2021-03-11 22:51:38,036 INFO org.apache.hadoop.yarn.server.resourcemanager.RMAuditLogger: USER=hadoopuser	IP=192.168.244.132	OPERATION=Register App Master	TARGET=ApplicationMasterService	RESULT=SUCCESS	APPID=application_1615531707627_0001	APPATTEMPTID=appattempt_1615531707627_0001_000001
2021-03-11 22:51:39,921 INFO org.apache.hadoop.yarn.server.resourcemanager.rmcontainer.RMContainerImpl: container_1615531707627_0001_01_000002 Container Transitioned from NEW to ALLOCATED
2021-03-11 22:51:39,921 INFO org.apache.hadoop.yarn.server.resourcemanager.RMAuditLogger: USER=hadoopuser	OPERATION=AM Allocated Container	TARGET=SchedulerApp	RESULT=SUCCESS	APPID=application_1615531707627_0001	CONTAINERID=container_1615531707627_0001_01_000002
2021-03-11 22:51:39,921 INFO org.apache.hadoop.yarn.server.resourcemanager.scheduler.SchedulerNode: Assigned container container_1615531707627_0001_01_000002 of capacity <memory:1024, vCores:1> on host tutrung-slave1:33619, which has 1 containers, <memory:1024, vCores:1> used and <memory:7168, vCores:7> available after allocation
2021-03-11 22:51:39,922 INFO org.apache.hadoop.yarn.server.resourcemanager.scheduler.capacity.LeafQueue: assignedContainer application attempt=appattempt_1615531707627_0001_000001 container=Container: [ContainerId: container_1615531707627_0001_01_000002, NodeId: tutrung-slave1:33619, NodeHttpAddress: tutrung-slave1:8042, Resource: <memory:1024, vCores:1>, Priority: 20, Token: null, ] queue=default: capacity=1.0, absoluteCapacity=1.0, usedResources=<memory:2048, vCores:1>, usedCapacity=0.125, absoluteUsedCapacity=0.125, numApps=1, numContainers=1 clusterResource=<memory:16384, vCores:16> type=NODE_LOCAL requestedPartition=
2021-03-11 22:51:39,922 INFO org.apache.hadoop.yarn.server.resourcemanager.scheduler.capacity.ParentQueue: Re-sorting assigned queue: root.default stats: default: capacity=1.0, absoluteCapacity=1.0, usedResources=<memory:3072, vCores:2>, usedCapacity=0.1875, absoluteUsedCapacity=0.1875, numApps=1, numContainers=2
2021-03-11 22:51:39,922 INFO org.apache.hadoop.yarn.server.resourcemanager.scheduler.capacity.ParentQueue: assignedContainer queue=root usedCapacity=0.1875 absoluteUsedCapacity=0.1875 used=<memory:3072, vCores:2> cluster=<memory:16384, vCores:16>
2021-03-11 22:51:40,197 INFO org.apache.hadoop.yarn.server.resourcemanager.security.NMTokenSecretManagerInRM: Sending NMToken for nodeId : tutrung-slave1:33619 for container : container_1615531707627_0001_01_000002
2021-03-11 22:51:40,198 INFO org.apache.hadoop.yarn.server.resourcemanager.rmcontainer.RMContainerImpl: container_1615531707627_0001_01_000002 Container Transitioned from ALLOCATED to ACQUIRED
2021-03-11 22:51:41,227 INFO org.apache.hadoop.yarn.server.resourcemanager.scheduler.AppSchedulingInfo: checking for deactivate of application :application_1615531707627_0001
2021-03-11 22:51:41,985 INFO org.apache.hadoop.yarn.server.resourcemanager.rmcontainer.RMContainerImpl: container_1615531707627_0001_01_000002 Container Transitioned from ACQUIRED to RUNNING
2021-03-11 22:52:18,735 INFO org.apache.hadoop.yarn.server.resourcemanager.rmcontainer.RMContainerImpl: container_1615531707627_0001_01_000002 Container Transitioned from RUNNING to COMPLETED
2021-03-11 22:52:18,735 INFO org.apache.hadoop.yarn.server.resourcemanager.scheduler.common.fica.FiCaSchedulerApp: Completed container: container_1615531707627_0001_01_000002 in state: COMPLETED event:FINISHED
2021-03-11 22:52:18,735 INFO org.apache.hadoop.yarn.server.resourcemanager.RMAuditLogger: USER=hadoopuser	OPERATION=AM Released Container	TARGET=SchedulerApp	RESULT=SUCCESS	APPID=application_1615531707627_0001	CONTAINERID=container_1615531707627_0001_01_000002
2021-03-11 22:52:18,735 INFO org.apache.hadoop.yarn.server.resourcemanager.scheduler.SchedulerNode: Released container container_1615531707627_0001_01_000002 of capacity <memory:1024, vCores:1> on host tutrung-slave1:33619, which currently has 0 containers, <memory:0, vCores:0> used and <memory:8192, vCores:8> available, release resources=true
2021-03-11 22:52:18,735 INFO org.apache.hadoop.yarn.server.resourcemanager.scheduler.capacity.LeafQueue: default used=<memory:2048, vCores:1> numContainers=1 user=hadoopuser user-resources=<memory:2048, vCores:1>
2021-03-11 22:52:18,736 INFO org.apache.hadoop.yarn.server.resourcemanager.scheduler.capacity.LeafQueue: completedContainer container=Container: [ContainerId: container_1615531707627_0001_01_000002, NodeId: tutrung-slave1:33619, NodeHttpAddress: tutrung-slave1:8042, Resource: <memory:1024, vCores:1>, Priority: 20, Token: Token { kind: ContainerToken, service: 192.168.244.131:33619 }, ] queue=default: capacity=1.0, absoluteCapacity=1.0, usedResources=<memory:2048, vCores:1>, usedCapacity=0.125, absoluteUsedCapacity=0.125, numApps=1, numContainers=1 cluster=<memory:16384, vCores:16>
2021-03-11 22:52:18,736 INFO org.apache.hadoop.yarn.server.resourcemanager.scheduler.capacity.ParentQueue: completedContainer queue=root usedCapacity=0.125 absoluteUsedCapacity=0.125 used=<memory:2048, vCores:1> cluster=<memory:16384, vCores:16>
2021-03-11 22:52:18,736 INFO org.apache.hadoop.yarn.server.resourcemanager.scheduler.capacity.ParentQueue: Re-sorting completed queue: root.default stats: default: capacity=1.0, absoluteCapacity=1.0, usedResources=<memory:2048, vCores:1>, usedCapacity=0.125, absoluteUsedCapacity=0.125, numApps=1, numContainers=1
2021-03-11 22:52:18,736 INFO org.apache.hadoop.yarn.server.resourcemanager.scheduler.capacity.CapacityScheduler: Application attempt appattempt_1615531707627_0001_000001 released container container_1615531707627_0001_01_000002 on node: host: tutrung-slave1:33619 #containers=0 available=<memory:8192, vCores:8> used=<memory:0, vCores:0> with event: FINISHED
2021-03-11 22:52:20,748 INFO org.apache.hadoop.yarn.server.resourcemanager.rmcontainer.RMContainerImpl: container_1615531707627_0001_01_000003 Container Transitioned from NEW to ALLOCATED
2021-03-11 22:52:20,749 INFO org.apache.hadoop.yarn.server.resourcemanager.RMAuditLogger: USER=hadoopuser	OPERATION=AM Allocated Container	TARGET=SchedulerApp	RESULT=SUCCESS	APPID=application_1615531707627_0001	CONTAINERID=container_1615531707627_0001_01_000003
2021-03-11 22:52:20,749 INFO org.apache.hadoop.yarn.server.resourcemanager.scheduler.SchedulerNode: Assigned container container_1615531707627_0001_01_000003 of capacity <memory:1024, vCores:1> on host tutrung-slave1:33619, which has 1 containers, <memory:1024, vCores:1> used and <memory:7168, vCores:7> available after allocation
2021-03-11 22:52:20,749 INFO org.apache.hadoop.yarn.server.resourcemanager.scheduler.capacity.LeafQueue: assignedContainer application attempt=appattempt_1615531707627_0001_000001 container=Container: [ContainerId: container_1615531707627_0001_01_000003, NodeId: tutrung-slave1:33619, NodeHttpAddress: tutrung-slave1:8042, Resource: <memory:1024, vCores:1>, Priority: 10, Token: null, ] queue=default: capacity=1.0, absoluteCapacity=1.0, usedResources=<memory:2048, vCores:1>, usedCapacity=0.125, absoluteUsedCapacity=0.125, numApps=1, numContainers=1 clusterResource=<memory:16384, vCores:16> type=OFF_SWITCH requestedPartition=
2021-03-11 22:52:20,750 INFO org.apache.hadoop.yarn.server.resourcemanager.scheduler.capacity.ParentQueue: Re-sorting assigned queue: root.default stats: default: capacity=1.0, absoluteCapacity=1.0, usedResources=<memory:3072, vCores:2>, usedCapacity=0.1875, absoluteUsedCapacity=0.1875, numApps=1, numContainers=2
2021-03-11 22:52:20,751 INFO org.apache.hadoop.yarn.server.resourcemanager.scheduler.capacity.ParentQueue: assignedContainer queue=root usedCapacity=0.1875 absoluteUsedCapacity=0.1875 used=<memory:3072, vCores:2> cluster=<memory:16384, vCores:16>
2021-03-11 22:52:21,438 INFO org.apache.hadoop.yarn.server.resourcemanager.rmcontainer.RMContainerImpl: container_1615531707627_0001_01_000003 Container Transitioned from ALLOCATED to ACQUIRED
2021-03-11 22:52:21,753 INFO org.apache.hadoop.yarn.server.resourcemanager.rmcontainer.RMContainerImpl: container_1615531707627_0001_01_000003 Container Transitioned from ACQUIRED to RUNNING
2021-03-11 22:52:22,468 INFO org.apache.hadoop.yarn.server.resourcemanager.scheduler.AppSchedulingInfo: checking for deactivate of application :application_1615531707627_0001
2021-03-11 22:52:38,720 INFO org.apache.hadoop.yarn.server.resourcemanager.rmcontainer.RMContainerImpl: container_1615531707627_0001_01_000003 Container Transitioned from RUNNING to COMPLETED
2021-03-11 22:52:38,720 INFO org.apache.hadoop.yarn.server.resourcemanager.scheduler.common.fica.FiCaSchedulerApp: Completed container: container_1615531707627_0001_01_000003 in state: COMPLETED event:FINISHED
2021-03-11 22:52:38,720 INFO org.apache.hadoop.yarn.server.resourcemanager.RMAuditLogger: USER=hadoopuser	OPERATION=AM Released Container	TARGET=SchedulerApp	RESULT=SUCCESS	APPID=application_1615531707627_0001	CONTAINERID=container_1615531707627_0001_01_000003
2021-03-11 22:52:38,720 INFO org.apache.hadoop.yarn.server.resourcemanager.scheduler.SchedulerNode: Released container container_1615531707627_0001_01_000003 of capacity <memory:1024, vCores:1> on host tutrung-slave1:33619, which currently has 0 containers, <memory:0, vCores:0> used and <memory:8192, vCores:8> available, release resources=true
2021-03-11 22:52:38,720 INFO org.apache.hadoop.yarn.server.resourcemanager.scheduler.capacity.LeafQueue: default used=<memory:2048, vCores:1> numContainers=1 user=hadoopuser user-resources=<memory:2048, vCores:1>
2021-03-11 22:52:38,720 INFO org.apache.hadoop.yarn.server.resourcemanager.scheduler.capacity.LeafQueue: completedContainer container=Container: [ContainerId: container_1615531707627_0001_01_000003, NodeId: tutrung-slave1:33619, NodeHttpAddress: tutrung-slave1:8042, Resource: <memory:1024, vCores:1>, Priority: 10, Token: Token { kind: ContainerToken, service: 192.168.244.131:33619 }, ] queue=default: capacity=1.0, absoluteCapacity=1.0, usedResources=<memory:2048, vCores:1>, usedCapacity=0.125, absoluteUsedCapacity=0.125, numApps=1, numContainers=1 cluster=<memory:16384, vCores:16>
2021-03-11 22:52:38,720 INFO org.apache.hadoop.yarn.server.resourcemanager.scheduler.capacity.ParentQueue: completedContainer queue=root usedCapacity=0.125 absoluteUsedCapacity=0.125 used=<memory:2048, vCores:1> cluster=<memory:16384, vCores:16>
2021-03-11 22:52:38,721 INFO org.apache.hadoop.yarn.server.resourcemanager.scheduler.capacity.ParentQueue: Re-sorting completed queue: root.default stats: default: capacity=1.0, absoluteCapacity=1.0, usedResources=<memory:2048, vCores:1>, usedCapacity=0.125, absoluteUsedCapacity=0.125, numApps=1, numContainers=1
2021-03-11 22:52:38,721 INFO org.apache.hadoop.yarn.server.resourcemanager.scheduler.capacity.CapacityScheduler: Application attempt appattempt_1615531707627_0001_000001 released container container_1615531707627_0001_01_000003 on node: host: tutrung-slave1:33619 #containers=0 available=<memory:8192, vCores:8> used=<memory:0, vCores:0> with event: FINISHED
2021-03-11 22:52:39,273 INFO org.apache.hadoop.yarn.server.resourcemanager.rmapp.attempt.RMAppAttemptImpl: Updating application attempt appattempt_1615531707627_0001_000001 with final state: FINISHING, and exit status: -1000
2021-03-11 22:52:39,275 INFO org.apache.hadoop.yarn.server.resourcemanager.rmapp.attempt.RMAppAttemptImpl: appattempt_1615531707627_0001_000001 State change from RUNNING to FINAL_SAVING
2021-03-11 22:52:39,275 INFO org.apache.hadoop.yarn.server.resourcemanager.rmapp.RMAppImpl: Updating application application_1615531707627_0001 with final state: FINISHING
2021-03-11 22:52:39,280 INFO org.apache.hadoop.yarn.server.resourcemanager.recovery.RMStateStore: Updating info for app: application_1615531707627_0001
2021-03-11 22:52:39,280 INFO org.apache.hadoop.yarn.server.resourcemanager.rmapp.RMAppImpl: application_1615531707627_0001 State change from RUNNING to FINAL_SAVING on event=ATTEMPT_UNREGISTERED
2021-03-11 22:52:39,281 INFO org.apache.hadoop.yarn.server.resourcemanager.rmapp.attempt.RMAppAttemptImpl: appattempt_1615531707627_0001_000001 State change from FINAL_SAVING to FINISHING
2021-03-11 22:52:39,281 INFO org.apache.hadoop.yarn.server.resourcemanager.rmapp.RMAppImpl: application_1615531707627_0001 State change from FINAL_SAVING to FINISHING on event=APP_UPDATE_SAVED
2021-03-11 22:52:40,299 INFO org.apache.hadoop.yarn.server.resourcemanager.ApplicationMasterService: application_1615531707627_0001 unregistered successfully. 
2021-03-11 22:52:45,777 INFO org.apache.hadoop.yarn.server.resourcemanager.rmcontainer.RMContainerImpl: container_1615531707627_0001_01_000001 Container Transitioned from RUNNING to COMPLETED
2021-03-11 22:52:45,778 INFO org.apache.hadoop.yarn.server.resourcemanager.scheduler.common.fica.FiCaSchedulerApp: Completed container: container_1615531707627_0001_01_000001 in state: COMPLETED event:FINISHED
2021-03-11 22:52:45,778 INFO org.apache.hadoop.yarn.server.resourcemanager.RMAuditLogger: USER=hadoopuser	OPERATION=AM Released Container	TARGET=SchedulerApp	RESULT=SUCCESS	APPID=application_1615531707627_0001	CONTAINERID=container_1615531707627_0001_01_000001
2021-03-11 22:52:45,778 INFO org.apache.hadoop.yarn.server.resourcemanager.scheduler.SchedulerNode: Released container container_1615531707627_0001_01_000001 of capacity <memory:2048, vCores:1> on host tutrung-slave2:46601, which currently has 0 containers, <memory:0, vCores:0> used and <memory:8192, vCores:8> available, release resources=true
2021-03-11 22:52:45,778 INFO org.apache.hadoop.yarn.server.resourcemanager.scheduler.capacity.LeafQueue: default used=<memory:0, vCores:0> numContainers=0 user=hadoopuser user-resources=<memory:0, vCores:0>
2021-03-11 22:52:45,778 INFO org.apache.hadoop.yarn.server.resourcemanager.scheduler.capacity.LeafQueue: completedContainer container=Container: [ContainerId: container_1615531707627_0001_01_000001, NodeId: tutrung-slave2:46601, NodeHttpAddress: tutrung-slave2:8042, Resource: <memory:2048, vCores:1>, Priority: 0, Token: Token { kind: ContainerToken, service: 192.168.244.132:46601 }, ] queue=default: capacity=1.0, absoluteCapacity=1.0, usedResources=<memory:0, vCores:0>, usedCapacity=0.0, absoluteUsedCapacity=0.0, numApps=1, numContainers=0 cluster=<memory:16384, vCores:16>
2021-03-11 22:52:45,778 INFO org.apache.hadoop.yarn.server.resourcemanager.scheduler.capacity.ParentQueue: completedContainer queue=root usedCapacity=0.0 absoluteUsedCapacity=0.0 used=<memory:0, vCores:0> cluster=<memory:16384, vCores:16>
2021-03-11 22:52:45,778 INFO org.apache.hadoop.yarn.server.resourcemanager.scheduler.capacity.ParentQueue: Re-sorting completed queue: root.default stats: default: capacity=1.0, absoluteCapacity=1.0, usedResources=<memory:0, vCores:0>, usedCapacity=0.0, absoluteUsedCapacity=0.0, numApps=1, numContainers=0
2021-03-11 22:52:45,778 INFO org.apache.hadoop.yarn.server.resourcemanager.scheduler.capacity.CapacityScheduler: Application attempt appattempt_1615531707627_0001_000001 released container container_1615531707627_0001_01_000001 on node: host: tutrung-slave2:46601 #containers=0 available=<memory:8192, vCores:8> used=<memory:0, vCores:0> with event: FINISHED
2021-03-11 22:52:45,779 INFO org.apache.hadoop.yarn.server.resourcemanager.ApplicationMasterService: Unregistering app attempt : appattempt_1615531707627_0001_000001
2021-03-11 22:52:45,780 INFO org.apache.hadoop.yarn.server.resourcemanager.security.AMRMTokenSecretManager: Application finished, removing password for appattempt_1615531707627_0001_000001
2021-03-11 22:52:45,780 INFO org.apache.hadoop.yarn.server.resourcemanager.rmapp.attempt.RMAppAttemptImpl: appattempt_1615531707627_0001_000001 State change from FINISHING to FINISHED
2021-03-11 22:52:45,783 INFO org.apache.hadoop.yarn.server.resourcemanager.rmapp.RMAppImpl: application_1615531707627_0001 State change from FINISHING to FINISHED on event=ATTEMPT_FINISHED
2021-03-11 22:52:45,783 INFO org.apache.hadoop.yarn.server.resourcemanager.scheduler.capacity.CapacityScheduler: Application Attempt appattempt_1615531707627_0001_000001 is done. finalState=FINISHED
2021-03-11 22:52:45,784 INFO org.apache.hadoop.yarn.server.resourcemanager.scheduler.AppSchedulingInfo: Application application_1615531707627_0001 requests cleared
2021-03-11 22:52:45,784 INFO org.apache.hadoop.yarn.server.resourcemanager.scheduler.capacity.LeafQueue: Application removed - appId: application_1615531707627_0001 user: hadoopuser queue: default #user-pending-applications: 0 #user-active-applications: 0 #queue-pending-applications: 0 #queue-active-applications: 0
2021-03-11 22:52:45,784 INFO org.apache.hadoop.yarn.server.resourcemanager.scheduler.capacity.ParentQueue: Application removed - appId: application_1615531707627_0001 user: hadoopuser leaf-queue of parent: root #applications: 0
2021-03-11 22:52:45,785 INFO org.apache.hadoop.yarn.server.resourcemanager.amlauncher.AMLauncher: Cleaning master appattempt_1615531707627_0001_000001
2021-03-11 22:52:45,793 INFO org.apache.hadoop.yarn.server.resourcemanager.RMAuditLogger: USER=hadoopuser	OPERATION=Application Finished - Succeeded	TARGET=RMAppManager	RESULT=SUCCESS	APPID=application_1615531707627_0001
2021-03-11 22:52:45,798 INFO org.apache.hadoop.yarn.server.resourcemanager.RMAppManager$ApplicationSummary: appId=application_1615531707627_0001,name=PigLatin:script1-hadoop.pig,user=hadoopuser,queue=default,state=FINISHED,trackingUrl=http://master:8088/proxy/application_1615531707627_0001/,appMasterHost=tutrung-slave2,startTime=1615531885425,finishTime=1615531959275,finalStatus=SUCCEEDED,memorySeconds=221450,vcoreSeconds=134,preemptedAMContainers=0,preemptedNonAMContainers=0,preemptedResources=<memory:0\, vCores:0>,applicationType=MAPREDUCE
2021-03-11 22:52:47,754 INFO org.apache.hadoop.yarn.server.resourcemanager.scheduler.capacity.CapacityScheduler: Null container completed...
2021-03-11 22:54:13,980 INFO org.apache.hadoop.yarn.server.resourcemanager.ClientRMService: Allocated new applicationId: 2
2021-03-11 22:54:14,371 INFO org.apache.hadoop.yarn.server.resourcemanager.ClientRMService: Application with id 2 submitted by user hadoopuser
2021-03-11 22:54:14,371 INFO org.apache.hadoop.yarn.server.resourcemanager.RMAuditLogger: USER=hadoopuser	IP=192.168.244.130	OPERATION=Submit Application Request	TARGET=ClientRMService	RESULT=SUCCESS	APPID=application_1615531707627_0002
2021-03-11 22:54:14,372 INFO org.apache.hadoop.yarn.server.resourcemanager.rmapp.RMAppImpl: Storing application with id application_1615531707627_0002
2021-03-11 22:54:14,372 INFO org.apache.hadoop.yarn.server.resourcemanager.rmapp.RMAppImpl: application_1615531707627_0002 State change from NEW to NEW_SAVING on event=START
2021-03-11 22:54:14,372 INFO org.apache.hadoop.yarn.server.resourcemanager.recovery.RMStateStore: Storing info for app: application_1615531707627_0002
2021-03-11 22:54:14,372 INFO org.apache.hadoop.yarn.server.resourcemanager.rmapp.RMAppImpl: application_1615531707627_0002 State change from NEW_SAVING to SUBMITTED on event=APP_NEW_SAVED
2021-03-11 22:54:14,373 INFO org.apache.hadoop.yarn.server.resourcemanager.scheduler.capacity.ParentQueue: Application added - appId: application_1615531707627_0002 user: hadoopuser leaf-queue of parent: root #applications: 1
2021-03-11 22:54:14,373 INFO org.apache.hadoop.yarn.server.resourcemanager.scheduler.capacity.CapacityScheduler: Accepted application application_1615531707627_0002 from user: hadoopuser, in queue: default
2021-03-11 22:54:14,375 INFO org.apache.hadoop.yarn.server.resourcemanager.rmapp.RMAppImpl: application_1615531707627_0002 State change from SUBMITTED to ACCEPTED on event=APP_ACCEPTED
2021-03-11 22:54:14,375 INFO org.apache.hadoop.yarn.server.resourcemanager.ApplicationMasterService: Registering app attempt : appattempt_1615531707627_0002_000001
2021-03-11 22:54:14,375 INFO org.apache.hadoop.yarn.server.resourcemanager.rmapp.attempt.RMAppAttemptImpl: appattempt_1615531707627_0002_000001 State change from NEW to SUBMITTED
2021-03-11 22:54:14,375 INFO org.apache.hadoop.yarn.server.resourcemanager.scheduler.capacity.LeafQueue: Application application_1615531707627_0002 from user: hadoopuser activated in queue: default
2021-03-11 22:54:14,375 INFO org.apache.hadoop.yarn.server.resourcemanager.scheduler.capacity.LeafQueue: Application added - appId: application_1615531707627_0002 user: org.apache.hadoop.yarn.server.resourcemanager.scheduler.capacity.LeafQueue$User@381eecec, leaf-queue: default #user-pending-applications: 0 #user-active-applications: 1 #queue-pending-applications: 0 #queue-active-applications: 1
2021-03-11 22:54:14,375 INFO org.apache.hadoop.yarn.server.resourcemanager.scheduler.capacity.CapacityScheduler: Added Application Attempt appattempt_1615531707627_0002_000001 to scheduler from user hadoopuser in queue default
2021-03-11 22:54:14,377 INFO org.apache.hadoop.yarn.server.resourcemanager.rmapp.attempt.RMAppAttemptImpl: appattempt_1615531707627_0002_000001 State change from SUBMITTED to SCHEDULED
2021-03-11 22:54:14,388 INFO org.apache.hadoop.yarn.server.resourcemanager.rmcontainer.RMContainerImpl: container_1615531707627_0002_01_000001 Container Transitioned from NEW to ALLOCATED
2021-03-11 22:54:14,388 INFO org.apache.hadoop.yarn.server.resourcemanager.RMAuditLogger: USER=hadoopuser	OPERATION=AM Allocated Container	TARGET=SchedulerApp	RESULT=SUCCESS	APPID=application_1615531707627_0002	CONTAINERID=container_1615531707627_0002_01_000001
2021-03-11 22:54:14,388 INFO org.apache.hadoop.yarn.server.resourcemanager.scheduler.SchedulerNode: Assigned container container_1615531707627_0002_01_000001 of capacity <memory:2048, vCores:1> on host tutrung-slave2:46601, which has 1 containers, <memory:2048, vCores:1> used and <memory:6144, vCores:7> available after allocation
2021-03-11 22:54:14,388 INFO org.apache.hadoop.yarn.server.resourcemanager.scheduler.capacity.LeafQueue: assignedContainer application attempt=appattempt_1615531707627_0002_000001 container=Container: [ContainerId: container_1615531707627_0002_01_000001, NodeId: tutrung-slave2:46601, NodeHttpAddress: tutrung-slave2:8042, Resource: <memory:2048, vCores:1>, Priority: 0, Token: null, ] queue=default: capacity=1.0, absoluteCapacity=1.0, usedResources=<memory:0, vCores:0>, usedCapacity=0.0, absoluteUsedCapacity=0.0, numApps=1, numContainers=0 clusterResource=<memory:16384, vCores:16> type=OFF_SWITCH requestedPartition=
2021-03-11 22:54:14,389 INFO org.apache.hadoop.yarn.server.resourcemanager.scheduler.capacity.ParentQueue: Re-sorting assigned queue: root.default stats: default: capacity=1.0, absoluteCapacity=1.0, usedResources=<memory:2048, vCores:1>, usedCapacity=0.125, absoluteUsedCapacity=0.125, numApps=1, numContainers=1
2021-03-11 22:54:14,389 INFO org.apache.hadoop.yarn.server.resourcemanager.scheduler.capacity.ParentQueue: assignedContainer queue=root usedCapacity=0.125 absoluteUsedCapacity=0.125 used=<memory:2048, vCores:1> cluster=<memory:16384, vCores:16>
2021-03-11 22:54:14,393 INFO org.apache.hadoop.yarn.server.resourcemanager.security.NMTokenSecretManagerInRM: Sending NMToken for nodeId : tutrung-slave2:46601 for container : container_1615531707627_0002_01_000001
2021-03-11 22:54:14,394 INFO org.apache.hadoop.yarn.server.resourcemanager.rmcontainer.RMContainerImpl: container_1615531707627_0002_01_000001 Container Transitioned from ALLOCATED to ACQUIRED
2021-03-11 22:54:14,394 INFO org.apache.hadoop.yarn.server.resourcemanager.security.NMTokenSecretManagerInRM: Clear node set for appattempt_1615531707627_0002_000001
2021-03-11 22:54:14,394 INFO org.apache.hadoop.yarn.server.resourcemanager.rmapp.attempt.RMAppAttemptImpl: Storing attempt: AppId: application_1615531707627_0002 AttemptId: appattempt_1615531707627_0002_000001 MasterContainer: Container: [ContainerId: container_1615531707627_0002_01_000001, NodeId: tutrung-slave2:46601, NodeHttpAddress: tutrung-slave2:8042, Resource: <memory:2048, vCores:1>, Priority: 0, Token: Token { kind: ContainerToken, service: 192.168.244.132:46601 }, ]
2021-03-11 22:54:14,395 INFO org.apache.hadoop.yarn.server.resourcemanager.rmapp.attempt.RMAppAttemptImpl: appattempt_1615531707627_0002_000001 State change from SCHEDULED to ALLOCATED_SAVING
2021-03-11 22:54:14,395 INFO org.apache.hadoop.yarn.server.resourcemanager.rmapp.attempt.RMAppAttemptImpl: appattempt_1615531707627_0002_000001 State change from ALLOCATED_SAVING to ALLOCATED
2021-03-11 22:54:14,397 INFO org.apache.hadoop.yarn.server.resourcemanager.amlauncher.AMLauncher: Launching masterappattempt_1615531707627_0002_000001
2021-03-11 22:54:14,404 INFO org.apache.hadoop.yarn.server.resourcemanager.amlauncher.AMLauncher: Setting up container Container: [ContainerId: container_1615531707627_0002_01_000001, NodeId: tutrung-slave2:46601, NodeHttpAddress: tutrung-slave2:8042, Resource: <memory:2048, vCores:1>, Priority: 0, Token: Token { kind: ContainerToken, service: 192.168.244.132:46601 }, ] for AM appattempt_1615531707627_0002_000001
2021-03-11 22:54:14,404 INFO org.apache.hadoop.yarn.server.resourcemanager.amlauncher.AMLauncher: Command to launch container container_1615531707627_0002_01_000001 : $JAVA_HOME/bin/java -Djava.io.tmpdir=$PWD/tmp -Dlog4j.configuration=container-log4j.properties -Dyarn.app.container.log.dir=<LOG_DIR> -Dyarn.app.container.log.filesize=0 -Dhadoop.root.logger=INFO,CLA -Dhadoop.root.logfile=syslog  -Xmx1024m org.apache.hadoop.mapreduce.v2.app.MRAppMaster 1><LOG_DIR>/stdout 2><LOG_DIR>/stderr 
2021-03-11 22:54:14,405 INFO org.apache.hadoop.yarn.server.resourcemanager.security.AMRMTokenSecretManager: Create AMRMToken for ApplicationAttempt: appattempt_1615531707627_0002_000001
2021-03-11 22:54:14,405 INFO org.apache.hadoop.yarn.server.resourcemanager.security.AMRMTokenSecretManager: Creating password for appattempt_1615531707627_0002_000001
2021-03-11 22:54:14,428 INFO org.apache.hadoop.yarn.server.resourcemanager.amlauncher.AMLauncher: Done launching container Container: [ContainerId: container_1615531707627_0002_01_000001, NodeId: tutrung-slave2:46601, NodeHttpAddress: tutrung-slave2:8042, Resource: <memory:2048, vCores:1>, Priority: 0, Token: Token { kind: ContainerToken, service: 192.168.244.132:46601 }, ] for AM appattempt_1615531707627_0002_000001
2021-03-11 22:54:14,428 INFO org.apache.hadoop.yarn.server.resourcemanager.rmapp.attempt.RMAppAttemptImpl: appattempt_1615531707627_0002_000001 State change from ALLOCATED to LAUNCHED
2021-03-11 22:54:15,390 INFO org.apache.hadoop.yarn.server.resourcemanager.rmcontainer.RMContainerImpl: container_1615531707627_0002_01_000001 Container Transitioned from ACQUIRED to RUNNING
2021-03-11 22:54:23,621 INFO SecurityLogger.org.apache.hadoop.ipc.Server: Auth successful for appattempt_1615531707627_0002_000001 (auth:SIMPLE)
2021-03-11 22:54:23,624 INFO org.apache.hadoop.yarn.server.resourcemanager.ApplicationMasterService: AM registration appattempt_1615531707627_0002_000001
2021-03-11 22:54:23,624 INFO org.apache.hadoop.yarn.server.resourcemanager.RMAuditLogger: USER=hadoopuser	IP=192.168.244.132	OPERATION=Register App Master	TARGET=ApplicationMasterService	RESULT=SUCCESS	APPID=application_1615531707627_0002	APPATTEMPTID=appattempt_1615531707627_0002_000001
2021-03-11 22:54:23,625 INFO org.apache.hadoop.yarn.server.resourcemanager.rmapp.attempt.RMAppAttemptImpl: appattempt_1615531707627_0002_000001 State change from LAUNCHED to RUNNING
2021-03-11 22:54:23,625 INFO org.apache.hadoop.yarn.server.resourcemanager.rmapp.RMAppImpl: application_1615531707627_0002 State change from ACCEPTED to RUNNING on event=ATTEMPT_REGISTERED
2021-03-11 22:54:25,423 INFO org.apache.hadoop.yarn.server.resourcemanager.rmcontainer.RMContainerImpl: container_1615531707627_0002_01_000002 Container Transitioned from NEW to ALLOCATED
2021-03-11 22:54:25,424 INFO org.apache.hadoop.yarn.server.resourcemanager.RMAuditLogger: USER=hadoopuser	OPERATION=AM Allocated Container	TARGET=SchedulerApp	RESULT=SUCCESS	APPID=application_1615531707627_0002	CONTAINERID=container_1615531707627_0002_01_000002
2021-03-11 22:54:25,424 INFO org.apache.hadoop.yarn.server.resourcemanager.scheduler.SchedulerNode: Assigned container container_1615531707627_0002_01_000002 of capacity <memory:1024, vCores:1> on host tutrung-slave2:46601, which has 2 containers, <memory:3072, vCores:2> used and <memory:5120, vCores:6> available after allocation
2021-03-11 22:54:25,424 INFO org.apache.hadoop.yarn.server.resourcemanager.scheduler.capacity.LeafQueue: assignedContainer application attempt=appattempt_1615531707627_0002_000001 container=Container: [ContainerId: container_1615531707627_0002_01_000002, NodeId: tutrung-slave2:46601, NodeHttpAddress: tutrung-slave2:8042, Resource: <memory:1024, vCores:1>, Priority: 20, Token: null, ] queue=default: capacity=1.0, absoluteCapacity=1.0, usedResources=<memory:2048, vCores:1>, usedCapacity=0.125, absoluteUsedCapacity=0.125, numApps=1, numContainers=1 clusterResource=<memory:16384, vCores:16> type=NODE_LOCAL requestedPartition=
2021-03-11 22:54:25,424 INFO org.apache.hadoop.yarn.server.resourcemanager.scheduler.capacity.ParentQueue: Re-sorting assigned queue: root.default stats: default: capacity=1.0, absoluteCapacity=1.0, usedResources=<memory:3072, vCores:2>, usedCapacity=0.1875, absoluteUsedCapacity=0.1875, numApps=1, numContainers=2
2021-03-11 22:54:25,431 INFO org.apache.hadoop.yarn.server.resourcemanager.scheduler.capacity.ParentQueue: assignedContainer queue=root usedCapacity=0.1875 absoluteUsedCapacity=0.1875 used=<memory:3072, vCores:2> cluster=<memory:16384, vCores:16>
2021-03-11 22:54:25,667 INFO org.apache.hadoop.yarn.server.resourcemanager.security.NMTokenSecretManagerInRM: Sending NMToken for nodeId : tutrung-slave2:46601 for container : container_1615531707627_0002_01_000002
2021-03-11 22:54:25,668 INFO org.apache.hadoop.yarn.server.resourcemanager.rmcontainer.RMContainerImpl: container_1615531707627_0002_01_000002 Container Transitioned from ALLOCATED to ACQUIRED
2021-03-11 22:54:26,427 INFO org.apache.hadoop.yarn.server.resourcemanager.rmcontainer.RMContainerImpl: container_1615531707627_0002_01_000002 Container Transitioned from ACQUIRED to RUNNING
2021-03-11 22:54:26,687 INFO org.apache.hadoop.yarn.server.resourcemanager.scheduler.AppSchedulingInfo: checking for deactivate of application :application_1615531707627_0002
2021-03-11 22:54:42,816 INFO org.apache.hadoop.yarn.server.resourcemanager.rmcontainer.RMContainerImpl: container_1615531707627_0002_01_000002 Container Transitioned from RUNNING to COMPLETED
2021-03-11 22:54:42,816 INFO org.apache.hadoop.yarn.server.resourcemanager.scheduler.common.fica.FiCaSchedulerApp: Completed container: container_1615531707627_0002_01_000002 in state: COMPLETED event:FINISHED
2021-03-11 22:54:42,816 INFO org.apache.hadoop.yarn.server.resourcemanager.RMAuditLogger: USER=hadoopuser	OPERATION=AM Released Container	TARGET=SchedulerApp	RESULT=SUCCESS	APPID=application_1615531707627_0002	CONTAINERID=container_1615531707627_0002_01_000002
2021-03-11 22:54:42,816 INFO org.apache.hadoop.yarn.server.resourcemanager.scheduler.SchedulerNode: Released container container_1615531707627_0002_01_000002 of capacity <memory:1024, vCores:1> on host tutrung-slave2:46601, which currently has 1 containers, <memory:2048, vCores:1> used and <memory:6144, vCores:7> available, release resources=true
2021-03-11 22:54:42,817 INFO org.apache.hadoop.yarn.server.resourcemanager.scheduler.capacity.LeafQueue: default used=<memory:2048, vCores:1> numContainers=1 user=hadoopuser user-resources=<memory:2048, vCores:1>
2021-03-11 22:54:42,817 INFO org.apache.hadoop.yarn.server.resourcemanager.scheduler.capacity.LeafQueue: completedContainer container=Container: [ContainerId: container_1615531707627_0002_01_000002, NodeId: tutrung-slave2:46601, NodeHttpAddress: tutrung-slave2:8042, Resource: <memory:1024, vCores:1>, Priority: 20, Token: Token { kind: ContainerToken, service: 192.168.244.132:46601 }, ] queue=default: capacity=1.0, absoluteCapacity=1.0, usedResources=<memory:2048, vCores:1>, usedCapacity=0.125, absoluteUsedCapacity=0.125, numApps=1, numContainers=1 cluster=<memory:16384, vCores:16>
2021-03-11 22:54:42,817 INFO org.apache.hadoop.yarn.server.resourcemanager.scheduler.capacity.ParentQueue: completedContainer queue=root usedCapacity=0.125 absoluteUsedCapacity=0.125 used=<memory:2048, vCores:1> cluster=<memory:16384, vCores:16>
2021-03-11 22:54:42,817 INFO org.apache.hadoop.yarn.server.resourcemanager.scheduler.capacity.ParentQueue: Re-sorting completed queue: root.default stats: default: capacity=1.0, absoluteCapacity=1.0, usedResources=<memory:2048, vCores:1>, usedCapacity=0.125, absoluteUsedCapacity=0.125, numApps=1, numContainers=1
2021-03-11 22:54:42,817 INFO org.apache.hadoop.yarn.server.resourcemanager.scheduler.capacity.CapacityScheduler: Application attempt appattempt_1615531707627_0002_000001 released container container_1615531707627_0002_01_000002 on node: host: tutrung-slave2:46601 #containers=1 available=<memory:6144, vCores:7> used=<memory:2048, vCores:1> with event: FINISHED
2021-03-11 22:54:43,818 INFO org.apache.hadoop.yarn.server.resourcemanager.rmcontainer.RMContainerImpl: container_1615531707627_0002_01_000003 Container Transitioned from NEW to ALLOCATED
2021-03-11 22:54:43,819 INFO org.apache.hadoop.yarn.server.resourcemanager.RMAuditLogger: USER=hadoopuser	OPERATION=AM Allocated Container	TARGET=SchedulerApp	RESULT=SUCCESS	APPID=application_1615531707627_0002	CONTAINERID=container_1615531707627_0002_01_000003
2021-03-11 22:54:43,819 INFO org.apache.hadoop.yarn.server.resourcemanager.scheduler.SchedulerNode: Assigned container container_1615531707627_0002_01_000003 of capacity <memory:1024, vCores:1> on host tutrung-slave2:46601, which has 2 containers, <memory:3072, vCores:2> used and <memory:5120, vCores:6> available after allocation
2021-03-11 22:54:43,819 INFO org.apache.hadoop.yarn.server.resourcemanager.scheduler.capacity.LeafQueue: assignedContainer application attempt=appattempt_1615531707627_0002_000001 container=Container: [ContainerId: container_1615531707627_0002_01_000003, NodeId: tutrung-slave2:46601, NodeHttpAddress: tutrung-slave2:8042, Resource: <memory:1024, vCores:1>, Priority: 10, Token: null, ] queue=default: capacity=1.0, absoluteCapacity=1.0, usedResources=<memory:2048, vCores:1>, usedCapacity=0.125, absoluteUsedCapacity=0.125, numApps=1, numContainers=1 clusterResource=<memory:16384, vCores:16> type=OFF_SWITCH requestedPartition=
2021-03-11 22:54:43,819 INFO org.apache.hadoop.yarn.server.resourcemanager.scheduler.capacity.ParentQueue: Re-sorting assigned queue: root.default stats: default: capacity=1.0, absoluteCapacity=1.0, usedResources=<memory:3072, vCores:2>, usedCapacity=0.1875, absoluteUsedCapacity=0.1875, numApps=1, numContainers=2
2021-03-11 22:54:43,819 INFO org.apache.hadoop.yarn.server.resourcemanager.scheduler.capacity.ParentQueue: assignedContainer queue=root usedCapacity=0.1875 absoluteUsedCapacity=0.1875 used=<memory:3072, vCores:2> cluster=<memory:16384, vCores:16>
2021-03-11 22:54:44,754 INFO org.apache.hadoop.yarn.server.resourcemanager.rmcontainer.RMContainerImpl: container_1615531707627_0002_01_000003 Container Transitioned from ALLOCATED to ACQUIRED
2021-03-11 22:54:44,820 INFO org.apache.hadoop.yarn.server.resourcemanager.rmcontainer.RMContainerImpl: container_1615531707627_0002_01_000003 Container Transitioned from ACQUIRED to RUNNING
2021-03-11 22:54:45,841 INFO org.apache.hadoop.yarn.server.resourcemanager.scheduler.AppSchedulingInfo: checking for deactivate of application :application_1615531707627_0002
2021-03-11 22:54:56,001 INFO org.apache.hadoop.yarn.server.resourcemanager.rmcontainer.RMContainerImpl: container_1615531707627_0002_01_000003 Container Transitioned from RUNNING to COMPLETED
2021-03-11 22:54:56,001 INFO org.apache.hadoop.yarn.server.resourcemanager.scheduler.common.fica.FiCaSchedulerApp: Completed container: container_1615531707627_0002_01_000003 in state: COMPLETED event:FINISHED
2021-03-11 22:54:56,001 INFO org.apache.hadoop.yarn.server.resourcemanager.RMAuditLogger: USER=hadoopuser	OPERATION=AM Released Container	TARGET=SchedulerApp	RESULT=SUCCESS	APPID=application_1615531707627_0002	CONTAINERID=container_1615531707627_0002_01_000003
2021-03-11 22:54:56,001 INFO org.apache.hadoop.yarn.server.resourcemanager.scheduler.SchedulerNode: Released container container_1615531707627_0002_01_000003 of capacity <memory:1024, vCores:1> on host tutrung-slave2:46601, which currently has 1 containers, <memory:2048, vCores:1> used and <memory:6144, vCores:7> available, release resources=true
2021-03-11 22:54:56,001 INFO org.apache.hadoop.yarn.server.resourcemanager.scheduler.capacity.LeafQueue: default used=<memory:2048, vCores:1> numContainers=1 user=hadoopuser user-resources=<memory:2048, vCores:1>
2021-03-11 22:54:56,001 INFO org.apache.hadoop.yarn.server.resourcemanager.scheduler.capacity.LeafQueue: completedContainer container=Container: [ContainerId: container_1615531707627_0002_01_000003, NodeId: tutrung-slave2:46601, NodeHttpAddress: tutrung-slave2:8042, Resource: <memory:1024, vCores:1>, Priority: 10, Token: Token { kind: ContainerToken, service: 192.168.244.132:46601 }, ] queue=default: capacity=1.0, absoluteCapacity=1.0, usedResources=<memory:2048, vCores:1>, usedCapacity=0.125, absoluteUsedCapacity=0.125, numApps=1, numContainers=1 cluster=<memory:16384, vCores:16>
2021-03-11 22:54:56,001 INFO org.apache.hadoop.yarn.server.resourcemanager.scheduler.capacity.ParentQueue: completedContainer queue=root usedCapacity=0.125 absoluteUsedCapacity=0.125 used=<memory:2048, vCores:1> cluster=<memory:16384, vCores:16>
2021-03-11 22:54:56,001 INFO org.apache.hadoop.yarn.server.resourcemanager.scheduler.capacity.ParentQueue: Re-sorting completed queue: root.default stats: default: capacity=1.0, absoluteCapacity=1.0, usedResources=<memory:2048, vCores:1>, usedCapacity=0.125, absoluteUsedCapacity=0.125, numApps=1, numContainers=1
2021-03-11 22:54:56,001 INFO org.apache.hadoop.yarn.server.resourcemanager.scheduler.capacity.CapacityScheduler: Application attempt appattempt_1615531707627_0002_000001 released container container_1615531707627_0002_01_000003 on node: host: tutrung-slave2:46601 #containers=1 available=<memory:6144, vCores:7> used=<memory:2048, vCores:1> with event: FINISHED
2021-03-11 22:54:56,213 INFO org.apache.hadoop.yarn.server.resourcemanager.rmapp.attempt.RMAppAttemptImpl: Updating application attempt appattempt_1615531707627_0002_000001 with final state: FINISHING, and exit status: -1000
2021-03-11 22:54:56,214 INFO org.apache.hadoop.yarn.server.resourcemanager.rmapp.attempt.RMAppAttemptImpl: appattempt_1615531707627_0002_000001 State change from RUNNING to FINAL_SAVING
2021-03-11 22:54:56,214 INFO org.apache.hadoop.yarn.server.resourcemanager.rmapp.attempt.RMAppAttemptImpl: appattempt_1615531707627_0002_000001 State change from FINAL_SAVING to FINISHING
2021-03-11 22:54:56,214 INFO org.apache.hadoop.yarn.server.resourcemanager.rmapp.RMAppImpl: Updating application application_1615531707627_0002 with final state: FINISHING
2021-03-11 22:54:56,214 INFO org.apache.hadoop.yarn.server.resourcemanager.recovery.RMStateStore: Updating info for app: application_1615531707627_0002
2021-03-11 22:54:56,215 INFO org.apache.hadoop.yarn.server.resourcemanager.rmapp.RMAppImpl: application_1615531707627_0002 State change from RUNNING to FINAL_SAVING on event=ATTEMPT_UNREGISTERED
2021-03-11 22:54:56,215 INFO org.apache.hadoop.yarn.server.resourcemanager.rmapp.RMAppImpl: application_1615531707627_0002 State change from FINAL_SAVING to FINISHING on event=APP_UPDATE_SAVED
2021-03-11 22:54:57,219 INFO org.apache.hadoop.yarn.server.resourcemanager.ApplicationMasterService: application_1615531707627_0002 unregistered successfully. 
2021-03-11 22:55:02,766 INFO org.apache.hadoop.yarn.server.resourcemanager.rmcontainer.RMContainerImpl: container_1615531707627_0002_01_000001 Container Transitioned from RUNNING to COMPLETED
2021-03-11 22:55:02,766 INFO org.apache.hadoop.yarn.server.resourcemanager.scheduler.common.fica.FiCaSchedulerApp: Completed container: container_1615531707627_0002_01_000001 in state: COMPLETED event:FINISHED
2021-03-11 22:55:02,767 INFO org.apache.hadoop.yarn.server.resourcemanager.RMAuditLogger: USER=hadoopuser	OPERATION=AM Released Container	TARGET=SchedulerApp	RESULT=SUCCESS	APPID=application_1615531707627_0002	CONTAINERID=container_1615531707627_0002_01_000001
2021-03-11 22:55:02,768 INFO org.apache.hadoop.yarn.server.resourcemanager.scheduler.SchedulerNode: Released container container_1615531707627_0002_01_000001 of capacity <memory:2048, vCores:1> on host tutrung-slave2:46601, which currently has 0 containers, <memory:0, vCores:0> used and <memory:8192, vCores:8> available, release resources=true
2021-03-11 22:55:02,769 INFO org.apache.hadoop.yarn.server.resourcemanager.ApplicationMasterService: Unregistering app attempt : appattempt_1615531707627_0002_000001
2021-03-11 22:55:02,769 INFO org.apache.hadoop.yarn.server.resourcemanager.security.AMRMTokenSecretManager: Application finished, removing password for appattempt_1615531707627_0002_000001
2021-03-11 22:55:02,770 INFO org.apache.hadoop.yarn.server.resourcemanager.rmapp.attempt.RMAppAttemptImpl: appattempt_1615531707627_0002_000001 State change from FINISHING to FINISHED
2021-03-11 22:55:02,770 INFO org.apache.hadoop.yarn.server.resourcemanager.rmapp.RMAppImpl: application_1615531707627_0002 State change from FINISHING to FINISHED on event=ATTEMPT_FINISHED
2021-03-11 22:55:02,770 INFO org.apache.hadoop.yarn.server.resourcemanager.RMAuditLogger: USER=hadoopuser	OPERATION=Application Finished - Succeeded	TARGET=RMAppManager	RESULT=SUCCESS	APPID=application_1615531707627_0002
2021-03-11 22:55:02,771 INFO org.apache.hadoop.yarn.server.resourcemanager.scheduler.capacity.LeafQueue: default used=<memory:0, vCores:0> numContainers=0 user=hadoopuser user-resources=<memory:0, vCores:0>
2021-03-11 22:55:02,771 INFO org.apache.hadoop.yarn.server.resourcemanager.scheduler.capacity.LeafQueue: completedContainer container=Container: [ContainerId: container_1615531707627_0002_01_000001, NodeId: tutrung-slave2:46601, NodeHttpAddress: tutrung-slave2:8042, Resource: <memory:2048, vCores:1>, Priority: 0, Token: Token { kind: ContainerToken, service: 192.168.244.132:46601 }, ] queue=default: capacity=1.0, absoluteCapacity=1.0, usedResources=<memory:0, vCores:0>, usedCapacity=0.0, absoluteUsedCapacity=0.0, numApps=1, numContainers=0 cluster=<memory:16384, vCores:16>
2021-03-11 22:55:02,771 INFO org.apache.hadoop.yarn.server.resourcemanager.scheduler.capacity.ParentQueue: completedContainer queue=root usedCapacity=0.0 absoluteUsedCapacity=0.0 used=<memory:0, vCores:0> cluster=<memory:16384, vCores:16>
2021-03-11 22:55:02,777 INFO org.apache.hadoop.yarn.server.resourcemanager.scheduler.capacity.ParentQueue: Re-sorting completed queue: root.default stats: default: capacity=1.0, absoluteCapacity=1.0, usedResources=<memory:0, vCores:0>, usedCapacity=0.0, absoluteUsedCapacity=0.0, numApps=1, numContainers=0
2021-03-11 22:55:02,777 INFO org.apache.hadoop.yarn.server.resourcemanager.scheduler.capacity.CapacityScheduler: Application attempt appattempt_1615531707627_0002_000001 released container container_1615531707627_0002_01_000001 on node: host: tutrung-slave2:46601 #containers=0 available=<memory:8192, vCores:8> used=<memory:0, vCores:0> with event: FINISHED
2021-03-11 22:55:02,778 INFO org.apache.hadoop.yarn.server.resourcemanager.scheduler.capacity.CapacityScheduler: Application Attempt appattempt_1615531707627_0002_000001 is done. finalState=FINISHED
2021-03-11 22:55:02,778 INFO org.apache.hadoop.yarn.server.resourcemanager.scheduler.AppSchedulingInfo: Application application_1615531707627_0002 requests cleared
2021-03-11 22:55:02,778 INFO org.apache.hadoop.yarn.server.resourcemanager.scheduler.capacity.LeafQueue: Application removed - appId: application_1615531707627_0002 user: hadoopuser queue: default #user-pending-applications: 0 #user-active-applications: 0 #queue-pending-applications: 0 #queue-active-applications: 0
2021-03-11 22:55:02,778 INFO org.apache.hadoop.yarn.server.resourcemanager.scheduler.capacity.ParentQueue: Application removed - appId: application_1615531707627_0002 user: hadoopuser leaf-queue of parent: root #applications: 0
2021-03-11 22:55:02,782 INFO org.apache.hadoop.yarn.server.resourcemanager.RMAppManager$ApplicationSummary: appId=application_1615531707627_0002,name=PigLatin:script1-hadoop.pig,user=hadoopuser,queue=default,state=FINISHED,trackingUrl=http://master:8088/proxy/application_1615531707627_0002/,appMasterHost=tutrung-slave2,startTime=1615532054371,finishTime=1615532096214,finalStatus=SUCCEEDED,memorySeconds=129364,vcoreSeconds=77,preemptedAMContainers=0,preemptedNonAMContainers=0,preemptedResources=<memory:0\, vCores:0>,applicationType=MAPREDUCE
2021-03-11 22:55:02,784 INFO org.apache.hadoop.yarn.server.resourcemanager.amlauncher.AMLauncher: Cleaning master appattempt_1615531707627_0002_000001
2021-03-11 22:55:04,770 INFO org.apache.hadoop.yarn.server.resourcemanager.scheduler.capacity.CapacityScheduler: Null container completed...
2021-03-11 22:56:32,266 INFO org.apache.hadoop.yarn.server.resourcemanager.ClientRMService: Allocated new applicationId: 3
2021-03-11 22:56:32,802 INFO org.apache.hadoop.yarn.server.resourcemanager.ClientRMService: Application with id 3 submitted by user hadoopuser
2021-03-11 22:56:32,803 INFO org.apache.hadoop.yarn.server.resourcemanager.rmapp.RMAppImpl: Storing application with id application_1615531707627_0003
2021-03-11 22:56:32,803 INFO org.apache.hadoop.yarn.server.resourcemanager.RMAuditLogger: USER=hadoopuser	IP=192.168.244.130	OPERATION=Submit Application Request	TARGET=ClientRMService	RESULT=SUCCESS	APPID=application_1615531707627_0003
2021-03-11 22:56:32,803 INFO org.apache.hadoop.yarn.server.resourcemanager.rmapp.RMAppImpl: application_1615531707627_0003 State change from NEW to NEW_SAVING on event=START
2021-03-11 22:56:32,804 INFO org.apache.hadoop.yarn.server.resourcemanager.recovery.RMStateStore: Storing info for app: application_1615531707627_0003
2021-03-11 22:56:32,804 INFO org.apache.hadoop.yarn.server.resourcemanager.rmapp.RMAppImpl: application_1615531707627_0003 State change from NEW_SAVING to SUBMITTED on event=APP_NEW_SAVED
2021-03-11 22:56:32,804 INFO org.apache.hadoop.yarn.server.resourcemanager.scheduler.capacity.ParentQueue: Application added - appId: application_1615531707627_0003 user: hadoopuser leaf-queue of parent: root #applications: 1
2021-03-11 22:56:32,804 INFO org.apache.hadoop.yarn.server.resourcemanager.scheduler.capacity.CapacityScheduler: Accepted application application_1615531707627_0003 from user: hadoopuser, in queue: default
2021-03-11 22:56:32,805 INFO org.apache.hadoop.yarn.server.resourcemanager.rmapp.RMAppImpl: application_1615531707627_0003 State change from SUBMITTED to ACCEPTED on event=APP_ACCEPTED
2021-03-11 22:56:32,805 INFO org.apache.hadoop.yarn.server.resourcemanager.ApplicationMasterService: Registering app attempt : appattempt_1615531707627_0003_000001
2021-03-11 22:56:32,805 INFO org.apache.hadoop.yarn.server.resourcemanager.rmapp.attempt.RMAppAttemptImpl: appattempt_1615531707627_0003_000001 State change from NEW to SUBMITTED
2021-03-11 22:56:32,805 INFO org.apache.hadoop.yarn.server.resourcemanager.scheduler.capacity.LeafQueue: Application application_1615531707627_0003 from user: hadoopuser activated in queue: default
2021-03-11 22:56:32,805 INFO org.apache.hadoop.yarn.server.resourcemanager.scheduler.capacity.LeafQueue: Application added - appId: application_1615531707627_0003 user: org.apache.hadoop.yarn.server.resourcemanager.scheduler.capacity.LeafQueue$User@3aef5adf, leaf-queue: default #user-pending-applications: 0 #user-active-applications: 1 #queue-pending-applications: 0 #queue-active-applications: 1
2021-03-11 22:56:32,805 INFO org.apache.hadoop.yarn.server.resourcemanager.scheduler.capacity.CapacityScheduler: Added Application Attempt appattempt_1615531707627_0003_000001 to scheduler from user hadoopuser in queue default
2021-03-11 22:56:32,806 INFO org.apache.hadoop.yarn.server.resourcemanager.rmapp.attempt.RMAppAttemptImpl: appattempt_1615531707627_0003_000001 State change from SUBMITTED to SCHEDULED
2021-03-11 22:56:33,187 INFO org.apache.hadoop.yarn.server.resourcemanager.rmcontainer.RMContainerImpl: container_1615531707627_0003_01_000001 Container Transitioned from NEW to ALLOCATED
2021-03-11 22:56:33,187 INFO org.apache.hadoop.yarn.server.resourcemanager.RMAuditLogger: USER=hadoopuser	OPERATION=AM Allocated Container	TARGET=SchedulerApp	RESULT=SUCCESS	APPID=application_1615531707627_0003	CONTAINERID=container_1615531707627_0003_01_000001
2021-03-11 22:56:33,188 INFO org.apache.hadoop.yarn.server.resourcemanager.scheduler.SchedulerNode: Assigned container container_1615531707627_0003_01_000001 of capacity <memory:2048, vCores:1> on host tutrung-slave1:33619, which has 1 containers, <memory:2048, vCores:1> used and <memory:6144, vCores:7> available after allocation
2021-03-11 22:56:33,188 INFO org.apache.hadoop.yarn.server.resourcemanager.scheduler.capacity.LeafQueue: assignedContainer application attempt=appattempt_1615531707627_0003_000001 container=Container: [ContainerId: container_1615531707627_0003_01_000001, NodeId: tutrung-slave1:33619, NodeHttpAddress: tutrung-slave1:8042, Resource: <memory:2048, vCores:1>, Priority: 0, Token: null, ] queue=default: capacity=1.0, absoluteCapacity=1.0, usedResources=<memory:0, vCores:0>, usedCapacity=0.0, absoluteUsedCapacity=0.0, numApps=1, numContainers=0 clusterResource=<memory:16384, vCores:16> type=OFF_SWITCH requestedPartition=
2021-03-11 22:56:33,188 INFO org.apache.hadoop.yarn.server.resourcemanager.scheduler.capacity.ParentQueue: Re-sorting assigned queue: root.default stats: default: capacity=1.0, absoluteCapacity=1.0, usedResources=<memory:2048, vCores:1>, usedCapacity=0.125, absoluteUsedCapacity=0.125, numApps=1, numContainers=1
2021-03-11 22:56:33,188 INFO org.apache.hadoop.yarn.server.resourcemanager.scheduler.capacity.ParentQueue: assignedContainer queue=root usedCapacity=0.125 absoluteUsedCapacity=0.125 used=<memory:2048, vCores:1> cluster=<memory:16384, vCores:16>
2021-03-11 22:56:33,189 INFO org.apache.hadoop.yarn.server.resourcemanager.security.NMTokenSecretManagerInRM: Sending NMToken for nodeId : tutrung-slave1:33619 for container : container_1615531707627_0003_01_000001
2021-03-11 22:56:33,190 INFO org.apache.hadoop.yarn.server.resourcemanager.rmcontainer.RMContainerImpl: container_1615531707627_0003_01_000001 Container Transitioned from ALLOCATED to ACQUIRED
2021-03-11 22:56:33,190 INFO org.apache.hadoop.yarn.server.resourcemanager.security.NMTokenSecretManagerInRM: Clear node set for appattempt_1615531707627_0003_000001
2021-03-11 22:56:33,190 INFO org.apache.hadoop.yarn.server.resourcemanager.rmapp.attempt.RMAppAttemptImpl: Storing attempt: AppId: application_1615531707627_0003 AttemptId: appattempt_1615531707627_0003_000001 MasterContainer: Container: [ContainerId: container_1615531707627_0003_01_000001, NodeId: tutrung-slave1:33619, NodeHttpAddress: tutrung-slave1:8042, Resource: <memory:2048, vCores:1>, Priority: 0, Token: Token { kind: ContainerToken, service: 192.168.244.131:33619 }, ]
2021-03-11 22:56:33,190 INFO org.apache.hadoop.yarn.server.resourcemanager.rmapp.attempt.RMAppAttemptImpl: appattempt_1615531707627_0003_000001 State change from SCHEDULED to ALLOCATED_SAVING
2021-03-11 22:56:33,190 INFO org.apache.hadoop.yarn.server.resourcemanager.rmapp.attempt.RMAppAttemptImpl: appattempt_1615531707627_0003_000001 State change from ALLOCATED_SAVING to ALLOCATED
2021-03-11 22:56:33,193 INFO org.apache.hadoop.yarn.server.resourcemanager.amlauncher.AMLauncher: Launching masterappattempt_1615531707627_0003_000001
2021-03-11 22:56:33,196 INFO org.apache.hadoop.yarn.server.resourcemanager.amlauncher.AMLauncher: Setting up container Container: [ContainerId: container_1615531707627_0003_01_000001, NodeId: tutrung-slave1:33619, NodeHttpAddress: tutrung-slave1:8042, Resource: <memory:2048, vCores:1>, Priority: 0, Token: Token { kind: ContainerToken, service: 192.168.244.131:33619 }, ] for AM appattempt_1615531707627_0003_000001
2021-03-11 22:56:33,196 INFO org.apache.hadoop.yarn.server.resourcemanager.amlauncher.AMLauncher: Command to launch container container_1615531707627_0003_01_000001 : $JAVA_HOME/bin/java -Djava.io.tmpdir=$PWD/tmp -Dlog4j.configuration=container-log4j.properties -Dyarn.app.container.log.dir=<LOG_DIR> -Dyarn.app.container.log.filesize=0 -Dhadoop.root.logger=INFO,CLA -Dhadoop.root.logfile=syslog  -Xmx1024m org.apache.hadoop.mapreduce.v2.app.MRAppMaster 1><LOG_DIR>/stdout 2><LOG_DIR>/stderr 
2021-03-11 22:56:33,197 INFO org.apache.hadoop.yarn.server.resourcemanager.security.AMRMTokenSecretManager: Create AMRMToken for ApplicationAttempt: appattempt_1615531707627_0003_000001
2021-03-11 22:56:33,197 INFO org.apache.hadoop.yarn.server.resourcemanager.security.AMRMTokenSecretManager: Creating password for appattempt_1615531707627_0003_000001
2021-03-11 22:56:33,218 INFO org.apache.hadoop.yarn.server.resourcemanager.amlauncher.AMLauncher: Done launching container Container: [ContainerId: container_1615531707627_0003_01_000001, NodeId: tutrung-slave1:33619, NodeHttpAddress: tutrung-slave1:8042, Resource: <memory:2048, vCores:1>, Priority: 0, Token: Token { kind: ContainerToken, service: 192.168.244.131:33619 }, ] for AM appattempt_1615531707627_0003_000001
2021-03-11 22:56:33,218 INFO org.apache.hadoop.yarn.server.resourcemanager.rmapp.attempt.RMAppAttemptImpl: appattempt_1615531707627_0003_000001 State change from ALLOCATED to LAUNCHED
2021-03-11 22:56:34,189 INFO org.apache.hadoop.yarn.server.resourcemanager.rmcontainer.RMContainerImpl: container_1615531707627_0003_01_000001 Container Transitioned from ACQUIRED to RUNNING
2021-03-11 22:56:40,475 INFO SecurityLogger.org.apache.hadoop.ipc.Server: Auth successful for appattempt_1615531707627_0003_000001 (auth:SIMPLE)
2021-03-11 22:56:40,478 INFO org.apache.hadoop.yarn.server.resourcemanager.ApplicationMasterService: AM registration appattempt_1615531707627_0003_000001
2021-03-11 22:56:40,478 INFO org.apache.hadoop.yarn.server.resourcemanager.RMAuditLogger: USER=hadoopuser	IP=192.168.244.131	OPERATION=Register App Master	TARGET=ApplicationMasterService	RESULT=SUCCESS	APPID=application_1615531707627_0003	APPATTEMPTID=appattempt_1615531707627_0003_000001
2021-03-11 22:56:40,478 INFO org.apache.hadoop.yarn.server.resourcemanager.rmapp.attempt.RMAppAttemptImpl: appattempt_1615531707627_0003_000001 State change from LAUNCHED to RUNNING
2021-03-11 22:56:40,478 INFO org.apache.hadoop.yarn.server.resourcemanager.rmapp.RMAppImpl: application_1615531707627_0003 State change from ACCEPTED to RUNNING on event=ATTEMPT_REGISTERED
2021-03-11 22:56:42,204 INFO org.apache.hadoop.yarn.server.resourcemanager.rmcontainer.RMContainerImpl: container_1615531707627_0003_01_000002 Container Transitioned from NEW to ALLOCATED
2021-03-11 22:56:42,204 INFO org.apache.hadoop.yarn.server.resourcemanager.RMAuditLogger: USER=hadoopuser	OPERATION=AM Allocated Container	TARGET=SchedulerApp	RESULT=SUCCESS	APPID=application_1615531707627_0003	CONTAINERID=container_1615531707627_0003_01_000002
2021-03-11 22:56:42,204 INFO org.apache.hadoop.yarn.server.resourcemanager.scheduler.SchedulerNode: Assigned container container_1615531707627_0003_01_000002 of capacity <memory:1024, vCores:1> on host tutrung-slave1:33619, which has 2 containers, <memory:3072, vCores:2> used and <memory:5120, vCores:6> available after allocation
2021-03-11 22:56:42,204 INFO org.apache.hadoop.yarn.server.resourcemanager.scheduler.capacity.LeafQueue: assignedContainer application attempt=appattempt_1615531707627_0003_000001 container=Container: [ContainerId: container_1615531707627_0003_01_000002, NodeId: tutrung-slave1:33619, NodeHttpAddress: tutrung-slave1:8042, Resource: <memory:1024, vCores:1>, Priority: 20, Token: null, ] queue=default: capacity=1.0, absoluteCapacity=1.0, usedResources=<memory:2048, vCores:1>, usedCapacity=0.125, absoluteUsedCapacity=0.125, numApps=1, numContainers=1 clusterResource=<memory:16384, vCores:16> type=NODE_LOCAL requestedPartition=
2021-03-11 22:56:42,205 INFO org.apache.hadoop.yarn.server.resourcemanager.scheduler.capacity.ParentQueue: Re-sorting assigned queue: root.default stats: default: capacity=1.0, absoluteCapacity=1.0, usedResources=<memory:3072, vCores:2>, usedCapacity=0.1875, absoluteUsedCapacity=0.1875, numApps=1, numContainers=2
2021-03-11 22:56:42,205 INFO org.apache.hadoop.yarn.server.resourcemanager.scheduler.capacity.ParentQueue: assignedContainer queue=root usedCapacity=0.1875 absoluteUsedCapacity=0.1875 used=<memory:3072, vCores:2> cluster=<memory:16384, vCores:16>
2021-03-11 22:56:42,633 INFO org.apache.hadoop.yarn.server.resourcemanager.security.NMTokenSecretManagerInRM: Sending NMToken for nodeId : tutrung-slave1:33619 for container : container_1615531707627_0003_01_000002
2021-03-11 22:56:42,635 INFO org.apache.hadoop.yarn.server.resourcemanager.rmcontainer.RMContainerImpl: container_1615531707627_0003_01_000002 Container Transitioned from ALLOCATED to ACQUIRED
2021-03-11 22:56:43,208 INFO org.apache.hadoop.yarn.server.resourcemanager.rmcontainer.RMContainerImpl: container_1615531707627_0003_01_000002 Container Transitioned from ACQUIRED to RUNNING
2021-03-11 22:56:43,679 INFO org.apache.hadoop.yarn.server.resourcemanager.scheduler.AppSchedulingInfo: checking for deactivate of application :application_1615531707627_0003
2021-03-11 22:56:52,434 INFO org.apache.hadoop.yarn.server.resourcemanager.rmcontainer.RMContainerImpl: container_1615531707627_0003_01_000002 Container Transitioned from RUNNING to COMPLETED
2021-03-11 22:56:52,434 INFO org.apache.hadoop.yarn.server.resourcemanager.scheduler.common.fica.FiCaSchedulerApp: Completed container: container_1615531707627_0003_01_000002 in state: COMPLETED event:FINISHED
2021-03-11 22:56:52,434 INFO org.apache.hadoop.yarn.server.resourcemanager.RMAuditLogger: USER=hadoopuser	OPERATION=AM Released Container	TARGET=SchedulerApp	RESULT=SUCCESS	APPID=application_1615531707627_0003	CONTAINERID=container_1615531707627_0003_01_000002
2021-03-11 22:56:52,434 INFO org.apache.hadoop.yarn.server.resourcemanager.scheduler.SchedulerNode: Released container container_1615531707627_0003_01_000002 of capacity <memory:1024, vCores:1> on host tutrung-slave1:33619, which currently has 1 containers, <memory:2048, vCores:1> used and <memory:6144, vCores:7> available, release resources=true
2021-03-11 22:56:52,434 INFO org.apache.hadoop.yarn.server.resourcemanager.scheduler.capacity.LeafQueue: default used=<memory:2048, vCores:1> numContainers=1 user=hadoopuser user-resources=<memory:2048, vCores:1>
2021-03-11 22:56:52,434 INFO org.apache.hadoop.yarn.server.resourcemanager.scheduler.capacity.LeafQueue: completedContainer container=Container: [ContainerId: container_1615531707627_0003_01_000002, NodeId: tutrung-slave1:33619, NodeHttpAddress: tutrung-slave1:8042, Resource: <memory:1024, vCores:1>, Priority: 20, Token: Token { kind: ContainerToken, service: 192.168.244.131:33619 }, ] queue=default: capacity=1.0, absoluteCapacity=1.0, usedResources=<memory:2048, vCores:1>, usedCapacity=0.125, absoluteUsedCapacity=0.125, numApps=1, numContainers=1 cluster=<memory:16384, vCores:16>
2021-03-11 22:56:52,434 INFO org.apache.hadoop.yarn.server.resourcemanager.scheduler.capacity.ParentQueue: completedContainer queue=root usedCapacity=0.125 absoluteUsedCapacity=0.125 used=<memory:2048, vCores:1> cluster=<memory:16384, vCores:16>
2021-03-11 22:56:52,434 INFO org.apache.hadoop.yarn.server.resourcemanager.scheduler.capacity.ParentQueue: Re-sorting completed queue: root.default stats: default: capacity=1.0, absoluteCapacity=1.0, usedResources=<memory:2048, vCores:1>, usedCapacity=0.125, absoluteUsedCapacity=0.125, numApps=1, numContainers=1
2021-03-11 22:56:52,435 INFO org.apache.hadoop.yarn.server.resourcemanager.scheduler.capacity.CapacityScheduler: Application attempt appattempt_1615531707627_0003_000001 released container container_1615531707627_0003_01_000002 on node: host: tutrung-slave1:33619 #containers=1 available=<memory:6144, vCores:7> used=<memory:2048, vCores:1> with event: FINISHED
2021-03-11 22:56:54,261 INFO org.apache.hadoop.yarn.server.resourcemanager.rmcontainer.RMContainerImpl: container_1615531707627_0003_01_000003 Container Transitioned from NEW to ALLOCATED
2021-03-11 22:56:54,261 INFO org.apache.hadoop.yarn.server.resourcemanager.RMAuditLogger: USER=hadoopuser	OPERATION=AM Allocated Container	TARGET=SchedulerApp	RESULT=SUCCESS	APPID=application_1615531707627_0003	CONTAINERID=container_1615531707627_0003_01_000003
2021-03-11 22:56:54,261 INFO org.apache.hadoop.yarn.server.resourcemanager.scheduler.SchedulerNode: Assigned container container_1615531707627_0003_01_000003 of capacity <memory:1024, vCores:1> on host tutrung-slave2:46601, which has 1 containers, <memory:1024, vCores:1> used and <memory:7168, vCores:7> available after allocation
2021-03-11 22:56:54,262 INFO org.apache.hadoop.yarn.server.resourcemanager.scheduler.capacity.LeafQueue: assignedContainer application attempt=appattempt_1615531707627_0003_000001 container=Container: [ContainerId: container_1615531707627_0003_01_000003, NodeId: tutrung-slave2:46601, NodeHttpAddress: tutrung-slave2:8042, Resource: <memory:1024, vCores:1>, Priority: 10, Token: null, ] queue=default: capacity=1.0, absoluteCapacity=1.0, usedResources=<memory:2048, vCores:1>, usedCapacity=0.125, absoluteUsedCapacity=0.125, numApps=1, numContainers=1 clusterResource=<memory:16384, vCores:16> type=OFF_SWITCH requestedPartition=
2021-03-11 22:56:54,262 INFO org.apache.hadoop.yarn.server.resourcemanager.scheduler.capacity.ParentQueue: Re-sorting assigned queue: root.default stats: default: capacity=1.0, absoluteCapacity=1.0, usedResources=<memory:3072, vCores:2>, usedCapacity=0.1875, absoluteUsedCapacity=0.1875, numApps=1, numContainers=2
2021-03-11 22:56:54,262 INFO org.apache.hadoop.yarn.server.resourcemanager.scheduler.capacity.ParentQueue: assignedContainer queue=root usedCapacity=0.1875 absoluteUsedCapacity=0.1875 used=<memory:3072, vCores:2> cluster=<memory:16384, vCores:16>
2021-03-11 22:56:54,721 INFO org.apache.hadoop.yarn.server.resourcemanager.security.NMTokenSecretManagerInRM: Sending NMToken for nodeId : tutrung-slave2:46601 for container : container_1615531707627_0003_01_000003
2021-03-11 22:56:54,722 INFO org.apache.hadoop.yarn.server.resourcemanager.rmcontainer.RMContainerImpl: container_1615531707627_0003_01_000003 Container Transitioned from ALLOCATED to ACQUIRED
2021-03-11 22:56:55,263 INFO org.apache.hadoop.yarn.server.resourcemanager.rmcontainer.RMContainerImpl: container_1615531707627_0003_01_000003 Container Transitioned from ACQUIRED to RUNNING
2021-03-11 22:56:55,732 INFO org.apache.hadoop.yarn.server.resourcemanager.scheduler.AppSchedulingInfo: checking for deactivate of application :application_1615531707627_0003
2021-03-11 22:57:03,194 INFO org.apache.hadoop.yarn.server.resourcemanager.rmcontainer.RMContainerImpl: container_1615531707627_0003_01_000003 Container Transitioned from RUNNING to COMPLETED
2021-03-11 22:57:03,195 INFO org.apache.hadoop.yarn.server.resourcemanager.scheduler.common.fica.FiCaSchedulerApp: Completed container: container_1615531707627_0003_01_000003 in state: COMPLETED event:FINISHED
2021-03-11 22:57:03,195 INFO org.apache.hadoop.yarn.server.resourcemanager.RMAuditLogger: USER=hadoopuser	OPERATION=AM Released Container	TARGET=SchedulerApp	RESULT=SUCCESS	APPID=application_1615531707627_0003	CONTAINERID=container_1615531707627_0003_01_000003
2021-03-11 22:57:03,195 INFO org.apache.hadoop.yarn.server.resourcemanager.scheduler.SchedulerNode: Released container container_1615531707627_0003_01_000003 of capacity <memory:1024, vCores:1> on host tutrung-slave2:46601, which currently has 0 containers, <memory:0, vCores:0> used and <memory:8192, vCores:8> available, release resources=true
2021-03-11 22:57:03,195 INFO org.apache.hadoop.yarn.server.resourcemanager.scheduler.capacity.LeafQueue: default used=<memory:2048, vCores:1> numContainers=1 user=hadoopuser user-resources=<memory:2048, vCores:1>
2021-03-11 22:57:03,195 INFO org.apache.hadoop.yarn.server.resourcemanager.scheduler.capacity.LeafQueue: completedContainer container=Container: [ContainerId: container_1615531707627_0003_01_000003, NodeId: tutrung-slave2:46601, NodeHttpAddress: tutrung-slave2:8042, Resource: <memory:1024, vCores:1>, Priority: 10, Token: Token { kind: ContainerToken, service: 192.168.244.132:46601 }, ] queue=default: capacity=1.0, absoluteCapacity=1.0, usedResources=<memory:2048, vCores:1>, usedCapacity=0.125, absoluteUsedCapacity=0.125, numApps=1, numContainers=1 cluster=<memory:16384, vCores:16>
2021-03-11 22:57:03,195 INFO org.apache.hadoop.yarn.server.resourcemanager.scheduler.capacity.ParentQueue: completedContainer queue=root usedCapacity=0.125 absoluteUsedCapacity=0.125 used=<memory:2048, vCores:1> cluster=<memory:16384, vCores:16>
2021-03-11 22:57:03,195 INFO org.apache.hadoop.yarn.server.resourcemanager.scheduler.capacity.ParentQueue: Re-sorting completed queue: root.default stats: default: capacity=1.0, absoluteCapacity=1.0, usedResources=<memory:2048, vCores:1>, usedCapacity=0.125, absoluteUsedCapacity=0.125, numApps=1, numContainers=1
2021-03-11 22:57:03,195 INFO org.apache.hadoop.yarn.server.resourcemanager.scheduler.capacity.CapacityScheduler: Application attempt appattempt_1615531707627_0003_000001 released container container_1615531707627_0003_01_000003 on node: host: tutrung-slave2:46601 #containers=0 available=<memory:8192, vCores:8> used=<memory:0, vCores:0> with event: FINISHED
2021-03-11 22:57:03,418 INFO org.apache.hadoop.yarn.server.resourcemanager.rmapp.attempt.RMAppAttemptImpl: Updating application attempt appattempt_1615531707627_0003_000001 with final state: FINISHING, and exit status: -1000
2021-03-11 22:57:03,418 INFO org.apache.hadoop.yarn.server.resourcemanager.rmapp.attempt.RMAppAttemptImpl: appattempt_1615531707627_0003_000001 State change from RUNNING to FINAL_SAVING
2021-03-11 22:57:03,419 INFO org.apache.hadoop.yarn.server.resourcemanager.rmapp.attempt.RMAppAttemptImpl: appattempt_1615531707627_0003_000001 State change from FINAL_SAVING to FINISHING
2021-03-11 22:57:03,419 INFO org.apache.hadoop.yarn.server.resourcemanager.rmapp.RMAppImpl: Updating application application_1615531707627_0003 with final state: FINISHING
2021-03-11 22:57:03,419 INFO org.apache.hadoop.yarn.server.resourcemanager.recovery.RMStateStore: Updating info for app: application_1615531707627_0003
2021-03-11 22:57:03,419 INFO org.apache.hadoop.yarn.server.resourcemanager.rmapp.RMAppImpl: application_1615531707627_0003 State change from RUNNING to FINAL_SAVING on event=ATTEMPT_UNREGISTERED
2021-03-11 22:57:03,419 INFO org.apache.hadoop.yarn.server.resourcemanager.rmapp.RMAppImpl: application_1615531707627_0003 State change from FINAL_SAVING to FINISHING on event=APP_UPDATE_SAVED
2021-03-11 22:57:04,433 INFO org.apache.hadoop.yarn.server.resourcemanager.ApplicationMasterService: application_1615531707627_0003 unregistered successfully. 
2021-03-11 22:57:09,957 INFO org.apache.hadoop.yarn.server.resourcemanager.rmcontainer.RMContainerImpl: container_1615531707627_0003_01_000001 Container Transitioned from RUNNING to COMPLETED
2021-03-11 22:57:09,957 INFO org.apache.hadoop.yarn.server.resourcemanager.scheduler.common.fica.FiCaSchedulerApp: Completed container: container_1615531707627_0003_01_000001 in state: COMPLETED event:FINISHED
2021-03-11 22:57:09,957 INFO org.apache.hadoop.yarn.server.resourcemanager.RMAuditLogger: USER=hadoopuser	OPERATION=AM Released Container	TARGET=SchedulerApp	RESULT=SUCCESS	APPID=application_1615531707627_0003	CONTAINERID=container_1615531707627_0003_01_000001
2021-03-11 22:57:09,957 INFO org.apache.hadoop.yarn.server.resourcemanager.scheduler.SchedulerNode: Released container container_1615531707627_0003_01_000001 of capacity <memory:2048, vCores:1> on host tutrung-slave1:33619, which currently has 0 containers, <memory:0, vCores:0> used and <memory:8192, vCores:8> available, release resources=true
2021-03-11 22:57:09,957 INFO org.apache.hadoop.yarn.server.resourcemanager.scheduler.capacity.LeafQueue: default used=<memory:0, vCores:0> numContainers=0 user=hadoopuser user-resources=<memory:0, vCores:0>
2021-03-11 22:57:09,958 INFO org.apache.hadoop.yarn.server.resourcemanager.scheduler.capacity.LeafQueue: completedContainer container=Container: [ContainerId: container_1615531707627_0003_01_000001, NodeId: tutrung-slave1:33619, NodeHttpAddress: tutrung-slave1:8042, Resource: <memory:2048, vCores:1>, Priority: 0, Token: Token { kind: ContainerToken, service: 192.168.244.131:33619 }, ] queue=default: capacity=1.0, absoluteCapacity=1.0, usedResources=<memory:0, vCores:0>, usedCapacity=0.0, absoluteUsedCapacity=0.0, numApps=1, numContainers=0 cluster=<memory:16384, vCores:16>
2021-03-11 22:57:09,958 INFO org.apache.hadoop.yarn.server.resourcemanager.scheduler.capacity.ParentQueue: completedContainer queue=root usedCapacity=0.0 absoluteUsedCapacity=0.0 used=<memory:0, vCores:0> cluster=<memory:16384, vCores:16>
2021-03-11 22:57:09,958 INFO org.apache.hadoop.yarn.server.resourcemanager.scheduler.capacity.ParentQueue: Re-sorting completed queue: root.default stats: default: capacity=1.0, absoluteCapacity=1.0, usedResources=<memory:0, vCores:0>, usedCapacity=0.0, absoluteUsedCapacity=0.0, numApps=1, numContainers=0
2021-03-11 22:57:09,958 INFO org.apache.hadoop.yarn.server.resourcemanager.scheduler.capacity.CapacityScheduler: Application attempt appattempt_1615531707627_0003_000001 released container container_1615531707627_0003_01_000001 on node: host: tutrung-slave1:33619 #containers=0 available=<memory:8192, vCores:8> used=<memory:0, vCores:0> with event: FINISHED
2021-03-11 22:57:09,958 INFO org.apache.hadoop.yarn.server.resourcemanager.ApplicationMasterService: Unregistering app attempt : appattempt_1615531707627_0003_000001
2021-03-11 22:57:09,958 INFO org.apache.hadoop.yarn.server.resourcemanager.security.AMRMTokenSecretManager: Application finished, removing password for appattempt_1615531707627_0003_000001
2021-03-11 22:57:09,958 INFO org.apache.hadoop.yarn.server.resourcemanager.rmapp.attempt.RMAppAttemptImpl: appattempt_1615531707627_0003_000001 State change from FINISHING to FINISHED
2021-03-11 22:57:09,958 INFO org.apache.hadoop.yarn.server.resourcemanager.rmapp.RMAppImpl: application_1615531707627_0003 State change from FINISHING to FINISHED on event=ATTEMPT_FINISHED
2021-03-11 22:57:09,958 INFO org.apache.hadoop.yarn.server.resourcemanager.RMAuditLogger: USER=hadoopuser	OPERATION=Application Finished - Succeeded	TARGET=RMAppManager	RESULT=SUCCESS	APPID=application_1615531707627_0003
2021-03-11 22:57:09,959 INFO org.apache.hadoop.yarn.server.resourcemanager.RMAppManager$ApplicationSummary: appId=application_1615531707627_0003,name=PigLatin:script1-hadoop.pig,user=hadoopuser,queue=default,state=FINISHED,trackingUrl=http://master:8088/proxy/application_1615531707627_0003/,appMasterHost=tutrung-slave1,startTime=1615532192801,finishTime=1615532223419,finalStatus=SUCCEEDED,memorySeconds=94926,vcoreSeconds=54,preemptedAMContainers=0,preemptedNonAMContainers=0,preemptedResources=<memory:0\, vCores:0>,applicationType=MAPREDUCE
2021-03-11 22:57:09,959 INFO org.apache.hadoop.yarn.server.resourcemanager.scheduler.capacity.CapacityScheduler: Application Attempt appattempt_1615531707627_0003_000001 is done. finalState=FINISHED
2021-03-11 22:57:09,960 INFO org.apache.hadoop.yarn.server.resourcemanager.scheduler.AppSchedulingInfo: Application application_1615531707627_0003 requests cleared
2021-03-11 22:57:09,960 INFO org.apache.hadoop.yarn.server.resourcemanager.scheduler.capacity.LeafQueue: Application removed - appId: application_1615531707627_0003 user: hadoopuser queue: default #user-pending-applications: 0 #user-active-applications: 0 #queue-pending-applications: 0 #queue-active-applications: 0
2021-03-11 22:57:09,960 INFO org.apache.hadoop.yarn.server.resourcemanager.scheduler.capacity.ParentQueue: Application removed - appId: application_1615531707627_0003 user: hadoopuser leaf-queue of parent: root #applications: 0
2021-03-11 22:57:09,960 INFO org.apache.hadoop.yarn.server.resourcemanager.amlauncher.AMLauncher: Cleaning master appattempt_1615531707627_0003_000001
2021-03-11 22:57:11,216 INFO org.apache.hadoop.yarn.server.resourcemanager.scheduler.capacity.CapacityScheduler: Null container completed...
2021-03-11 22:58:27,469 INFO org.apache.hadoop.yarn.server.resourcemanager.scheduler.AbstractYarnScheduler: Release request cache is cleaned up
2021-03-11 22:58:41,153 INFO org.apache.hadoop.yarn.server.resourcemanager.ClientRMService: Allocated new applicationId: 4
2021-03-11 22:58:42,383 INFO org.apache.hadoop.yarn.server.resourcemanager.ClientRMService: Application with id 4 submitted by user hadoopuser
2021-03-11 22:58:42,383 INFO org.apache.hadoop.yarn.server.resourcemanager.RMAuditLogger: USER=hadoopuser	IP=192.168.244.130	OPERATION=Submit Application Request	TARGET=ClientRMService	RESULT=SUCCESS	APPID=application_1615531707627_0004
2021-03-11 22:58:42,384 INFO org.apache.hadoop.yarn.server.resourcemanager.rmapp.RMAppImpl: Storing application with id application_1615531707627_0004
2021-03-11 22:58:42,384 INFO org.apache.hadoop.yarn.server.resourcemanager.rmapp.RMAppImpl: application_1615531707627_0004 State change from NEW to NEW_SAVING on event=START
2021-03-11 22:58:42,384 INFO org.apache.hadoop.yarn.server.resourcemanager.recovery.RMStateStore: Storing info for app: application_1615531707627_0004
2021-03-11 22:58:42,384 INFO org.apache.hadoop.yarn.server.resourcemanager.rmapp.RMAppImpl: application_1615531707627_0004 State change from NEW_SAVING to SUBMITTED on event=APP_NEW_SAVED
2021-03-11 22:58:42,384 INFO org.apache.hadoop.yarn.server.resourcemanager.scheduler.capacity.ParentQueue: Application added - appId: application_1615531707627_0004 user: hadoopuser leaf-queue of parent: root #applications: 1
2021-03-11 22:58:42,384 INFO org.apache.hadoop.yarn.server.resourcemanager.scheduler.capacity.CapacityScheduler: Accepted application application_1615531707627_0004 from user: hadoopuser, in queue: default
2021-03-11 22:58:42,386 INFO org.apache.hadoop.yarn.server.resourcemanager.rmapp.RMAppImpl: application_1615531707627_0004 State change from SUBMITTED to ACCEPTED on event=APP_ACCEPTED
2021-03-11 22:58:42,386 INFO org.apache.hadoop.yarn.server.resourcemanager.ApplicationMasterService: Registering app attempt : appattempt_1615531707627_0004_000001
2021-03-11 22:58:42,386 INFO org.apache.hadoop.yarn.server.resourcemanager.rmapp.attempt.RMAppAttemptImpl: appattempt_1615531707627_0004_000001 State change from NEW to SUBMITTED
2021-03-11 22:58:42,386 INFO org.apache.hadoop.yarn.server.resourcemanager.scheduler.capacity.LeafQueue: Application application_1615531707627_0004 from user: hadoopuser activated in queue: default
2021-03-11 22:58:42,386 INFO org.apache.hadoop.yarn.server.resourcemanager.scheduler.capacity.LeafQueue: Application added - appId: application_1615531707627_0004 user: org.apache.hadoop.yarn.server.resourcemanager.scheduler.capacity.LeafQueue$User@7882799a, leaf-queue: default #user-pending-applications: 0 #user-active-applications: 1 #queue-pending-applications: 0 #queue-active-applications: 1
2021-03-11 22:58:42,386 INFO org.apache.hadoop.yarn.server.resourcemanager.scheduler.capacity.CapacityScheduler: Added Application Attempt appattempt_1615531707627_0004_000001 to scheduler from user hadoopuser in queue default
2021-03-11 22:58:42,389 INFO org.apache.hadoop.yarn.server.resourcemanager.rmapp.attempt.RMAppAttemptImpl: appattempt_1615531707627_0004_000001 State change from SUBMITTED to SCHEDULED
2021-03-11 22:58:42,756 INFO org.apache.hadoop.yarn.server.resourcemanager.rmcontainer.RMContainerImpl: container_1615531707627_0004_01_000001 Container Transitioned from NEW to ALLOCATED
2021-03-11 22:58:42,756 INFO org.apache.hadoop.yarn.server.resourcemanager.RMAuditLogger: USER=hadoopuser	OPERATION=AM Allocated Container	TARGET=SchedulerApp	RESULT=SUCCESS	APPID=application_1615531707627_0004	CONTAINERID=container_1615531707627_0004_01_000001
2021-03-11 22:58:42,756 INFO org.apache.hadoop.yarn.server.resourcemanager.scheduler.SchedulerNode: Assigned container container_1615531707627_0004_01_000001 of capacity <memory:2048, vCores:1> on host tutrung-slave2:46601, which has 1 containers, <memory:2048, vCores:1> used and <memory:6144, vCores:7> available after allocation
2021-03-11 22:58:42,756 INFO org.apache.hadoop.yarn.server.resourcemanager.scheduler.capacity.LeafQueue: assignedContainer application attempt=appattempt_1615531707627_0004_000001 container=Container: [ContainerId: container_1615531707627_0004_01_000001, NodeId: tutrung-slave2:46601, NodeHttpAddress: tutrung-slave2:8042, Resource: <memory:2048, vCores:1>, Priority: 0, Token: null, ] queue=default: capacity=1.0, absoluteCapacity=1.0, usedResources=<memory:0, vCores:0>, usedCapacity=0.0, absoluteUsedCapacity=0.0, numApps=1, numContainers=0 clusterResource=<memory:16384, vCores:16> type=OFF_SWITCH requestedPartition=
2021-03-11 22:58:42,756 INFO org.apache.hadoop.yarn.server.resourcemanager.scheduler.capacity.ParentQueue: Re-sorting assigned queue: root.default stats: default: capacity=1.0, absoluteCapacity=1.0, usedResources=<memory:2048, vCores:1>, usedCapacity=0.125, absoluteUsedCapacity=0.125, numApps=1, numContainers=1
2021-03-11 22:58:42,756 INFO org.apache.hadoop.yarn.server.resourcemanager.scheduler.capacity.ParentQueue: assignedContainer queue=root usedCapacity=0.125 absoluteUsedCapacity=0.125 used=<memory:2048, vCores:1> cluster=<memory:16384, vCores:16>
2021-03-11 22:58:42,757 INFO org.apache.hadoop.yarn.server.resourcemanager.security.NMTokenSecretManagerInRM: Sending NMToken for nodeId : tutrung-slave2:46601 for container : container_1615531707627_0004_01_000001
2021-03-11 22:58:42,758 INFO org.apache.hadoop.yarn.server.resourcemanager.rmcontainer.RMContainerImpl: container_1615531707627_0004_01_000001 Container Transitioned from ALLOCATED to ACQUIRED
2021-03-11 22:58:42,758 INFO org.apache.hadoop.yarn.server.resourcemanager.security.NMTokenSecretManagerInRM: Clear node set for appattempt_1615531707627_0004_000001
2021-03-11 22:58:42,758 INFO org.apache.hadoop.yarn.server.resourcemanager.rmapp.attempt.RMAppAttemptImpl: Storing attempt: AppId: application_1615531707627_0004 AttemptId: appattempt_1615531707627_0004_000001 MasterContainer: Container: [ContainerId: container_1615531707627_0004_01_000001, NodeId: tutrung-slave2:46601, NodeHttpAddress: tutrung-slave2:8042, Resource: <memory:2048, vCores:1>, Priority: 0, Token: Token { kind: ContainerToken, service: 192.168.244.132:46601 }, ]
2021-03-11 22:58:42,758 INFO org.apache.hadoop.yarn.server.resourcemanager.rmapp.attempt.RMAppAttemptImpl: appattempt_1615531707627_0004_000001 State change from SCHEDULED to ALLOCATED_SAVING
2021-03-11 22:58:42,759 INFO org.apache.hadoop.yarn.server.resourcemanager.rmapp.attempt.RMAppAttemptImpl: appattempt_1615531707627_0004_000001 State change from ALLOCATED_SAVING to ALLOCATED
2021-03-11 22:58:42,762 INFO org.apache.hadoop.yarn.server.resourcemanager.amlauncher.AMLauncher: Launching masterappattempt_1615531707627_0004_000001
2021-03-11 22:58:42,765 INFO org.apache.hadoop.yarn.server.resourcemanager.amlauncher.AMLauncher: Setting up container Container: [ContainerId: container_1615531707627_0004_01_000001, NodeId: tutrung-slave2:46601, NodeHttpAddress: tutrung-slave2:8042, Resource: <memory:2048, vCores:1>, Priority: 0, Token: Token { kind: ContainerToken, service: 192.168.244.132:46601 }, ] for AM appattempt_1615531707627_0004_000001
2021-03-11 22:58:42,766 INFO org.apache.hadoop.yarn.server.resourcemanager.amlauncher.AMLauncher: Command to launch container container_1615531707627_0004_01_000001 : $JAVA_HOME/bin/java -Djava.io.tmpdir=$PWD/tmp -Dlog4j.configuration=container-log4j.properties -Dyarn.app.container.log.dir=<LOG_DIR> -Dyarn.app.container.log.filesize=0 -Dhadoop.root.logger=INFO,CLA -Dhadoop.root.logfile=syslog  -Xmx1024m org.apache.hadoop.mapreduce.v2.app.MRAppMaster 1><LOG_DIR>/stdout 2><LOG_DIR>/stderr 
2021-03-11 22:58:42,766 INFO org.apache.hadoop.yarn.server.resourcemanager.security.AMRMTokenSecretManager: Create AMRMToken for ApplicationAttempt: appattempt_1615531707627_0004_000001
2021-03-11 22:58:42,766 INFO org.apache.hadoop.yarn.server.resourcemanager.security.AMRMTokenSecretManager: Creating password for appattempt_1615531707627_0004_000001
2021-03-11 22:58:42,821 INFO org.apache.hadoop.yarn.server.resourcemanager.amlauncher.AMLauncher: Done launching container Container: [ContainerId: container_1615531707627_0004_01_000001, NodeId: tutrung-slave2:46601, NodeHttpAddress: tutrung-slave2:8042, Resource: <memory:2048, vCores:1>, Priority: 0, Token: Token { kind: ContainerToken, service: 192.168.244.132:46601 }, ] for AM appattempt_1615531707627_0004_000001
2021-03-11 22:58:42,824 INFO org.apache.hadoop.yarn.server.resourcemanager.rmapp.attempt.RMAppAttemptImpl: appattempt_1615531707627_0004_000001 State change from ALLOCATED to LAUNCHED
2021-03-11 22:58:43,768 INFO org.apache.hadoop.yarn.server.resourcemanager.rmcontainer.RMContainerImpl: container_1615531707627_0004_01_000001 Container Transitioned from ACQUIRED to RUNNING
2021-03-11 22:58:50,963 INFO SecurityLogger.org.apache.hadoop.ipc.Server: Auth successful for appattempt_1615531707627_0004_000001 (auth:SIMPLE)
2021-03-11 22:58:50,969 INFO org.apache.hadoop.yarn.server.resourcemanager.ApplicationMasterService: AM registration appattempt_1615531707627_0004_000001
2021-03-11 22:58:50,969 INFO org.apache.hadoop.yarn.server.resourcemanager.RMAuditLogger: USER=hadoopuser	IP=192.168.244.132	OPERATION=Register App Master	TARGET=ApplicationMasterService	RESULT=SUCCESS	APPID=application_1615531707627_0004	APPATTEMPTID=appattempt_1615531707627_0004_000001
2021-03-11 22:58:50,970 INFO org.apache.hadoop.yarn.server.resourcemanager.rmapp.attempt.RMAppAttemptImpl: appattempt_1615531707627_0004_000001 State change from LAUNCHED to RUNNING
2021-03-11 22:58:50,970 INFO org.apache.hadoop.yarn.server.resourcemanager.rmapp.RMAppImpl: application_1615531707627_0004 State change from ACCEPTED to RUNNING on event=ATTEMPT_REGISTERED
2021-03-11 22:58:52,812 INFO org.apache.hadoop.yarn.server.resourcemanager.rmcontainer.RMContainerImpl: container_1615531707627_0004_01_000002 Container Transitioned from NEW to ALLOCATED
2021-03-11 22:58:52,812 INFO org.apache.hadoop.yarn.server.resourcemanager.RMAuditLogger: USER=hadoopuser	OPERATION=AM Allocated Container	TARGET=SchedulerApp	RESULT=SUCCESS	APPID=application_1615531707627_0004	CONTAINERID=container_1615531707627_0004_01_000002
2021-03-11 22:58:52,812 INFO org.apache.hadoop.yarn.server.resourcemanager.scheduler.SchedulerNode: Assigned container container_1615531707627_0004_01_000002 of capacity <memory:1024, vCores:1> on host tutrung-slave2:46601, which has 2 containers, <memory:3072, vCores:2> used and <memory:5120, vCores:6> available after allocation
2021-03-11 22:58:52,812 INFO org.apache.hadoop.yarn.server.resourcemanager.scheduler.capacity.LeafQueue: assignedContainer application attempt=appattempt_1615531707627_0004_000001 container=Container: [ContainerId: container_1615531707627_0004_01_000002, NodeId: tutrung-slave2:46601, NodeHttpAddress: tutrung-slave2:8042, Resource: <memory:1024, vCores:1>, Priority: 20, Token: null, ] queue=default: capacity=1.0, absoluteCapacity=1.0, usedResources=<memory:2048, vCores:1>, usedCapacity=0.125, absoluteUsedCapacity=0.125, numApps=1, numContainers=1 clusterResource=<memory:16384, vCores:16> type=NODE_LOCAL requestedPartition=
2021-03-11 22:58:52,813 INFO org.apache.hadoop.yarn.server.resourcemanager.scheduler.capacity.ParentQueue: Re-sorting assigned queue: root.default stats: default: capacity=1.0, absoluteCapacity=1.0, usedResources=<memory:3072, vCores:2>, usedCapacity=0.1875, absoluteUsedCapacity=0.1875, numApps=1, numContainers=2
2021-03-11 22:58:52,813 INFO org.apache.hadoop.yarn.server.resourcemanager.scheduler.capacity.ParentQueue: assignedContainer queue=root usedCapacity=0.1875 absoluteUsedCapacity=0.1875 used=<memory:3072, vCores:2> cluster=<memory:16384, vCores:16>
2021-03-11 22:58:53,051 INFO org.apache.hadoop.yarn.server.resourcemanager.security.NMTokenSecretManagerInRM: Sending NMToken for nodeId : tutrung-slave2:46601 for container : container_1615531707627_0004_01_000002
2021-03-11 22:58:53,053 INFO org.apache.hadoop.yarn.server.resourcemanager.rmcontainer.RMContainerImpl: container_1615531707627_0004_01_000002 Container Transitioned from ALLOCATED to ACQUIRED
2021-03-11 22:58:53,817 INFO org.apache.hadoop.yarn.server.resourcemanager.rmcontainer.RMContainerImpl: container_1615531707627_0004_01_000002 Container Transitioned from ACQUIRED to RUNNING
2021-03-11 22:58:54,068 INFO org.apache.hadoop.yarn.server.resourcemanager.scheduler.AppSchedulingInfo: checking for deactivate of application :application_1615531707627_0004
2021-03-11 22:59:01,064 INFO org.apache.hadoop.yarn.server.resourcemanager.rmcontainer.RMContainerImpl: container_1615531707627_0004_01_000002 Container Transitioned from RUNNING to COMPLETED
2021-03-11 22:59:01,064 INFO org.apache.hadoop.yarn.server.resourcemanager.scheduler.common.fica.FiCaSchedulerApp: Completed container: container_1615531707627_0004_01_000002 in state: COMPLETED event:FINISHED
2021-03-11 22:59:01,064 INFO org.apache.hadoop.yarn.server.resourcemanager.RMAuditLogger: USER=hadoopuser	OPERATION=AM Released Container	TARGET=SchedulerApp	RESULT=SUCCESS	APPID=application_1615531707627_0004	CONTAINERID=container_1615531707627_0004_01_000002
2021-03-11 22:59:01,064 INFO org.apache.hadoop.yarn.server.resourcemanager.scheduler.SchedulerNode: Released container container_1615531707627_0004_01_000002 of capacity <memory:1024, vCores:1> on host tutrung-slave2:46601, which currently has 1 containers, <memory:2048, vCores:1> used and <memory:6144, vCores:7> available, release resources=true
2021-03-11 22:59:01,064 INFO org.apache.hadoop.yarn.server.resourcemanager.scheduler.capacity.LeafQueue: default used=<memory:2048, vCores:1> numContainers=1 user=hadoopuser user-resources=<memory:2048, vCores:1>
2021-03-11 22:59:01,065 INFO org.apache.hadoop.yarn.server.resourcemanager.scheduler.capacity.LeafQueue: completedContainer container=Container: [ContainerId: container_1615531707627_0004_01_000002, NodeId: tutrung-slave2:46601, NodeHttpAddress: tutrung-slave2:8042, Resource: <memory:1024, vCores:1>, Priority: 20, Token: Token { kind: ContainerToken, service: 192.168.244.132:46601 }, ] queue=default: capacity=1.0, absoluteCapacity=1.0, usedResources=<memory:2048, vCores:1>, usedCapacity=0.125, absoluteUsedCapacity=0.125, numApps=1, numContainers=1 cluster=<memory:16384, vCores:16>
2021-03-11 22:59:01,065 INFO org.apache.hadoop.yarn.server.resourcemanager.scheduler.capacity.ParentQueue: completedContainer queue=root usedCapacity=0.125 absoluteUsedCapacity=0.125 used=<memory:2048, vCores:1> cluster=<memory:16384, vCores:16>
2021-03-11 22:59:01,065 INFO org.apache.hadoop.yarn.server.resourcemanager.scheduler.capacity.ParentQueue: Re-sorting completed queue: root.default stats: default: capacity=1.0, absoluteCapacity=1.0, usedResources=<memory:2048, vCores:1>, usedCapacity=0.125, absoluteUsedCapacity=0.125, numApps=1, numContainers=1
2021-03-11 22:59:01,065 INFO org.apache.hadoop.yarn.server.resourcemanager.scheduler.capacity.CapacityScheduler: Application attempt appattempt_1615531707627_0004_000001 released container container_1615531707627_0004_01_000002 on node: host: tutrung-slave2:46601 #containers=1 available=<memory:6144, vCores:7> used=<memory:2048, vCores:1> with event: FINISHED
2021-03-11 22:59:02,881 INFO org.apache.hadoop.yarn.server.resourcemanager.rmcontainer.RMContainerImpl: container_1615531707627_0004_01_000003 Container Transitioned from NEW to ALLOCATED
2021-03-11 22:59:02,881 INFO org.apache.hadoop.yarn.server.resourcemanager.RMAuditLogger: USER=hadoopuser	OPERATION=AM Allocated Container	TARGET=SchedulerApp	RESULT=SUCCESS	APPID=application_1615531707627_0004	CONTAINERID=container_1615531707627_0004_01_000003
2021-03-11 22:59:02,881 INFO org.apache.hadoop.yarn.server.resourcemanager.scheduler.SchedulerNode: Assigned container container_1615531707627_0004_01_000003 of capacity <memory:1024, vCores:1> on host tutrung-slave1:33619, which has 1 containers, <memory:1024, vCores:1> used and <memory:7168, vCores:7> available after allocation
2021-03-11 22:59:02,881 INFO org.apache.hadoop.yarn.server.resourcemanager.scheduler.capacity.LeafQueue: assignedContainer application attempt=appattempt_1615531707627_0004_000001 container=Container: [ContainerId: container_1615531707627_0004_01_000003, NodeId: tutrung-slave1:33619, NodeHttpAddress: tutrung-slave1:8042, Resource: <memory:1024, vCores:1>, Priority: 10, Token: null, ] queue=default: capacity=1.0, absoluteCapacity=1.0, usedResources=<memory:2048, vCores:1>, usedCapacity=0.125, absoluteUsedCapacity=0.125, numApps=1, numContainers=1 clusterResource=<memory:16384, vCores:16> type=OFF_SWITCH requestedPartition=
2021-03-11 22:59:02,881 INFO org.apache.hadoop.yarn.server.resourcemanager.scheduler.capacity.ParentQueue: Re-sorting assigned queue: root.default stats: default: capacity=1.0, absoluteCapacity=1.0, usedResources=<memory:3072, vCores:2>, usedCapacity=0.1875, absoluteUsedCapacity=0.1875, numApps=1, numContainers=2
2021-03-11 22:59:02,881 INFO org.apache.hadoop.yarn.server.resourcemanager.scheduler.capacity.ParentQueue: assignedContainer queue=root usedCapacity=0.1875 absoluteUsedCapacity=0.1875 used=<memory:3072, vCores:2> cluster=<memory:16384, vCores:16>
2021-03-11 22:59:03,205 INFO org.apache.hadoop.yarn.server.resourcemanager.security.NMTokenSecretManagerInRM: Sending NMToken for nodeId : tutrung-slave1:33619 for container : container_1615531707627_0004_01_000003
2021-03-11 22:59:03,205 INFO org.apache.hadoop.yarn.server.resourcemanager.rmcontainer.RMContainerImpl: container_1615531707627_0004_01_000003 Container Transitioned from ALLOCATED to ACQUIRED
2021-03-11 22:59:03,884 INFO org.apache.hadoop.yarn.server.resourcemanager.rmcontainer.RMContainerImpl: container_1615531707627_0004_01_000003 Container Transitioned from ACQUIRED to RUNNING
2021-03-11 22:59:04,212 INFO org.apache.hadoop.yarn.server.resourcemanager.scheduler.AppSchedulingInfo: checking for deactivate of application :application_1615531707627_0004
2021-03-11 22:59:10,819 INFO org.apache.hadoop.yarn.server.resourcemanager.rmcontainer.RMContainerImpl: container_1615531707627_0004_01_000003 Container Transitioned from RUNNING to COMPLETED
2021-03-11 22:59:10,819 INFO org.apache.hadoop.yarn.server.resourcemanager.scheduler.common.fica.FiCaSchedulerApp: Completed container: container_1615531707627_0004_01_000003 in state: COMPLETED event:FINISHED
2021-03-11 22:59:10,820 INFO org.apache.hadoop.yarn.server.resourcemanager.RMAuditLogger: USER=hadoopuser	OPERATION=AM Released Container	TARGET=SchedulerApp	RESULT=SUCCESS	APPID=application_1615531707627_0004	CONTAINERID=container_1615531707627_0004_01_000003
2021-03-11 22:59:10,820 INFO org.apache.hadoop.yarn.server.resourcemanager.scheduler.SchedulerNode: Released container container_1615531707627_0004_01_000003 of capacity <memory:1024, vCores:1> on host tutrung-slave1:33619, which currently has 0 containers, <memory:0, vCores:0> used and <memory:8192, vCores:8> available, release resources=true
2021-03-11 22:59:10,820 INFO org.apache.hadoop.yarn.server.resourcemanager.scheduler.capacity.LeafQueue: default used=<memory:2048, vCores:1> numContainers=1 user=hadoopuser user-resources=<memory:2048, vCores:1>
2021-03-11 22:59:10,820 INFO org.apache.hadoop.yarn.server.resourcemanager.scheduler.capacity.LeafQueue: completedContainer container=Container: [ContainerId: container_1615531707627_0004_01_000003, NodeId: tutrung-slave1:33619, NodeHttpAddress: tutrung-slave1:8042, Resource: <memory:1024, vCores:1>, Priority: 10, Token: Token { kind: ContainerToken, service: 192.168.244.131:33619 }, ] queue=default: capacity=1.0, absoluteCapacity=1.0, usedResources=<memory:2048, vCores:1>, usedCapacity=0.125, absoluteUsedCapacity=0.125, numApps=1, numContainers=1 cluster=<memory:16384, vCores:16>
2021-03-11 22:59:10,820 INFO org.apache.hadoop.yarn.server.resourcemanager.scheduler.capacity.ParentQueue: completedContainer queue=root usedCapacity=0.125 absoluteUsedCapacity=0.125 used=<memory:2048, vCores:1> cluster=<memory:16384, vCores:16>
2021-03-11 22:59:10,820 INFO org.apache.hadoop.yarn.server.resourcemanager.scheduler.capacity.ParentQueue: Re-sorting completed queue: root.default stats: default: capacity=1.0, absoluteCapacity=1.0, usedResources=<memory:2048, vCores:1>, usedCapacity=0.125, absoluteUsedCapacity=0.125, numApps=1, numContainers=1
2021-03-11 22:59:10,820 INFO org.apache.hadoop.yarn.server.resourcemanager.scheduler.capacity.CapacityScheduler: Application attempt appattempt_1615531707627_0004_000001 released container container_1615531707627_0004_01_000003 on node: host: tutrung-slave1:33619 #containers=0 available=<memory:8192, vCores:8> used=<memory:0, vCores:0> with event: FINISHED
2021-03-11 22:59:11,331 INFO org.apache.hadoop.yarn.server.resourcemanager.rmapp.attempt.RMAppAttemptImpl: Updating application attempt appattempt_1615531707627_0004_000001 with final state: FINISHING, and exit status: -1000
2021-03-11 22:59:11,331 INFO org.apache.hadoop.yarn.server.resourcemanager.rmapp.attempt.RMAppAttemptImpl: appattempt_1615531707627_0004_000001 State change from RUNNING to FINAL_SAVING
2021-03-11 22:59:11,331 INFO org.apache.hadoop.yarn.server.resourcemanager.rmapp.RMAppImpl: Updating application application_1615531707627_0004 with final state: FINISHING
2021-03-11 22:59:11,331 INFO org.apache.hadoop.yarn.server.resourcemanager.rmapp.RMAppImpl: application_1615531707627_0004 State change from RUNNING to FINAL_SAVING on event=ATTEMPT_UNREGISTERED
2021-03-11 22:59:11,332 INFO org.apache.hadoop.yarn.server.resourcemanager.recovery.RMStateStore: Updating info for app: application_1615531707627_0004
2021-03-11 22:59:11,332 INFO org.apache.hadoop.yarn.server.resourcemanager.rmapp.attempt.RMAppAttemptImpl: appattempt_1615531707627_0004_000001 State change from FINAL_SAVING to FINISHING
2021-03-11 22:59:11,332 INFO org.apache.hadoop.yarn.server.resourcemanager.rmapp.RMAppImpl: application_1615531707627_0004 State change from FINAL_SAVING to FINISHING on event=APP_UPDATE_SAVED
2021-03-11 22:59:12,391 INFO org.apache.hadoop.yarn.server.resourcemanager.ApplicationMasterService: application_1615531707627_0004 unregistered successfully. 
2021-03-11 22:59:17,996 INFO org.apache.hadoop.yarn.server.resourcemanager.rmcontainer.RMContainerImpl: container_1615531707627_0004_01_000001 Container Transitioned from RUNNING to COMPLETED
2021-03-11 22:59:17,997 INFO org.apache.hadoop.yarn.server.resourcemanager.scheduler.common.fica.FiCaSchedulerApp: Completed container: container_1615531707627_0004_01_000001 in state: COMPLETED event:FINISHED
2021-03-11 22:59:17,997 INFO org.apache.hadoop.yarn.server.resourcemanager.RMAuditLogger: USER=hadoopuser	OPERATION=AM Released Container	TARGET=SchedulerApp	RESULT=SUCCESS	APPID=application_1615531707627_0004	CONTAINERID=container_1615531707627_0004_01_000001
2021-03-11 22:59:17,997 INFO org.apache.hadoop.yarn.server.resourcemanager.scheduler.SchedulerNode: Released container container_1615531707627_0004_01_000001 of capacity <memory:2048, vCores:1> on host tutrung-slave2:46601, which currently has 0 containers, <memory:0, vCores:0> used and <memory:8192, vCores:8> available, release resources=true
2021-03-11 22:59:17,997 INFO org.apache.hadoop.yarn.server.resourcemanager.scheduler.capacity.LeafQueue: default used=<memory:0, vCores:0> numContainers=0 user=hadoopuser user-resources=<memory:0, vCores:0>
2021-03-11 22:59:17,997 INFO org.apache.hadoop.yarn.server.resourcemanager.scheduler.capacity.LeafQueue: completedContainer container=Container: [ContainerId: container_1615531707627_0004_01_000001, NodeId: tutrung-slave2:46601, NodeHttpAddress: tutrung-slave2:8042, Resource: <memory:2048, vCores:1>, Priority: 0, Token: Token { kind: ContainerToken, service: 192.168.244.132:46601 }, ] queue=default: capacity=1.0, absoluteCapacity=1.0, usedResources=<memory:0, vCores:0>, usedCapacity=0.0, absoluteUsedCapacity=0.0, numApps=1, numContainers=0 cluster=<memory:16384, vCores:16>
2021-03-11 22:59:17,997 INFO org.apache.hadoop.yarn.server.resourcemanager.scheduler.capacity.ParentQueue: completedContainer queue=root usedCapacity=0.0 absoluteUsedCapacity=0.0 used=<memory:0, vCores:0> cluster=<memory:16384, vCores:16>
2021-03-11 22:59:17,997 INFO org.apache.hadoop.yarn.server.resourcemanager.scheduler.capacity.ParentQueue: Re-sorting completed queue: root.default stats: default: capacity=1.0, absoluteCapacity=1.0, usedResources=<memory:0, vCores:0>, usedCapacity=0.0, absoluteUsedCapacity=0.0, numApps=1, numContainers=0
2021-03-11 22:59:17,997 INFO org.apache.hadoop.yarn.server.resourcemanager.scheduler.capacity.CapacityScheduler: Application attempt appattempt_1615531707627_0004_000001 released container container_1615531707627_0004_01_000001 on node: host: tutrung-slave2:46601 #containers=0 available=<memory:8192, vCores:8> used=<memory:0, vCores:0> with event: FINISHED
2021-03-11 22:59:17,997 INFO org.apache.hadoop.yarn.server.resourcemanager.ApplicationMasterService: Unregistering app attempt : appattempt_1615531707627_0004_000001
2021-03-11 22:59:17,997 INFO org.apache.hadoop.yarn.server.resourcemanager.security.AMRMTokenSecretManager: Application finished, removing password for appattempt_1615531707627_0004_000001
2021-03-11 22:59:17,997 INFO org.apache.hadoop.yarn.server.resourcemanager.rmapp.attempt.RMAppAttemptImpl: appattempt_1615531707627_0004_000001 State change from FINISHING to FINISHED
2021-03-11 22:59:17,997 INFO org.apache.hadoop.yarn.server.resourcemanager.rmapp.RMAppImpl: application_1615531707627_0004 State change from FINISHING to FINISHED on event=ATTEMPT_FINISHED
2021-03-11 22:59:17,997 INFO org.apache.hadoop.yarn.server.resourcemanager.RMAuditLogger: USER=hadoopuser	OPERATION=Application Finished - Succeeded	TARGET=RMAppManager	RESULT=SUCCESS	APPID=application_1615531707627_0004
2021-03-11 22:59:17,999 INFO org.apache.hadoop.yarn.server.resourcemanager.scheduler.capacity.CapacityScheduler: Application Attempt appattempt_1615531707627_0004_000001 is done. finalState=FINISHED
2021-03-11 22:59:17,999 INFO org.apache.hadoop.yarn.server.resourcemanager.scheduler.AppSchedulingInfo: Application application_1615531707627_0004 requests cleared
2021-03-11 22:59:17,999 INFO org.apache.hadoop.yarn.server.resourcemanager.scheduler.capacity.LeafQueue: Application removed - appId: application_1615531707627_0004 user: hadoopuser queue: default #user-pending-applications: 0 #user-active-applications: 0 #queue-pending-applications: 0 #queue-active-applications: 0
2021-03-11 22:59:17,999 INFO org.apache.hadoop.yarn.server.resourcemanager.RMAppManager$ApplicationSummary: appId=application_1615531707627_0004,name=PigLatin:script1-hadoop.pig,user=hadoopuser,queue=default,state=FINISHED,trackingUrl=http://master:8088/proxy/application_1615531707627_0004/,appMasterHost=tutrung-slave2,startTime=1615532322383,finishTime=1615532351331,finalStatus=SUCCEEDED,memorySeconds=88752,vcoreSeconds=50,preemptedAMContainers=0,preemptedNonAMContainers=0,preemptedResources=<memory:0\, vCores:0>,applicationType=MAPREDUCE
2021-03-11 22:59:17,999 INFO org.apache.hadoop.yarn.server.resourcemanager.scheduler.capacity.ParentQueue: Application removed - appId: application_1615531707627_0004 user: hadoopuser leaf-queue of parent: root #applications: 0
2021-03-11 22:59:17,999 INFO org.apache.hadoop.yarn.server.resourcemanager.amlauncher.AMLauncher: Cleaning master appattempt_1615531707627_0004_000001
2021-03-11 22:59:19,846 INFO org.apache.hadoop.yarn.server.resourcemanager.scheduler.capacity.CapacityScheduler: Null container completed...
2021-03-11 23:00:45,504 INFO org.apache.hadoop.yarn.server.resourcemanager.ClientRMService: Allocated new applicationId: 5
2021-03-11 23:00:45,853 INFO org.apache.hadoop.yarn.server.resourcemanager.ClientRMService: Application with id 5 submitted by user hadoopuser
2021-03-11 23:00:45,854 INFO org.apache.hadoop.yarn.server.resourcemanager.RMAuditLogger: USER=hadoopuser	IP=192.168.244.130	OPERATION=Submit Application Request	TARGET=ClientRMService	RESULT=SUCCESS	APPID=application_1615531707627_0005
2021-03-11 23:00:45,854 INFO org.apache.hadoop.yarn.server.resourcemanager.rmapp.RMAppImpl: Storing application with id application_1615531707627_0005
2021-03-11 23:00:45,854 INFO org.apache.hadoop.yarn.server.resourcemanager.rmapp.RMAppImpl: application_1615531707627_0005 State change from NEW to NEW_SAVING on event=START
2021-03-11 23:00:45,855 INFO org.apache.hadoop.yarn.server.resourcemanager.recovery.RMStateStore: Storing info for app: application_1615531707627_0005
2021-03-11 23:00:45,855 INFO org.apache.hadoop.yarn.server.resourcemanager.rmapp.RMAppImpl: application_1615531707627_0005 State change from NEW_SAVING to SUBMITTED on event=APP_NEW_SAVED
2021-03-11 23:00:45,855 INFO org.apache.hadoop.yarn.server.resourcemanager.scheduler.capacity.ParentQueue: Application added - appId: application_1615531707627_0005 user: hadoopuser leaf-queue of parent: root #applications: 1
2021-03-11 23:00:45,855 INFO org.apache.hadoop.yarn.server.resourcemanager.scheduler.capacity.CapacityScheduler: Accepted application application_1615531707627_0005 from user: hadoopuser, in queue: default
2021-03-11 23:00:45,855 INFO org.apache.hadoop.yarn.server.resourcemanager.rmapp.RMAppImpl: application_1615531707627_0005 State change from SUBMITTED to ACCEPTED on event=APP_ACCEPTED
2021-03-11 23:00:45,855 INFO org.apache.hadoop.yarn.server.resourcemanager.ApplicationMasterService: Registering app attempt : appattempt_1615531707627_0005_000001
2021-03-11 23:00:45,855 INFO org.apache.hadoop.yarn.server.resourcemanager.rmapp.attempt.RMAppAttemptImpl: appattempt_1615531707627_0005_000001 State change from NEW to SUBMITTED
2021-03-11 23:00:45,856 INFO org.apache.hadoop.yarn.server.resourcemanager.scheduler.capacity.LeafQueue: Application application_1615531707627_0005 from user: hadoopuser activated in queue: default
2021-03-11 23:00:45,856 INFO org.apache.hadoop.yarn.server.resourcemanager.scheduler.capacity.LeafQueue: Application added - appId: application_1615531707627_0005 user: org.apache.hadoop.yarn.server.resourcemanager.scheduler.capacity.LeafQueue$User@b4b01b2, leaf-queue: default #user-pending-applications: 0 #user-active-applications: 1 #queue-pending-applications: 0 #queue-active-applications: 1
2021-03-11 23:00:45,856 INFO org.apache.hadoop.yarn.server.resourcemanager.scheduler.capacity.CapacityScheduler: Added Application Attempt appattempt_1615531707627_0005_000001 to scheduler from user hadoopuser in queue default
2021-03-11 23:00:45,856 INFO org.apache.hadoop.yarn.server.resourcemanager.rmapp.attempt.RMAppAttemptImpl: appattempt_1615531707627_0005_000001 State change from SUBMITTED to SCHEDULED
2021-03-11 23:00:46,209 INFO org.apache.hadoop.yarn.server.resourcemanager.rmcontainer.RMContainerImpl: container_1615531707627_0005_01_000001 Container Transitioned from NEW to ALLOCATED
2021-03-11 23:00:46,210 INFO org.apache.hadoop.yarn.server.resourcemanager.RMAuditLogger: USER=hadoopuser	OPERATION=AM Allocated Container	TARGET=SchedulerApp	RESULT=SUCCESS	APPID=application_1615531707627_0005	CONTAINERID=container_1615531707627_0005_01_000001
2021-03-11 23:00:46,210 INFO org.apache.hadoop.yarn.server.resourcemanager.scheduler.SchedulerNode: Assigned container container_1615531707627_0005_01_000001 of capacity <memory:2048, vCores:1> on host tutrung-slave1:33619, which has 1 containers, <memory:2048, vCores:1> used and <memory:6144, vCores:7> available after allocation
2021-03-11 23:00:46,210 INFO org.apache.hadoop.yarn.server.resourcemanager.scheduler.capacity.LeafQueue: assignedContainer application attempt=appattempt_1615531707627_0005_000001 container=Container: [ContainerId: container_1615531707627_0005_01_000001, NodeId: tutrung-slave1:33619, NodeHttpAddress: tutrung-slave1:8042, Resource: <memory:2048, vCores:1>, Priority: 0, Token: null, ] queue=default: capacity=1.0, absoluteCapacity=1.0, usedResources=<memory:0, vCores:0>, usedCapacity=0.0, absoluteUsedCapacity=0.0, numApps=1, numContainers=0 clusterResource=<memory:16384, vCores:16> type=OFF_SWITCH requestedPartition=
2021-03-11 23:00:46,210 INFO org.apache.hadoop.yarn.server.resourcemanager.scheduler.capacity.ParentQueue: Re-sorting assigned queue: root.default stats: default: capacity=1.0, absoluteCapacity=1.0, usedResources=<memory:2048, vCores:1>, usedCapacity=0.125, absoluteUsedCapacity=0.125, numApps=1, numContainers=1
2021-03-11 23:00:46,210 INFO org.apache.hadoop.yarn.server.resourcemanager.scheduler.capacity.ParentQueue: assignedContainer queue=root usedCapacity=0.125 absoluteUsedCapacity=0.125 used=<memory:2048, vCores:1> cluster=<memory:16384, vCores:16>
2021-03-11 23:00:46,211 INFO org.apache.hadoop.yarn.server.resourcemanager.security.NMTokenSecretManagerInRM: Sending NMToken for nodeId : tutrung-slave1:33619 for container : container_1615531707627_0005_01_000001
2021-03-11 23:00:46,211 INFO org.apache.hadoop.yarn.server.resourcemanager.rmcontainer.RMContainerImpl: container_1615531707627_0005_01_000001 Container Transitioned from ALLOCATED to ACQUIRED
2021-03-11 23:00:46,211 INFO org.apache.hadoop.yarn.server.resourcemanager.security.NMTokenSecretManagerInRM: Clear node set for appattempt_1615531707627_0005_000001
2021-03-11 23:00:46,211 INFO org.apache.hadoop.yarn.server.resourcemanager.rmapp.attempt.RMAppAttemptImpl: Storing attempt: AppId: application_1615531707627_0005 AttemptId: appattempt_1615531707627_0005_000001 MasterContainer: Container: [ContainerId: container_1615531707627_0005_01_000001, NodeId: tutrung-slave1:33619, NodeHttpAddress: tutrung-slave1:8042, Resource: <memory:2048, vCores:1>, Priority: 0, Token: Token { kind: ContainerToken, service: 192.168.244.131:33619 }, ]
2021-03-11 23:00:46,211 INFO org.apache.hadoop.yarn.server.resourcemanager.rmapp.attempt.RMAppAttemptImpl: appattempt_1615531707627_0005_000001 State change from SCHEDULED to ALLOCATED_SAVING
2021-03-11 23:00:46,211 INFO org.apache.hadoop.yarn.server.resourcemanager.rmapp.attempt.RMAppAttemptImpl: appattempt_1615531707627_0005_000001 State change from ALLOCATED_SAVING to ALLOCATED
2021-03-11 23:00:46,213 INFO org.apache.hadoop.yarn.server.resourcemanager.amlauncher.AMLauncher: Launching masterappattempt_1615531707627_0005_000001
2021-03-11 23:00:46,215 INFO org.apache.hadoop.yarn.server.resourcemanager.amlauncher.AMLauncher: Setting up container Container: [ContainerId: container_1615531707627_0005_01_000001, NodeId: tutrung-slave1:33619, NodeHttpAddress: tutrung-slave1:8042, Resource: <memory:2048, vCores:1>, Priority: 0, Token: Token { kind: ContainerToken, service: 192.168.244.131:33619 }, ] for AM appattempt_1615531707627_0005_000001
2021-03-11 23:00:46,216 INFO org.apache.hadoop.yarn.server.resourcemanager.amlauncher.AMLauncher: Command to launch container container_1615531707627_0005_01_000001 : $JAVA_HOME/bin/java -Djava.io.tmpdir=$PWD/tmp -Dlog4j.configuration=container-log4j.properties -Dyarn.app.container.log.dir=<LOG_DIR> -Dyarn.app.container.log.filesize=0 -Dhadoop.root.logger=INFO,CLA -Dhadoop.root.logfile=syslog  -Xmx1024m org.apache.hadoop.mapreduce.v2.app.MRAppMaster 1><LOG_DIR>/stdout 2><LOG_DIR>/stderr 
2021-03-11 23:00:46,216 INFO org.apache.hadoop.yarn.server.resourcemanager.security.AMRMTokenSecretManager: Create AMRMToken for ApplicationAttempt: appattempt_1615531707627_0005_000001
2021-03-11 23:00:46,216 INFO org.apache.hadoop.yarn.server.resourcemanager.security.AMRMTokenSecretManager: Creating password for appattempt_1615531707627_0005_000001
2021-03-11 23:00:46,232 INFO org.apache.hadoop.yarn.server.resourcemanager.amlauncher.AMLauncher: Done launching container Container: [ContainerId: container_1615531707627_0005_01_000001, NodeId: tutrung-slave1:33619, NodeHttpAddress: tutrung-slave1:8042, Resource: <memory:2048, vCores:1>, Priority: 0, Token: Token { kind: ContainerToken, service: 192.168.244.131:33619 }, ] for AM appattempt_1615531707627_0005_000001
2021-03-11 23:00:46,232 INFO org.apache.hadoop.yarn.server.resourcemanager.rmapp.attempt.RMAppAttemptImpl: appattempt_1615531707627_0005_000001 State change from ALLOCATED to LAUNCHED
2021-03-11 23:00:47,212 INFO org.apache.hadoop.yarn.server.resourcemanager.rmcontainer.RMContainerImpl: container_1615531707627_0005_01_000001 Container Transitioned from ACQUIRED to RUNNING
2021-03-11 23:00:53,130 INFO SecurityLogger.org.apache.hadoop.ipc.Server: Auth successful for appattempt_1615531707627_0005_000001 (auth:SIMPLE)
2021-03-11 23:00:53,133 INFO org.apache.hadoop.yarn.server.resourcemanager.ApplicationMasterService: AM registration appattempt_1615531707627_0005_000001
2021-03-11 23:00:53,133 INFO org.apache.hadoop.yarn.server.resourcemanager.RMAuditLogger: USER=hadoopuser	IP=192.168.244.131	OPERATION=Register App Master	TARGET=ApplicationMasterService	RESULT=SUCCESS	APPID=application_1615531707627_0005	APPATTEMPTID=appattempt_1615531707627_0005_000001
2021-03-11 23:00:53,133 INFO org.apache.hadoop.yarn.server.resourcemanager.rmapp.attempt.RMAppAttemptImpl: appattempt_1615531707627_0005_000001 State change from LAUNCHED to RUNNING
2021-03-11 23:00:53,133 INFO org.apache.hadoop.yarn.server.resourcemanager.rmapp.RMAppImpl: application_1615531707627_0005 State change from ACCEPTED to RUNNING on event=ATTEMPT_REGISTERED
2021-03-11 23:00:54,229 INFO org.apache.hadoop.yarn.server.resourcemanager.rmcontainer.RMContainerImpl: container_1615531707627_0005_01_000002 Container Transitioned from NEW to ALLOCATED
2021-03-11 23:00:54,229 INFO org.apache.hadoop.yarn.server.resourcemanager.RMAuditLogger: USER=hadoopuser	OPERATION=AM Allocated Container	TARGET=SchedulerApp	RESULT=SUCCESS	APPID=application_1615531707627_0005	CONTAINERID=container_1615531707627_0005_01_000002
2021-03-11 23:00:54,229 INFO org.apache.hadoop.yarn.server.resourcemanager.scheduler.SchedulerNode: Assigned container container_1615531707627_0005_01_000002 of capacity <memory:1024, vCores:1> on host tutrung-slave1:33619, which has 2 containers, <memory:3072, vCores:2> used and <memory:5120, vCores:6> available after allocation
2021-03-11 23:00:54,229 INFO org.apache.hadoop.yarn.server.resourcemanager.scheduler.capacity.LeafQueue: assignedContainer application attempt=appattempt_1615531707627_0005_000001 container=Container: [ContainerId: container_1615531707627_0005_01_000002, NodeId: tutrung-slave1:33619, NodeHttpAddress: tutrung-slave1:8042, Resource: <memory:1024, vCores:1>, Priority: 20, Token: null, ] queue=default: capacity=1.0, absoluteCapacity=1.0, usedResources=<memory:2048, vCores:1>, usedCapacity=0.125, absoluteUsedCapacity=0.125, numApps=1, numContainers=1 clusterResource=<memory:16384, vCores:16> type=NODE_LOCAL requestedPartition=
2021-03-11 23:00:54,229 INFO org.apache.hadoop.yarn.server.resourcemanager.scheduler.capacity.ParentQueue: Re-sorting assigned queue: root.default stats: default: capacity=1.0, absoluteCapacity=1.0, usedResources=<memory:3072, vCores:2>, usedCapacity=0.1875, absoluteUsedCapacity=0.1875, numApps=1, numContainers=2
2021-03-11 23:00:54,229 INFO org.apache.hadoop.yarn.server.resourcemanager.scheduler.capacity.ParentQueue: assignedContainer queue=root usedCapacity=0.1875 absoluteUsedCapacity=0.1875 used=<memory:3072, vCores:2> cluster=<memory:16384, vCores:16>
2021-03-11 23:00:55,182 INFO org.apache.hadoop.yarn.server.resourcemanager.security.NMTokenSecretManagerInRM: Sending NMToken for nodeId : tutrung-slave1:33619 for container : container_1615531707627_0005_01_000002
2021-03-11 23:00:55,183 INFO org.apache.hadoop.yarn.server.resourcemanager.rmcontainer.RMContainerImpl: container_1615531707627_0005_01_000002 Container Transitioned from ALLOCATED to ACQUIRED
2021-03-11 23:00:56,206 INFO org.apache.hadoop.yarn.server.resourcemanager.scheduler.AppSchedulingInfo: checking for deactivate of application :application_1615531707627_0005
2021-03-11 23:00:56,236 INFO org.apache.hadoop.yarn.server.resourcemanager.rmcontainer.RMContainerImpl: container_1615531707627_0005_01_000002 Container Transitioned from ACQUIRED to RUNNING
2021-03-11 23:01:00,795 INFO org.apache.hadoop.yarn.server.resourcemanager.rmcontainer.RMContainerImpl: container_1615531707627_0005_01_000002 Container Transitioned from RUNNING to COMPLETED
2021-03-11 23:01:00,795 INFO org.apache.hadoop.yarn.server.resourcemanager.scheduler.common.fica.FiCaSchedulerApp: Completed container: container_1615531707627_0005_01_000002 in state: COMPLETED event:FINISHED
2021-03-11 23:01:00,795 INFO org.apache.hadoop.yarn.server.resourcemanager.RMAuditLogger: USER=hadoopuser	OPERATION=AM Released Container	TARGET=SchedulerApp	RESULT=SUCCESS	APPID=application_1615531707627_0005	CONTAINERID=container_1615531707627_0005_01_000002
2021-03-11 23:01:00,795 INFO org.apache.hadoop.yarn.server.resourcemanager.scheduler.SchedulerNode: Released container container_1615531707627_0005_01_000002 of capacity <memory:1024, vCores:1> on host tutrung-slave1:33619, which currently has 1 containers, <memory:2048, vCores:1> used and <memory:6144, vCores:7> available, release resources=true
2021-03-11 23:01:00,796 INFO org.apache.hadoop.yarn.server.resourcemanager.scheduler.capacity.LeafQueue: default used=<memory:2048, vCores:1> numContainers=1 user=hadoopuser user-resources=<memory:2048, vCores:1>
2021-03-11 23:01:00,796 INFO org.apache.hadoop.yarn.server.resourcemanager.scheduler.capacity.LeafQueue: completedContainer container=Container: [ContainerId: container_1615531707627_0005_01_000002, NodeId: tutrung-slave1:33619, NodeHttpAddress: tutrung-slave1:8042, Resource: <memory:1024, vCores:1>, Priority: 20, Token: Token { kind: ContainerToken, service: 192.168.244.131:33619 }, ] queue=default: capacity=1.0, absoluteCapacity=1.0, usedResources=<memory:2048, vCores:1>, usedCapacity=0.125, absoluteUsedCapacity=0.125, numApps=1, numContainers=1 cluster=<memory:16384, vCores:16>
2021-03-11 23:01:00,796 INFO org.apache.hadoop.yarn.server.resourcemanager.scheduler.capacity.ParentQueue: completedContainer queue=root usedCapacity=0.125 absoluteUsedCapacity=0.125 used=<memory:2048, vCores:1> cluster=<memory:16384, vCores:16>
2021-03-11 23:01:00,796 INFO org.apache.hadoop.yarn.server.resourcemanager.scheduler.capacity.ParentQueue: Re-sorting completed queue: root.default stats: default: capacity=1.0, absoluteCapacity=1.0, usedResources=<memory:2048, vCores:1>, usedCapacity=0.125, absoluteUsedCapacity=0.125, numApps=1, numContainers=1
2021-03-11 23:01:00,796 INFO org.apache.hadoop.yarn.server.resourcemanager.scheduler.capacity.CapacityScheduler: Application attempt appattempt_1615531707627_0005_000001 released container container_1615531707627_0005_01_000002 on node: host: tutrung-slave1:33619 #containers=1 available=<memory:6144, vCores:7> used=<memory:2048, vCores:1> with event: FINISHED
2021-03-11 23:01:02,386 INFO org.apache.hadoop.yarn.server.resourcemanager.rmcontainer.RMContainerImpl: container_1615531707627_0005_01_000003 Container Transitioned from NEW to ALLOCATED
2021-03-11 23:01:02,387 INFO org.apache.hadoop.yarn.server.resourcemanager.RMAuditLogger: USER=hadoopuser	OPERATION=AM Allocated Container	TARGET=SchedulerApp	RESULT=SUCCESS	APPID=application_1615531707627_0005	CONTAINERID=container_1615531707627_0005_01_000003
2021-03-11 23:01:02,387 INFO org.apache.hadoop.yarn.server.resourcemanager.scheduler.SchedulerNode: Assigned container container_1615531707627_0005_01_000003 of capacity <memory:1024, vCores:1> on host tutrung-slave2:46601, which has 1 containers, <memory:1024, vCores:1> used and <memory:7168, vCores:7> available after allocation
2021-03-11 23:01:02,389 INFO org.apache.hadoop.yarn.server.resourcemanager.scheduler.capacity.LeafQueue: assignedContainer application attempt=appattempt_1615531707627_0005_000001 container=Container: [ContainerId: container_1615531707627_0005_01_000003, NodeId: tutrung-slave2:46601, NodeHttpAddress: tutrung-slave2:8042, Resource: <memory:1024, vCores:1>, Priority: 10, Token: null, ] queue=default: capacity=1.0, absoluteCapacity=1.0, usedResources=<memory:2048, vCores:1>, usedCapacity=0.125, absoluteUsedCapacity=0.125, numApps=1, numContainers=1 clusterResource=<memory:16384, vCores:16> type=OFF_SWITCH requestedPartition=
2021-03-11 23:01:02,389 INFO org.apache.hadoop.yarn.server.resourcemanager.scheduler.capacity.ParentQueue: Re-sorting assigned queue: root.default stats: default: capacity=1.0, absoluteCapacity=1.0, usedResources=<memory:3072, vCores:2>, usedCapacity=0.1875, absoluteUsedCapacity=0.1875, numApps=1, numContainers=2
2021-03-11 23:01:02,390 INFO org.apache.hadoop.yarn.server.resourcemanager.scheduler.capacity.ParentQueue: assignedContainer queue=root usedCapacity=0.1875 absoluteUsedCapacity=0.1875 used=<memory:3072, vCores:2> cluster=<memory:16384, vCores:16>
2021-03-11 23:01:03,243 INFO org.apache.hadoop.yarn.server.resourcemanager.security.NMTokenSecretManagerInRM: Sending NMToken for nodeId : tutrung-slave2:46601 for container : container_1615531707627_0005_01_000003
2021-03-11 23:01:03,243 INFO org.apache.hadoop.yarn.server.resourcemanager.rmcontainer.RMContainerImpl: container_1615531707627_0005_01_000003 Container Transitioned from ALLOCATED to ACQUIRED
2021-03-11 23:01:03,396 INFO org.apache.hadoop.yarn.server.resourcemanager.rmcontainer.RMContainerImpl: container_1615531707627_0005_01_000003 Container Transitioned from ACQUIRED to RUNNING
2021-03-11 23:01:04,251 INFO org.apache.hadoop.yarn.server.resourcemanager.scheduler.AppSchedulingInfo: checking for deactivate of application :application_1615531707627_0005
2021-03-11 23:01:08,211 INFO org.apache.hadoop.yarn.server.resourcemanager.rmcontainer.RMContainerImpl: container_1615531707627_0005_01_000003 Container Transitioned from RUNNING to COMPLETED
2021-03-11 23:01:08,212 INFO org.apache.hadoop.yarn.server.resourcemanager.scheduler.common.fica.FiCaSchedulerApp: Completed container: container_1615531707627_0005_01_000003 in state: COMPLETED event:FINISHED
2021-03-11 23:01:08,212 INFO org.apache.hadoop.yarn.server.resourcemanager.RMAuditLogger: USER=hadoopuser	OPERATION=AM Released Container	TARGET=SchedulerApp	RESULT=SUCCESS	APPID=application_1615531707627_0005	CONTAINERID=container_1615531707627_0005_01_000003
2021-03-11 23:01:08,212 INFO org.apache.hadoop.yarn.server.resourcemanager.scheduler.SchedulerNode: Released container container_1615531707627_0005_01_000003 of capacity <memory:1024, vCores:1> on host tutrung-slave2:46601, which currently has 0 containers, <memory:0, vCores:0> used and <memory:8192, vCores:8> available, release resources=true
2021-03-11 23:01:08,212 INFO org.apache.hadoop.yarn.server.resourcemanager.scheduler.capacity.LeafQueue: default used=<memory:2048, vCores:1> numContainers=1 user=hadoopuser user-resources=<memory:2048, vCores:1>
2021-03-11 23:01:08,212 INFO org.apache.hadoop.yarn.server.resourcemanager.scheduler.capacity.LeafQueue: completedContainer container=Container: [ContainerId: container_1615531707627_0005_01_000003, NodeId: tutrung-slave2:46601, NodeHttpAddress: tutrung-slave2:8042, Resource: <memory:1024, vCores:1>, Priority: 10, Token: Token { kind: ContainerToken, service: 192.168.244.132:46601 }, ] queue=default: capacity=1.0, absoluteCapacity=1.0, usedResources=<memory:2048, vCores:1>, usedCapacity=0.125, absoluteUsedCapacity=0.125, numApps=1, numContainers=1 cluster=<memory:16384, vCores:16>
2021-03-11 23:01:08,212 INFO org.apache.hadoop.yarn.server.resourcemanager.scheduler.capacity.ParentQueue: completedContainer queue=root usedCapacity=0.125 absoluteUsedCapacity=0.125 used=<memory:2048, vCores:1> cluster=<memory:16384, vCores:16>
2021-03-11 23:01:08,212 INFO org.apache.hadoop.yarn.server.resourcemanager.scheduler.capacity.ParentQueue: Re-sorting completed queue: root.default stats: default: capacity=1.0, absoluteCapacity=1.0, usedResources=<memory:2048, vCores:1>, usedCapacity=0.125, absoluteUsedCapacity=0.125, numApps=1, numContainers=1
2021-03-11 23:01:08,212 INFO org.apache.hadoop.yarn.server.resourcemanager.scheduler.capacity.CapacityScheduler: Application attempt appattempt_1615531707627_0005_000001 released container container_1615531707627_0005_01_000003 on node: host: tutrung-slave2:46601 #containers=0 available=<memory:8192, vCores:8> used=<memory:0, vCores:0> with event: FINISHED
2021-03-11 23:01:08,432 INFO org.apache.hadoop.yarn.server.resourcemanager.rmapp.attempt.RMAppAttemptImpl: Updating application attempt appattempt_1615531707627_0005_000001 with final state: FINISHING, and exit status: -1000
2021-03-11 23:01:08,432 INFO org.apache.hadoop.yarn.server.resourcemanager.rmapp.attempt.RMAppAttemptImpl: appattempt_1615531707627_0005_000001 State change from RUNNING to FINAL_SAVING
2021-03-11 23:01:08,432 INFO org.apache.hadoop.yarn.server.resourcemanager.rmapp.RMAppImpl: Updating application application_1615531707627_0005 with final state: FINISHING
2021-03-11 23:01:08,432 INFO org.apache.hadoop.yarn.server.resourcemanager.rmapp.RMAppImpl: application_1615531707627_0005 State change from RUNNING to FINAL_SAVING on event=ATTEMPT_UNREGISTERED
2021-03-11 23:01:08,434 INFO org.apache.hadoop.yarn.server.resourcemanager.rmapp.attempt.RMAppAttemptImpl: appattempt_1615531707627_0005_000001 State change from FINAL_SAVING to FINISHING
2021-03-11 23:01:08,434 INFO org.apache.hadoop.yarn.server.resourcemanager.recovery.RMStateStore: Updating info for app: application_1615531707627_0005
2021-03-11 23:01:08,435 INFO org.apache.hadoop.yarn.server.resourcemanager.rmapp.RMAppImpl: application_1615531707627_0005 State change from FINAL_SAVING to FINISHING on event=APP_UPDATE_SAVED
2021-03-11 23:01:09,438 INFO org.apache.hadoop.yarn.server.resourcemanager.ApplicationMasterService: application_1615531707627_0005 unregistered successfully. 
2021-03-11 23:01:15,048 INFO org.apache.hadoop.yarn.server.resourcemanager.rmcontainer.RMContainerImpl: container_1615531707627_0005_01_000001 Container Transitioned from RUNNING to COMPLETED
2021-03-11 23:01:15,048 INFO org.apache.hadoop.yarn.server.resourcemanager.scheduler.common.fica.FiCaSchedulerApp: Completed container: container_1615531707627_0005_01_000001 in state: COMPLETED event:FINISHED
2021-03-11 23:01:15,048 INFO org.apache.hadoop.yarn.server.resourcemanager.RMAuditLogger: USER=hadoopuser	OPERATION=AM Released Container	TARGET=SchedulerApp	RESULT=SUCCESS	APPID=application_1615531707627_0005	CONTAINERID=container_1615531707627_0005_01_000001
2021-03-11 23:01:15,048 INFO org.apache.hadoop.yarn.server.resourcemanager.scheduler.SchedulerNode: Released container container_1615531707627_0005_01_000001 of capacity <memory:2048, vCores:1> on host tutrung-slave1:33619, which currently has 0 containers, <memory:0, vCores:0> used and <memory:8192, vCores:8> available, release resources=true
2021-03-11 23:01:15,048 INFO org.apache.hadoop.yarn.server.resourcemanager.scheduler.capacity.LeafQueue: default used=<memory:0, vCores:0> numContainers=0 user=hadoopuser user-resources=<memory:0, vCores:0>
2021-03-11 23:01:15,049 INFO org.apache.hadoop.yarn.server.resourcemanager.scheduler.capacity.LeafQueue: completedContainer container=Container: [ContainerId: container_1615531707627_0005_01_000001, NodeId: tutrung-slave1:33619, NodeHttpAddress: tutrung-slave1:8042, Resource: <memory:2048, vCores:1>, Priority: 0, Token: Token { kind: ContainerToken, service: 192.168.244.131:33619 }, ] queue=default: capacity=1.0, absoluteCapacity=1.0, usedResources=<memory:0, vCores:0>, usedCapacity=0.0, absoluteUsedCapacity=0.0, numApps=1, numContainers=0 cluster=<memory:16384, vCores:16>
2021-03-11 23:01:15,049 INFO org.apache.hadoop.yarn.server.resourcemanager.scheduler.capacity.ParentQueue: completedContainer queue=root usedCapacity=0.0 absoluteUsedCapacity=0.0 used=<memory:0, vCores:0> cluster=<memory:16384, vCores:16>
2021-03-11 23:01:15,049 INFO org.apache.hadoop.yarn.server.resourcemanager.scheduler.capacity.ParentQueue: Re-sorting completed queue: root.default stats: default: capacity=1.0, absoluteCapacity=1.0, usedResources=<memory:0, vCores:0>, usedCapacity=0.0, absoluteUsedCapacity=0.0, numApps=1, numContainers=0
2021-03-11 23:01:15,049 INFO org.apache.hadoop.yarn.server.resourcemanager.scheduler.capacity.CapacityScheduler: Application attempt appattempt_1615531707627_0005_000001 released container container_1615531707627_0005_01_000001 on node: host: tutrung-slave1:33619 #containers=0 available=<memory:8192, vCores:8> used=<memory:0, vCores:0> with event: FINISHED
2021-03-11 23:01:15,049 INFO org.apache.hadoop.yarn.server.resourcemanager.ApplicationMasterService: Unregistering app attempt : appattempt_1615531707627_0005_000001
2021-03-11 23:01:15,049 INFO org.apache.hadoop.yarn.server.resourcemanager.security.AMRMTokenSecretManager: Application finished, removing password for appattempt_1615531707627_0005_000001
2021-03-11 23:01:15,049 INFO org.apache.hadoop.yarn.server.resourcemanager.rmapp.attempt.RMAppAttemptImpl: appattempt_1615531707627_0005_000001 State change from FINISHING to FINISHED
2021-03-11 23:01:15,049 INFO org.apache.hadoop.yarn.server.resourcemanager.rmapp.RMAppImpl: application_1615531707627_0005 State change from FINISHING to FINISHED on event=ATTEMPT_FINISHED
2021-03-11 23:01:15,049 INFO org.apache.hadoop.yarn.server.resourcemanager.RMAuditLogger: USER=hadoopuser	OPERATION=Application Finished - Succeeded	TARGET=RMAppManager	RESULT=SUCCESS	APPID=application_1615531707627_0005
2021-03-11 23:01:15,050 INFO org.apache.hadoop.yarn.server.resourcemanager.RMAppManager$ApplicationSummary: appId=application_1615531707627_0005,name=PigLatin:script1-hadoop.pig,user=hadoopuser,queue=default,state=FINISHED,trackingUrl=http://master:8088/proxy/application_1615531707627_0005/,appMasterHost=tutrung-slave1,startTime=1615532445852,finishTime=1615532468432,finalStatus=SUCCEEDED,memorySeconds=71749,vcoreSeconds=39,preemptedAMContainers=0,preemptedNonAMContainers=0,preemptedResources=<memory:0\, vCores:0>,applicationType=MAPREDUCE
2021-03-11 23:01:15,050 INFO org.apache.hadoop.yarn.server.resourcemanager.scheduler.capacity.CapacityScheduler: Application Attempt appattempt_1615531707627_0005_000001 is done. finalState=FINISHED
2021-03-11 23:01:15,050 INFO org.apache.hadoop.yarn.server.resourcemanager.scheduler.AppSchedulingInfo: Application application_1615531707627_0005 requests cleared
2021-03-11 23:01:15,050 INFO org.apache.hadoop.yarn.server.resourcemanager.scheduler.capacity.LeafQueue: Application removed - appId: application_1615531707627_0005 user: hadoopuser queue: default #user-pending-applications: 0 #user-active-applications: 0 #queue-pending-applications: 0 #queue-active-applications: 0
2021-03-11 23:01:15,050 INFO org.apache.hadoop.yarn.server.resourcemanager.scheduler.capacity.ParentQueue: Application removed - appId: application_1615531707627_0005 user: hadoopuser leaf-queue of parent: root #applications: 0
2021-03-11 23:01:15,053 INFO org.apache.hadoop.yarn.server.resourcemanager.amlauncher.AMLauncher: Cleaning master appattempt_1615531707627_0005_000001
2021-03-11 23:20:31,084 INFO org.apache.hadoop.yarn.server.resourcemanager.ClientRMService: Allocated new applicationId: 6
2021-03-11 23:20:36,823 INFO org.apache.hadoop.ipc.Server: IPC Server handler 0 on 8032, call org.apache.hadoop.yarn.api.ApplicationClientProtocolPB.getApplicationReport from 192.168.244.130:48672 Call#161 Retry#0
org.apache.hadoop.yarn.exceptions.ApplicationNotFoundException: Application with id 'application_1615531707627_0006' doesn't exist in RM.
	at org.apache.hadoop.yarn.server.resourcemanager.ClientRMService.getApplicationReport(ClientRMService.java:327)
	at org.apache.hadoop.yarn.api.impl.pb.service.ApplicationClientProtocolPBServiceImpl.getApplicationReport(ApplicationClientProtocolPBServiceImpl.java:175)
	at org.apache.hadoop.yarn.proto.ApplicationClientProtocol$ApplicationClientProtocolService$2.callBlockingMethod(ApplicationClientProtocol.java:417)
	at org.apache.hadoop.ipc.ProtobufRpcEngine$Server$ProtoBufRpcInvoker.call(ProtobufRpcEngine.java:616)
	at org.apache.hadoop.ipc.RPC$Server.call(RPC.java:982)
	at org.apache.hadoop.ipc.Server$Handler$1.run(Server.java:2217)
	at org.apache.hadoop.ipc.Server$Handler$1.run(Server.java:2213)
	at java.base/java.security.AccessController.doPrivileged(AccessController.java:691)
	at java.base/javax.security.auth.Subject.doAs(Subject.java:425)
	at org.apache.hadoop.security.UserGroupInformation.doAs(UserGroupInformation.java:1762)
	at org.apache.hadoop.ipc.Server$Handler.run(Server.java:2211)
2021-03-11 23:20:46,964 INFO org.apache.hadoop.ipc.Server: IPC Server handler 12 on 8032, call org.apache.hadoop.yarn.api.ApplicationClientProtocolPB.getApplicationReport from 192.168.244.130:48698 Call#163 Retry#0
org.apache.hadoop.yarn.exceptions.ApplicationNotFoundException: Application with id 'application_1615531707627_0006' doesn't exist in RM.
	at org.apache.hadoop.yarn.server.resourcemanager.ClientRMService.getApplicationReport(ClientRMService.java:327)
	at org.apache.hadoop.yarn.api.impl.pb.service.ApplicationClientProtocolPBServiceImpl.getApplicationReport(ApplicationClientProtocolPBServiceImpl.java:175)
	at org.apache.hadoop.yarn.proto.ApplicationClientProtocol$ApplicationClientProtocolService$2.callBlockingMethod(ApplicationClientProtocol.java:417)
	at org.apache.hadoop.ipc.ProtobufRpcEngine$Server$ProtoBufRpcInvoker.call(ProtobufRpcEngine.java:616)
	at org.apache.hadoop.ipc.RPC$Server.call(RPC.java:982)
	at org.apache.hadoop.ipc.Server$Handler$1.run(Server.java:2217)
	at org.apache.hadoop.ipc.Server$Handler$1.run(Server.java:2213)
	at java.base/java.security.AccessController.doPrivileged(AccessController.java:691)
	at java.base/javax.security.auth.Subject.doAs(Subject.java:425)
	at org.apache.hadoop.security.UserGroupInformation.doAs(UserGroupInformation.java:1762)
	at org.apache.hadoop.ipc.Server$Handler.run(Server.java:2211)
2021-03-11 23:20:57,085 INFO org.apache.hadoop.ipc.Server: IPC Server handler 15 on 8032, call org.apache.hadoop.yarn.api.ApplicationClientProtocolPB.getApplicationReport from 192.168.244.130:48722 Call#165 Retry#0
org.apache.hadoop.yarn.exceptions.ApplicationNotFoundException: Application with id 'application_1615531707627_0006' doesn't exist in RM.
	at org.apache.hadoop.yarn.server.resourcemanager.ClientRMService.getApplicationReport(ClientRMService.java:327)
	at org.apache.hadoop.yarn.api.impl.pb.service.ApplicationClientProtocolPBServiceImpl.getApplicationReport(ApplicationClientProtocolPBServiceImpl.java:175)
	at org.apache.hadoop.yarn.proto.ApplicationClientProtocol$ApplicationClientProtocolService$2.callBlockingMethod(ApplicationClientProtocol.java:417)
	at org.apache.hadoop.ipc.ProtobufRpcEngine$Server$ProtoBufRpcInvoker.call(ProtobufRpcEngine.java:616)
	at org.apache.hadoop.ipc.RPC$Server.call(RPC.java:982)
	at org.apache.hadoop.ipc.Server$Handler$1.run(Server.java:2217)
	at org.apache.hadoop.ipc.Server$Handler$1.run(Server.java:2213)
	at java.base/java.security.AccessController.doPrivileged(AccessController.java:691)
	at java.base/javax.security.auth.Subject.doAs(Subject.java:425)
	at org.apache.hadoop.security.UserGroupInformation.doAs(UserGroupInformation.java:1762)
	at org.apache.hadoop.ipc.Server$Handler.run(Server.java:2211)
2021-03-12 22:34:09,406 INFO org.apache.hadoop.yarn.server.resourcemanager.ResourceManager: STARTUP_MSG: 
/************************************************************
STARTUP_MSG: Starting ResourceManager
STARTUP_MSG:   host = master/192.168.244.130
STARTUP_MSG:   args = []
STARTUP_MSG:   version = 2.7.7
STARTUP_MSG:   build = Unknown -r c1aad84bd27cd79c3d1a7dd58202a8c3ee1ed3ac; compiled by 'stevel' on 2018-07-18T22:47Z
STARTUP_MSG:   java = 15.0.2
************************************************************/
2021-03-12 22:34:09,418 INFO org.apache.hadoop.yarn.server.resourcemanager.ResourceManager: registered UNIX signal handlers for [TERM, HUP, INT]
2021-03-12 22:34:09,686 INFO org.apache.hadoop.conf.Configuration: found resource core-site.xml at file:/home/hadoopuser/hadoop/etc/hadoop/core-site.xml
2021-03-12 22:34:09,766 WARN org.apache.hadoop.util.NativeCodeLoader: Unable to load native-hadoop library for your platform... using builtin-java classes where applicable
2021-03-12 22:34:09,792 INFO org.apache.hadoop.security.Groups: clearing userToGroupsMap cache
2021-03-12 22:34:09,911 INFO org.apache.hadoop.conf.Configuration: found resource yarn-site.xml at file:/home/hadoopuser/hadoop/etc/hadoop/yarn-site.xml
2021-03-12 22:34:10,295 INFO org.apache.hadoop.yarn.event.AsyncDispatcher: Registering class org.apache.hadoop.yarn.server.resourcemanager.RMFatalEventType for class org.apache.hadoop.yarn.server.resourcemanager.ResourceManager$RMFatalEventDispatcher
2021-03-12 22:34:10,484 INFO org.apache.hadoop.yarn.server.resourcemanager.security.NMTokenSecretManagerInRM: NMTokenKeyRollingInterval: 86400000ms and NMTokenKeyActivationDelay: 900000ms
2021-03-12 22:34:10,489 INFO org.apache.hadoop.yarn.server.resourcemanager.security.RMContainerTokenSecretManager: ContainerTokenKeyRollingInterval: 86400000ms and ContainerTokenKeyActivationDelay: 900000ms
2021-03-12 22:34:10,498 INFO org.apache.hadoop.yarn.server.resourcemanager.security.AMRMTokenSecretManager: AMRMTokenKeyRollingInterval: 86400000ms and AMRMTokenKeyActivationDelay: 900000 ms
2021-03-12 22:34:10,547 INFO org.apache.hadoop.yarn.event.AsyncDispatcher: Registering class org.apache.hadoop.yarn.server.resourcemanager.recovery.RMStateStoreEventType for class org.apache.hadoop.yarn.server.resourcemanager.recovery.RMStateStore$ForwardingEventHandler
2021-03-12 22:34:10,551 INFO org.apache.hadoop.yarn.event.AsyncDispatcher: Registering class org.apache.hadoop.yarn.server.resourcemanager.NodesListManagerEventType for class org.apache.hadoop.yarn.server.resourcemanager.NodesListManager
2021-03-12 22:34:10,552 INFO org.apache.hadoop.yarn.server.resourcemanager.ResourceManager: Using Scheduler: org.apache.hadoop.yarn.server.resourcemanager.scheduler.capacity.CapacityScheduler
2021-03-12 22:34:10,579 INFO org.apache.hadoop.yarn.event.AsyncDispatcher: Registering class org.apache.hadoop.yarn.server.resourcemanager.scheduler.event.SchedulerEventType for class org.apache.hadoop.yarn.server.resourcemanager.ResourceManager$SchedulerEventDispatcher
2021-03-12 22:34:10,580 INFO org.apache.hadoop.yarn.event.AsyncDispatcher: Registering class org.apache.hadoop.yarn.server.resourcemanager.rmapp.RMAppEventType for class org.apache.hadoop.yarn.server.resourcemanager.ResourceManager$ApplicationEventDispatcher
2021-03-12 22:34:10,581 INFO org.apache.hadoop.yarn.event.AsyncDispatcher: Registering class org.apache.hadoop.yarn.server.resourcemanager.rmapp.attempt.RMAppAttemptEventType for class org.apache.hadoop.yarn.server.resourcemanager.ResourceManager$ApplicationAttemptEventDispatcher
2021-03-12 22:34:10,582 INFO org.apache.hadoop.yarn.event.AsyncDispatcher: Registering class org.apache.hadoop.yarn.server.resourcemanager.rmnode.RMNodeEventType for class org.apache.hadoop.yarn.server.resourcemanager.ResourceManager$NodeEventDispatcher
2021-03-12 22:34:10,665 INFO org.apache.hadoop.metrics2.impl.MetricsConfig: loaded properties from hadoop-metrics2.properties
2021-03-12 22:34:10,825 INFO org.apache.hadoop.metrics2.impl.MetricsSystemImpl: Scheduled snapshot period at 10 second(s).
2021-03-12 22:34:10,825 INFO org.apache.hadoop.metrics2.impl.MetricsSystemImpl: ResourceManager metrics system started
2021-03-12 22:34:10,865 INFO org.apache.hadoop.yarn.event.AsyncDispatcher: Registering class org.apache.hadoop.yarn.server.resourcemanager.RMAppManagerEventType for class org.apache.hadoop.yarn.server.resourcemanager.RMAppManager
2021-03-12 22:34:10,877 INFO org.apache.hadoop.yarn.event.AsyncDispatcher: Registering class org.apache.hadoop.yarn.server.resourcemanager.amlauncher.AMLauncherEventType for class org.apache.hadoop.yarn.server.resourcemanager.amlauncher.ApplicationMasterLauncher
2021-03-12 22:34:10,881 INFO org.apache.hadoop.yarn.server.resourcemanager.RMNMInfo: Registered RMNMInfo MBean
2021-03-12 22:34:10,886 INFO org.apache.hadoop.yarn.security.YarnAuthorizationProvider: org.apache.hadoop.yarn.security.ConfiguredYarnAuthorizer is instiantiated.
2021-03-12 22:34:10,887 INFO org.apache.hadoop.util.HostsFileReader: Refreshing hosts (include/exclude) list
2021-03-12 22:34:10,889 INFO org.apache.hadoop.conf.Configuration: found resource capacity-scheduler.xml at file:/home/hadoopuser/hadoop/etc/hadoop/capacity-scheduler.xml
2021-03-12 22:34:10,953 INFO org.apache.hadoop.yarn.server.resourcemanager.scheduler.capacity.CapacitySchedulerConfiguration: max alloc mb per queue for root is undefined
2021-03-12 22:34:10,954 INFO org.apache.hadoop.yarn.server.resourcemanager.scheduler.capacity.CapacitySchedulerConfiguration: max alloc vcore per queue for root is undefined
2021-03-12 22:34:10,960 INFO org.apache.hadoop.yarn.server.resourcemanager.scheduler.capacity.ParentQueue: root, capacity=1.0, asboluteCapacity=1.0, maxCapacity=1.0, asboluteMaxCapacity=1.0, state=RUNNING, acls=SUBMIT_APP:*ADMINISTER_QUEUE:*, labels=*,
, reservationsContinueLooking=true
2021-03-12 22:34:10,960 INFO org.apache.hadoop.yarn.server.resourcemanager.scheduler.capacity.ParentQueue: Initialized parent-queue root name=root, fullname=root
2021-03-12 22:34:10,973 INFO org.apache.hadoop.yarn.server.resourcemanager.scheduler.capacity.CapacitySchedulerConfiguration: max alloc mb per queue for root.default is undefined
2021-03-12 22:34:10,973 INFO org.apache.hadoop.yarn.server.resourcemanager.scheduler.capacity.CapacitySchedulerConfiguration: max alloc vcore per queue for root.default is undefined
2021-03-12 22:34:10,979 INFO org.apache.hadoop.yarn.server.resourcemanager.scheduler.capacity.LeafQueue: Initializing default
capacity = 1.0 [= (float) configuredCapacity / 100 ]
asboluteCapacity = 1.0 [= parentAbsoluteCapacity * capacity ]
maxCapacity = 1.0 [= configuredMaxCapacity ]
absoluteMaxCapacity = 1.0 [= 1.0 maximumCapacity undefined, (parentAbsoluteMaxCapacity * maximumCapacity) / 100 otherwise ]
userLimit = 100 [= configuredUserLimit ]
userLimitFactor = 1.0 [= configuredUserLimitFactor ]
maxApplications = 10000 [= configuredMaximumSystemApplicationsPerQueue or (int)(configuredMaximumSystemApplications * absoluteCapacity)]
maxApplicationsPerUser = 10000 [= (int)(maxApplications * (userLimit / 100.0f) * userLimitFactor) ]
usedCapacity = 0.0 [= usedResourcesMemory / (clusterResourceMemory * absoluteCapacity)]
absoluteUsedCapacity = 0.0 [= usedResourcesMemory / clusterResourceMemory]
maxAMResourcePerQueuePercent = 0.1 [= configuredMaximumAMResourcePercent ]
minimumAllocationFactor = 0.875 [= (float)(maximumAllocationMemory - minimumAllocationMemory) / maximumAllocationMemory ]
maximumAllocation = <memory:8192, vCores:32> [= configuredMaxAllocation ]
numContainers = 0 [= currentNumContainers ]
state = RUNNING [= configuredState ]
acls = SUBMIT_APP:*ADMINISTER_QUEUE:* [= configuredAcls ]
nodeLocalityDelay = 40
labels=*,
nodeLocalityDelay = 40
reservationsContinueLooking = true
preemptionDisabled = true

2021-03-12 22:34:10,979 INFO org.apache.hadoop.yarn.server.resourcemanager.scheduler.capacity.CapacityScheduler: Initialized queue: default: capacity=1.0, absoluteCapacity=1.0, usedResources=<memory:0, vCores:0>, usedCapacity=0.0, absoluteUsedCapacity=0.0, numApps=0, numContainers=0
2021-03-12 22:34:10,979 INFO org.apache.hadoop.yarn.server.resourcemanager.scheduler.capacity.CapacityScheduler: Initialized queue: root: numChildQueue= 1, capacity=1.0, absoluteCapacity=1.0, usedResources=<memory:0, vCores:0>usedCapacity=0.0, numApps=0, numContainers=0
2021-03-12 22:34:10,980 INFO org.apache.hadoop.yarn.server.resourcemanager.scheduler.capacity.CapacityScheduler: Initialized root queue root: numChildQueue= 1, capacity=1.0, absoluteCapacity=1.0, usedResources=<memory:0, vCores:0>usedCapacity=0.0, numApps=0, numContainers=0
2021-03-12 22:34:10,980 INFO org.apache.hadoop.yarn.server.resourcemanager.scheduler.capacity.CapacityScheduler: Initialized queue mappings, override: false
2021-03-12 22:34:10,981 INFO org.apache.hadoop.yarn.server.resourcemanager.scheduler.capacity.CapacityScheduler: Initialized CapacityScheduler with calculator=class org.apache.hadoop.yarn.util.resource.DefaultResourceCalculator, minimumAllocation=<<memory:1024, vCores:1>>, maximumAllocation=<<memory:8192, vCores:32>>, asynchronousScheduling=false, asyncScheduleInterval=5ms
2021-03-12 22:34:11,000 INFO org.apache.hadoop.yarn.server.resourcemanager.metrics.SystemMetricsPublisher: YARN system metrics publishing service is not enabled
2021-03-12 22:34:11,000 INFO org.apache.hadoop.yarn.server.resourcemanager.ResourceManager: Transitioning to active state
2021-03-12 22:34:11,021 INFO org.apache.hadoop.yarn.server.resourcemanager.recovery.RMStateStore: Updating AMRMToken
2021-03-12 22:34:11,021 INFO org.apache.hadoop.yarn.server.resourcemanager.security.RMContainerTokenSecretManager: Rolling master-key for container-tokens
2021-03-12 22:34:11,021 INFO org.apache.hadoop.yarn.server.resourcemanager.security.NMTokenSecretManagerInRM: Rolling master-key for nm-tokens
2021-03-12 22:34:11,021 INFO org.apache.hadoop.security.token.delegation.AbstractDelegationTokenSecretManager: Updating the current master key for generating delegation tokens
2021-03-12 22:34:11,022 INFO org.apache.hadoop.yarn.server.resourcemanager.security.RMDelegationTokenSecretManager: storing master key with keyID 1
2021-03-12 22:34:11,022 INFO org.apache.hadoop.yarn.server.resourcemanager.recovery.RMStateStore: Storing RMDTMasterKey.
2021-03-12 22:34:11,031 INFO org.apache.hadoop.security.token.delegation.AbstractDelegationTokenSecretManager: Starting expired delegation token remover thread, tokenRemoverScanInterval=60 min(s)
2021-03-12 22:34:11,031 INFO org.apache.hadoop.security.token.delegation.AbstractDelegationTokenSecretManager: Updating the current master key for generating delegation tokens
2021-03-12 22:34:11,031 INFO org.apache.hadoop.yarn.server.resourcemanager.security.RMDelegationTokenSecretManager: storing master key with keyID 2
2021-03-12 22:34:11,032 INFO org.apache.hadoop.yarn.server.resourcemanager.recovery.RMStateStore: Storing RMDTMasterKey.
2021-03-12 22:34:11,048 INFO org.apache.hadoop.yarn.event.AsyncDispatcher: Registering class org.apache.hadoop.yarn.nodelabels.event.NodeLabelsStoreEventType for class org.apache.hadoop.yarn.nodelabels.CommonNodeLabelsManager$ForwardingEventHandler
2021-03-12 22:34:11,098 INFO org.apache.hadoop.ipc.CallQueueManager: Using callQueue: class java.util.concurrent.LinkedBlockingQueue queueCapacity: 5000
2021-03-12 22:34:11,133 INFO org.apache.hadoop.ipc.Server: Starting Socket Reader #1 for port 8031
2021-03-12 22:34:11,418 INFO org.apache.hadoop.yarn.factories.impl.pb.RpcServerFactoryPBImpl: Adding protocol org.apache.hadoop.yarn.server.api.ResourceTrackerPB to the server
2021-03-12 22:34:11,419 INFO org.apache.hadoop.ipc.Server: IPC Server Responder: starting
2021-03-12 22:34:11,427 INFO org.apache.hadoop.ipc.Server: IPC Server listener on 8031: starting
2021-03-12 22:34:11,541 INFO org.apache.hadoop.ipc.CallQueueManager: Using callQueue: class java.util.concurrent.LinkedBlockingQueue queueCapacity: 5000
2021-03-12 22:34:11,549 INFO org.apache.hadoop.ipc.Server: Starting Socket Reader #1 for port 8030
2021-03-12 22:34:11,629 INFO org.apache.hadoop.yarn.factories.impl.pb.RpcServerFactoryPBImpl: Adding protocol org.apache.hadoop.yarn.api.ApplicationMasterProtocolPB to the server
2021-03-12 22:34:11,630 INFO org.apache.hadoop.ipc.Server: IPC Server Responder: starting
2021-03-12 22:34:11,632 INFO org.apache.hadoop.ipc.Server: IPC Server listener on 8030: starting
2021-03-12 22:34:11,845 INFO org.apache.hadoop.ipc.CallQueueManager: Using callQueue: class java.util.concurrent.LinkedBlockingQueue queueCapacity: 5000
2021-03-12 22:34:11,854 INFO org.apache.hadoop.yarn.factories.impl.pb.RpcServerFactoryPBImpl: Adding protocol org.apache.hadoop.yarn.api.ApplicationClientProtocolPB to the server
2021-03-12 22:34:11,854 INFO org.apache.hadoop.ipc.Server: Starting Socket Reader #1 for port 8032
2021-03-12 22:34:11,855 INFO org.apache.hadoop.ipc.Server: IPC Server Responder: starting
2021-03-12 22:34:11,855 INFO org.apache.hadoop.ipc.Server: IPC Server listener on 8032: starting
2021-03-12 22:34:11,904 INFO org.apache.hadoop.yarn.server.resourcemanager.ResourceManager: Transitioned to active state
2021-03-12 22:34:11,981 INFO org.mortbay.log: Logging to org.slf4j.impl.Log4jLoggerAdapter(org.mortbay.log) via org.mortbay.log.Slf4jLog
2021-03-12 22:34:11,988 INFO org.apache.hadoop.security.authentication.server.AuthenticationFilter: Unable to initialize FileSignerSecretProvider, falling back to use random secrets.
2021-03-12 22:34:11,996 INFO org.apache.hadoop.http.HttpRequestLog: Http request log for http.requests.resourcemanager is not defined
2021-03-12 22:34:12,008 INFO org.apache.hadoop.http.HttpServer2: Added global filter 'safety' (class=org.apache.hadoop.http.HttpServer2$QuotingInputFilter)
2021-03-12 22:34:12,017 INFO org.apache.hadoop.http.HttpServer2: Added filter RMAuthenticationFilter (class=org.apache.hadoop.yarn.server.security.http.RMAuthenticationFilter) to context cluster
2021-03-12 22:34:12,018 INFO org.apache.hadoop.http.HttpServer2: Added filter RMAuthenticationFilter (class=org.apache.hadoop.yarn.server.security.http.RMAuthenticationFilter) to context static
2021-03-12 22:34:12,018 INFO org.apache.hadoop.http.HttpServer2: Added filter RMAuthenticationFilter (class=org.apache.hadoop.yarn.server.security.http.RMAuthenticationFilter) to context logs
2021-03-12 22:34:12,019 INFO org.apache.hadoop.http.HttpServer2: Added filter static_user_filter (class=org.apache.hadoop.http.lib.StaticUserWebFilter$StaticUserFilter) to context cluster
2021-03-12 22:34:12,019 INFO org.apache.hadoop.http.HttpServer2: Added filter static_user_filter (class=org.apache.hadoop.http.lib.StaticUserWebFilter$StaticUserFilter) to context static
2021-03-12 22:34:12,019 INFO org.apache.hadoop.http.HttpServer2: Added filter static_user_filter (class=org.apache.hadoop.http.lib.StaticUserWebFilter$StaticUserFilter) to context logs
2021-03-12 22:34:12,026 INFO org.apache.hadoop.http.HttpServer2: adding path spec: /cluster/*
2021-03-12 22:34:12,026 INFO org.apache.hadoop.http.HttpServer2: adding path spec: /ws/*
2021-03-12 22:34:12,821 INFO org.apache.hadoop.yarn.webapp.WebApps: Registered webapp guice modules
2021-03-12 22:34:12,823 INFO org.apache.hadoop.http.HttpServer2: Jetty bound to port 8088
2021-03-12 22:34:12,824 INFO org.mortbay.log: jetty-6.1.26
2021-03-12 22:34:12,899 INFO org.mortbay.log: Extract jar:file:/home/hadoopuser/hadoop/share/hadoop/yarn/hadoop-yarn-common-2.7.7.jar!/webapps/cluster to /tmp/Jetty_master_8088_cluster____i4ls4w/webapp
2021-03-12 22:34:13,049 INFO org.apache.hadoop.security.token.delegation.AbstractDelegationTokenSecretManager: Updating the current master key for generating delegation tokens
2021-03-12 22:34:13,050 INFO org.apache.hadoop.security.token.delegation.AbstractDelegationTokenSecretManager: Starting expired delegation token remover thread, tokenRemoverScanInterval=60 min(s)
2021-03-12 22:34:13,056 INFO org.apache.hadoop.security.token.delegation.AbstractDelegationTokenSecretManager: Updating the current master key for generating delegation tokens
2021-03-12 22:34:15,574 INFO org.mortbay.log: Started HttpServer2$SelectChannelConnectorWithSafeStartup@master:8088
2021-03-12 22:34:15,574 INFO org.apache.hadoop.yarn.webapp.WebApps: Web app cluster started at 8088
2021-03-12 22:34:15,663 INFO org.apache.hadoop.ipc.CallQueueManager: Using callQueue: class java.util.concurrent.LinkedBlockingQueue queueCapacity: 100
2021-03-12 22:34:15,665 INFO org.apache.hadoop.ipc.Server: Starting Socket Reader #1 for port 8033
2021-03-12 22:34:15,670 INFO org.apache.hadoop.yarn.factories.impl.pb.RpcServerFactoryPBImpl: Adding protocol org.apache.hadoop.yarn.server.api.ResourceManagerAdministrationProtocolPB to the server
2021-03-12 22:34:15,674 INFO org.apache.hadoop.ipc.Server: IPC Server Responder: starting
2021-03-12 22:34:15,679 INFO org.apache.hadoop.ipc.Server: IPC Server listener on 8033: starting
2021-03-12 22:34:17,606 INFO org.apache.hadoop.yarn.util.RackResolver: Resolved tutrung-slave1 to /default-rack
2021-03-12 22:34:17,608 INFO org.apache.hadoop.yarn.server.resourcemanager.ResourceTrackerService: NodeManager from node tutrung-slave1(cmPort: 46449 httpPort: 8042) registered with capability: <memory:8192, vCores:8>, assigned nodeId tutrung-slave1:46449
2021-03-12 22:34:17,614 INFO org.apache.hadoop.yarn.server.resourcemanager.rmnode.RMNodeImpl: tutrung-slave1:46449 Node Transitioned from NEW to RUNNING
2021-03-12 22:34:17,619 INFO org.apache.hadoop.yarn.server.resourcemanager.scheduler.capacity.CapacityScheduler: Added node tutrung-slave1:46449 clusterResource: <memory:8192, vCores:8>
2021-03-12 22:34:17,996 INFO org.apache.hadoop.yarn.util.RackResolver: Resolved tutrung-slave2 to /default-rack
2021-03-12 22:34:17,996 INFO org.apache.hadoop.yarn.server.resourcemanager.ResourceTrackerService: NodeManager from node tutrung-slave2(cmPort: 33513 httpPort: 8042) registered with capability: <memory:8192, vCores:8>, assigned nodeId tutrung-slave2:33513
2021-03-12 22:34:17,996 INFO org.apache.hadoop.yarn.server.resourcemanager.rmnode.RMNodeImpl: tutrung-slave2:33513 Node Transitioned from NEW to RUNNING
2021-03-12 22:34:17,997 INFO org.apache.hadoop.yarn.server.resourcemanager.scheduler.capacity.CapacityScheduler: Added node tutrung-slave2:33513 clusterResource: <memory:16384, vCores:16>
2021-03-12 22:46:00,290 INFO org.apache.hadoop.yarn.server.resourcemanager.scheduler.AbstractYarnScheduler: Release request cache is cleaned up
2021-03-12 23:31:52,801 INFO logs: Aliases are enabled
2021-03-12 23:34:56,211 INFO org.apache.hadoop.http.HttpServer2: Process Thread Dump: jsp requested
193 active threads
Thread 2 (Reference Handler):
  State: RUNNABLE
  Blocked count: 0
  Waited count: 0
  Stack:
    java.base@15.0.2/java.lang.ref.Reference.waitForReferencePendingList(Native Method)
    java.base@15.0.2/java.lang.ref.Reference.processPendingReferences(Reference.java:241)
    java.base@15.0.2/java.lang.ref.Reference$ReferenceHandler.run(Reference.java:213)
Thread 3 (Finalizer):
  State: WAITING
  Blocked count: 4
  Waited count: 5
  Waiting on java.lang.ref.ReferenceQueue$Lock@69653e16
  Stack:
    java.base@15.0.2/java.lang.Object.wait(Native Method)
    java.base@15.0.2/java.lang.ref.ReferenceQueue.remove(ReferenceQueue.java:155)
    java.base@15.0.2/java.lang.ref.ReferenceQueue.remove(ReferenceQueue.java:176)
    java.base@15.0.2/java.lang.ref.Finalizer$FinalizerThread.run(Finalizer.java:170)
Thread 4 (Signal Dispatcher):
  State: RUNNABLE
  Blocked count: 0
  Waited count: 0
  Stack:
Thread 9 (Notification Thread):
  State: RUNNABLE
  Blocked count: 0
  Waited count: 0
  Stack:
Thread 10 (Common-Cleaner):
  State: TIMED_WAITING
  Blocked count: 14
  Waited count: 72
  Stack:
    java.base@15.0.2/java.lang.Object.wait(Native Method)
    java.base@15.0.2/java.lang.ref.ReferenceQueue.remove(ReferenceQueue.java:155)
    java.base@15.0.2/jdk.internal.ref.CleanerImpl.run(CleanerImpl.java:148)
    java.base@15.0.2/java.lang.Thread.run(Thread.java:832)
    java.base@15.0.2/jdk.internal.misc.InnocuousThread.run(InnocuousThread.java:134)
Thread 15 (Timer-0):
  State: TIMED_WAITING
  Blocked count: 1
  Waited count: 2
  Stack:
    java.base@15.0.2/java.lang.Object.wait(Native Method)
    java.base@15.0.2/java.util.TimerThread.mainLoop(Timer.java:553)
    java.base@15.0.2/java.util.TimerThread.run(Timer.java:506)
Thread 16 (Timer-1):
  State: TIMED_WAITING
  Blocked count: 1
  Waited count: 2
  Stack:
    java.base@15.0.2/java.lang.Object.wait(Native Method)
    java.base@15.0.2/java.util.TimerThread.mainLoop(Timer.java:553)
    java.base@15.0.2/java.util.TimerThread.run(Timer.java:506)
Thread 17 (Timer-2):
  State: TIMED_WAITING
  Blocked count: 1
  Waited count: 2
  Stack:
    java.base@15.0.2/java.lang.Object.wait(Native Method)
    java.base@15.0.2/java.util.TimerThread.mainLoop(Timer.java:553)
    java.base@15.0.2/java.util.TimerThread.run(Timer.java:506)
Thread 19 (Timer for 'ResourceManager' metrics system):
  State: TIMED_WAITING
  Blocked count: 0
  Waited count: 356
  Stack:
    java.base@15.0.2/java.lang.Object.wait(Native Method)
    java.base@15.0.2/java.util.TimerThread.mainLoop(Timer.java:553)
    java.base@15.0.2/java.util.TimerThread.run(Timer.java:506)
Thread 22 (AsyncDispatcher event handler):
  State: WAITING
  Blocked count: 0
  Waited count: 1
  Waiting on java.util.concurrent.locks.AbstractQueuedSynchronizer$ConditionObject@31952ed2
  Stack:
    java.base@15.0.2/jdk.internal.misc.Unsafe.park(Native Method)
    java.base@15.0.2/java.util.concurrent.locks.LockSupport.park(LockSupport.java:341)
    java.base@15.0.2/java.util.concurrent.locks.AbstractQueuedSynchronizer$ConditionNode.block(AbstractQueuedSynchronizer.java:505)
    java.base@15.0.2/java.util.concurrent.ForkJoinPool.managedBlock(ForkJoinPool.java:3137)
    java.base@15.0.2/java.util.concurrent.locks.AbstractQueuedSynchronizer$ConditionObject.await(AbstractQueuedSynchronizer.java:1614)
    java.base@15.0.2/java.util.concurrent.LinkedBlockingQueue.take(LinkedBlockingQueue.java:435)
    app//org.apache.hadoop.yarn.event.AsyncDispatcher$1.run(AsyncDispatcher.java:102)
    java.base@15.0.2/java.lang.Thread.run(Thread.java:832)
Thread 24 (Thread[Thread-9,5,main]):
  State: TIMED_WAITING
  Blocked count: 0
  Waited count: 706
  Stack:
    java.base@15.0.2/java.lang.Thread.sleep(Native Method)
    app//org.apache.hadoop.security.token.delegation.AbstractDelegationTokenSecretManager$ExpiredTokenRemover.run(AbstractDelegationTokenSecretManager.java:663)
    java.base@15.0.2/java.lang.Thread.run(Thread.java:832)
Thread 25 (Ping Checker):
  State: TIMED_WAITING
  Blocked count: 0
  Waited count: 18
  Stack:
    java.base@15.0.2/java.lang.Thread.sleep(Native Method)
    app//org.apache.hadoop.yarn.util.AbstractLivelinessMonitor$PingChecker.run(AbstractLivelinessMonitor.java:133)
    java.base@15.0.2/java.lang.Thread.run(Thread.java:832)
Thread 26 (Ping Checker):
  State: TIMED_WAITING
  Blocked count: 0
  Waited count: 18
  Stack:
    java.base@15.0.2/java.lang.Thread.sleep(Native Method)
    app//org.apache.hadoop.yarn.util.AbstractLivelinessMonitor$PingChecker.run(AbstractLivelinessMonitor.java:133)
    java.base@15.0.2/java.lang.Thread.run(Thread.java:832)
Thread 27 (Ping Checker):
  State: TIMED_WAITING
  Blocked count: 0
  Waited count: 18
  Stack:
    java.base@15.0.2/java.lang.Thread.sleep(Native Method)
    app//org.apache.hadoop.yarn.util.AbstractLivelinessMonitor$PingChecker.run(AbstractLivelinessMonitor.java:133)
    java.base@15.0.2/java.lang.Thread.run(Thread.java:832)
Thread 28 (AsyncDispatcher event handler):
  State: WAITING
  Blocked count: 0
  Waited count: 1
  Waiting on java.util.concurrent.locks.AbstractQueuedSynchronizer$ConditionObject@8262872
  Stack:
    java.base@15.0.2/jdk.internal.misc.Unsafe.park(Native Method)
    java.base@15.0.2/java.util.concurrent.locks.LockSupport.park(LockSupport.java:341)
    java.base@15.0.2/java.util.concurrent.locks.AbstractQueuedSynchronizer$ConditionNode.block(AbstractQueuedSynchronizer.java:505)
    java.base@15.0.2/java.util.concurrent.ForkJoinPool.managedBlock(ForkJoinPool.java:3137)
    java.base@15.0.2/java.util.concurrent.locks.AbstractQueuedSynchronizer$ConditionObject.await(AbstractQueuedSynchronizer.java:1614)
    java.base@15.0.2/java.util.concurrent.LinkedBlockingQueue.take(LinkedBlockingQueue.java:435)
    app//org.apache.hadoop.yarn.event.AsyncDispatcher$1.run(AsyncDispatcher.java:102)
    java.base@15.0.2/java.lang.Thread.run(Thread.java:832)
Thread 18 (ResourceManager Event Processor):
  State: WAITING
  Blocked count: 1
  Waited count: 6750
  Waiting on java.util.concurrent.locks.AbstractQueuedSynchronizer$ConditionObject@64eb6b39
  Stack:
    java.base@15.0.2/jdk.internal.misc.Unsafe.park(Native Method)
    java.base@15.0.2/java.util.concurrent.locks.LockSupport.park(LockSupport.java:341)
    java.base@15.0.2/java.util.concurrent.locks.AbstractQueuedSynchronizer$ConditionNode.block(AbstractQueuedSynchronizer.java:505)
    java.base@15.0.2/java.util.concurrent.ForkJoinPool.managedBlock(ForkJoinPool.java:3137)
    java.base@15.0.2/java.util.concurrent.locks.AbstractQueuedSynchronizer$ConditionObject.await(AbstractQueuedSynchronizer.java:1614)
    java.base@15.0.2/java.util.concurrent.LinkedBlockingQueue.take(LinkedBlockingQueue.java:435)
    app//org.apache.hadoop.yarn.server.resourcemanager.ResourceManager$SchedulerEventDispatcher$EventProcessor.run(ResourceManager.java:672)
    java.base@15.0.2/java.lang.Thread.run(Thread.java:832)
Thread 29 (Ping Checker):
  State: TIMED_WAITING
  Blocked count: 0
  Waited count: 18
  Stack:
    java.base@15.0.2/java.lang.Thread.sleep(Native Method)
    app//org.apache.hadoop.yarn.util.AbstractLivelinessMonitor$PingChecker.run(AbstractLivelinessMonitor.java:133)
    java.base@15.0.2/java.lang.Thread.run(Thread.java:832)
Thread 31 (Socket Reader #1 for port 8031):
  State: RUNNABLE
  Blocked count: 1
  Waited count: 1
  Stack:
    java.base@15.0.2/sun.nio.ch.EPoll.wait(Native Method)
    java.base@15.0.2/sun.nio.ch.EPollSelectorImpl.doSelect(EPollSelectorImpl.java:120)
    java.base@15.0.2/sun.nio.ch.SelectorImpl.lockAndDoSelect(SelectorImpl.java:129)
    java.base@15.0.2/sun.nio.ch.SelectorImpl.select(SelectorImpl.java:146)
    app//org.apache.hadoop.ipc.Server$Listener$Reader.doRunLoop(Server.java:745)
    app//org.apache.hadoop.ipc.Server$Listener$Reader.run(Server.java:724)
Thread 32 (IPC Server idle connection scanner for port 8031):
  State: TIMED_WAITING
  Blocked count: 1
  Waited count: 356
  Stack:
    java.base@15.0.2/java.lang.Object.wait(Native Method)
    java.base@15.0.2/java.util.TimerThread.mainLoop(Timer.java:553)
    java.base@15.0.2/java.util.TimerThread.run(Timer.java:506)
Thread 33 (IPC Server Responder):
  State: RUNNABLE
  Blocked count: 0
  Waited count: 0
  Stack:
    java.base@15.0.2/sun.nio.ch.EPoll.wait(Native Method)
    java.base@15.0.2/sun.nio.ch.EPollSelectorImpl.doSelect(EPollSelectorImpl.java:120)
    java.base@15.0.2/sun.nio.ch.SelectorImpl.lockAndDoSelect(SelectorImpl.java:129)
    java.base@15.0.2/sun.nio.ch.SelectorImpl.select(SelectorImpl.java:141)
    app//org.apache.hadoop.ipc.Server$Responder.doRunLoop(Server.java:982)
    app//org.apache.hadoop.ipc.Server$Responder.run(Server.java:965)
Thread 30 (IPC Server listener on 8031):
  State: RUNNABLE
  Blocked count: 0
  Waited count: 0
  Stack:
    java.base@15.0.2/sun.nio.ch.EPoll.wait(Native Method)
    java.base@15.0.2/sun.nio.ch.EPollSelectorImpl.doSelect(EPollSelectorImpl.java:120)
    java.base@15.0.2/sun.nio.ch.SelectorImpl.lockAndDoSelect(SelectorImpl.java:129)
    java.base@15.0.2/sun.nio.ch.SelectorImpl.select(SelectorImpl.java:146)
    app//org.apache.hadoop.ipc.Server$Listener.run(Server.java:807)
Thread 34 (IPC Server handler 0 on 8031):
  State: TIMED_WAITING
  Blocked count: 0
  Waited count: 3851
  Stack:
    java.base@15.0.2/jdk.internal.misc.Unsafe.park(Native Method)
    java.base@15.0.2/java.util.concurrent.locks.LockSupport.parkNanos(LockSupport.java:252)
    java.base@15.0.2/java.util.concurrent.locks.AbstractQueuedSynchronizer$ConditionObject.awaitNanos(AbstractQueuedSynchronizer.java:1661)
    java.base@15.0.2/java.util.concurrent.LinkedBlockingQueue.poll(LinkedBlockingQueue.java:460)
    app//org.apache.hadoop.ipc.CallQueueManager.take(CallQueueManager.java:136)
    app//org.apache.hadoop.ipc.Server$Handler.run(Server.java:2185)
Thread 35 (IPC Server handler 1 on 8031):
  State: TIMED_WAITING
  Blocked count: 3
  Waited count: 3792
  Stack:
    java.base@15.0.2/jdk.internal.misc.Unsafe.park(Native Method)
    java.base@15.0.2/java.util.concurrent.locks.LockSupport.parkNanos(LockSupport.java:252)
    java.base@15.0.2/java.util.concurrent.locks.AbstractQueuedSynchronizer$ConditionObject.awaitNanos(AbstractQueuedSynchronizer.java:1661)
    java.base@15.0.2/java.util.concurrent.LinkedBlockingQueue.poll(LinkedBlockingQueue.java:460)
    app//org.apache.hadoop.ipc.CallQueueManager.take(CallQueueManager.java:136)
    app//org.apache.hadoop.ipc.Server$Handler.run(Server.java:2185)
Thread 36 (IPC Server handler 2 on 8031):
  State: TIMED_WAITING
  Blocked count: 1
  Waited count: 3826
  Stack:
    java.base@15.0.2/jdk.internal.misc.Unsafe.park(Native Method)
    java.base@15.0.2/java.util.concurrent.locks.LockSupport.parkNanos(LockSupport.java:252)
    java.base@15.0.2/java.util.concurrent.locks.AbstractQueuedSynchronizer$ConditionObject.awaitNanos(AbstractQueuedSynchronizer.java:1661)
    java.base@15.0.2/java.util.concurrent.LinkedBlockingQueue.poll(LinkedBlockingQueue.java:460)
    app//org.apache.hadoop.ipc.CallQueueManager.take(CallQueueManager.java:136)
    app//org.apache.hadoop.ipc.Server$Handler.run(Server.java:2185)
Thread 37 (IPC Server handler 3 on 8031):
  State: TIMED_WAITING
  Blocked count: 1
  Waited count: 3810
  Stack:
    java.base@15.0.2/jdk.internal.misc.Unsafe.park(Native Method)
    java.base@15.0.2/java.util.concurrent.locks.LockSupport.parkNanos(LockSupport.java:252)
    java.base@15.0.2/java.util.concurrent.locks.AbstractQueuedSynchronizer$ConditionObject.awaitNanos(AbstractQueuedSynchronizer.java:1661)
    java.base@15.0.2/java.util.concurrent.LinkedBlockingQueue.poll(LinkedBlockingQueue.java:460)
    app//org.apache.hadoop.ipc.CallQueueManager.take(CallQueueManager.java:136)
    app//org.apache.hadoop.ipc.Server$Handler.run(Server.java:2185)
Thread 38 (IPC Server handler 4 on 8031):
  State: TIMED_WAITING
  Blocked count: 0
  Waited count: 3792
  Stack:
    java.base@15.0.2/jdk.internal.misc.Unsafe.park(Native Method)
    java.base@15.0.2/java.util.concurrent.locks.LockSupport.parkNanos(LockSupport.java:252)
    java.base@15.0.2/java.util.concurrent.locks.AbstractQueuedSynchronizer$ConditionObject.awaitNanos(AbstractQueuedSynchronizer.java:1661)
    java.base@15.0.2/java.util.concurrent.LinkedBlockingQueue.poll(LinkedBlockingQueue.java:460)
    app//org.apache.hadoop.ipc.CallQueueManager.take(CallQueueManager.java:136)
    app//org.apache.hadoop.ipc.Server$Handler.run(Server.java:2185)
Thread 39 (IPC Server handler 5 on 8031):
  State: TIMED_WAITING
  Blocked count: 0
  Waited count: 3824
  Stack:
    java.base@15.0.2/jdk.internal.misc.Unsafe.park(Native Method)
    java.base@15.0.2/java.util.concurrent.locks.LockSupport.parkNanos(LockSupport.java:252)
    java.base@15.0.2/java.util.concurrent.locks.AbstractQueuedSynchronizer$ConditionObject.awaitNanos(AbstractQueuedSynchronizer.java:1661)
    java.base@15.0.2/java.util.concurrent.LinkedBlockingQueue.poll(LinkedBlockingQueue.java:460)
    app//org.apache.hadoop.ipc.CallQueueManager.take(CallQueueManager.java:136)
    app//org.apache.hadoop.ipc.Server$Handler.run(Server.java:2185)
Thread 40 (IPC Server handler 6 on 8031):
  State: TIMED_WAITING
  Blocked count: 0
  Waited count: 3800
  Stack:
    java.base@15.0.2/jdk.internal.misc.Unsafe.park(Native Method)
    java.base@15.0.2/java.util.concurrent.locks.LockSupport.parkNanos(LockSupport.java:252)
    java.base@15.0.2/java.util.concurrent.locks.AbstractQueuedSynchronizer$ConditionObject.awaitNanos(AbstractQueuedSynchronizer.java:1661)
    java.base@15.0.2/java.util.concurrent.LinkedBlockingQueue.poll(LinkedBlockingQueue.java:460)
    app//org.apache.hadoop.ipc.CallQueueManager.take(CallQueueManager.java:136)
    app//org.apache.hadoop.ipc.Server$Handler.run(Server.java:2185)
Thread 41 (IPC Server handler 7 on 8031):
  State: TIMED_WAITING
  Blocked count: 2
  Waited count: 3852
  Stack:
    java.base@15.0.2/jdk.internal.misc.Unsafe.park(Native Method)
    java.base@15.0.2/java.util.concurrent.locks.LockSupport.parkNanos(LockSupport.java:252)
    java.base@15.0.2/java.util.concurrent.locks.AbstractQueuedSynchronizer$ConditionObject.awaitNanos(AbstractQueuedSynchronizer.java:1661)
    java.base@15.0.2/java.util.concurrent.LinkedBlockingQueue.poll(LinkedBlockingQueue.java:460)
    app//org.apache.hadoop.ipc.CallQueueManager.take(CallQueueManager.java:136)
    app//org.apache.hadoop.ipc.Server$Handler.run(Server.java:2185)
Thread 42 (IPC Server handler 8 on 8031):
  State: TIMED_WAITING
  Blocked count: 1
  Waited count: 3856
  Stack:
    java.base@15.0.2/jdk.internal.misc.Unsafe.park(Native Method)
    java.base@15.0.2/java.util.concurrent.locks.LockSupport.parkNanos(LockSupport.java:252)
    java.base@15.0.2/java.util.concurrent.locks.AbstractQueuedSynchronizer$ConditionObject.awaitNanos(AbstractQueuedSynchronizer.java:1661)
    java.base@15.0.2/java.util.concurrent.LinkedBlockingQueue.poll(LinkedBlockingQueue.java:460)
    app//org.apache.hadoop.ipc.CallQueueManager.take(CallQueueManager.java:136)
    app//org.apache.hadoop.ipc.Server$Handler.run(Server.java:2185)
Thread 43 (IPC Server handler 9 on 8031):
  State: TIMED_WAITING
  Blocked count: 1
  Waited count: 3886
  Stack:
    java.base@15.0.2/jdk.internal.misc.Unsafe.park(Native Method)
    java.base@15.0.2/java.util.concurrent.locks.LockSupport.parkNanos(LockSupport.java:252)
    java.base@15.0.2/java.util.concurrent.locks.AbstractQueuedSynchronizer$ConditionObject.awaitNanos(AbstractQueuedSynchronizer.java:1661)
    java.base@15.0.2/java.util.concurrent.LinkedBlockingQueue.poll(LinkedBlockingQueue.java:460)
    app//org.apache.hadoop.ipc.CallQueueManager.take(CallQueueManager.java:136)
    app//org.apache.hadoop.ipc.Server$Handler.run(Server.java:2185)
Thread 44 (IPC Server handler 10 on 8031):
  State: TIMED_WAITING
  Blocked count: 0
  Waited count: 3809
  Stack:
    java.base@15.0.2/jdk.internal.misc.Unsafe.park(Native Method)
    java.base@15.0.2/java.util.concurrent.locks.LockSupport.parkNanos(LockSupport.java:252)
    java.base@15.0.2/java.util.concurrent.locks.AbstractQueuedSynchronizer$ConditionObject.awaitNanos(AbstractQueuedSynchronizer.java:1661)
    java.base@15.0.2/java.util.concurrent.LinkedBlockingQueue.poll(LinkedBlockingQueue.java:460)
    app//org.apache.hadoop.ipc.CallQueueManager.take(CallQueueManager.java:136)
    app//org.apache.hadoop.ipc.Server$Handler.run(Server.java:2185)
Thread 45 (IPC Server handler 11 on 8031):
  State: TIMED_WAITING
  Blocked count: 2
  Waited count: 3809
  Stack:
    java.base@15.0.2/jdk.internal.misc.Unsafe.park(Native Method)
    java.base@15.0.2/java.util.concurrent.locks.LockSupport.parkNanos(LockSupport.java:252)
    java.base@15.0.2/java.util.concurrent.locks.AbstractQueuedSynchronizer$ConditionObject.awaitNanos(AbstractQueuedSynchronizer.java:1661)
    java.base@15.0.2/java.util.concurrent.LinkedBlockingQueue.poll(LinkedBlockingQueue.java:460)
    app//org.apache.hadoop.ipc.CallQueueManager.take(CallQueueManager.java:136)
    app//org.apache.hadoop.ipc.Server$Handler.run(Server.java:2185)
Thread 46 (IPC Server handler 12 on 8031):
  State: TIMED_WAITING
  Blocked count: 2
  Waited count: 3795
  Stack:
    java.base@15.0.2/jdk.internal.misc.Unsafe.park(Native Method)
    java.base@15.0.2/java.util.concurrent.locks.LockSupport.parkNanos(LockSupport.java:252)
    java.base@15.0.2/java.util.concurrent.locks.AbstractQueuedSynchronizer$ConditionObject.awaitNanos(AbstractQueuedSynchronizer.java:1661)
    java.base@15.0.2/java.util.concurrent.LinkedBlockingQueue.poll(LinkedBlockingQueue.java:460)
    app//org.apache.hadoop.ipc.CallQueueManager.take(CallQueueManager.java:136)
    app//org.apache.hadoop.ipc.Server$Handler.run(Server.java:2185)
Thread 47 (IPC Server handler 13 on 8031):
  State: TIMED_WAITING
  Blocked count: 0
  Waited count: 3853
  Stack:
    java.base@15.0.2/jdk.internal.misc.Unsafe.park(Native Method)
    java.base@15.0.2/java.util.concurrent.locks.LockSupport.parkNanos(LockSupport.java:252)
    java.base@15.0.2/java.util.concurrent.locks.AbstractQueuedSynchronizer$ConditionObject.awaitNanos(AbstractQueuedSynchronizer.java:1661)
    java.base@15.0.2/java.util.concurrent.LinkedBlockingQueue.poll(LinkedBlockingQueue.java:460)
    app//org.apache.hadoop.ipc.CallQueueManager.take(CallQueueManager.java:136)
    app//org.apache.hadoop.ipc.Server$Handler.run(Server.java:2185)
Thread 48 (IPC Server handler 14 on 8031):
  State: TIMED_WAITING
  Blocked count: 1
  Waited count: 3873
  Stack:
    java.base@15.0.2/jdk.internal.misc.Unsafe.park(Native Method)
    java.base@15.0.2/java.util.concurrent.locks.LockSupport.parkNanos(LockSupport.java:252)
    java.base@15.0.2/java.util.concurrent.locks.AbstractQueuedSynchronizer$ConditionObject.awaitNanos(AbstractQueuedSynchronizer.java:1661)
    java.base@15.0.2/java.util.concurrent.LinkedBlockingQueue.poll(LinkedBlockingQueue.java:460)
    app//org.apache.hadoop.ipc.CallQueueManager.take(CallQueueManager.java:136)
    app//org.apache.hadoop.ipc.Server$Handler.run(Server.java:2185)
Thread 49 (IPC Server handler 15 on 8031):
  State: TIMED_WAITING
  Blocked count: 2
  Waited count: 3812
  Stack:
    java.base@15.0.2/jdk.internal.misc.Unsafe.park(Native Method)
    java.base@15.0.2/java.util.concurrent.locks.LockSupport.parkNanos(LockSupport.java:252)
    java.base@15.0.2/java.util.concurrent.locks.AbstractQueuedSynchronizer$ConditionObject.awaitNanos(AbstractQueuedSynchronizer.java:1661)
    java.base@15.0.2/java.util.concurrent.LinkedBlockingQueue.poll(LinkedBlockingQueue.java:460)
    app//org.apache.hadoop.ipc.CallQueueManager.take(CallQueueManager.java:136)
    app//org.apache.hadoop.ipc.Server$Handler.run(Server.java:2185)
Thread 50 (IPC Server handler 16 on 8031):
  State: TIMED_WAITING
  Blocked count: 0
  Waited count: 3806
  Stack:
    java.base@15.0.2/jdk.internal.misc.Unsafe.park(Native Method)
    java.base@15.0.2/java.util.concurrent.locks.LockSupport.parkNanos(LockSupport.java:252)
    java.base@15.0.2/java.util.concurrent.locks.AbstractQueuedSynchronizer$ConditionObject.awaitNanos(AbstractQueuedSynchronizer.java:1661)
    java.base@15.0.2/java.util.concurrent.LinkedBlockingQueue.poll(LinkedBlockingQueue.java:460)
    app//org.apache.hadoop.ipc.CallQueueManager.take(CallQueueManager.java:136)
    app//org.apache.hadoop.ipc.Server$Handler.run(Server.java:2185)
Thread 51 (IPC Server handler 17 on 8031):
  State: TIMED_WAITING
  Blocked count: 1
  Waited count: 3849
  Stack:
    java.base@15.0.2/jdk.internal.misc.Unsafe.park(Native Method)
    java.base@15.0.2/java.util.concurrent.locks.LockSupport.parkNanos(LockSupport.java:252)
    java.base@15.0.2/java.util.concurrent.locks.AbstractQueuedSynchronizer$ConditionObject.awaitNanos(AbstractQueuedSynchronizer.java:1661)
    java.base@15.0.2/java.util.concurrent.LinkedBlockingQueue.poll(LinkedBlockingQueue.java:460)
    app//org.apache.hadoop.ipc.CallQueueManager.take(CallQueueManager.java:136)
    app//org.apache.hadoop.ipc.Server$Handler.run(Server.java:2185)
Thread 52 (IPC Server handler 18 on 8031):
  State: TIMED_WAITING
  Blocked count: 4
  Waited count: 3870
  Stack:
    java.base@15.0.2/jdk.internal.misc.Unsafe.park(Native Method)
    java.base@15.0.2/java.util.concurrent.locks.LockSupport.parkNanos(LockSupport.java:252)
    java.base@15.0.2/java.util.concurrent.locks.AbstractQueuedSynchronizer$ConditionObject.awaitNanos(AbstractQueuedSynchronizer.java:1661)
    java.base@15.0.2/java.util.concurrent.LinkedBlockingQueue.poll(LinkedBlockingQueue.java:460)
    app//org.apache.hadoop.ipc.CallQueueManager.take(CallQueueManager.java:136)
    app//org.apache.hadoop.ipc.Server$Handler.run(Server.java:2185)
Thread 53 (IPC Server handler 19 on 8031):
  State: TIMED_WAITING
  Blocked count: 1
  Waited count: 3830
  Stack:
    java.base@15.0.2/jdk.internal.misc.Unsafe.park(Native Method)
    java.base@15.0.2/java.util.concurrent.locks.LockSupport.parkNanos(LockSupport.java:252)
    java.base@15.0.2/java.util.concurrent.locks.AbstractQueuedSynchronizer$ConditionObject.awaitNanos(AbstractQueuedSynchronizer.java:1661)
    java.base@15.0.2/java.util.concurrent.LinkedBlockingQueue.poll(LinkedBlockingQueue.java:460)
    app//org.apache.hadoop.ipc.CallQueueManager.take(CallQueueManager.java:136)
    app//org.apache.hadoop.ipc.Server$Handler.run(Server.java:2185)
Thread 54 (IPC Server handler 20 on 8031):
  State: TIMED_WAITING
  Blocked count: 1
  Waited count: 3856
  Stack:
    java.base@15.0.2/jdk.internal.misc.Unsafe.park(Native Method)
    java.base@15.0.2/java.util.concurrent.locks.LockSupport.parkNanos(LockSupport.java:252)
    java.base@15.0.2/java.util.concurrent.locks.AbstractQueuedSynchronizer$ConditionObject.awaitNanos(AbstractQueuedSynchronizer.java:1661)
    java.base@15.0.2/java.util.concurrent.LinkedBlockingQueue.poll(LinkedBlockingQueue.java:460)
    app//org.apache.hadoop.ipc.CallQueueManager.take(CallQueueManager.java:136)
    app//org.apache.hadoop.ipc.Server$Handler.run(Server.java:2185)
Thread 55 (IPC Server handler 21 on 8031):
  State: TIMED_WAITING
  Blocked count: 4
  Waited count: 3856
  Stack:
    java.base@15.0.2/jdk.internal.misc.Unsafe.park(Native Method)
    java.base@15.0.2/java.util.concurrent.locks.LockSupport.parkNanos(LockSupport.java:252)
    java.base@15.0.2/java.util.concurrent.locks.AbstractQueuedSynchronizer$ConditionObject.awaitNanos(AbstractQueuedSynchronizer.java:1661)
    java.base@15.0.2/java.util.concurrent.LinkedBlockingQueue.poll(LinkedBlockingQueue.java:460)
    app//org.apache.hadoop.ipc.CallQueueManager.take(CallQueueManager.java:136)
    app//org.apache.hadoop.ipc.Server$Handler.run(Server.java:2185)
Thread 56 (IPC Server handler 22 on 8031):
  State: TIMED_WAITING
  Blocked count: 1
  Waited count: 3788
  Stack:
    java.base@15.0.2/jdk.internal.misc.Unsafe.park(Native Method)
    java.base@15.0.2/java.util.concurrent.locks.LockSupport.parkNanos(LockSupport.java:252)
    java.base@15.0.2/java.util.concurrent.locks.AbstractQueuedSynchronizer$ConditionObject.awaitNanos(AbstractQueuedSynchronizer.java:1661)
    java.base@15.0.2/java.util.concurrent.LinkedBlockingQueue.poll(LinkedBlockingQueue.java:460)
    app//org.apache.hadoop.ipc.CallQueueManager.take(CallQueueManager.java:136)
    app//org.apache.hadoop.ipc.Server$Handler.run(Server.java:2185)
Thread 57 (IPC Server handler 23 on 8031):
  State: TIMED_WAITING
  Blocked count: 2
  Waited count: 3829
  Stack:
    java.base@15.0.2/jdk.internal.misc.Unsafe.park(Native Method)
    java.base@15.0.2/java.util.concurrent.locks.LockSupport.parkNanos(LockSupport.java:252)
    java.base@15.0.2/java.util.concurrent.locks.AbstractQueuedSynchronizer$ConditionObject.awaitNanos(AbstractQueuedSynchronizer.java:1661)
    java.base@15.0.2/java.util.concurrent.LinkedBlockingQueue.poll(LinkedBlockingQueue.java:460)
    app//org.apache.hadoop.ipc.CallQueueManager.take(CallQueueManager.java:136)
    app//org.apache.hadoop.ipc.Server$Handler.run(Server.java:2185)
Thread 58 (IPC Server handler 24 on 8031):
  State: TIMED_WAITING
  Blocked count: 3
  Waited count: 3845
  Stack:
    java.base@15.0.2/jdk.internal.misc.Unsafe.park(Native Method)
    java.base@15.0.2/java.util.concurrent.locks.LockSupport.parkNanos(LockSupport.java:252)
    java.base@15.0.2/java.util.concurrent.locks.AbstractQueuedSynchronizer$ConditionObject.awaitNanos(AbstractQueuedSynchronizer.java:1661)
    java.base@15.0.2/java.util.concurrent.LinkedBlockingQueue.poll(LinkedBlockingQueue.java:460)
    app//org.apache.hadoop.ipc.CallQueueManager.take(CallQueueManager.java:136)
    app//org.apache.hadoop.ipc.Server$Handler.run(Server.java:2185)
Thread 59 (IPC Server handler 25 on 8031):
  State: TIMED_WAITING
  Blocked count: 2
  Waited count: 3828
  Stack:
    java.base@15.0.2/jdk.internal.misc.Unsafe.park(Native Method)
    java.base@15.0.2/java.util.concurrent.locks.LockSupport.parkNanos(LockSupport.java:252)
    java.base@15.0.2/java.util.concurrent.locks.AbstractQueuedSynchronizer$ConditionObject.awaitNanos(AbstractQueuedSynchronizer.java:1661)
    java.base@15.0.2/java.util.concurrent.LinkedBlockingQueue.poll(LinkedBlockingQueue.java:460)
    app//org.apache.hadoop.ipc.CallQueueManager.take(CallQueueManager.java:136)
    app//org.apache.hadoop.ipc.Server$Handler.run(Server.java:2185)
Thread 60 (IPC Server handler 26 on 8031):
  State: TIMED_WAITING
  Blocked count: 2
  Waited count: 3853
  Stack:
    java.base@15.0.2/jdk.internal.misc.Unsafe.park(Native Method)
    java.base@15.0.2/java.util.concurrent.locks.LockSupport.parkNanos(LockSupport.java:252)
    java.base@15.0.2/java.util.concurrent.locks.AbstractQueuedSynchronizer$ConditionObject.awaitNanos(AbstractQueuedSynchronizer.java:1661)
    java.base@15.0.2/java.util.concurrent.LinkedBlockingQueue.poll(LinkedBlockingQueue.java:460)
    app//org.apache.hadoop.ipc.CallQueueManager.take(CallQueueManager.java:136)
    app//org.apache.hadoop.ipc.Server$Handler.run(Server.java:2185)
Thread 61 (IPC Server handler 27 on 8031):
  State: TIMED_WAITING
  Blocked count: 0
  Waited count: 3883
  Stack:
    java.base@15.0.2/jdk.internal.misc.Unsafe.park(Native Method)
    java.base@15.0.2/java.util.concurrent.locks.LockSupport.parkNanos(LockSupport.java:252)
    java.base@15.0.2/java.util.concurrent.locks.AbstractQueuedSynchronizer$ConditionObject.awaitNanos(AbstractQueuedSynchronizer.java:1661)
    java.base@15.0.2/java.util.concurrent.LinkedBlockingQueue.poll(LinkedBlockingQueue.java:460)
    app//org.apache.hadoop.ipc.CallQueueManager.take(CallQueueManager.java:136)
    app//org.apache.hadoop.ipc.Server$Handler.run(Server.java:2185)
Thread 62 (IPC Server handler 28 on 8031):
  State: TIMED_WAITING
  Blocked count: 0
  Waited count: 3790
  Stack:
    java.base@15.0.2/jdk.internal.misc.Unsafe.park(Native Method)
    java.base@15.0.2/java.util.concurrent.locks.LockSupport.parkNanos(LockSupport.java:252)
    java.base@15.0.2/java.util.concurrent.locks.AbstractQueuedSynchronizer$ConditionObject.awaitNanos(AbstractQueuedSynchronizer.java:1661)
    java.base@15.0.2/java.util.concurrent.LinkedBlockingQueue.poll(LinkedBlockingQueue.java:460)
    app//org.apache.hadoop.ipc.CallQueueManager.take(CallQueueManager.java:136)
    app//org.apache.hadoop.ipc.Server$Handler.run(Server.java:2185)
Thread 63 (IPC Server handler 29 on 8031):
  State: TIMED_WAITING
  Blocked count: 1
  Waited count: 3810
  Stack:
    java.base@15.0.2/jdk.internal.misc.Unsafe.park(Native Method)
    java.base@15.0.2/java.util.concurrent.locks.LockSupport.parkNanos(LockSupport.java:252)
    java.base@15.0.2/java.util.concurrent.locks.AbstractQueuedSynchronizer$ConditionObject.awaitNanos(AbstractQueuedSynchronizer.java:1661)
    java.base@15.0.2/java.util.concurrent.LinkedBlockingQueue.poll(LinkedBlockingQueue.java:460)
    app//org.apache.hadoop.ipc.CallQueueManager.take(CallQueueManager.java:136)
    app//org.apache.hadoop.ipc.Server$Handler.run(Server.java:2185)
Thread 64 (IPC Server handler 30 on 8031):
  State: TIMED_WAITING
  Blocked count: 1
  Waited count: 3835
  Stack:
    java.base@15.0.2/jdk.internal.misc.Unsafe.park(Native Method)
    java.base@15.0.2/java.util.concurrent.locks.LockSupport.parkNanos(LockSupport.java:252)
    java.base@15.0.2/java.util.concurrent.locks.AbstractQueuedSynchronizer$ConditionObject.awaitNanos(AbstractQueuedSynchronizer.java:1661)
    java.base@15.0.2/java.util.concurrent.LinkedBlockingQueue.poll(LinkedBlockingQueue.java:460)
    app//org.apache.hadoop.ipc.CallQueueManager.take(CallQueueManager.java:136)
    app//org.apache.hadoop.ipc.Server$Handler.run(Server.java:2185)
Thread 65 (IPC Server handler 31 on 8031):
  State: TIMED_WAITING
  Blocked count: 1
  Waited count: 3911
  Stack:
    java.base@15.0.2/jdk.internal.misc.Unsafe.park(Native Method)
    java.base@15.0.2/java.util.concurrent.locks.LockSupport.parkNanos(LockSupport.java:252)
    java.base@15.0.2/java.util.concurrent.locks.AbstractQueuedSynchronizer$ConditionObject.awaitNanos(AbstractQueuedSynchronizer.java:1661)
    java.base@15.0.2/java.util.concurrent.LinkedBlockingQueue.poll(LinkedBlockingQueue.java:460)
    app//org.apache.hadoop.ipc.CallQueueManager.take(CallQueueManager.java:136)
    app//org.apache.hadoop.ipc.Server$Handler.run(Server.java:2185)
Thread 66 (IPC Server handler 32 on 8031):
  State: TIMED_WAITING
  Blocked count: 1
  Waited count: 3867
  Stack:
    java.base@15.0.2/jdk.internal.misc.Unsafe.park(Native Method)
    java.base@15.0.2/java.util.concurrent.locks.LockSupport.parkNanos(LockSupport.java:252)
    java.base@15.0.2/java.util.concurrent.locks.AbstractQueuedSynchronizer$ConditionObject.awaitNanos(AbstractQueuedSynchronizer.java:1661)
    java.base@15.0.2/java.util.concurrent.LinkedBlockingQueue.poll(LinkedBlockingQueue.java:460)
    app//org.apache.hadoop.ipc.CallQueueManager.take(CallQueueManager.java:136)
    app//org.apache.hadoop.ipc.Server$Handler.run(Server.java:2185)
Thread 67 (IPC Server handler 33 on 8031):
  State: TIMED_WAITING
  Blocked count: 0
  Waited count: 3930
  Stack:
    java.base@15.0.2/jdk.internal.misc.Unsafe.park(Native Method)
    java.base@15.0.2/java.util.concurrent.locks.LockSupport.parkNanos(LockSupport.java:252)
    java.base@15.0.2/java.util.concurrent.locks.AbstractQueuedSynchronizer$ConditionObject.awaitNanos(AbstractQueuedSynchronizer.java:1661)
    java.base@15.0.2/java.util.concurrent.LinkedBlockingQueue.poll(LinkedBlockingQueue.java:460)
    app//org.apache.hadoop.ipc.CallQueueManager.take(CallQueueManager.java:136)
    app//org.apache.hadoop.ipc.Server$Handler.run(Server.java:2185)
Thread 68 (IPC Server handler 34 on 8031):
  State: TIMED_WAITING
  Blocked count: 0
  Waited count: 3843
  Stack:
    java.base@15.0.2/jdk.internal.misc.Unsafe.park(Native Method)
    java.base@15.0.2/java.util.concurrent.locks.LockSupport.parkNanos(LockSupport.java:252)
    java.base@15.0.2/java.util.concurrent.locks.AbstractQueuedSynchronizer$ConditionObject.awaitNanos(AbstractQueuedSynchronizer.java:1661)
    java.base@15.0.2/java.util.concurrent.LinkedBlockingQueue.poll(LinkedBlockingQueue.java:460)
    app//org.apache.hadoop.ipc.CallQueueManager.take(CallQueueManager.java:136)
    app//org.apache.hadoop.ipc.Server$Handler.run(Server.java:2185)
Thread 69 (IPC Server handler 35 on 8031):
  State: TIMED_WAITING
  Blocked count: 2
  Waited count: 3867
  Stack:
    java.base@15.0.2/jdk.internal.misc.Unsafe.park(Native Method)
    java.base@15.0.2/java.util.concurrent.locks.LockSupport.parkNanos(LockSupport.java:252)
    java.base@15.0.2/java.util.concurrent.locks.AbstractQueuedSynchronizer$ConditionObject.awaitNanos(AbstractQueuedSynchronizer.java:1661)
    java.base@15.0.2/java.util.concurrent.LinkedBlockingQueue.poll(LinkedBlockingQueue.java:460)
    app//org.apache.hadoop.ipc.CallQueueManager.take(CallQueueManager.java:136)
    app//org.apache.hadoop.ipc.Server$Handler.run(Server.java:2185)
Thread 70 (IPC Server handler 36 on 8031):
  State: TIMED_WAITING
  Blocked count: 4
  Waited count: 3809
  Stack:
    java.base@15.0.2/jdk.internal.misc.Unsafe.park(Native Method)
    java.base@15.0.2/java.util.concurrent.locks.LockSupport.parkNanos(LockSupport.java:252)
    java.base@15.0.2/java.util.concurrent.locks.AbstractQueuedSynchronizer$ConditionObject.awaitNanos(AbstractQueuedSynchronizer.java:1661)
    java.base@15.0.2/java.util.concurrent.LinkedBlockingQueue.poll(LinkedBlockingQueue.java:460)
    app//org.apache.hadoop.ipc.CallQueueManager.take(CallQueueManager.java:136)
    app//org.apache.hadoop.ipc.Server$Handler.run(Server.java:2185)
Thread 71 (IPC Server handler 37 on 8031):
  State: TIMED_WAITING
  Blocked count: 0
  Waited count: 3831
  Stack:
    java.base@15.0.2/jdk.internal.misc.Unsafe.park(Native Method)
    java.base@15.0.2/java.util.concurrent.locks.LockSupport.parkNanos(LockSupport.java:252)
    java.base@15.0.2/java.util.concurrent.locks.AbstractQueuedSynchronizer$ConditionObject.awaitNanos(AbstractQueuedSynchronizer.java:1661)
    java.base@15.0.2/java.util.concurrent.LinkedBlockingQueue.poll(LinkedBlockingQueue.java:460)
    app//org.apache.hadoop.ipc.CallQueueManager.take(CallQueueManager.java:136)
    app//org.apache.hadoop.ipc.Server$Handler.run(Server.java:2185)
Thread 72 (IPC Server handler 38 on 8031):
  State: TIMED_WAITING
  Blocked count: 0
  Waited count: 3822
  Stack:
    java.base@15.0.2/jdk.internal.misc.Unsafe.park(Native Method)
    java.base@15.0.2/java.util.concurrent.locks.LockSupport.parkNanos(LockSupport.java:252)
    java.base@15.0.2/java.util.concurrent.locks.AbstractQueuedSynchronizer$ConditionObject.awaitNanos(AbstractQueuedSynchronizer.java:1661)
    java.base@15.0.2/java.util.concurrent.LinkedBlockingQueue.poll(LinkedBlockingQueue.java:460)
    app//org.apache.hadoop.ipc.CallQueueManager.take(CallQueueManager.java:136)
    app//org.apache.hadoop.ipc.Server$Handler.run(Server.java:2185)
Thread 73 (IPC Server handler 39 on 8031):
  State: TIMED_WAITING
  Blocked count: 2
  Waited count: 3862
  Stack:
    java.base@15.0.2/jdk.internal.misc.Unsafe.park(Native Method)
    java.base@15.0.2/java.util.concurrent.locks.LockSupport.parkNanos(LockSupport.java:252)
    java.base@15.0.2/java.util.concurrent.locks.AbstractQueuedSynchronizer$ConditionObject.awaitNanos(AbstractQueuedSynchronizer.java:1661)
    java.base@15.0.2/java.util.concurrent.LinkedBlockingQueue.poll(LinkedBlockingQueue.java:460)
    app//org.apache.hadoop.ipc.CallQueueManager.take(CallQueueManager.java:136)
    app//org.apache.hadoop.ipc.Server$Handler.run(Server.java:2185)
Thread 74 (IPC Server handler 40 on 8031):
  State: TIMED_WAITING
  Blocked count: 1
  Waited count: 3795
  Stack:
    java.base@15.0.2/jdk.internal.misc.Unsafe.park(Native Method)
    java.base@15.0.2/java.util.concurrent.locks.LockSupport.parkNanos(LockSupport.java:252)
    java.base@15.0.2/java.util.concurrent.locks.AbstractQueuedSynchronizer$ConditionObject.awaitNanos(AbstractQueuedSynchronizer.java:1661)
    java.base@15.0.2/java.util.concurrent.LinkedBlockingQueue.poll(LinkedBlockingQueue.java:460)
    app//org.apache.hadoop.ipc.CallQueueManager.take(CallQueueManager.java:136)
    app//org.apache.hadoop.ipc.Server$Handler.run(Server.java:2185)
Thread 75 (IPC Server handler 41 on 8031):
  State: TIMED_WAITING
  Blocked count: 0
  Waited count: 3811
  Stack:
    java.base@15.0.2/jdk.internal.misc.Unsafe.park(Native Method)
    java.base@15.0.2/java.util.concurrent.locks.LockSupport.parkNanos(LockSupport.java:252)
    java.base@15.0.2/java.util.concurrent.locks.AbstractQueuedSynchronizer$ConditionObject.awaitNanos(AbstractQueuedSynchronizer.java:1661)
    java.base@15.0.2/java.util.concurrent.LinkedBlockingQueue.poll(LinkedBlockingQueue.java:460)
    app//org.apache.hadoop.ipc.CallQueueManager.take(CallQueueManager.java:136)
    app//org.apache.hadoop.ipc.Server$Handler.run(Server.java:2185)
Thread 76 (IPC Server handler 42 on 8031):
  State: TIMED_WAITING
  Blocked count: 0
  Waited count: 3827
  Stack:
    java.base@15.0.2/jdk.internal.misc.Unsafe.park(Native Method)
    java.base@15.0.2/java.util.concurrent.locks.LockSupport.parkNanos(LockSupport.java:252)
    java.base@15.0.2/java.util.concurrent.locks.AbstractQueuedSynchronizer$ConditionObject.awaitNanos(AbstractQueuedSynchronizer.java:1661)
    java.base@15.0.2/java.util.concurrent.LinkedBlockingQueue.poll(LinkedBlockingQueue.java:460)
    app//org.apache.hadoop.ipc.CallQueueManager.take(CallQueueManager.java:136)
    app//org.apache.hadoop.ipc.Server$Handler.run(Server.java:2185)
Thread 77 (IPC Server handler 43 on 8031):
  State: TIMED_WAITING
  Blocked count: 1
  Waited count: 3865
  Stack:
    java.base@15.0.2/jdk.internal.misc.Unsafe.park(Native Method)
    java.base@15.0.2/java.util.concurrent.locks.LockSupport.parkNanos(LockSupport.java:252)
    java.base@15.0.2/java.util.concurrent.locks.AbstractQueuedSynchronizer$ConditionObject.awaitNanos(AbstractQueuedSynchronizer.java:1661)
    java.base@15.0.2/java.util.concurrent.LinkedBlockingQueue.poll(LinkedBlockingQueue.java:460)
    app//org.apache.hadoop.ipc.CallQueueManager.take(CallQueueManager.java:136)
    app//org.apache.hadoop.ipc.Server$Handler.run(Server.java:2185)
Thread 78 (IPC Server handler 44 on 8031):
  State: TIMED_WAITING
  Blocked count: 1
  Waited count: 3815
  Stack:
    java.base@15.0.2/jdk.internal.misc.Unsafe.park(Native Method)
    java.base@15.0.2/java.util.concurrent.locks.LockSupport.parkNanos(LockSupport.java:252)
    java.base@15.0.2/java.util.concurrent.locks.AbstractQueuedSynchronizer$ConditionObject.awaitNanos(AbstractQueuedSynchronizer.java:1661)
    java.base@15.0.2/java.util.concurrent.LinkedBlockingQueue.poll(LinkedBlockingQueue.java:460)
    app//org.apache.hadoop.ipc.CallQueueManager.take(CallQueueManager.java:136)
    app//org.apache.hadoop.ipc.Server$Handler.run(Server.java:2185)
Thread 79 (IPC Server handler 45 on 8031):
  State: TIMED_WAITING
  Blocked count: 2
  Waited count: 3802
  Stack:
    java.base@15.0.2/jdk.internal.misc.Unsafe.park(Native Method)
    java.base@15.0.2/java.util.concurrent.locks.LockSupport.parkNanos(LockSupport.java:252)
    java.base@15.0.2/java.util.concurrent.locks.AbstractQueuedSynchronizer$ConditionObject.awaitNanos(AbstractQueuedSynchronizer.java:1661)
    java.base@15.0.2/java.util.concurrent.LinkedBlockingQueue.poll(LinkedBlockingQueue.java:460)
    app//org.apache.hadoop.ipc.CallQueueManager.take(CallQueueManager.java:136)
    app//org.apache.hadoop.ipc.Server$Handler.run(Server.java:2185)
Thread 80 (IPC Server handler 46 on 8031):
  State: TIMED_WAITING
  Blocked count: 3
  Waited count: 3808
  Stack:
    java.base@15.0.2/jdk.internal.misc.Unsafe.park(Native Method)
    java.base@15.0.2/java.util.concurrent.locks.LockSupport.parkNanos(LockSupport.java:252)
    java.base@15.0.2/java.util.concurrent.locks.AbstractQueuedSynchronizer$ConditionObject.awaitNanos(AbstractQueuedSynchronizer.java:1661)
    java.base@15.0.2/java.util.concurrent.LinkedBlockingQueue.poll(LinkedBlockingQueue.java:460)
    app//org.apache.hadoop.ipc.CallQueueManager.take(CallQueueManager.java:136)
    app//org.apache.hadoop.ipc.Server$Handler.run(Server.java:2185)
Thread 81 (IPC Server handler 47 on 8031):
  State: TIMED_WAITING
  Blocked count: 1
  Waited count: 3836
  Stack:
    java.base@15.0.2/jdk.internal.misc.Unsafe.park(Native Method)
    java.base@15.0.2/java.util.concurrent.locks.LockSupport.parkNanos(LockSupport.java:252)
    java.base@15.0.2/java.util.concurrent.locks.AbstractQueuedSynchronizer$ConditionObject.awaitNanos(AbstractQueuedSynchronizer.java:1661)
    java.base@15.0.2/java.util.concurrent.LinkedBlockingQueue.poll(LinkedBlockingQueue.java:460)
    app//org.apache.hadoop.ipc.CallQueueManager.take(CallQueueManager.java:136)
    app//org.apache.hadoop.ipc.Server$Handler.run(Server.java:2185)
Thread 82 (IPC Server handler 48 on 8031):
  State: TIMED_WAITING
  Blocked count: 3
  Waited count: 3789
  Stack:
    java.base@15.0.2/jdk.internal.misc.Unsafe.park(Native Method)
    java.base@15.0.2/java.util.concurrent.locks.LockSupport.parkNanos(LockSupport.java:252)
    java.base@15.0.2/java.util.concurrent.locks.AbstractQueuedSynchronizer$ConditionObject.awaitNanos(AbstractQueuedSynchronizer.java:1661)
    java.base@15.0.2/java.util.concurrent.LinkedBlockingQueue.poll(LinkedBlockingQueue.java:460)
    app//org.apache.hadoop.ipc.CallQueueManager.take(CallQueueManager.java:136)
    app//org.apache.hadoop.ipc.Server$Handler.run(Server.java:2185)
Thread 83 (IPC Server handler 49 on 8031):
  State: TIMED_WAITING
  Blocked count: 1
  Waited count: 3842
  Stack:
    java.base@15.0.2/jdk.internal.misc.Unsafe.park(Native Method)
    java.base@15.0.2/java.util.concurrent.locks.LockSupport.parkNanos(LockSupport.java:252)
    java.base@15.0.2/java.util.concurrent.locks.AbstractQueuedSynchronizer$ConditionObject.awaitNanos(AbstractQueuedSynchronizer.java:1661)
    java.base@15.0.2/java.util.concurrent.LinkedBlockingQueue.poll(LinkedBlockingQueue.java:460)
    app//org.apache.hadoop.ipc.CallQueueManager.take(CallQueueManager.java:136)
    app//org.apache.hadoop.ipc.Server$Handler.run(Server.java:2185)
Thread 85 (Socket Reader #1 for port 8030):
  State: RUNNABLE
  Blocked count: 0
  Waited count: 0
  Stack:
    java.base@15.0.2/sun.nio.ch.EPoll.wait(Native Method)
    java.base@15.0.2/sun.nio.ch.EPollSelectorImpl.doSelect(EPollSelectorImpl.java:120)
    java.base@15.0.2/sun.nio.ch.SelectorImpl.lockAndDoSelect(SelectorImpl.java:129)
    java.base@15.0.2/sun.nio.ch.SelectorImpl.select(SelectorImpl.java:146)
    app//org.apache.hadoop.ipc.Server$Listener$Reader.doRunLoop(Server.java:745)
    app//org.apache.hadoop.ipc.Server$Listener$Reader.run(Server.java:724)
Thread 86 (IPC Server idle connection scanner for port 8030):
  State: TIMED_WAITING
  Blocked count: 1
  Waited count: 356
  Stack:
    java.base@15.0.2/java.lang.Object.wait(Native Method)
    java.base@15.0.2/java.util.TimerThread.mainLoop(Timer.java:553)
    java.base@15.0.2/java.util.TimerThread.run(Timer.java:506)
Thread 87 (IPC Server Responder):
  State: RUNNABLE
  Blocked count: 0
  Waited count: 0
  Stack:
    java.base@15.0.2/sun.nio.ch.EPoll.wait(Native Method)
    java.base@15.0.2/sun.nio.ch.EPollSelectorImpl.doSelect(EPollSelectorImpl.java:120)
    java.base@15.0.2/sun.nio.ch.SelectorImpl.lockAndDoSelect(SelectorImpl.java:129)
    java.base@15.0.2/sun.nio.ch.SelectorImpl.select(SelectorImpl.java:141)
    app//org.apache.hadoop.ipc.Server$Responder.doRunLoop(Server.java:982)
    app//org.apache.hadoop.ipc.Server$Responder.run(Server.java:965)
Thread 84 (IPC Server listener on 8030):
  State: RUNNABLE
  Blocked count: 0
  Waited count: 0
  Stack:
    java.base@15.0.2/sun.nio.ch.EPoll.wait(Native Method)
    java.base@15.0.2/sun.nio.ch.EPollSelectorImpl.doSelect(EPollSelectorImpl.java:120)
    java.base@15.0.2/sun.nio.ch.SelectorImpl.lockAndDoSelect(SelectorImpl.java:129)
    java.base@15.0.2/sun.nio.ch.SelectorImpl.select(SelectorImpl.java:146)
    app//org.apache.hadoop.ipc.Server$Listener.run(Server.java:807)
Thread 88 (IPC Server handler 0 on 8030):
  State: TIMED_WAITING
  Blocked count: 0
  Waited count: 3695
  Stack:
    java.base@15.0.2/jdk.internal.misc.Unsafe.park(Native Method)
    java.base@15.0.2/java.util.concurrent.locks.LockSupport.parkNanos(LockSupport.java:252)
    java.base@15.0.2/java.util.concurrent.locks.AbstractQueuedSynchronizer$ConditionObject.awaitNanos(AbstractQueuedSynchronizer.java:1661)
    java.base@15.0.2/java.util.concurrent.LinkedBlockingQueue.poll(LinkedBlockingQueue.java:460)
    app//org.apache.hadoop.ipc.CallQueueManager.take(CallQueueManager.java:136)
    app//org.apache.hadoop.ipc.Server$Handler.run(Server.java:2185)
Thread 89 (IPC Server handler 1 on 8030):
  State: TIMED_WAITING
  Blocked count: 0
  Waited count: 3675
  Stack:
    java.base@15.0.2/jdk.internal.misc.Unsafe.park(Native Method)
    java.base@15.0.2/java.util.concurrent.locks.LockSupport.parkNanos(LockSupport.java:252)
    java.base@15.0.2/java.util.concurrent.locks.AbstractQueuedSynchronizer$ConditionObject.awaitNanos(AbstractQueuedSynchronizer.java:1661)
    java.base@15.0.2/java.util.concurrent.LinkedBlockingQueue.poll(LinkedBlockingQueue.java:460)
    app//org.apache.hadoop.ipc.CallQueueManager.take(CallQueueManager.java:136)
    app//org.apache.hadoop.ipc.Server$Handler.run(Server.java:2185)
Thread 90 (IPC Server handler 2 on 8030):
  State: TIMED_WAITING
  Blocked count: 0
  Waited count: 3703
  Stack:
    java.base@15.0.2/jdk.internal.misc.Unsafe.park(Native Method)
    java.base@15.0.2/java.util.concurrent.locks.LockSupport.parkNanos(LockSupport.java:252)
    java.base@15.0.2/java.util.concurrent.locks.AbstractQueuedSynchronizer$ConditionObject.awaitNanos(AbstractQueuedSynchronizer.java:1661)
    java.base@15.0.2/java.util.concurrent.LinkedBlockingQueue.poll(LinkedBlockingQueue.java:460)
    app//org.apache.hadoop.ipc.CallQueueManager.take(CallQueueManager.java:136)
    app//org.apache.hadoop.ipc.Server$Handler.run(Server.java:2185)
Thread 91 (IPC Server handler 3 on 8030):
  State: TIMED_WAITING
  Blocked count: 0
  Waited count: 3686
  Stack:
    java.base@15.0.2/jdk.internal.misc.Unsafe.park(Native Method)
    java.base@15.0.2/java.util.concurrent.locks.LockSupport.parkNanos(LockSupport.java:252)
    java.base@15.0.2/java.util.concurrent.locks.AbstractQueuedSynchronizer$ConditionObject.awaitNanos(AbstractQueuedSynchronizer.java:1661)
    java.base@15.0.2/java.util.concurrent.LinkedBlockingQueue.poll(LinkedBlockingQueue.java:460)
    app//org.apache.hadoop.ipc.CallQueueManager.take(CallQueueManager.java:136)
    app//org.apache.hadoop.ipc.Server$Handler.run(Server.java:2185)
Thread 92 (IPC Server handler 4 on 8030):
  State: TIMED_WAITING
  Blocked count: 0
  Waited count: 3720
  Stack:
    java.base@15.0.2/jdk.internal.misc.Unsafe.park(Native Method)
    java.base@15.0.2/java.util.concurrent.locks.LockSupport.parkNanos(LockSupport.java:252)
    java.base@15.0.2/java.util.concurrent.locks.AbstractQueuedSynchronizer$ConditionObject.awaitNanos(AbstractQueuedSynchronizer.java:1661)
    java.base@15.0.2/java.util.concurrent.LinkedBlockingQueue.poll(LinkedBlockingQueue.java:460)
    app//org.apache.hadoop.ipc.CallQueueManager.take(CallQueueManager.java:136)
    app//org.apache.hadoop.ipc.Server$Handler.run(Server.java:2185)
Thread 93 (IPC Server handler 5 on 8030):
  State: TIMED_WAITING
  Blocked count: 0
  Waited count: 3691
  Stack:
    java.base@15.0.2/jdk.internal.misc.Unsafe.park(Native Method)
    java.base@15.0.2/java.util.concurrent.locks.LockSupport.parkNanos(LockSupport.java:252)
    java.base@15.0.2/java.util.concurrent.locks.AbstractQueuedSynchronizer$ConditionObject.awaitNanos(AbstractQueuedSynchronizer.java:1661)
    java.base@15.0.2/java.util.concurrent.LinkedBlockingQueue.poll(LinkedBlockingQueue.java:460)
    app//org.apache.hadoop.ipc.CallQueueManager.take(CallQueueManager.java:136)
    app//org.apache.hadoop.ipc.Server$Handler.run(Server.java:2185)
Thread 94 (IPC Server handler 6 on 8030):
  State: TIMED_WAITING
  Blocked count: 0
  Waited count: 3702
  Stack:
    java.base@15.0.2/jdk.internal.misc.Unsafe.park(Native Method)
    java.base@15.0.2/java.util.concurrent.locks.LockSupport.parkNanos(LockSupport.java:252)
    java.base@15.0.2/java.util.concurrent.locks.AbstractQueuedSynchronizer$ConditionObject.awaitNanos(AbstractQueuedSynchronizer.java:1661)
    java.base@15.0.2/java.util.concurrent.LinkedBlockingQueue.poll(LinkedBlockingQueue.java:460)
    app//org.apache.hadoop.ipc.CallQueueManager.take(CallQueueManager.java:136)
    app//org.apache.hadoop.ipc.Server$Handler.run(Server.java:2185)
Thread 95 (IPC Server handler 7 on 8030):
  State: TIMED_WAITING
  Blocked count: 0
  Waited count: 3676
  Stack:
    java.base@15.0.2/jdk.internal.misc.Unsafe.park(Native Method)
    java.base@15.0.2/java.util.concurrent.locks.LockSupport.parkNanos(LockSupport.java:252)
    java.base@15.0.2/java.util.concurrent.locks.AbstractQueuedSynchronizer$ConditionObject.awaitNanos(AbstractQueuedSynchronizer.java:1661)
    java.base@15.0.2/java.util.concurrent.LinkedBlockingQueue.poll(LinkedBlockingQueue.java:460)
    app//org.apache.hadoop.ipc.CallQueueManager.take(CallQueueManager.java:136)
    app//org.apache.hadoop.ipc.Server$Handler.run(Server.java:2185)
Thread 96 (IPC Server handler 8 on 8030):
  State: TIMED_WAITING
  Blocked count: 0
  Waited count: 3671
  Stack:
    java.base@15.0.2/jdk.internal.misc.Unsafe.park(Native Method)
    java.base@15.0.2/java.util.concurrent.locks.LockSupport.parkNanos(LockSupport.java:252)
    java.base@15.0.2/java.util.concurrent.locks.AbstractQueuedSynchronizer$ConditionObject.awaitNanos(AbstractQueuedSynchronizer.java:1661)
    java.base@15.0.2/java.util.concurrent.LinkedBlockingQueue.poll(LinkedBlockingQueue.java:460)
    app//org.apache.hadoop.ipc.CallQueueManager.take(CallQueueManager.java:136)
    app//org.apache.hadoop.ipc.Server$Handler.run(Server.java:2185)
Thread 97 (IPC Server handler 9 on 8030):
  State: TIMED_WAITING
  Blocked count: 0
  Waited count: 3669
  Stack:
    java.base@15.0.2/jdk.internal.misc.Unsafe.park(Native Method)
    java.base@15.0.2/java.util.concurrent.locks.LockSupport.parkNanos(LockSupport.java:252)
    java.base@15.0.2/java.util.concurrent.locks.AbstractQueuedSynchronizer$ConditionObject.awaitNanos(AbstractQueuedSynchronizer.java:1661)
    java.base@15.0.2/java.util.concurrent.LinkedBlockingQueue.poll(LinkedBlockingQueue.java:460)
    app//org.apache.hadoop.ipc.CallQueueManager.take(CallQueueManager.java:136)
    app//org.apache.hadoop.ipc.Server$Handler.run(Server.java:2185)
Thread 98 (IPC Server handler 10 on 8030):
  State: TIMED_WAITING
  Blocked count: 0
  Waited count: 3684
  Stack:
    java.base@15.0.2/jdk.internal.misc.Unsafe.park(Native Method)
    java.base@15.0.2/java.util.concurrent.locks.LockSupport.parkNanos(LockSupport.java:252)
    java.base@15.0.2/java.util.concurrent.locks.AbstractQueuedSynchronizer$ConditionObject.awaitNanos(AbstractQueuedSynchronizer.java:1661)
    java.base@15.0.2/java.util.concurrent.LinkedBlockingQueue.poll(LinkedBlockingQueue.java:460)
    app//org.apache.hadoop.ipc.CallQueueManager.take(CallQueueManager.java:136)
    app//org.apache.hadoop.ipc.Server$Handler.run(Server.java:2185)
Thread 99 (IPC Server handler 11 on 8030):
  State: TIMED_WAITING
  Blocked count: 0
  Waited count: 3686
  Stack:
    java.base@15.0.2/jdk.internal.misc.Unsafe.park(Native Method)
    java.base@15.0.2/java.util.concurrent.locks.LockSupport.parkNanos(LockSupport.java:252)
    java.base@15.0.2/java.util.concurrent.locks.AbstractQueuedSynchronizer$ConditionObject.awaitNanos(AbstractQueuedSynchronizer.java:1661)
    java.base@15.0.2/java.util.concurrent.LinkedBlockingQueue.poll(LinkedBlockingQueue.java:460)
    app//org.apache.hadoop.ipc.CallQueueManager.take(CallQueueManager.java:136)
    app//org.apache.hadoop.ipc.Server$Handler.run(Server.java:2185)
Thread 100 (IPC Server handler 12 on 8030):
  State: TIMED_WAITING
  Blocked count: 0
  Waited count: 3680
  Stack:
    java.base@15.0.2/jdk.internal.misc.Unsafe.park(Native Method)
    java.base@15.0.2/java.util.concurrent.locks.LockSupport.parkNanos(LockSupport.java:252)
    java.base@15.0.2/java.util.concurrent.locks.AbstractQueuedSynchronizer$ConditionObject.awaitNanos(AbstractQueuedSynchronizer.java:1661)
    java.base@15.0.2/java.util.concurrent.LinkedBlockingQueue.poll(LinkedBlockingQueue.java:460)
    app//org.apache.hadoop.ipc.CallQueueManager.take(CallQueueManager.java:136)
    app//org.apache.hadoop.ipc.Server$Handler.run(Server.java:2185)
Thread 101 (IPC Server handler 13 on 8030):
  State: TIMED_WAITING
  Blocked count: 0
  Waited count: 3656
  Stack:
    java.base@15.0.2/jdk.internal.misc.Unsafe.park(Native Method)
    java.base@15.0.2/java.util.concurrent.locks.LockSupport.parkNanos(LockSupport.java:252)
    java.base@15.0.2/java.util.concurrent.locks.AbstractQueuedSynchronizer$ConditionObject.awaitNanos(AbstractQueuedSynchronizer.java:1661)
    java.base@15.0.2/java.util.concurrent.LinkedBlockingQueue.poll(LinkedBlockingQueue.java:460)
    app//org.apache.hadoop.ipc.CallQueueManager.take(CallQueueManager.java:136)
    app//org.apache.hadoop.ipc.Server$Handler.run(Server.java:2185)
Thread 102 (IPC Server handler 14 on 8030):
  State: TIMED_WAITING
  Blocked count: 0
  Waited count: 3677
  Stack:
    java.base@15.0.2/jdk.internal.misc.Unsafe.park(Native Method)
    java.base@15.0.2/java.util.concurrent.locks.LockSupport.parkNanos(LockSupport.java:252)
    java.base@15.0.2/java.util.concurrent.locks.AbstractQueuedSynchronizer$ConditionObject.awaitNanos(AbstractQueuedSynchronizer.java:1661)
    java.base@15.0.2/java.util.concurrent.LinkedBlockingQueue.poll(LinkedBlockingQueue.java:460)
    app//org.apache.hadoop.ipc.CallQueueManager.take(CallQueueManager.java:136)
    app//org.apache.hadoop.ipc.Server$Handler.run(Server.java:2185)
Thread 103 (IPC Server handler 15 on 8030):
  State: TIMED_WAITING
  Blocked count: 0
  Waited count: 3670
  Stack:
    java.base@15.0.2/jdk.internal.misc.Unsafe.park(Native Method)
    java.base@15.0.2/java.util.concurrent.locks.LockSupport.parkNanos(LockSupport.java:252)
    java.base@15.0.2/java.util.concurrent.locks.AbstractQueuedSynchronizer$ConditionObject.awaitNanos(AbstractQueuedSynchronizer.java:1661)
    java.base@15.0.2/java.util.concurrent.LinkedBlockingQueue.poll(LinkedBlockingQueue.java:460)
    app//org.apache.hadoop.ipc.CallQueueManager.take(CallQueueManager.java:136)
    app//org.apache.hadoop.ipc.Server$Handler.run(Server.java:2185)
Thread 104 (IPC Server handler 16 on 8030):
  State: TIMED_WAITING
  Blocked count: 0
  Waited count: 3702
  Stack:
    java.base@15.0.2/jdk.internal.misc.Unsafe.park(Native Method)
    java.base@15.0.2/java.util.concurrent.locks.LockSupport.parkNanos(LockSupport.java:252)
    java.base@15.0.2/java.util.concurrent.locks.AbstractQueuedSynchronizer$ConditionObject.awaitNanos(AbstractQueuedSynchronizer.java:1661)
    java.base@15.0.2/java.util.concurrent.LinkedBlockingQueue.poll(LinkedBlockingQueue.java:460)
    app//org.apache.hadoop.ipc.CallQueueManager.take(CallQueueManager.java:136)
    app//org.apache.hadoop.ipc.Server$Handler.run(Server.java:2185)
Thread 105 (IPC Server handler 17 on 8030):
  State: TIMED_WAITING
  Blocked count: 0
  Waited count: 3698
  Stack:
    java.base@15.0.2/jdk.internal.misc.Unsafe.park(Native Method)
    java.base@15.0.2/java.util.concurrent.locks.LockSupport.parkNanos(LockSupport.java:252)
    java.base@15.0.2/java.util.concurrent.locks.AbstractQueuedSynchronizer$ConditionObject.awaitNanos(AbstractQueuedSynchronizer.java:1661)
    java.base@15.0.2/java.util.concurrent.LinkedBlockingQueue.poll(LinkedBlockingQueue.java:460)
    app//org.apache.hadoop.ipc.CallQueueManager.take(CallQueueManager.java:136)
    app//org.apache.hadoop.ipc.Server$Handler.run(Server.java:2185)
Thread 106 (IPC Server handler 18 on 8030):
  State: TIMED_WAITING
  Blocked count: 0
  Waited count: 3690
  Stack:
    java.base@15.0.2/jdk.internal.misc.Unsafe.park(Native Method)
    java.base@15.0.2/java.util.concurrent.locks.LockSupport.parkNanos(LockSupport.java:252)
    java.base@15.0.2/java.util.concurrent.locks.AbstractQueuedSynchronizer$ConditionObject.awaitNanos(AbstractQueuedSynchronizer.java:1661)
    java.base@15.0.2/java.util.concurrent.LinkedBlockingQueue.poll(LinkedBlockingQueue.java:460)
    app//org.apache.hadoop.ipc.CallQueueManager.take(CallQueueManager.java:136)
    app//org.apache.hadoop.ipc.Server$Handler.run(Server.java:2185)
Thread 107 (IPC Server handler 19 on 8030):
  State: TIMED_WAITING
  Blocked count: 0
  Waited count: 3682
  Stack:
    java.base@15.0.2/jdk.internal.misc.Unsafe.park(Native Method)
    java.base@15.0.2/java.util.concurrent.locks.LockSupport.parkNanos(LockSupport.java:252)
    java.base@15.0.2/java.util.concurrent.locks.AbstractQueuedSynchronizer$ConditionObject.awaitNanos(AbstractQueuedSynchronizer.java:1661)
    java.base@15.0.2/java.util.concurrent.LinkedBlockingQueue.poll(LinkedBlockingQueue.java:460)
    app//org.apache.hadoop.ipc.CallQueueManager.take(CallQueueManager.java:136)
    app//org.apache.hadoop.ipc.Server$Handler.run(Server.java:2185)
Thread 108 (IPC Server handler 20 on 8030):
  State: TIMED_WAITING
  Blocked count: 0
  Waited count: 3664
  Stack:
    java.base@15.0.2/jdk.internal.misc.Unsafe.park(Native Method)
    java.base@15.0.2/java.util.concurrent.locks.LockSupport.parkNanos(LockSupport.java:252)
    java.base@15.0.2/java.util.concurrent.locks.AbstractQueuedSynchronizer$ConditionObject.awaitNanos(AbstractQueuedSynchronizer.java:1661)
    java.base@15.0.2/java.util.concurrent.LinkedBlockingQueue.poll(LinkedBlockingQueue.java:460)
    app//org.apache.hadoop.ipc.CallQueueManager.take(CallQueueManager.java:136)
    app//org.apache.hadoop.ipc.Server$Handler.run(Server.java:2185)
Thread 109 (IPC Server handler 21 on 8030):
  State: TIMED_WAITING
  Blocked count: 0
  Waited count: 3679
  Stack:
    java.base@15.0.2/jdk.internal.misc.Unsafe.park(Native Method)
    java.base@15.0.2/java.util.concurrent.locks.LockSupport.parkNanos(LockSupport.java:252)
    java.base@15.0.2/java.util.concurrent.locks.AbstractQueuedSynchronizer$ConditionObject.awaitNanos(AbstractQueuedSynchronizer.java:1661)
    java.base@15.0.2/java.util.concurrent.LinkedBlockingQueue.poll(LinkedBlockingQueue.java:460)
    app//org.apache.hadoop.ipc.CallQueueManager.take(CallQueueManager.java:136)
    app//org.apache.hadoop.ipc.Server$Handler.run(Server.java:2185)
Thread 110 (IPC Server handler 22 on 8030):
  State: TIMED_WAITING
  Blocked count: 0
  Waited count: 3720
  Stack:
    java.base@15.0.2/jdk.internal.misc.Unsafe.park(Native Method)
    java.base@15.0.2/java.util.concurrent.locks.LockSupport.parkNanos(LockSupport.java:252)
    java.base@15.0.2/java.util.concurrent.locks.AbstractQueuedSynchronizer$ConditionObject.awaitNanos(AbstractQueuedSynchronizer.java:1661)
    java.base@15.0.2/java.util.concurrent.LinkedBlockingQueue.poll(LinkedBlockingQueue.java:460)
    app//org.apache.hadoop.ipc.CallQueueManager.take(CallQueueManager.java:136)
    app//org.apache.hadoop.ipc.Server$Handler.run(Server.java:2185)
Thread 111 (IPC Server handler 23 on 8030):
  State: TIMED_WAITING
  Blocked count: 0
  Waited count: 3702
  Stack:
    java.base@15.0.2/jdk.internal.misc.Unsafe.park(Native Method)
    java.base@15.0.2/java.util.concurrent.locks.LockSupport.parkNanos(LockSupport.java:252)
    java.base@15.0.2/java.util.concurrent.locks.AbstractQueuedSynchronizer$ConditionObject.awaitNanos(AbstractQueuedSynchronizer.java:1661)
    java.base@15.0.2/java.util.concurrent.LinkedBlockingQueue.poll(LinkedBlockingQueue.java:460)
    app//org.apache.hadoop.ipc.CallQueueManager.take(CallQueueManager.java:136)
    app//org.apache.hadoop.ipc.Server$Handler.run(Server.java:2185)
Thread 112 (IPC Server handler 24 on 8030):
  State: TIMED_WAITING
  Blocked count: 0
  Waited count: 3717
  Stack:
    java.base@15.0.2/jdk.internal.misc.Unsafe.park(Native Method)
    java.base@15.0.2/java.util.concurrent.locks.LockSupport.parkNanos(LockSupport.java:252)
    java.base@15.0.2/java.util.concurrent.locks.AbstractQueuedSynchronizer$ConditionObject.awaitNanos(AbstractQueuedSynchronizer.java:1661)
    java.base@15.0.2/java.util.concurrent.LinkedBlockingQueue.poll(LinkedBlockingQueue.java:460)
    app//org.apache.hadoop.ipc.CallQueueManager.take(CallQueueManager.java:136)
    app//org.apache.hadoop.ipc.Server$Handler.run(Server.java:2185)
Thread 113 (IPC Server handler 25 on 8030):
  State: TIMED_WAITING
  Blocked count: 0
  Waited count: 3673
  Stack:
    java.base@15.0.2/jdk.internal.misc.Unsafe.park(Native Method)
    java.base@15.0.2/java.util.concurrent.locks.LockSupport.parkNanos(LockSupport.java:252)
    java.base@15.0.2/java.util.concurrent.locks.AbstractQueuedSynchronizer$ConditionObject.awaitNanos(AbstractQueuedSynchronizer.java:1661)
    java.base@15.0.2/java.util.concurrent.LinkedBlockingQueue.poll(LinkedBlockingQueue.java:460)
    app//org.apache.hadoop.ipc.CallQueueManager.take(CallQueueManager.java:136)
    app//org.apache.hadoop.ipc.Server$Handler.run(Server.java:2185)
Thread 114 (IPC Server handler 26 on 8030):
  State: TIMED_WAITING
  Blocked count: 0
  Waited count: 3695
  Stack:
    java.base@15.0.2/jdk.internal.misc.Unsafe.park(Native Method)
    java.base@15.0.2/java.util.concurrent.locks.LockSupport.parkNanos(LockSupport.java:252)
    java.base@15.0.2/java.util.concurrent.locks.AbstractQueuedSynchronizer$ConditionObject.awaitNanos(AbstractQueuedSynchronizer.java:1661)
    java.base@15.0.2/java.util.concurrent.LinkedBlockingQueue.poll(LinkedBlockingQueue.java:460)
    app//org.apache.hadoop.ipc.CallQueueManager.take(CallQueueManager.java:136)
    app//org.apache.hadoop.ipc.Server$Handler.run(Server.java:2185)
Thread 115 (IPC Server handler 27 on 8030):
  State: TIMED_WAITING
  Blocked count: 0
  Waited count: 3669
  Stack:
    java.base@15.0.2/jdk.internal.misc.Unsafe.park(Native Method)
    java.base@15.0.2/java.util.concurrent.locks.LockSupport.parkNanos(LockSupport.java:252)
    java.base@15.0.2/java.util.concurrent.locks.AbstractQueuedSynchronizer$ConditionObject.awaitNanos(AbstractQueuedSynchronizer.java:1661)
    java.base@15.0.2/java.util.concurrent.LinkedBlockingQueue.poll(LinkedBlockingQueue.java:460)
    app//org.apache.hadoop.ipc.CallQueueManager.take(CallQueueManager.java:136)
    app//org.apache.hadoop.ipc.Server$Handler.run(Server.java:2185)
Thread 116 (IPC Server handler 28 on 8030):
  State: TIMED_WAITING
  Blocked count: 0
  Waited count: 3690
  Stack:
    java.base@15.0.2/jdk.internal.misc.Unsafe.park(Native Method)
    java.base@15.0.2/java.util.concurrent.locks.LockSupport.parkNanos(LockSupport.java:252)
    java.base@15.0.2/java.util.concurrent.locks.AbstractQueuedSynchronizer$ConditionObject.awaitNanos(AbstractQueuedSynchronizer.java:1661)
    java.base@15.0.2/java.util.concurrent.LinkedBlockingQueue.poll(LinkedBlockingQueue.java:460)
    app//org.apache.hadoop.ipc.CallQueueManager.take(CallQueueManager.java:136)
    app//org.apache.hadoop.ipc.Server$Handler.run(Server.java:2185)
Thread 117 (IPC Server handler 29 on 8030):
  State: TIMED_WAITING
  Blocked count: 0
  Waited count: 3690
  Stack:
    java.base@15.0.2/jdk.internal.misc.Unsafe.park(Native Method)
    java.base@15.0.2/java.util.concurrent.locks.LockSupport.parkNanos(LockSupport.java:252)
    java.base@15.0.2/java.util.concurrent.locks.AbstractQueuedSynchronizer$ConditionObject.awaitNanos(AbstractQueuedSynchronizer.java:1661)
    java.base@15.0.2/java.util.concurrent.LinkedBlockingQueue.poll(LinkedBlockingQueue.java:460)
    app//org.apache.hadoop.ipc.CallQueueManager.take(CallQueueManager.java:136)
    app//org.apache.hadoop.ipc.Server$Handler.run(Server.java:2185)
Thread 118 (IPC Server handler 30 on 8030):
  State: TIMED_WAITING
  Blocked count: 0
  Waited count: 3699
  Stack:
    java.base@15.0.2/jdk.internal.misc.Unsafe.park(Native Method)
    java.base@15.0.2/java.util.concurrent.locks.LockSupport.parkNanos(LockSupport.java:252)
    java.base@15.0.2/java.util.concurrent.locks.AbstractQueuedSynchronizer$ConditionObject.awaitNanos(AbstractQueuedSynchronizer.java:1661)
    java.base@15.0.2/java.util.concurrent.LinkedBlockingQueue.poll(LinkedBlockingQueue.java:460)
    app//org.apache.hadoop.ipc.CallQueueManager.take(CallQueueManager.java:136)
    app//org.apache.hadoop.ipc.Server$Handler.run(Server.java:2185)
Thread 119 (IPC Server handler 31 on 8030):
  State: TIMED_WAITING
  Blocked count: 0
  Waited count: 3696
  Stack:
    java.base@15.0.2/jdk.internal.misc.Unsafe.park(Native Method)
    java.base@15.0.2/java.util.concurrent.locks.LockSupport.parkNanos(LockSupport.java:252)
    java.base@15.0.2/java.util.concurrent.locks.AbstractQueuedSynchronizer$ConditionObject.awaitNanos(AbstractQueuedSynchronizer.java:1661)
    java.base@15.0.2/java.util.concurrent.LinkedBlockingQueue.poll(LinkedBlockingQueue.java:460)
    app//org.apache.hadoop.ipc.CallQueueManager.take(CallQueueManager.java:136)
    app//org.apache.hadoop.ipc.Server$Handler.run(Server.java:2185)
Thread 120 (IPC Server handler 32 on 8030):
  State: TIMED_WAITING
  Blocked count: 0
  Waited count: 3724
  Stack:
    java.base@15.0.2/jdk.internal.misc.Unsafe.park(Native Method)
    java.base@15.0.2/java.util.concurrent.locks.LockSupport.parkNanos(LockSupport.java:252)
    java.base@15.0.2/java.util.concurrent.locks.AbstractQueuedSynchronizer$ConditionObject.awaitNanos(AbstractQueuedSynchronizer.java:1661)
    java.base@15.0.2/java.util.concurrent.LinkedBlockingQueue.poll(LinkedBlockingQueue.java:460)
    app//org.apache.hadoop.ipc.CallQueueManager.take(CallQueueManager.java:136)
    app//org.apache.hadoop.ipc.Server$Handler.run(Server.java:2185)
Thread 121 (IPC Server handler 33 on 8030):
  State: TIMED_WAITING
  Blocked count: 0
  Waited count: 3666
  Stack:
    java.base@15.0.2/jdk.internal.misc.Unsafe.park(Native Method)
    java.base@15.0.2/java.util.concurrent.locks.LockSupport.parkNanos(LockSupport.java:252)
    java.base@15.0.2/java.util.concurrent.locks.AbstractQueuedSynchronizer$ConditionObject.awaitNanos(AbstractQueuedSynchronizer.java:1661)
    java.base@15.0.2/java.util.concurrent.LinkedBlockingQueue.poll(LinkedBlockingQueue.java:460)
    app//org.apache.hadoop.ipc.CallQueueManager.take(CallQueueManager.java:136)
    app//org.apache.hadoop.ipc.Server$Handler.run(Server.java:2185)
Thread 122 (IPC Server handler 34 on 8030):
  State: TIMED_WAITING
  Blocked count: 0
  Waited count: 3725
  Stack:
    java.base@15.0.2/jdk.internal.misc.Unsafe.park(Native Method)
    java.base@15.0.2/java.util.concurrent.locks.LockSupport.parkNanos(LockSupport.java:252)
    java.base@15.0.2/java.util.concurrent.locks.AbstractQueuedSynchronizer$ConditionObject.awaitNanos(AbstractQueuedSynchronizer.java:1661)
    java.base@15.0.2/java.util.concurrent.LinkedBlockingQueue.poll(LinkedBlockingQueue.java:460)
    app//org.apache.hadoop.ipc.CallQueueManager.take(CallQueueManager.java:136)
    app//org.apache.hadoop.ipc.Server$Handler.run(Server.java:2185)
Thread 123 (IPC Server handler 35 on 8030):
  State: TIMED_WAITING
  Blocked count: 0
  Waited count: 3659
  Stack:
    java.base@15.0.2/jdk.internal.misc.Unsafe.park(Native Method)
    java.base@15.0.2/java.util.concurrent.locks.LockSupport.parkNanos(LockSupport.java:252)
    java.base@15.0.2/java.util.concurrent.locks.AbstractQueuedSynchronizer$ConditionObject.awaitNanos(AbstractQueuedSynchronizer.java:1661)
    java.base@15.0.2/java.util.concurrent.LinkedBlockingQueue.poll(LinkedBlockingQueue.java:460)
    app//org.apache.hadoop.ipc.CallQueueManager.take(CallQueueManager.java:136)
    app//org.apache.hadoop.ipc.Server$Handler.run(Server.java:2185)
Thread 124 (IPC Server handler 36 on 8030):
  State: TIMED_WAITING
  Blocked count: 0
  Waited count: 3666
  Stack:
    java.base@15.0.2/jdk.internal.misc.Unsafe.park(Native Method)
    java.base@15.0.2/java.util.concurrent.locks.LockSupport.parkNanos(LockSupport.java:252)
    java.base@15.0.2/java.util.concurrent.locks.AbstractQueuedSynchronizer$ConditionObject.awaitNanos(AbstractQueuedSynchronizer.java:1661)
    java.base@15.0.2/java.util.concurrent.LinkedBlockingQueue.poll(LinkedBlockingQueue.java:460)
    app//org.apache.hadoop.ipc.CallQueueManager.take(CallQueueManager.java:136)
    app//org.apache.hadoop.ipc.Server$Handler.run(Server.java:2185)
Thread 125 (IPC Server handler 37 on 8030):
  State: TIMED_WAITING
  Blocked count: 0
  Waited count: 3701
  Stack:
    java.base@15.0.2/jdk.internal.misc.Unsafe.park(Native Method)
    java.base@15.0.2/java.util.concurrent.locks.LockSupport.parkNanos(LockSupport.java:252)
    java.base@15.0.2/java.util.concurrent.locks.AbstractQueuedSynchronizer$ConditionObject.awaitNanos(AbstractQueuedSynchronizer.java:1661)
    java.base@15.0.2/java.util.concurrent.LinkedBlockingQueue.poll(LinkedBlockingQueue.java:460)
    app//org.apache.hadoop.ipc.CallQueueManager.take(CallQueueManager.java:136)
    app//org.apache.hadoop.ipc.Server$Handler.run(Server.java:2185)
Thread 126 (IPC Server handler 38 on 8030):
  State: TIMED_WAITING
  Blocked count: 0
  Waited count: 3668
  Stack:
    java.base@15.0.2/jdk.internal.misc.Unsafe.park(Native Method)
    java.base@15.0.2/java.util.concurrent.locks.LockSupport.parkNanos(LockSupport.java:252)
    java.base@15.0.2/java.util.concurrent.locks.AbstractQueuedSynchronizer$ConditionObject.awaitNanos(AbstractQueuedSynchronizer.java:1661)
    java.base@15.0.2/java.util.concurrent.LinkedBlockingQueue.poll(LinkedBlockingQueue.java:460)
    app//org.apache.hadoop.ipc.CallQueueManager.take(CallQueueManager.java:136)
    app//org.apache.hadoop.ipc.Server$Handler.run(Server.java:2185)
Thread 127 (IPC Server handler 39 on 8030):
  State: TIMED_WAITING
  Blocked count: 0
  Waited count: 3707
  Stack:
    java.base@15.0.2/jdk.internal.misc.Unsafe.park(Native Method)
    java.base@15.0.2/java.util.concurrent.locks.LockSupport.parkNanos(LockSupport.java:252)
    java.base@15.0.2/java.util.concurrent.locks.AbstractQueuedSynchronizer$ConditionObject.awaitNanos(AbstractQueuedSynchronizer.java:1661)
    java.base@15.0.2/java.util.concurrent.LinkedBlockingQueue.poll(LinkedBlockingQueue.java:460)
    app//org.apache.hadoop.ipc.CallQueueManager.take(CallQueueManager.java:136)
    app//org.apache.hadoop.ipc.Server$Handler.run(Server.java:2185)
Thread 128 (IPC Server handler 40 on 8030):
  State: TIMED_WAITING
  Blocked count: 0
  Waited count: 3692
  Stack:
    java.base@15.0.2/jdk.internal.misc.Unsafe.park(Native Method)
    java.base@15.0.2/java.util.concurrent.locks.LockSupport.parkNanos(LockSupport.java:252)
    java.base@15.0.2/java.util.concurrent.locks.AbstractQueuedSynchronizer$ConditionObject.awaitNanos(AbstractQueuedSynchronizer.java:1661)
    java.base@15.0.2/java.util.concurrent.LinkedBlockingQueue.poll(LinkedBlockingQueue.java:460)
    app//org.apache.hadoop.ipc.CallQueueManager.take(CallQueueManager.java:136)
    app//org.apache.hadoop.ipc.Server$Handler.run(Server.java:2185)
Thread 129 (IPC Server handler 41 on 8030):
  State: TIMED_WAITING
  Blocked count: 0
  Waited count: 3706
  Stack:
    java.base@15.0.2/jdk.internal.misc.Unsafe.park(Native Method)
    java.base@15.0.2/java.util.concurrent.locks.LockSupport.parkNanos(LockSupport.java:252)
    java.base@15.0.2/java.util.concurrent.locks.AbstractQueuedSynchronizer$ConditionObject.awaitNanos(AbstractQueuedSynchronizer.java:1661)
    java.base@15.0.2/java.util.concurrent.LinkedBlockingQueue.poll(LinkedBlockingQueue.java:460)
    app//org.apache.hadoop.ipc.CallQueueManager.take(CallQueueManager.java:136)
    app//org.apache.hadoop.ipc.Server$Handler.run(Server.java:2185)
Thread 130 (IPC Server handler 42 on 8030):
  State: TIMED_WAITING
  Blocked count: 0
  Waited count: 3677
  Stack:
    java.base@15.0.2/jdk.internal.misc.Unsafe.park(Native Method)
    java.base@15.0.2/java.util.concurrent.locks.LockSupport.parkNanos(LockSupport.java:252)
    java.base@15.0.2/java.util.concurrent.locks.AbstractQueuedSynchronizer$ConditionObject.awaitNanos(AbstractQueuedSynchronizer.java:1661)
    java.base@15.0.2/java.util.concurrent.LinkedBlockingQueue.poll(LinkedBlockingQueue.java:460)
    app//org.apache.hadoop.ipc.CallQueueManager.take(CallQueueManager.java:136)
    app//org.apache.hadoop.ipc.Server$Handler.run(Server.java:2185)
Thread 131 (IPC Server handler 43 on 8030):
  State: TIMED_WAITING
  Blocked count: 0
  Waited count: 3710
  Stack:
    java.base@15.0.2/jdk.internal.misc.Unsafe.park(Native Method)
    java.base@15.0.2/java.util.concurrent.locks.LockSupport.parkNanos(LockSupport.java:252)
    java.base@15.0.2/java.util.concurrent.locks.AbstractQueuedSynchronizer$ConditionObject.awaitNanos(AbstractQueuedSynchronizer.java:1661)
    java.base@15.0.2/java.util.concurrent.LinkedBlockingQueue.poll(LinkedBlockingQueue.java:460)
    app//org.apache.hadoop.ipc.CallQueueManager.take(CallQueueManager.java:136)
    app//org.apache.hadoop.ipc.Server$Handler.run(Server.java:2185)
Thread 132 (IPC Server handler 44 on 8030):
  State: TIMED_WAITING
  Blocked count: 0
  Waited count: 3682
  Stack:
    java.base@15.0.2/jdk.internal.misc.Unsafe.park(Native Method)
    java.base@15.0.2/java.util.concurrent.locks.LockSupport.parkNanos(LockSupport.java:252)
    java.base@15.0.2/java.util.concurrent.locks.AbstractQueuedSynchronizer$ConditionObject.awaitNanos(AbstractQueuedSynchronizer.java:1661)
    java.base@15.0.2/java.util.concurrent.LinkedBlockingQueue.poll(LinkedBlockingQueue.java:460)
    app//org.apache.hadoop.ipc.CallQueueManager.take(CallQueueManager.java:136)
    app//org.apache.hadoop.ipc.Server$Handler.run(Server.java:2185)
Thread 133 (IPC Server handler 45 on 8030):
  State: TIMED_WAITING
  Blocked count: 0
  Waited count: 3711
  Stack:
    java.base@15.0.2/jdk.internal.misc.Unsafe.park(Native Method)
    java.base@15.0.2/java.util.concurrent.locks.LockSupport.parkNanos(LockSupport.java:252)
    java.base@15.0.2/java.util.concurrent.locks.AbstractQueuedSynchronizer$ConditionObject.awaitNanos(AbstractQueuedSynchronizer.java:1661)
    java.base@15.0.2/java.util.concurrent.LinkedBlockingQueue.poll(LinkedBlockingQueue.java:460)
    app//org.apache.hadoop.ipc.CallQueueManager.take(CallQueueManager.java:136)
    app//org.apache.hadoop.ipc.Server$Handler.run(Server.java:2185)
Thread 134 (IPC Server handler 46 on 8030):
  State: TIMED_WAITING
  Blocked count: 0
  Waited count: 3713
  Stack:
    java.base@15.0.2/jdk.internal.misc.Unsafe.park(Native Method)
    java.base@15.0.2/java.util.concurrent.locks.LockSupport.parkNanos(LockSupport.java:252)
    java.base@15.0.2/java.util.concurrent.locks.AbstractQueuedSynchronizer$ConditionObject.awaitNanos(AbstractQueuedSynchronizer.java:1661)
    java.base@15.0.2/java.util.concurrent.LinkedBlockingQueue.poll(LinkedBlockingQueue.java:460)
    app//org.apache.hadoop.ipc.CallQueueManager.take(CallQueueManager.java:136)
    app//org.apache.hadoop.ipc.Server$Handler.run(Server.java:2185)
Thread 135 (IPC Server handler 47 on 8030):
  State: TIMED_WAITING
  Blocked count: 0
  Waited count: 3694
  Stack:
    java.base@15.0.2/jdk.internal.misc.Unsafe.park(Native Method)
    java.base@15.0.2/java.util.concurrent.locks.LockSupport.parkNanos(LockSupport.java:252)
    java.base@15.0.2/java.util.concurrent.locks.AbstractQueuedSynchronizer$ConditionObject.awaitNanos(AbstractQueuedSynchronizer.java:1661)
    java.base@15.0.2/java.util.concurrent.LinkedBlockingQueue.poll(LinkedBlockingQueue.java:460)
    app//org.apache.hadoop.ipc.CallQueueManager.take(CallQueueManager.java:136)
    app//org.apache.hadoop.ipc.Server$Handler.run(Server.java:2185)
Thread 136 (IPC Server handler 48 on 8030):
  State: TIMED_WAITING
  Blocked count: 0
  Waited count: 3690
  Stack:
    java.base@15.0.2/jdk.internal.misc.Unsafe.park(Native Method)
    java.base@15.0.2/java.util.concurrent.locks.LockSupport.parkNanos(LockSupport.java:252)
    java.base@15.0.2/java.util.concurrent.locks.AbstractQueuedSynchronizer$ConditionObject.awaitNanos(AbstractQueuedSynchronizer.java:1661)
    java.base@15.0.2/java.util.concurrent.LinkedBlockingQueue.poll(LinkedBlockingQueue.java:460)
    app//org.apache.hadoop.ipc.CallQueueManager.take(CallQueueManager.java:136)
    app//org.apache.hadoop.ipc.Server$Handler.run(Server.java:2185)
Thread 137 (IPC Server handler 49 on 8030):
  State: TIMED_WAITING
  Blocked count: 0
  Waited count: 3677
  Stack:
    java.base@15.0.2/jdk.internal.misc.Unsafe.park(Native Method)
    java.base@15.0.2/java.util.concurrent.locks.LockSupport.parkNanos(LockSupport.java:252)
    java.base@15.0.2/java.util.concurrent.locks.AbstractQueuedSynchronizer$ConditionObject.awaitNanos(AbstractQueuedSynchronizer.java:1661)
    java.base@15.0.2/java.util.concurrent.LinkedBlockingQueue.poll(LinkedBlockingQueue.java:460)
    app//org.apache.hadoop.ipc.CallQueueManager.take(CallQueueManager.java:136)
    app//org.apache.hadoop.ipc.Server$Handler.run(Server.java:2185)
Thread 139 (Socket Reader #1 for port 8032):
  State: RUNNABLE
  Blocked count: 0
  Waited count: 0
  Stack:
    java.base@15.0.2/sun.nio.ch.EPoll.wait(Native Method)
    java.base@15.0.2/sun.nio.ch.EPollSelectorImpl.doSelect(EPollSelectorImpl.java:120)
    java.base@15.0.2/sun.nio.ch.SelectorImpl.lockAndDoSelect(SelectorImpl.java:129)
    java.base@15.0.2/sun.nio.ch.SelectorImpl.select(SelectorImpl.java:146)
    app//org.apache.hadoop.ipc.Server$Listener$Reader.doRunLoop(Server.java:745)
    app//org.apache.hadoop.ipc.Server$Listener$Reader.run(Server.java:724)
Thread 140 (IPC Server idle connection scanner for port 8032):
  State: TIMED_WAITING
  Blocked count: 1
  Waited count: 356
  Stack:
    java.base@15.0.2/java.lang.Object.wait(Native Method)
    java.base@15.0.2/java.util.TimerThread.mainLoop(Timer.java:553)
    java.base@15.0.2/java.util.TimerThread.run(Timer.java:506)
Thread 141 (IPC Server Responder):
  State: RUNNABLE
  Blocked count: 0
  Waited count: 0
  Stack:
    java.base@15.0.2/sun.nio.ch.EPoll.wait(Native Method)
    java.base@15.0.2/sun.nio.ch.EPollSelectorImpl.doSelect(EPollSelectorImpl.java:120)
    java.base@15.0.2/sun.nio.ch.SelectorImpl.lockAndDoSelect(SelectorImpl.java:129)
    java.base@15.0.2/sun.nio.ch.SelectorImpl.select(SelectorImpl.java:141)
    app//org.apache.hadoop.ipc.Server$Responder.doRunLoop(Server.java:982)
    app//org.apache.hadoop.ipc.Server$Responder.run(Server.java:965)
Thread 138 (IPC Server listener on 8032):
  State: RUNNABLE
  Blocked count: 0
  Waited count: 0
  Stack:
    java.base@15.0.2/sun.nio.ch.EPoll.wait(Native Method)
    java.base@15.0.2/sun.nio.ch.EPollSelectorImpl.doSelect(EPollSelectorImpl.java:120)
    java.base@15.0.2/sun.nio.ch.SelectorImpl.lockAndDoSelect(SelectorImpl.java:129)
    java.base@15.0.2/sun.nio.ch.SelectorImpl.select(SelectorImpl.java:146)
    app//org.apache.hadoop.ipc.Server$Listener.run(Server.java:807)
Thread 142 (IPC Server handler 0 on 8032):
  State: TIMED_WAITING
  Blocked count: 0
  Waited count: 3648
  Stack:
    java.base@15.0.2/jdk.internal.misc.Unsafe.park(Native Method)
    java.base@15.0.2/java.util.concurrent.locks.LockSupport.parkNanos(LockSupport.java:252)
    java.base@15.0.2/java.util.concurrent.locks.AbstractQueuedSynchronizer$ConditionObject.awaitNanos(AbstractQueuedSynchronizer.java:1661)
    java.base@15.0.2/java.util.concurrent.LinkedBlockingQueue.poll(LinkedBlockingQueue.java:460)
    app//org.apache.hadoop.ipc.CallQueueManager.take(CallQueueManager.java:136)
    app//org.apache.hadoop.ipc.Server$Handler.run(Server.java:2185)
Thread 143 (IPC Server handler 1 on 8032):
  State: TIMED_WAITING
  Blocked count: 0
  Waited count: 3663
  Stack:
    java.base@15.0.2/jdk.internal.misc.Unsafe.park(Native Method)
    java.base@15.0.2/java.util.concurrent.locks.LockSupport.parkNanos(LockSupport.java:252)
    java.base@15.0.2/java.util.concurrent.locks.AbstractQueuedSynchronizer$ConditionObject.awaitNanos(AbstractQueuedSynchronizer.java:1661)
    java.base@15.0.2/java.util.concurrent.LinkedBlockingQueue.poll(LinkedBlockingQueue.java:460)
    app//org.apache.hadoop.ipc.CallQueueManager.take(CallQueueManager.java:136)
    app//org.apache.hadoop.ipc.Server$Handler.run(Server.java:2185)
Thread 144 (IPC Server handler 2 on 8032):
  State: TIMED_WAITING
  Blocked count: 0
  Waited count: 3661
  Stack:
    java.base@15.0.2/jdk.internal.misc.Unsafe.park(Native Method)
    java.base@15.0.2/java.util.concurrent.locks.LockSupport.parkNanos(LockSupport.java:252)
    java.base@15.0.2/java.util.concurrent.locks.AbstractQueuedSynchronizer$ConditionObject.awaitNanos(AbstractQueuedSynchronizer.java:1661)
    java.base@15.0.2/java.util.concurrent.LinkedBlockingQueue.poll(LinkedBlockingQueue.java:460)
    app//org.apache.hadoop.ipc.CallQueueManager.take(CallQueueManager.java:136)
    app//org.apache.hadoop.ipc.Server$Handler.run(Server.java:2185)
Thread 145 (IPC Server handler 3 on 8032):
  State: TIMED_WAITING
  Blocked count: 0
  Waited count: 3670
  Stack:
    java.base@15.0.2/jdk.internal.misc.Unsafe.park(Native Method)
    java.base@15.0.2/java.util.concurrent.locks.LockSupport.parkNanos(LockSupport.java:252)
    java.base@15.0.2/java.util.concurrent.locks.AbstractQueuedSynchronizer$ConditionObject.awaitNanos(AbstractQueuedSynchronizer.java:1661)
    java.base@15.0.2/java.util.concurrent.LinkedBlockingQueue.poll(LinkedBlockingQueue.java:460)
    app//org.apache.hadoop.ipc.CallQueueManager.take(CallQueueManager.java:136)
    app//org.apache.hadoop.ipc.Server$Handler.run(Server.java:2185)
Thread 146 (IPC Server handler 4 on 8032):
  State: TIMED_WAITING
  Blocked count: 0
  Waited count: 3640
  Stack:
    java.base@15.0.2/jdk.internal.misc.Unsafe.park(Native Method)
    java.base@15.0.2/java.util.concurrent.locks.LockSupport.parkNanos(LockSupport.java:252)
    java.base@15.0.2/java.util.concurrent.locks.AbstractQueuedSynchronizer$ConditionObject.awaitNanos(AbstractQueuedSynchronizer.java:1661)
    java.base@15.0.2/java.util.concurrent.LinkedBlockingQueue.poll(LinkedBlockingQueue.java:460)
    app//org.apache.hadoop.ipc.CallQueueManager.take(CallQueueManager.java:136)
    app//org.apache.hadoop.ipc.Server$Handler.run(Server.java:2185)
Thread 147 (IPC Server handler 5 on 8032):
  State: TIMED_WAITING
  Blocked count: 0
  Waited count: 3668
  Stack:
    java.base@15.0.2/jdk.internal.misc.Unsafe.park(Native Method)
    java.base@15.0.2/java.util.concurrent.locks.LockSupport.parkNanos(LockSupport.java:252)
    java.base@15.0.2/java.util.concurrent.locks.AbstractQueuedSynchronizer$ConditionObject.awaitNanos(AbstractQueuedSynchronizer.java:1661)
    java.base@15.0.2/java.util.concurrent.LinkedBlockingQueue.poll(LinkedBlockingQueue.java:460)
    app//org.apache.hadoop.ipc.CallQueueManager.take(CallQueueManager.java:136)
    app//org.apache.hadoop.ipc.Server$Handler.run(Server.java:2185)
Thread 148 (IPC Server handler 6 on 8032):
  State: TIMED_WAITING
  Blocked count: 0
  Waited count: 3667
  Stack:
    java.base@15.0.2/jdk.internal.misc.Unsafe.park(Native Method)
    java.base@15.0.2/java.util.concurrent.locks.LockSupport.parkNanos(LockSupport.java:252)
    java.base@15.0.2/java.util.concurrent.locks.AbstractQueuedSynchronizer$ConditionObject.awaitNanos(AbstractQueuedSynchronizer.java:1661)
    java.base@15.0.2/java.util.concurrent.LinkedBlockingQueue.poll(LinkedBlockingQueue.java:460)
    app//org.apache.hadoop.ipc.CallQueueManager.take(CallQueueManager.java:136)
    app//org.apache.hadoop.ipc.Server$Handler.run(Server.java:2185)
Thread 149 (IPC Server handler 7 on 8032):
  State: TIMED_WAITING
  Blocked count: 0
  Waited count: 3618
  Stack:
    java.base@15.0.2/jdk.internal.misc.Unsafe.park(Native Method)
    java.base@15.0.2/java.util.concurrent.locks.LockSupport.parkNanos(LockSupport.java:252)
    java.base@15.0.2/java.util.concurrent.locks.AbstractQueuedSynchronizer$ConditionObject.awaitNanos(AbstractQueuedSynchronizer.java:1661)
    java.base@15.0.2/java.util.concurrent.LinkedBlockingQueue.poll(LinkedBlockingQueue.java:460)
    app//org.apache.hadoop.ipc.CallQueueManager.take(CallQueueManager.java:136)
    app//org.apache.hadoop.ipc.Server$Handler.run(Server.java:2185)
Thread 150 (IPC Server handler 8 on 8032):
  State: TIMED_WAITING
  Blocked count: 0
  Waited count: 3644
  Stack:
    java.base@15.0.2/jdk.internal.misc.Unsafe.park(Native Method)
    java.base@15.0.2/java.util.concurrent.locks.LockSupport.parkNanos(LockSupport.java:252)
    java.base@15.0.2/java.util.concurrent.locks.AbstractQueuedSynchronizer$ConditionObject.awaitNanos(AbstractQueuedSynchronizer.java:1661)
    java.base@15.0.2/java.util.concurrent.LinkedBlockingQueue.poll(LinkedBlockingQueue.java:460)
    app//org.apache.hadoop.ipc.CallQueueManager.take(CallQueueManager.java:136)
    app//org.apache.hadoop.ipc.Server$Handler.run(Server.java:2185)
Thread 151 (IPC Server handler 9 on 8032):
  State: TIMED_WAITING
  Blocked count: 0
  Waited count: 3679
  Stack:
    java.base@15.0.2/jdk.internal.misc.Unsafe.park(Native Method)
    java.base@15.0.2/java.util.concurrent.locks.LockSupport.parkNanos(LockSupport.java:252)
    java.base@15.0.2/java.util.concurrent.locks.AbstractQueuedSynchronizer$ConditionObject.awaitNanos(AbstractQueuedSynchronizer.java:1661)
    java.base@15.0.2/java.util.concurrent.LinkedBlockingQueue.poll(LinkedBlockingQueue.java:460)
    app//org.apache.hadoop.ipc.CallQueueManager.take(CallQueueManager.java:136)
    app//org.apache.hadoop.ipc.Server$Handler.run(Server.java:2185)
Thread 152 (IPC Server handler 10 on 8032):
  State: TIMED_WAITING
